Workbook

Sheet СВОД
D1: Форма 1пс
A3: СВОДНАЯ СМЕТА
A4: на проектные работы и инженерные изыскания
A6: По объекту: | D6: «Реконструкция газопромысловых сооружений Степновской СПХГ»
A9: Наименование строительства и стадии проектирования | D9: Рабочая документация
A14: Наименование проектной организации-генерального проектировщика | D14: ОАО «СИБНЕФТЕТРАНСПРОЕКТ»
A16: Наименование организации заказчика | D16: ООО «Газпром проектирование»
A18: №пп | B18: Перечень выполняемых работ | E18: Ссылка на № смет по формам 2П, 3П | F18: Полная стоимость работ, руб.
F19: изыскательских | G19: проектных | H19: Всего
B20: Корректировка рабочей документации по этапу 3 (Объекты на площадке ГРП 2А)
A21: 1 | B21: Рабочая документация
A22: 1.1 | B22: Генеральный план | E22: =CONCATENATE("Смета №",A22) -> Смета №1.1 | G22: ='РД 1.1 ГП+'!R32 -> 1643029.3 | H22: =G22+F22 -> 1643029.3
A23: 1.2 | B23: Автомобильные дороги | E23: =CONCATENATE("Смета №",A23) -> Смета №1.2 | G23: ='1.2 Автодороги'!R28 -> 1188800 | H23: =G23+F23 -> 1188800
A24: 1.3 | B24: Технология производства | E24: =CONCATENATE("Сметы №",A24,".1","-№",A24,".2") -> Сметы №1.3.1-№1.3.2 | G24: ='1.3.1 ТХ'!R80+'1.3.2 ТХ+'!R52 -> 26164692 | H24: =G24+F24 -> 26164692
A25: 1.4 | B25: Отопление, вентиляция и кондиционирование | E25: =CONCATENATE("Смета №",A25) -> Смета №1.4 | G25: ='1.4 ОВ'!R61 -> 8441774 | H25: =G25+F25 -> 8441774
A26: 1.5 | B26: Автоматизированная система управления технологическим процессом (АСУ ТП) | E26: =CONCATENATE("Смета №",A26) -> Смета №1.5 | G26: ='1.5 АСУТП этап3'!Y174 -> 3980436 | H26: =G26+F26 -> 3980436
A27: 1.6 | B27: Автоматизированная система управления энергоснабжением (АСУ Э) | E27: =CONCATENATE("Смета №",A27) -> Смета №1.6 | G27: ='1.6 АСУЭ этап3'!Y174 -> 1426262 | H27: =G27+F27 -> 1426262
A28: 1.7 | B28: Автоматизация электрического освещения (АЭО) | E28: =CONCATENATE("Смета №",A28) -> Смета №1.7 | G28: ='1.7 АЭО этап3'!Y174 -> 760673 | H28: =G28+F28 -> 760673
A29: 1.8 | B29: Система противопожарной безопасности и автоматики (СПБА) | E29: =CONCATENATE("Смета №",A29) -> Смета №1.8 | G29: ='1.8 СПБА этап3'!Y174 -> 2977054 | H29: =G29+F29 -> 2977054
A30: 1.9 | B30: Сети связи и сигнализации | E30: =CONCATENATE("Смета №",A30) -> Смета №1.9 | G30: ='1.9 СС'!E243 -> 5598494.6 | H30: =G30+F30 -> 5598494.6
A31: 1.10 | B31: Электроснабжение | E31: =CONCATENATE("Смета №",A31) -> Смета №1.10 | G31: ='1.10 ЭС+'!E381 -> 30972770 | H31: =G31+F31 -> 30972770
A32: 1.11 | B32: Электрохимическая защита | E32: =CONCATENATE("Смета №",A32) -> Смета №1.11 | G32: ='1.11 ЭХЗ+'!E279 -> 22463924 | H32: =G32+F32 -> 22463924
A33: 1.12 | B33: Сети водоснабжения и канализации | E33: =CONCATENATE("Смета №",A33) -> Смета №1.12 | G33: ='1.12 ВК'!E97 -> 3867569.2 | H33: =G33+F33 -> 3867569.2
A34: 1.13 | B34: Линейная часть | E34: =CONCATENATE("Смета №",A34) -> Смета №1.13 | G34: ='1.13 ЛЧ+'!R94 -> 1105622.4 | H34: =G34+F34 -> 1105622.4
A35: 1.14 | B35: Проект бурения скважин | E35: =CONCATENATE("Смета №",A35) -> Смета №1.14 | G35: ='1.14 ПроектБур+'!G37 -> 526369.2 | H35: =G35+F35 -> 526369.2
A36: 1.15 | B36: =CONCATENATE("Итого ",B21,":") -> Итого Рабочая документация: | F36: =ROUND(SUM(F32:F33),2) -> 0 | G36: =ROUND(SUM(G22:G35),2) -> 1.1111747e+08 | H36: =ROUND(SUM(H22:H35),2) -> 1.1111747e+08
A38: 2 | B38: Итого по сводной смете: | F38: =F36 -> 0 | G38: =G36 -> 1.1111747e+08 | H38: =H36 -> 1.1111747e+08
A39: 3 | B39: Кроме того, НДС | E39: 0.22 | F39: =ROUND(($F$38) * (22/100),2) -> 0 | G39: =ROUND(G38*0.22,2) -> 24445844 | H39: =G39+F39 -> 24445844
A40: 4 | B40: Всего по сводной смете: | F40: =ROUND((SUM($F$38:$F$39)) * 1,2) -> 0 | G40: =ROUND((SUM($G$38:$G$39)) * 1,2) -> 1.3556331e+08 | H40: =G40+F40 -> 1.3556331e+08
A43: Примечание: Стоимость согласованного объема корректировки РД и СД (ГРП 2А) составляет 45 835 568,66 руб. с НДС 22%.Стоимость корректировки требующего согласования составляет 52 408 303,99 руб. с НДС 22% | I43: ** ГИП

Sheet РД 1.1 ГП+
E1: форма 2П, 707/пр
A3: =СВОД!E22 -> Смета №1.1
A4: на проектные (изыскательские) работы
A6: Наименование предприятия, здания, сооружения, стадии проектирования, этапа, вида проектных или изыскательских работ | F6: =СВОД!B22 -> Генеральный план
A8: Наименование проектной (изыскательской) организации | F8: =СВОД!D14 -> ОАО «СИБНЕФТЕТРАНСПРОЕКТ»
A10: Наименование организации заказчика | F10: =СВОД!D16 -> ООО «Газпром проектирование»
A12: № пп | B12: Наименование объекта проектирования или вида проектных работ | G12: Наименование, номера глав, таблиц, параграфов и пунктов МНЗ на проектные работы | K12: Расчет стоимости | O12: Стоимость, руб.
A13: 1 | B13: 2 | G13: 3 | K13: 4 | O13: 5
A14: Этап 3 (Объекты на площадке ГРП 2А) Разработка комплекта "4212.012.Р.3/0.0004.ГРП.02А.00000.000-ГП"
A15: 1 | B15: Генеральный план и транспорт в составе: вертикальная планировка, благоустройство и озеленение, внутриплощадочные автодороги, сводный план коммуникаций и сетей, участка. Площадь от 0.5 га до 10 га включительно. | G15: НЗ №849/пр Объекты газовой промышленности. 2023 г. Таблица 3.8. Объекты общетехнического назначения, п.10 A = 31.1 тыс.руб; B = 122.993 тыс.руб; Xзад = 5 (га); Количество = 1 | K15: Полный комплекс работ (100%): (A + B * Xзад) * Количество * Ктек * Кст (31 100 руб. + 122 993 руб. * 5) * 1 * 1,56 * 0.6 | O15: =ROUND((31100 + 122993 * 5) * 1 * 1.56 * 0.6, 2) -> 604716.84
B16: Коэффициенты
B17: Стадия: Рабочая документация | G17: Кст = 0.6
B18: инд.3кв.2026г.к 01.01.2022 на пр.раб. | G18: Ктек = 1,56 Письмо Минстроя России от 22.07.2026 №45358-ИФ/09
A19: Этап 3 (Объекты на площадке ГРП 2А) Разработка комплекта "4212.012.Р.3/0.0004.ГРП.02А.00000.000-ГП"
A20: 2 | B20: Инженерная подготовка территории. Объем отсыпки (намыва) грунта от 20 до 50 тыс.куб.м. включительно. | G20: НЗ №912/пр Инженерная защита территорий, зданий и сооружений от опасных геологических процессов. 2023 г. Таблица 3.2. Объекты регулирования стока поверхностных вод, водопонижения, п.1 A = 87,22 тыс.руб; B = 24.266 тыс.руб; Xзад = 50 (тыс.куб.м.); Количество = 1 | K20: (A + B * Xзад) * Количество * Ктек * Кст (87 100 руб. + 24 266 руб. * 50) * 1 * 1,56 * 0.6 | O20: =ROUND((87100 + 24266 * 50) * 1 * 1.56 * 0.6, 2) -> 1217174.4
B21: Коэффициенты
B22: Стадия: Рабочая документация | G22: Кст = 0.6
B23: инд.3кв.2026г.к 01.01.2022 на пр.раб. | G23: Ктек = 1,56 Письмо Минстроя России от 22.07.2026 №45358-ИФ/09
A24: Этап 3 (Шг.2А - Сеть газосборная ГРП 2А). Площадки БКЭС.
A25: 3 | B25: Генеральный план и транспорт в составе: вертикальная планировка, благоустройство и озеленение, внутриплощадочные автодороги, сводный план коммуникаций и сетей, участка. Площадь от 0.5 га до 10 га включительно. | G25: НЗ №849/пр Объекты газовой промышленности. 2023 г. Таблица 3.8. Объекты общетехнического назначения, п.10 A = 31.1 тыс.руб; B = 122.993 тыс.руб; Xмин = 0.5; Xзад = 0.4 (га); Количество = 1 | K25: Полный комплекс работ (100%): (A + B * (0.4 * Xмин + 0.6 * Xзад)) * Количество * Ктек * Кст (31 100 руб. + 122 993 руб. * (0.4 * 0.5 + 0.6 * 0.4)) * 1 * 1,56 * 0.6 | O25: =ROUND((31100 + 122993 * (0.4 * 0.5 + 0.6 * 0.4)) * 1 * 1.56 * 0.6, 2) -> 79763.04
B26: Коэффициенты
B27: Стадия: Рабочая документация | G27: Кст = 0.6
B28: инд.3кв.2026г.к 01.01.2022 на пр.раб. | G28: Ктек = 1,56 Письмо Минстроя России от 22.07.2026 №45358-ИФ/09
A29: 4 | B29: Итого по смете: | O29: =ROUND(SUM($O$15:$O$25),2) -> 1901654.3
A30: 5 | B30: Новое начисление | G30: К1 = 0.8 Коэффициент оптимизации ПАО "Газпром" («Порядок формирования стоимости проектно-изыскательских работ для строительства и реконструкции объектов ПАО «Газпром» от 28.12.2017г. п.5.41) (Ценообразующий) | K30: Коэф-т 1 от п.4 * 0.8 1 865 084.00 руб. * 1 * 0.8 | O30: =ROUND(($O$29) * 1 * 0.8,2) -> 1521323.4
A31: 6 | B31: Новое начисление | G31: К1 = 1.08 Коэффициент районный (Письмо ГК РФ по жилищной и строительной политике от 30 июня 1998 г. N 9-10-17/40) (Ценообразующий) | K31: Коэф-т 1 от п.5 * 1.08 1 492 067.20 руб. * 1 * 1.08 | O31: =ROUND(($O$30) * 1 * 1.08,2) -> 1643029.3
A32: 7 | B32: Всего по смете: | O32: =ROUND(($O$31),2) -> 1643029.3 | R32: =O32 -> 1643029.3

Sheet 1.2 Автодороги
E1: форма 2П, 707/пр
A3: =СВОД!E23 -> Смета №1.2
A4: на проектные (изыскательские) работы
A6: Наименование предприятия, здания, сооружения, стадии проектирования, этапа, вида проектных или изыскательских работ | F6: =СВОД!B23 -> Автомобильные дороги
A8: Наименование проектной (изыскательской) организации | F8: =СВОД!D14 -> ОАО «СИБНЕФТЕТРАНСПРОЕКТ»
A10: Наименование организации заказчика | F10: =СВОД!D16 -> ООО «Газпром проектирование»
A12: № пп | B12: Наименование объекта проектирования или вида проектных работ | G12: Наименование, номера глав, таблиц, параграфов и пунктов МНЗ на проектные работы | K12: Расчет стоимости | O12: Стоимость, руб.
A13: 1 | B13: 2 | G13: 3 | K13: 4 | O13: 5
A14: Этап 3 (Объекты на площадке ГРП 2А) ПАД.02А - Подъездная автомобильная дорога к ГРП 2А Разработка комплекта 4212.012.Р.3/0.0004.ПАД.02А.40712.000-АД
A15: 1 | B15: Автомобильные дороги технической категории IV. Категория сложности проектирования: 3. Протяженность от 0.2 до 0.5 километра включительно. | G15: НЗ №51/пр Строительство, реконструкция и капитальный ремонт автомобильных дорог, их конструктивных элементов и сооружений на них. 2025 г. Таблица 3.5. Автомобильные дороги технической категории IV, п.2.3 A = 290.1 тыс.руб; B = 1 856.633 тыс.руб; Протяженность дороги L = 0.31524 км; Количество = 1; | K15: (A + B * L) * Количество * Ктек * Кст (290 100 руб. + 1 856 633 руб. * 0.31524) * 1 * 1,40 * 0.6 | O15: =ROUND((290100 + 1856633 * 0.31524) * 1 * 1.4 * 0.6, 2) -> 735323.39
B16: Коэффициенты
B17: Стадия: Рабочая документация | G17: Кст = 0.6
B18: инд.3кв.2026г.к 01.01.2023 на пр.раб. | G18: Ктек = 1,40 Письмо Минстроя России от 22.07.2026 №45358-ИФ/09
A19: Этап 3 (Объекты на площадке ГРП 2А) ПАД.02А - Подъездная автомобильная дорога к ГРП 2А Разработка комплекта 4212.012.Р.3/0.0004.ПАД.02А.40712.000-АД
A20: 2 | B20: Примыкание автомобильных дорог в одном уровне с устройством переходно-скоростных полос движения, островков безопасности. Категория сложности проектирования: 3. | G20: НЗ №51/пр Строительство, реконструкция и капитальный ремонт автомобильных дорог, их конструктивных элементов и сооружений на них. 2025 г. Таблица 3.7. Развязки, п.2.3 A = 1 622.6 тыс.руб; Количество = 1 (объект) | K20: A * Количество * Ктек * Кст * K1 1 622 600 руб. * 1 * 1,40 * 0.6 * 0.47 | O20: =ROUND(1622600 * 1 * 1.4 * 0.6 * 0.47, 2) -> 640602.48
B21: Коэффициенты
B22: Стадия: Рабочая документация | G22: Кст = 0.6
B23: инд.3кв.2026г.к 01.01.2023 на пр.раб. | G23: Ктек = 1,40 Письмо Минстроя России от 22.07.2026 №45358-ИФ/09
B24: Пересечение (примыкание) автомобильных дорог в одном уровне определяется с корректирующим коэффициентом для примыканий без устройства переходно-скоростных полос | G24: K1 = 0.47 Табл.4, п.9 (Ценообразующий)
A25: 3 | B25: Итого по смете: | O25: =ROUND(SUM($O$15:$O$24),2) -> 1375925.9
A26: 4 | B26: Новое начисление | G26: К1 = 0.8 Коэффициент оптимизации ПАО "Газпром" («Порядок формирования стоимости проектно-изыскательских работ для строительства и реконструкции объектов ПАО «Газпром» от 28.12.2017г. п.5.41) (Ценообразующий) | K26: Коэф-т 1 от п.15 * 0.8 8 906 372.63 руб. * 1 * 0.8 | O26: =ROUND(($O$25) * 1 * 0.8,2) -> 1100740.7
A27: 5 | B27: Новое начисление | G27: К1 = 1.08 Коэффициент районный (Письмо ГК РФ по жилищной и строительной политике от 30 июня 1998 г. N 9-10-17/40) (Ценообразующий) | K27: Коэф-т 1 от п.16 * 1.08 7 125 098.10 руб. * 1 * 1.08 | O27: =ROUND(($O$26) * 1 * 1.08,2) -> 1188800
A28: 6 | B28: Всего по смете: | O28: =ROUND(($O$27),2) -> 1188800 | R28: =O28 -> 1188800

Sheet 1.3.1 ТХ
E1: форма 2П, 707/пр
A3: =СВОД!E24 -> Сметы №1.3.1-№1.3.2
A4: на проектные (изыскательские) работы
A6: Наименование предприятия, здания, сооружения, стадии проектирования, этапа, вида проектных или изыскательских работ | F6: =СВОД!B24 -> Технология производства
A8: Наименование проектной (изыскательской) организации | F8: =СВОД!D14 -> ОАО «СИБНЕФТЕТРАНСПРОЕКТ»
A10: Наименование организации заказчика | F10: =СВОД!D16 -> ООО «Газпром проектирование»
A12: № пп | B12: Наименование объекта проектирования или вида проектных работ | G12: Наименование, номера глав, таблиц, параграфов и пунктов МНЗ на проектные работы | K12: Расчет стоимости | O12: Стоимость, руб.
A13: 1 | B13: 2 | G13: 3 | K13: 4 | O13: 5
A14: Этап 3 (Объекты на площадке ГРП 2А)
A15: 001 - Технологический корпус №1
A16: 1 | B16: Установка первичной сепарации газа производительностью от 10 млн.куб.м/сут до 60 млн.куб.м/сут включительно | G16: НЗ №849/пр Объекты газовой промышленности. 2023 г. Таблица 3.7. Объекты подготовки газа, газового конденсата (УКПГ, УППГ, УПТГ, ГС), п.2 A = 1 493.1 тыс. руб.B = 22.794 тыс. руб.; Хзад = 10.95 (млн.куб.м/сут); Количество = 1 | K16: (A + B * Xзад) * Количество * Ктек * Кст (1 493 100 руб. + 22 794 руб. * 10.95) * 1 * 1,56 * 0.6 | O16: =ROUND((1493100 + 22794 * 10.95) * 1 * 1.56 * 0.6, 2) -> 1631161.9
B17: Коэффициенты
B18: Стадия: Рабочая документация | G18: Кст = 0.6
B19: инд.3кв.2026г.к 01.01.2022 на пр.раб. | G19: Ктек = 1,56 Письмо Минстроя России от 22.07.2026 №45358-ИФ/09
A20: 002 - Технологический корпус №2
A21: 2 | B21: Установка первичной сепарации газа производительностью от 10 млн.куб.м/сут до 60 млн.куб.м/сут включительно | G21: НЗ №849/пр Объекты газовой промышленности. 2023 г. Таблица 3.7. Объекты подготовки газа, газового конденсата (УКПГ, УППГ, УПТГ, ГС), п.2 A = 1 493.1 тыс. руб.B = 22.794 тыс. руб.; Хзад = 10.95 (млн.куб.м/сут); Количество = 1 | K21: (A + B * Xзад) * Количество * Ктек * Кст (1 493 100 руб. + 22 794 руб. * 10.95) * 1 * 1,56 * 0.6 | O21: =ROUND((1493100 + 22794 * 10.95) * 1 * 1.56 * 0.6, 2) -> 1631161.9
B22: Коэффициенты
B23: Стадия: Рабочая документация | G23: Кст = 0.6
B24: инд.3кв.2026г.к 01.01.2022 на пр.раб. | G24: Ктек = 1,56 Письмо Минстроя России от 22.07.2026 №45358-ИФ/09
A25: 004 - Резервуар, емкость дренажно-аварийная
A26: 3 | B26: Установка дренажной емкости без погружного насоса объемом до 50 куб.м | G26: НЗ №849/пр Объекты газовой промышленности. 2023 г. Таблица 3.7. Объекты подготовки газа, газового конденсата (УКПГ, УППГ, УПТГ, ГС), п.40 A = 699.9 тыс. руб. Количество = 1 (объект) | K26: A * Количество * Ктек * Кст 699 900 руб. * 1 * 1,56 * 0.6 | O26: =ROUND(699900 * 1 * 1.56 * 0.6, 2) -> 655106.4
B27: Коэффициенты
B28: Стадия: Рабочая документация | G28: Кст = 0.6
B29: инд.3кв.2026г.к 01.01.2022 на пр.раб. | G29: Ктек = 1,56 Письмо Минстроя России от 22.07.2026 №45358-ИФ/09
A30: 005 - Резервуар, емкость расходная метанола
A31: 4 | B31: Промежуточный склад ГЖ и ЛВЖ из горизонтальных стальных резервуаров объемом от 50 куб.м до 200 куб.м включительно | G31: НЗ №849/пр Объекты газовой промышленности. 2023 г. Таблица 3.7. Объекты подготовки газа, газового конденсата (УКПГ, УППГ, УПТГ, ГС), п.31 A = 467.7 тыс. руб.B = 0.398 тыс. руб.; Хзад = 100 (куб.м); Количество = 1 | K31: (A + B * Xзад) * Количество * Ктек * Кст (467 700 руб. + 398 руб. * 100) * 1 * 1,56 * 0.6 | O31: =ROUND((467700 + 398 * 100) * 1 * 1.56 * 0.6, 2) -> 475020
B32: Коэффициенты
B33: Стадия: Рабочая документация | G33: Кст = 0.6
B34: инд.3кв.2026г.к 01.01.2022 на пр.раб. | G34: Ктек = 1,56 Письмо Минстроя России от 22.07.2026 №45358-ИФ/09
A35: 006 - Резервуар, емкость дренажно-аварийная
A36: 5 | B36: Установка дренажной емкости без погружного насоса объемом до 50 куб.м | G36: НЗ №849/пр Объекты газовой промышленности. 2023 г. Таблица 3.7. Объекты подготовки газа, газового конденсата (УКПГ, УППГ, УПТГ, ГС), п.40 A = 699.9 тыс. руб. Количество = 1 (объект) | K36: A * Количество * Ктек * Кст 699 900 руб. * 1 * 1,56 * 0.6 | O36: =ROUND(699900 * 1 * 1.56 * 0.6, 2) -> 655106.4
B37: Коэффициенты
B38: Стадия: Рабочая документация | G38: Кст = 0.6
B39: инд.3кв.2026г.к 01.01.2022 на пр.раб. | G39: Ктек = 1,56 Письмо Минстроя России от 22.07.2026 №45358-ИФ/09
A40: 008 - Станция насосная
A41: 6 | B41: Установка приема, смешения и подачи ингибитора в скважины производительностью от 20 л/час до 200 л/час включительно | G41: НЗ №849/пр Объекты газовой промышленности. 2023 г. Таблица 3.7. Объекты подготовки газа, газового конденсата (УКПГ, УППГ, УПТГ, ГС), п.20 A = 114.1 тыс. руб.B = 19.581 тыс. руб.; Xмакс = 200; Хзад = 1000 (л/час); Количество = 1 | K41: (A + B * (0.4 * Xмакс + 0.6 * Xзад)) * Количество * Ктек * Кст (114 100 руб. + 19 581 руб. * (0.4 * 200 + 0.6 * 1000)) * 1 * 1,56 * 0.6 | O41: =ROUND((114100 + 19581 * (0.4 * 200 + 0.6 * 1000)) * 1 * 1.56 * 0.6, 2) -> 12569712
B42: Коэффициенты
B43: Стадия: Рабочая документация | G43: Кст = 0.6
B44: инд.3кв.2026г.к 01.01.2022 на пр.раб. | G44: Ктек = 1,56 Письмо Минстроя России от 22.07.2026 №45358-ИФ/09
A45: 016 - Склад дизтоплива расходный V=10 м3
...

Sheet 1.3.2 ТХ+
E1: форма 2П, 707/пр
A3: Смета №1.3.2
A4: на проектные (изыскательские) работы
A6: Наименование предприятия, здания, сооружения, стадии проектирования, этапа, вида проектных или изыскательских работ | F6: ='1.3.1 ТХ'!F6:P6 -> Технология производства
A8: Наименование проектной (изыскательской) организации | F8: =СВОД!D14 -> ОАО «СИБНЕФТЕТРАНСПРОЕКТ»
A10: Наименование организации заказчика | F10: =СВОД!D16 -> ООО «Газпром проектирование»
A12: № пп | B12: Наименование объекта проектирования или вида проектных работ | G12: Наименование, номера глав, таблиц, параграфов и пунктов МНЗ на проектные работы | K12: Расчет стоимости | O12: Стоимость, руб.
A13: 1 | B13: 2 | G13: 3 | K13: 4 | O13: 5
A14: Этап 3
A15: ВТМ.2А - Метанолопровод внутрипромысловый к ГРП.2А
A16: 4212.00.Р.04.ВТМ.2А.000.Л.000 Инв номер 783977
A17: 1 | B17: Трубопроводы (межцеховые и шлейфы) диаметром до 300 мм. Протяженность от 1 км до 5 км включительно. | G17: НЗ №849/пр Объекты газовой промышленности. 2023 г. Таблица 3.6. Объекты сбора газа (шлейфы, коллекторы и межцеховые трубопроводы), п.1 A = 61.9 тыс.руб; B = 15.484 тыс.руб; Xзад = 1.485 (км); Количество = 1 | K17: (A + B * Xзад) * Количество * Ктек * Кст (61 900 руб. + 15 484 руб. * 1.485) * 1 * 1.56 * 0.6 | O17: =ROUND((61900 + 15484 * 1.485) * 1 * 1.56 * 0.6, 2) -> 79460.54
B18: Коэффициенты
B19: Стадия: Рабочая документация | G19: Кст = 0.6
B20: инд.3кв.2026г.к 01.01.2022 на пр.раб. | G20: Ктек = 1.56 Письмо Минстроя России от 23.07.2026 №45358-ИФ/09
A21: Г3.2А - Межпоселковый газопровод высокого давления II категории от коллектора ПППГ-ГРП5 до ГРП 2А
A22: 4212.00.Р.04.Г3.2А.000.ГСН.000 Инв номер 784436
A23: 2 | B23: Трубопроводы (межцеховые и шлейфы) диаметром до 300 мм. Протяженность от 1 км до 5 км включительно. | G23: НЗ №849/пр Объекты газовой промышленности. 2023 г. Таблица 3.6. Объекты сбора газа (шлейфы, коллекторы и межцеховые трубопроводы), п.1 A = 61.9 тыс.руб; B = 15.484 тыс.руб; Xзад = 2.42 (км); Количество = 1 | K23: (A + B * Xзад) * Количество * Ктек * Кст (61 900 руб. + 15 484 руб. * 2.42) * 1 * 1.56 * 0.6 | O23: =ROUND((61900 + 15484 * 2.42) * 1 * 1.56 * 0.6, 2) -> 93011.52
B24: Коэффициенты
B25: Стадия: Рабочая документация | G25: Кст = 0.6
B26: инд.3кв.2026г.к 01.01.2022 на пр.раб. | G26: Ктек = 1.56 Письмо Минстроя России от 23.07.2026 №45358-ИФ/09
A27: Внутриплощадочные сети 4212.00.Р.04 - Реконструкция газопромысловых сооружений Степновской СПХГ.
A28: 4212.012.Р.3/0.0004.ГРП.02А.31610.000-ТХ
A29: 3 | B29: Трубопроводы (межцеховые и шлейфы) диаметром до 300 мм. Протяженность от 1 км до 5 км включительно. | G29: НЗ №849/пр Объекты газовой промышленности. 2023 г. Таблица 3.6. Объекты сбора газа (шлейфы, коллекторы и межцеховые трубопроводы), п.1 A = 61.9 тыс.руб; B = 15.484 тыс.руб; Xмин = 1; Xзад = 0.235 (км); Количество = 1 | K29: (A + B * (0.4 * Xмин + 0.6 * (Xмин / 2))) * Количество * Кпон * Ктек * Кст (61 900 руб. + 15 484 руб. * (0.4 * 1 + 0.6 * (1 / 2))) * 1 * 0.47 * 1.56 * 0.6 | O29: =ROUND((61900 + 15484 * (0.4 * 1 + 0.6 * (1 / 2))) * 1 * 0.47 * 1.56 * 0.6, 2) -> 31999.25
B30: Коэффициенты
B31: Стадия: Рабочая документация | G31: Кст = 0.6
B32: инд.3кв.2026г.к 01.01.2022 на пр.раб. | G32: Ктек = 1.56 Письмо Минстроя России от 23.07.2026 №45358-ИФ/09
B33: К'пон = Xзад / (0.5 * Xмин) | G33: К'пон = 0.47 понижающий коэффициент, учитывающий разницу в трудоемкости работ по проектируемому объекту и объекту аналогу. (Методика 707/пр п.131(3)) (Ценообразующий)
A34: 4212.00.Р.04.ВТГз.2А.000.Л.000
A35: 4 | B35: Трубопроводы (межцеховые и шлейфы) диаметром до 300 мм. Протяженность от 1 км до 5 км включительно. | G35: НЗ №849/пр Объекты газовой промышленности. 2023 г. Таблица 3.6. Объекты сбора газа (шлейфы, коллекторы и межцеховые трубопроводы), п.1 A = 61.9 тыс.руб; B = 15.484 тыс.руб; Xзад = 2 (км); Количество = 1 | K35: (A + B * Xзад) * Количество * Ктек * Кст (61 900 руб. + 15 484 руб. * 2) * 1 * 1.56 * 0.6 | O35: =ROUND((61900 + 15484 * 2) * 1 * 1.56 * 0.6, 2) -> 86924.45
B36: Коэффициенты
B37: Стадия: Рабочая документация | G37: Кст = 0.6
B38: инд.3кв.2026г.к 01.01.2022 на пр.раб. | G38: Ктек = 1.56 Письмо Минстроя России от 23.07.2026 №45358-ИФ/09
A39: 4212.00.Р.04.ВТК.ГРП.2А.000.Л.000
A40: 5 | B40: Трубопроводы (межцеховые и шлейфы) диаметром до 300 мм. Протяженность от 1 км до 5 км включительно. | G40: НЗ №849/пр Объекты газовой промышленности. 2023 г. Таблица 3.6. Объекты сбора газа (шлейфы, коллекторы и межцеховые трубопроводы), п.1 A = 61.9 тыс.руб; B = 15.484 тыс.руб; Xзад = 2 (км); Количество = 1 | K40: (A + B * Xзад) * Количество * Ктек * Кст (61 900 руб. + 15 484 руб. * 2) * 1 * 1.56 * 0.6 | O40: =ROUND((61900 + 15484 * 2) * 1 * 1.56 * 0.6, 2) -> 86924.45
B41: Коэффициенты
B42: Стадия: Рабочая документация | G42: Кст = 0.6
B43: инд.3кв.2026г.к 01.01.2022 на пр.раб. | G43: Ктек = 1.56 Письмо Минстроя России от 23.07.2026 №45358-ИФ/09
A44: 4212.00.Р.04.ГК.2 А.000.Л.000
A45: 6 | B45: Трубопроводы (межцеховые и шлейфы) диаметром до 300 мм. Протяженность от 1 км до 5 км включительно. | G45: НЗ №849/пр Объекты газовой промышленности. 2023 г. Таблица 3.6. Объекты сбора газа (шлейфы, коллекторы и межцеховые трубопроводы), п.1 A = 61.9 тыс.руб; B = 15.484 тыс.руб; Xзад = 2 (км); Количество = 1 | K45: (A + B * Xзад) * Количество * Ктек * Кст (61 900 руб. + 15 484 руб. * 2) * 1 * 1.56 * 0.6 | O45: =ROUND((61900 + 15484 * 2) * 1 * 1.56 * 0.6, 2) -> 86924.45
...

Sheet 1.4 ОВ
E1: форма 2П, 707/пр
A3: =СВОД!E25 -> Смета №1.4
A4: на проектные (изыскательские) работы
A6: Наименование предприятия, здания, сооружения, стадии проектирования, этапа, вида проектных или изыскательских работ | F6: =СВОД!B25 -> Отопление, вентиляция и кондиционирование
A8: Наименование проектной (изыскательской) организации | F8: =СВОД!D14 -> ОАО «СИБНЕФТЕТРАНСПРОЕКТ»
A10: Наименование организации заказчика | F10: =СВОД!D16 -> ООО «Газпром проектирование»
A12: № пп | B12: Наименование объекта проектирования или вида проектных работ | G12: Наименование, номера глав, таблиц, параграфов и пунктов МНЗ на проектные работы | K12: Расчет стоимости | O12: Стоимость, руб.
A13: 1 | B13: 2 | G13: 3 | K13: 4 | O13: 5
A14: Этап 3 (Объекты на площадке ГРП 2А)
A15: 4212.012.Р.3/0.0004.ГРП.02А.31201.025-ТС
A16: 1 | B16: Внутриплощадочные инженерные сети. Тепло-, газо-, материалопроводы на эстакадах. Длина трассы до 0.1 км. | G16: Объекты нефтеперерабатывающей и нефтехимической промышленности. 2015 г. Таблица 8. Объекты подсобно-производственного, вспомогательного и общезаводского назначения, внутриплощадочные инженерные сети, схема планировочной организации земельного участка, п.2.3 A = 1 695.18 тыс.руб; B = 1 100.96 тыс.руб; Xмин = 0.1; Xзад = 0.015 (км); Количество = 1 | K16: (A + B * (0.4 * Xмин + 0.6 * (Xмин / 2))) * Количество * Кпон * Ктек * Кст * K1 (1 695 180 руб. + 1 100 960 руб. * (0.4 * 0.1 + 0.6 * (0.1 / 2))) * 1 * 0.3 * 7,22 * 0.6 * 0.5 * 0.7 | O16: =ROUND((1695180 + 1100960 * (0.4 * 0.1 + 0.6 * (0.1 / 2))) * 1 * 0.3 * 7.22 * 0.6 * 0.5 * 0.7, 2) -> 806124.36
B17: Коэффициенты
B18: Стадия: Рабочая документация | G18: Кст = 0.6
B19: инд.3кв.2026г.к 01.01.2001 на пр.раб. | G19: Ктек = 7,22 Письмо Минстроя России от 22.07.2026 №45358-ИФ/09
B20: К'пон = Xзад / (0.5 * Xмин) | G20: К'пон = 0.3 понижающий коэффициент, учитывающий разницу в трудоемкости работ по проектируемому объекту и объекту аналогу. (Методика 707/пр п.131(3)) (Ценообразующий)
B21: При проектировании трассы с 1-5 трубопроводами вводится коэффициент | G21: K1 = 0.5 Глава 2.5, п.2.5.6 (Ценообразующий)
B22: Исключенные разделы документации
B23: 1. Схема планировочной организации земельного участка | G23: 5%
B24: 2. Архитектурные решения. Конструктивные и объемно-планировочные решения | G24: 25%
A25: 4212.012.Р.3/0.0004.ГРП.02А.31111.004-ТС
A26: 2 | B26: Внутриплощадочные инженерные сети. Тепло-, газо-, материалопроводы на эстакадах. Длина трассы до 0.1 км. | G26: Объекты нефтеперерабатывающей и нефтехимической промышленности. 2015 г. Таблица 8. Объекты подсобно-производственного, вспомогательного и общезаводского назначения, внутриплощадочные инженерные сети, схема планировочной организации земельного участка, п.2.3 A = 1 695.18 тыс.руб; B = 1 100.96 тыс.руб; Xмин = 0.1; Xзад = 0.01 (км); Количество = 1 | K26: (A + B * (0.4 * Xмин + 0.6 * (Xмин / 2))) * Количество * Кпон * Ктек * Кст * K1 (1 695 180 руб. + 1 100 960 руб. * (0.4 * 0.1 + 0.6 * (0.1 / 2))) * 1 * 0.2 * 7,22 * 0.6 * 0.5 * 0.7 | O26: =ROUND((1695180 + 1100960 * (0.4 * 0.1 + 0.6 * (0.1 / 2))) * 1 * 0.2 * 7.22 * 0.6 * 0.5 * 0.7, 2) -> 537416.24
B27: Коэффициенты
B28: Стадия: Рабочая документация | G28: Кст = 0.6
B29: инд.3кв.2026г.к 01.01.2001 на пр.раб. | G29: Ктек = 7,22 Письмо Минстроя России от 22.07.2026 №45358-ИФ/09
B30: К'пон = Xзад / (0.5 * Xмин) | G30: К'пон = 0.2 понижающий коэффициент, учитывающий разницу в трудоемкости работ по проектируемому объекту и объекту аналогу. (Методика 707/пр п.131(3)) (Ценообразующий)
B31: При проектировании трассы с 1-5 трубопроводами вводится коэффициент | G31: K1 = 0.5 Глава 2.5, п.2.5.6 (Ценообразующий)
B32: Исключенные разделы документации
B33: 1. Схема планировочной организации земельного участка | G33: 5%
B34: 2. Архитектурные решения. Конструктивные и объемно-планировочные решения | G34: 25%
A35: 4212.00.Р.04.ГРП.2А.000.ТК2.000
A36: 3 | B36: Внутриплощадочные инженерные сети. Тепло-, газо-, материалопроводы на эстакадах. Длина трассы свыше 0.1 до 0.3 км. | G36: Объекты нефтеперерабатывающей и нефтехимической промышленности. 2015 г. Таблица 8. Объекты подсобно-производственного, вспомогательного и общезаводского назначения, внутриплощадочные инженерные сети, схема планировочной организации земельного участка, п.2.4 A = 1 700.5 тыс.руб; B = 1 047.8 тыс.руб; Xзад = 0.25 (км); Количество = 1 | K36: (A + B * Xзад) * Количество * Ктек * Кст * K1 (1 700 500 руб. + 1 047 800 руб. * 0.25) * 1 * 7,22 * 0.6 * 0.5 * 0.7 | O36: =ROUND((1700500 + 1047800 * 0.25) * 1 * 7.22 * 0.6 * 0.5 * 0.7, 2) -> 2975466.7
B37: Коэффициенты
B38: Стадия: Рабочая документация | G38: Кст = 0.6
B39: инд.3кв.2026г.к 01.01.2001 на пр.раб. | G39: Ктек = 7,22 Письмо Минстроя России от 22.07.2026 №45358-ИФ/09
B40: При проектировании трассы с 1-5 трубопроводами вводится коэффициент | G40: K1 = 0.5 Глава 2.5, п.2.5.6 (Ценообразующий)
B41: Исключенные разделы документации
B42: 1. Схема планировочной организации земельного участка | G42: 5%
B43: 2. Архитектурные решения. Конструктивные и объемно-планировочные решения | G43: 25%
A44: 4212.00.Р.04.ГРП.2А.000.ТК4.000
A45: 4 | B45: Внутриплощадочные инженерные сети. Тепло-, газо-, материалопроводы на эстакадах. Длина трассы свыше 0.3 до 0.5 км. | G45: Объекты нефтеперерабатывающей и нефтехимической промышленности. 2015 г. Таблица 8. Объекты подсобно-производственного, вспомогательного и общезаводского назначения, внутриплощадочные инженерные сети, схема планировочной организации земельного участка, п.2.5 A = 1 712.5 тыс.руб; B = 1 007.8 тыс.руб; Xзад = 0.37 (км); Количество = 1 | K45: (A + B * Xзад) * Количество * Ктек * Кст * K1 (1 712 500 руб. + 1 007 800 руб. * 0.37) * 1 * 7,22 * 0.6 * 0.5 * 0.7 | O45: =ROUND((1712500 + 1007800 * 0.37) * 1 * 7.22 * 0.6 * 0.5 * 0.7, 2) -> 3161862.2
...

Sheet 1.5 АСУТП этап3
B1: 5
B4: =СВОД!E26 -> Смета №1.5
B5: Этап 3 (Объекты на площадке ГРП 2А) АСУ ТП
B6: Наименование объекта | G6: Сети внутриплощадочные 001 - Технологический корпус №1 002 - Технологический корпус №2 004 - Резервуар, емкость дренажно-аварийная 005 - Резервуар, емкость расходная метанола 006 - Резервуар, емкость дренажно-аварийная 008 - Станция насосная 009 - Здание станции насосной водоснабжения производственного 016 - Склад дизтоплива расходный V=10 м3 019 - Здание операторной 022 - Здание контрольно- пропускного пункта
B8: Стадия | G8: Рабочая документация
B10: Наименование организации Заказчика
B11: Наименование проектной организации | G11: =СВОД!D14 -> ОАО «СИБНЕФТЕТРАНСПРОЕКТ»
B13: Смета составлена на основании "СБЦ на проектные работы в строительстве "Автоматизированные системы управления технологическими процессами (АСУТП)" (2016г.)
B15: 1. Краткая характеристика объекта автоматизации:
B16: Новое строительство
B17: Новое строительство
B18: Реконструкция, модернизация, тех. перевооружение
B19: Требование на разработку ТЗ к созданию АСУ ТП: | H19: Нет
H20: Да
H21: Нет
B22: Требуемые части документации АСУ ТП:
D23: ОР | E23: ОО | F23: ИО | G23: ТО | H23: МО | I23: ПО
D24: Да | E24: Нет | F24: Нет | G24: Да | H24: Нет | I24: Нет
D25: Да | E25: Да | F25: Да | G25: Да | H25: Да | I25: Да
D26: Нет | E26: Нет | F26: Нет | G26: Нет | H26: Нет | I26: Нет
B27: 2. Исходные данные:
B28: Трудоемкость разработки ТЗ на создание АСУ ТП
B29: Основные факторы, определяющие трудоемкость разработки | M29: Количество баллов
B30: № пп | C30: Фактор | E30: Наименование | H30: Определение | M30: ТЗ
B31: 1 | C31: Ф1 | E31: Степень научно-технической новизны (ТОУ) | H31: I степень - ТОУ имеет действующие аналоги в России и, возможно за рубежом | M31: =IF(H19="Да",SUMIF($H32:$L35,$H31,M32:N35),0) -> 0
B32: 1.1 | H32: I степень - ТОУ имеет действующие аналоги в России и, возможно за рубежом | M32: 1
B33: 1.2 | H33: II степень - ТОУ имеет действующие аналоги только за рубежом | M33: 2
B34: 1.3 | H34: III степень - ни с конструкторской, ни с технологической точек зрения ТОУ не является принципиально новым объектом, но действующих аналогов не имеет | M34: 4
B35: 1.4 | H35: IV степень - с конструкторской и (или) технологической точек зрения ТОУ является принципиально новым объектом | M35: 8
B36: 2 | C36: Ф2 | E36: Характер протекания управляемого технологического процесса во времени | H36: Непрерывный (с длительным поддержанием режимов, близких к установившимся, и практически безостановочной подачей сырья и реагентов) | M36: =IF(H19="Да",SUMIF($H37:$L42,$H36,M37:N42),0) -> 0
B37: 2.1 | H37: Непрерывный (с длительным поддержанием режимов, близких к установившимся, и практически безостановочной подачей сырья и реагентов) | M37: 1
B38: 2.2 | H38: Полунепрерывный (непрерывный, с существенными для управления переходными режимами, вызванными либо добавками (заменами) сырья или реагентов, либо выдачей продукции) | M38: 2
B39: 2.3 | H39: Непрерывно-дискретный - I (сочетающий непрерывные и прерывистые режимы на различных стадиях процесса) | M39: 4
B40: 2.4 | H40: Непрерывно-дискретный - II (сочетающий непрерывные и прерывистые режимы с малой длительностью непрерывных режимов в аварийных условиях) | M40: 5
B41: 2.5 | H41: Циклический (прерывистый, с существенной для управления длительностью интервалов непрерывного функционирования и циклическим следованием интервалов с различными режимами) | M41: 4
B42: 2.6 | H42: Дискретный (прерывистый, с малой, несущественной для управления, длительностью непрерывных технологических операций) | M42: 3
B43: 3 | C43: Ф3 | E43: Количество технологических операций, выполняемых на ТОУ | H43: свыше 10 до 20 | M43: =IF(H19="Да",SUMIF($H44:$L51,$H43,M44:N51),0) -> 0
B44: 3.1 | H44: до 5 | M44: 1
B45: 3.2 | H45: свыше 5 до 10 | M45: 2
B46: 3.3 | H46: свыше 10 до 20 | M46: 4
...

Sheet 1.6 АСУЭ этап3
B1: 5
B4: =СВОД!E27 -> Смета №1.6
B5: Этап 3 (Объекты на площадке ГРП 2А) АСУ Э
B6: Наименование объекта | G6: Сети внутриплощадочные
B8: Стадия | G8: Рабочая документация
B10: Наименование организации Заказчика
B11: Наименование проектной организации | G11: =СВОД!D14 -> ОАО «СИБНЕФТЕТРАНСПРОЕКТ»
B13: Смета составлена на основании "СБЦ на проектные работы в строительстве "Автоматизированные системы управления технологическими процессами (АСУТП)" (2016г.)
B15: 1. Краткая характеристика объекта автоматизации:
B16: Новое строительство
B17: Новое строительство
B18: Реконструкция, модернизация, тех. перевооружение
B19: Требование на разработку ТЗ к созданию АСУ ТП: | H19: Нет
H20: Да
H21: Нет
B22: Требуемые части документации АСУ ТП:
D23: ОР | E23: ОО | F23: ИО | G23: ТО | H23: МО | I23: ПО
D24: Да | E24: Нет | F24: Нет | G24: Да | H24: Нет | I24: Нет
D25: Да | E25: Да | F25: Да | G25: Да | H25: Да | I25: Да
D26: Нет | E26: Нет | F26: Нет | G26: Нет | H26: Нет | I26: Нет
B27: 2. Исходные данные:
B28: Трудоемкость разработки ТЗ на создание АСУ ТП
B29: Основные факторы, определяющие трудоемкость разработки | M29: Количество баллов
B30: № пп | C30: Фактор | E30: Наименование | H30: Определение | M30: ТЗ
B31: 1 | C31: Ф1 | E31: Степень научно-технической новизны (ТОУ) | H31: I степень - ТОУ имеет действующие аналоги в России и, возможно за рубежом | M31: =IF(H19="Да",SUMIF($H32:$L35,$H31,M32:N35),0) -> 0
B32: 1.1 | H32: I степень - ТОУ имеет действующие аналоги в России и, возможно за рубежом | M32: 1
B33: 1.2 | H33: II степень - ТОУ имеет действующие аналоги только за рубежом | M33: 2
B34: 1.3 | H34: III степень - ни с конструкторской, ни с технологической точек зрения ТОУ не является принципиально новым объектом, но действующих аналогов не имеет | M34: 4
B35: 1.4 | H35: IV степень - с конструкторской и (или) технологической точек зрения ТОУ является принципиально новым объектом | M35: 8
B36: 2 | C36: Ф2 | E36: Характер протекания управляемого технологического процесса во времени | H36: Непрерывный (с длительным поддержанием режимов, близких к установившимся, и практически безостановочной подачей сырья и реагентов) | M36: =IF(H19="Да",SUMIF($H37:$L42,$H36,M37:N42),0) -> 0
B37: 2.1 | H37: Непрерывный (с длительным поддержанием режимов, близких к установившимся, и практически безостановочной подачей сырья и реагентов) | M37: 1
B38: 2.2 | H38: Полунепрерывный (непрерывный, с существенными для управления переходными режимами, вызванными либо добавками (заменами) сырья или реагентов, либо выдачей продукции) | M38: 2
B39: 2.3 | H39: Непрерывно-дискретный - I (сочетающий непрерывные и прерывистые режимы на различных стадиях процесса) | M39: 4
B40: 2.4 | H40: Непрерывно-дискретный - II (сочетающий непрерывные и прерывистые режимы с малой длительностью непрерывных режимов в аварийных условиях) | M40: 5
B41: 2.5 | H41: Циклический (прерывистый, с существенной для управления длительностью интервалов непрерывного функционирования и циклическим следованием интервалов с различными режимами) | M41: 4
B42: 2.6 | H42: Дискретный (прерывистый, с малой, несущественной для управления, длительностью непрерывных технологических операций) | M42: 3
B43: 3 | C43: Ф3 | E43: Количество технологических операций, выполняемых на ТОУ | H43: свыше 10 до 20 | M43: =IF(H19="Да",SUMIF($H44:$L51,$H43,M44:N51),0) -> 0
B44: 3.1 | H44: до 5 | M44: 1
B45: 3.2 | H45: свыше 5 до 10 | M45: 2
B46: 3.3 | H46: свыше 10 до 20 | M46: 4
...

Sheet 1.7 АЭО этап3
B1: 5
B4: =СВОД!E28 -> Смета №1.7
B5: Этап 3 (Объекты на площадке ГРП 2А) АЭО
B6: Наименование объекта | G6: Сети внутриплощадочные
B8: Стадия | G8: Рабочая документация
B10: Наименование организации Заказчика
B11: Наименование проектной организации | G11: =СВОД!D14 -> ОАО «СИБНЕФТЕТРАНСПРОЕКТ»
B13: Смета составлена на основании "СБЦ на проектные работы в строительстве "Автоматизированные системы управления технологическими процессами (АСУТП)" (2016г.)
B15: 1. Краткая характеристика объекта автоматизации:
B16: Новое строительство
B17: Новое строительство
B18: Реконструкция, модернизация, тех. перевооружение
B19: Требование на разработку ТЗ к созданию АСУ ТП: | H19: Нет
H20: Да
H21: Нет
B22: Требуемые части документации АСУ ТП:
D23: ОР | E23: ОО | F23: ИО | G23: ТО | H23: МО | I23: ПО
D24: Да | E24: Нет | F24: Нет | G24: Да | H24: Нет | I24: Нет
D25: Да | E25: Да | F25: Да | G25: Да | H25: Да | I25: Да
D26: Нет | E26: Нет | F26: Нет | G26: Нет | H26: Нет | I26: Нет
B27: 2. Исходные данные:
B28: Трудоемкость разработки ТЗ на создание АСУ ТП
B29: Основные факторы, определяющие трудоемкость разработки | M29: Количество баллов
B30: № пп | C30: Фактор | E30: Наименование | H30: Определение | M30: ТЗ
B31: 1 | C31: Ф1 | E31: Степень научно-технической новизны (ТОУ) | H31: I степень - ТОУ имеет действующие аналоги в России и, возможно за рубежом | M31: =IF(H19="Да",SUMIF($H32:$L35,$H31,M32:N35),0) -> 0
B32: 1.1 | H32: I степень - ТОУ имеет действующие аналоги в России и, возможно за рубежом | M32: 1
B33: 1.2 | H33: II степень - ТОУ имеет действующие аналоги только за рубежом | M33: 2
B34: 1.3 | H34: III степень - ни с конструкторской, ни с технологической точек зрения ТОУ не является принципиально новым объектом, но действующих аналогов не имеет | M34: 4
B35: 1.4 | H35: IV степень - с конструкторской и (или) технологической точек зрения ТОУ является принципиально новым объектом | M35: 8
B36: 2 | C36: Ф2 | E36: Характер протекания управляемого технологического процесса во времени | H36: Непрерывный (с длительным поддержанием режимов, близких к установившимся, и практически безостановочной подачей сырья и реагентов) | M36: =IF(H19="Да",SUMIF($H37:$L42,$H36,M37:N42),0) -> 0
B37: 2.1 | H37: Непрерывный (с длительным поддержанием режимов, близких к установившимся, и практически безостановочной подачей сырья и реагентов) | M37: 1
B38: 2.2 | H38: Полунепрерывный (непрерывный, с существенными для управления переходными режимами, вызванными либо добавками (заменами) сырья или реагентов, либо выдачей продукции) | M38: 2
B39: 2.3 | H39: Непрерывно-дискретный - I (сочетающий непрерывные и прерывистые режимы на различных стадиях процесса) | M39: 4
B40: 2.4 | H40: Непрерывно-дискретный - II (сочетающий непрерывные и прерывистые режимы с малой длительностью непрерывных режимов в аварийных условиях) | M40: 5
B41: 2.5 | H41: Циклический (прерывистый, с существенной для управления длительностью интервалов непрерывного функционирования и циклическим следованием интервалов с различными режимами) | M41: 4
B42: 2.6 | H42: Дискретный (прерывистый, с малой, несущественной для управления, длительностью непрерывных технологических операций) | M42: 3
B43: 3 | C43: Ф3 | E43: Количество технологических операций, выполняемых на ТОУ | H43: свыше 10 до 20 | M43: =IF(H19="Да",SUMIF($H44:$L51,$H43,M44:N51),0) -> 0
B44: 3.1 | H44: до 5 | M44: 1
B45: 3.2 | H45: свыше 5 до 10 | M45: 2
B46: 3.3 | H46: свыше 10 до 20 | M46: 4
...

Sheet 1.8 СПБА этап3
B1: 5
B4: =СВОД!E29 -> Смета №1.8
B5: Этап 3 (Объекты на площадке ГРП 2А) СПБА
B6: Наименование объекта | G6: Сети внутриплощадочные 001 - Технологический корпус №1 002 - Технологический корпус №2 008 - Станция насосная 009 - Здание станции насосной водоснабжения производственного 019 - Здание операторной
B8: Стадия | G8: Рабочая документация
B10: Наименование организации Заказчика
B11: Наименование проектной организации | G11: =СВОД!D14 -> ОАО «СИБНЕФТЕТРАНСПРОЕКТ»
B13: Смета составлена на основании "СБЦ на проектные работы в строительстве "Автоматизированные системы управления технологическими процессами (АСУТП)" (2016г.)
B15: 1. Краткая характеристика объекта автоматизации:
B16: Новое строительство
B17: Новое строительство
B18: Реконструкция, модернизация, тех. перевооружение
B19: Требование на разработку ТЗ к созданию АСУ ТП: | H19: Нет
H20: Да
H21: Нет
B22: Требуемые части документации АСУ ТП:
D23: ОР | E23: ОО | F23: ИО | G23: ТО | H23: МО | I23: ПО
D24: Да | E24: Нет | F24: Нет | G24: Да | H24: Нет | I24: Нет
D25: Да | E25: Да | F25: Да | G25: Да | H25: Да | I25: Да
D26: Нет | E26: Нет | F26: Нет | G26: Нет | H26: Нет | I26: Нет
B27: 2. Исходные данные:
B28: Трудоемкость разработки ТЗ на создание АСУ ТП
B29: Основные факторы, определяющие трудоемкость разработки | M29: Количество баллов
B30: № пп | C30: Фактор | E30: Наименование | H30: Определение | M30: ТЗ
B31: 1 | C31: Ф1 | E31: Степень научно-технической новизны (ТОУ) | H31: I степень - ТОУ имеет действующие аналоги в России и, возможно за рубежом | M31: =IF(H19="Да",SUMIF($H32:$L35,$H31,M32:N35),0) -> 0
B32: 1.1 | H32: I степень - ТОУ имеет действующие аналоги в России и, возможно за рубежом | M32: 1
B33: 1.2 | H33: II степень - ТОУ имеет действующие аналоги только за рубежом | M33: 2
B34: 1.3 | H34: III степень - ни с конструкторской, ни с технологической точек зрения ТОУ не является принципиально новым объектом, но действующих аналогов не имеет | M34: 4
B35: 1.4 | H35: IV степень - с конструкторской и (или) технологической точек зрения ТОУ является принципиально новым объектом | M35: 8
B36: 2 | C36: Ф2 | E36: Характер протекания управляемого технологического процесса во времени | H36: Непрерывный (с длительным поддержанием режимов, близких к установившимся, и практически безостановочной подачей сырья и реагентов) | M36: =IF(H19="Да",SUMIF($H37:$L42,$H36,M37:N42),0) -> 0
B37: 2.1 | H37: Непрерывный (с длительным поддержанием режимов, близких к установившимся, и практически безостановочной подачей сырья и реагентов) | M37: 1
B38: 2.2 | H38: Полунепрерывный (непрерывный, с существенными для управления переходными режимами, вызванными либо добавками (заменами) сырья или реагентов, либо выдачей продукции) | M38: 2
B39: 2.3 | H39: Непрерывно-дискретный - I (сочетающий непрерывные и прерывистые режимы на различных стадиях процесса) | M39: 4
B40: 2.4 | H40: Непрерывно-дискретный - II (сочетающий непрерывные и прерывистые режимы с малой длительностью непрерывных режимов в аварийных условиях) | M40: 5
B41: 2.5 | H41: Циклический (прерывистый, с существенной для управления длительностью интервалов непрерывного функционирования и циклическим следованием интервалов с различными режимами) | M41: 4
B42: 2.6 | H42: Дискретный (прерывистый, с малой, несущественной для управления, длительностью непрерывных технологических операций) | M42: 3
B43: 3 | C43: Ф3 | E43: Количество технологических операций, выполняемых на ТОУ | H43: свыше 10 до 20 | M43: =IF(H19="Да",SUMIF($H44:$L51,$H43,M44:N51),0) -> 0
B44: 3.1 | H44: до 5 | M44: 1
B45: 3.2 | H45: свыше 5 до 10 | M45: 2
B46: 3.3 | H46: свыше 10 до 20 | M46: 4
...

Sheet 1.9 СС
E1: Форма 2П
A3: =СВОД!E30 -> Смета №1.9
A4: на проектные работы
B6: Наименование объекта, стадии, этапа проектных работ | C6: =СВОД!B30 -> Сети связи и сигнализации
C7: Этап 3
B8: Наименование проектной | C8: =СВОД!D14 -> ОАО «СИБНЕФТЕТРАНСПРОЕКТ»
B9: (изыскательской) организации
B11: Наименование организации | C11: =СВОД!D16 -> ООО «Газпром проектирование»
B12: заказчика
A14: № пп. | B14: Характеристика предприятия, здания, сооружения или виды работ | C14: Номер частей, глав, таблиц, процентов, параграфов и пунктов указаний к разделу Справочника базовых цен на проектные и изыскательские работы для строительства | D14: Расчет стоимости: (a+bx)*Ki, или (объем строительно-монтажных работ) * проц./100 или количество x цена | E14: Стоимость, руб.
A15: 1 | B15: 2 | C15: 3 | D15: 4 | E15: 5
A17: 001 - Технологический корпус №1
A18: 1 | B18: Пожарная сигнализация на площади 80,8*15= 1212м2 | C18: СБЦ на ПРС "Системы противопожарной и охранной защиты" (табл. 3 п.6) | D18: 2304x0,6x55,26x1,5x1,2x1,1x1,3 | E18: =2304*0.6*55.26*1.5*1.2*1.1*1.3 -> 196631.53
C19: К=0,6(стадия Р)
C20: К=55,26(инфляц.)
C21: К=1,5 п.3 (управление ПЗ и ПБ)
C22: К=1,2 п.2.2 (установка вне здания РПИ)
C23: К=1,1 п.2.5 (вынос оборудования из здания)
C24: К=1,3 п.2.5 (взрывоопасность )
A25: 2 | B25: Система оповещения людей о пожаре на площади 80,8*15= 1212м2 | C25: СБЦ на ПРС "Системы противопожарной и охранной защиты" (табл. 4 п.6) | D25: 1843x0,6x55,26x1,4x1,1x1,3 | E25: =1843*0.6*55.26*1.4*1.1*1.3 -> 122335.23
C26: К=0,6(стадия Р)
C27: К=55,26(инфляц.)
C28: К=1,4 (тип 3)
C29: К=1,1 п.2.5 (вынос оборудования из здания)
C30: К=1,3 п.2.5 (взрывоопасность)
A31: 3 | B31: Установка оперативно-диспетчерской связи до 50 | C31: СБЦ ПР для стр-ва, объекты связи, 2010г. (табл.9 п.1) | D31: (1020+15x15)x0,52x7,22 | E31: =(1020+15*15)*0.52*7.22 -> 4674.228
C32: К=0,52(стадия Р)
C33: К=7,22 (инфляц.)
A34: 4 | B34: Производственная громкоговорящая связь 12 абонентов | C34: СБЦ ПР для стр-ва, объекты связи, 2010г. (табл.9 п.4) | D34: (1650+76x15)x0,52x7,22 | E34: =(1650+76*15)*0.52*7.22 -> 10474.776
C35: К=0,52(стадия Р)
C36: К=7,22 (инфляц.)
A37: 5 | B37: Сеть комплексная средств связи и передачи информации на промплощадке 50 пар (телефон,ГГС) | C37: СЦБ ПР для стр-ва, объекты связи (табл.9 п.11) | D37: (1950+19x10)x0,52x7,22 | E37: =(1950+19*10)*0.52*7.22 -> 8034.416
C38: К=0,52(стадия Р)
C39: К=7,22 (инфляц.)
A40: 6 | B40: Локальная вычислительная сеть с числом узлов 1 | C40: СБЦ ПР для стр-ва, объекты связи, 2010г. (табл.24 п.2) | D40: (2450+3680x1)x0,5x7,22 | E40: =(2450+3680*1)*0.5*7.22 -> 22129.3
C41: К=0,5 (стадия Р)
C42: К=7,22 (инфляц.)
A43: 7 | B43: СКС в здании | C43: СБЦ ПР для стр-ва, объекты связи, 2010г. (табл.24 п.8) | D43: (2450+3680x15)x0,5x7,22 | E43: =(2450+3680*15)*0.5*7.22 -> 208116.5
C44: К=0,5 (стадия Р)
C45: К=7,22 (инфляц.)
...

Sheet 1.10 ЭС+
E1: Форма 2П
A3: =СВОД!E31 -> Смета №1.10
A4: на проектные работы
B6: Наименование объекта, стадии, этапа проектных работ | C6: =СВОД!B31 -> Электроснабжение
B8: Наименование проектной | C8: =СВОД!D14 -> ОАО «СИБНЕФТЕТРАНСПРОЕКТ»
B9: (изыскательской) организации
B11: Наименование организации | C11: =СВОД!D16 -> ООО «Газпром проектирование»
B12: заказчика
A14: № пп. | B14: Характеристика предприятия, здания, сооружения или виды работ | C14: Номер частей, глав, таблиц, процентов, параграфов и пунктов указаний к разделу Справочника базовых цен на проектные и изыскательские работы для строительства | D14: Расчет стоимости: (a+bx)*Ki, или (объем строительно-монтажных работ) * проц./100 или количество x цена | E14: Стоимость, руб.
A15: 1 | B15: 2 | C15: 3 | D15: 4 | E15: 5
A17: Этап 3 (Объекты на площадке ГРП 2А)
A18: 1 - Технологический корпус №1
A19: 1 | B19: Установка низковольтных щитов управления (НКУ-0,4 кВ), в помещении размером до 20 м2. Всего 6 шт. (компл. ЭМ, ЭО) | C19: СБЦ на проектные работы "Объекты магистрального транспорта нефти". т.4, п.24.2. | D19: 21120x6x7,22x0,6x1,08 | E19: =21120*6*7.22*0.6*1.08 -> 592867.12
C20: К1=7,22-инфляционный коэффициент
C21: К2=0,6 - ст. "Р"
C22: К3=1,08 - районный коэф-т
A23: 2 | B23: Проектирование системы бесперебойного питания , системы постоянного тока. Всего 4 панели. (ЭМ) | C23: СБЦ «Газооборудование и газоснабжение промышленных предприятий, зданий и сооружений», 2015г., таб. 19, п.1. | D23: 11083x4x7,22x0,6x1,08 | E23: 11083*4*7,22*0,6*1,08
C24: К1=7,22-инфляционный коэффициент
C25: К2=0,6 - Cтадия "Р"
C26: К3=1,08 - районный коэф-т
A27: 3 | B27: Прокладка кабельных линий 0,4 кВ до потребителей по кабельным конструкциям. Суммарная протяжённость трассы -0,6 км. (ЭМ, ЭМ1, ЭО) | C27: СБЦ «Объекты нефтеперерабатывающей и нефтехимической промышленности», 2015 г, табл.8, п.2.10. | D27: 433690x0,6x7,22x0,6x1,08 | E27: =433690*0.6*7.22*0.6*1.08 -> 1217426.8
C28: К1=7,22-инфляционный коэффициент
C29: К2=0,6 - ст. "Р"
C30: К3=1,08 - районный коэф-т
A31: 4 | B31: Расчет токов короткого замыкания в сети 0,4 кВ. Всего 9 линий.(ЭМ,ЭО) | C31: СБЦ «Объекты нефтеперерабатывающей и нефтехимической промышленность», 2015г, таб.11 п.19. | D31: 10070x9x7,22x0,6x1,08 | E31: =10070*9*7.22*0.6*1.08 -> 424017.89
C32: К1=7,22-инфляционный коэффициент
C33: К2=0,6 - ст. "Р"
C34: К3=1,08 - районный коэф-т
A35: 5 | B35: Проектирование заземляющего устройства зданий и сооружений. Всего 1 объект (ЭМ1) | C35: СБЦ на проектные работы "Объекты магистрального транспорта нефти". т.4, п.22.1. | D35: 8870x1x7,22x0,6x1,08 | E35: =8870*1*7.22*0.6*1.08 -> 41498.827
C36: К1=7,22-инфляционный коэффициент
C37: К2=0,6 - ст. "Р"
C38: К3=1,08 - районный коэф-т
A39: 6 | B39: Рассмотрение конструкторской документации на оборудование, предоставляемой Заказчиком от заводов-изготовителей или поставщиков до ее окончательного утверждения, при необходимости корректировка проекта с учетом утвержденных Заказчиком материалов конструкторской документации заводов-изготовителей. | C39: Методические указания от 29.12.2009 г. Часть III п.3.9. До 2% от цены разработки документации по пп.1, 2 | D39: 800277,04512x0,02 | E39: =800277.04512*0.02 -> 16005.541
A40: 2 - Технологический корпус №2
A41: 1 | B41: Установка низковольтных щитов управления (НКУ-0,4 кВ), в помещении размером до 20 м2. Всего 6 шт. (компл. ЭМ, ЭО) | C41: СБЦ на проектные работы "Объекты магистрального транспорта нефти". т.4, п.24.2. | D41: 21120x6x7,22x0,6x1,08 | E41: =21120*6*7.22*0.6*1.08 -> 592867.12
C42: К1=7,22-инфляционный коэффициент
C43: К2=0,6 - ст. "Р"
C44: К3=1,08 - районный коэф-т
A45: 2 | B45: Проектирование системы бесперебойного питания , системы постоянного тока. Всего 4 панели. (ЭМ) | C45: СБЦ «Газооборудование и газоснабжение промышленных предприятий, зданий и сооружений», 2015г., таб. 19, п.1. | D45: 11083x4x7,22x0,6x1,08 | E45: =11083*4*7.22*0.6*1.08 -> 207409.92
C46: К1=7,22-инфляционный коэффициент
...

Sheet 1.11 ЭХЗ+
E1: Форма 2П
A3: =СВОД!E32 -> Смета №1.11
A4: на проектные работы
B6: Наименование объекта, стадии, этапа проектных работ | C6: =СВОД!B32 -> Электрохимическая защита
B8: Наименование проектной | C8: =СВОД!D14 -> ОАО «СИБНЕФТЕТРАНСПРОЕКТ»
B9: (изыскательской) организации
B11: Наименование организации | C11: =СВОД!D16 -> ООО «Газпром проектирование»
B12: заказчика
A14: № пп. | B14: Характеристика предприятия, здания, сооружения или виды работ | C14: Номер частей, глав, таблиц, процентов, параграфов и пунктов указаний к разделу Справочника базовых цен на проектные и изыскательские работы для строительства | D14: Расчет стоимости: (a+bx)*Ki, или (объем строительно-монтажных работ) * проц./100 или количество x цена | E14: Стоимость, руб.
A15: 1 | B15: 2 | C15: 3 | D15: 4 | E15: 5
A17: Этап 3 (Объекты на площадке ГРП 2А)
A18: 4212.012.Р.3/0.0004.ГРП.02А.00000.000-ЭХЗ1, 4212.012.Р.3/0.0004.ГРП.02А.00000.000-ЭХЗ2, 4212.012.Р.3/0.0004.ГРП.02А.00000.000-ЭХЗ3
A19: 1 | B19: Электрозащитная установка от коррозии (катодная, электродренажная). От 1 до 5 установок. Всего 1 установка | C19: СБЦ-2015 (Приказ Минстроя от 27.02.2015 № 140/пр, приложение №4 "СБЦ на преоктные работы в строительстве "Газооборудование и газоснабжение промышленных предприятий, зданий и сооружений" табл. 16 п.1 | D19: (5148+30850x1)x7,22x0,6 | E19: =(5148+30850*1)*7.22*0.6 -> 155943.34
C20: К1=7,22-инфляционный коэффициент
C21: К2=0,6 Cтадия "Р"
A22: 2 | B22: Проектирование вентильных перемычек (блоки БСЗ)..Всего 4 установки | C22: СБЦ-2015 (Приказ Минстроя от 27.02.2015 № 140/пр, приложение №4 "СБЦ на преоктные работы в строительстве "Газооборудование и газоснабжение промышленных предприятий, зданий и сооружений" табл. 16 п.1 | D22: (5148+30850x4)x7,22x0,6x0,031 | E22: =(5148+30850*4)*7.22*0.6*0.031 -> 17262.968
C23: К1=7,22-инфляционный коэффициент
C24: К2=0,6 Cтадия "Р"
C25: К3=0,031 п.2.4.3 СБЦ
A26: 3 | B26: Проектирование глубинного анадного заземлителя (ГАЗ). Всего 8 шт | C26: СБЦ-2015 "Газооборудование и газоснабжение промышленных предприятий, зданий и сооружений" глава 2.4 п. 2.4.2 ,табл. 19 п.4 | D26: 20435x7,22x0,6x8 | E26: =20435*7.22*0.6*8 -> 708195.36
C27: К1=7,22-инфляционный коэффициент
C28: К2=0,6 Cтадия "Р"
C29: К3=8 Ценообразующий коэф-т
A30: 4 | B30: Контрольно-измерительные пункты (КИП). Количество КИП всего по объекту -40 шт. | C30: СБЦ-2015 (Приказ Минстроя от 27.02.2015 № 140/пр, приложение №4 "СБЦ на преоктные работы в строительстве "Газооборудование и газоснабжение промышленных предприятий, зданий и сооружений" табл. 16 п.5 | D30: 495483x7,22x0,6x0,007x40 | E30: =495483*7.22*0.6*0.007*40 -> 601001.06
C31: К1=7,22-инфляционный коэффициент
C32: К2=0,6 Cтадия "Р"
C33: К3=0,007 п.2.4.3 СБЦ
C34: К4=40 Ценообразующий коэф-т
A35: 5 | B35: Проектирование протекторной установки (УПЗ).Количество УПЗ всего по объекту -40 шт. | C35: СБЦ-2015"Газооборудование и газоснабжение промышленных предприятий, зданий и сооружений" глава 2.4 п. 2.4.2 ,табл. 19 п.4 | D35: 20435x7,22x0,6x40x0,1 | E35: =20435*7.22*0.6*40*0.1 -> 354097.68
C36: К1=7,22-инфляционный коэффициент
C37: К2=0,6 Cтадия "Р"
C38: К3=40 Ценообразующий коэф-т
C39: К4=0,1- СБЦ-2015 глава 2.4 п. 2.4.1
A40: 6 | B40: Проектирование кабельных линий напряжением до 1.0 кВ. Всего 4 км | C40: СБЦ-2015 "Газооборудование и газоснабжение промышленных предприятий, зданий и сооружений"глава 2.4 п. 2.4.2 ,табл. 19 п.2 | D40: (9996+22090x4)x7,22x0,6 | E40: =(9996+22090*4)*7.22*0.6 -> 426078.19
C41: К1=7,22-инфляционный коэффициент
C42: К2=0,6 Cтадия "Р"
A43: ГК.2 А - Коллектор газосборный КС 3 - ГРП 2А | G43: дополнено
A44: 4212.001.Р.007.0004.ГК.2А.0000.000-ЭХЗ1
A45: 1 | B45: Проектирование вентильных перемычек (блоки БСЗ)..Всего 100 установок | C45: СБЦ-2015 (Приказ Минстроя от 27.02.2015 № 140/пр, приложение №4 "СБЦ на преоктные работы в строительстве "Газооборудование и газоснабжение промышленных предприятий, зданий и сооружений" табл. 16 п.5 | D45: 495483x7,22x0,6x0,031x30,7 | E45: 2042760
C46: К1=7,22-инфляционный коэффициент
...

Sheet 1.12 ВК
E1: Форма 2П
A3: =СВОД!E33 -> Смета №1.12
A4: на проектные работы
B6: Наименование объекта, стадии, этапа проектных работ | C6: =СВОД!B33 -> Сети водоснабжения и канализации
B8: Наименование проектной | C8: =СВОД!D14 -> ОАО «СИБНЕФТЕТРАНСПРОЕКТ»
B9: (изыскательской) организации
B11: Наименование организации | C11: =СВОД!D16 -> ООО «Газпром проектирование»
B12: заказчика
A14: № пп. | B14: Характеристика предприятия, здания, сооружения или виды работ | C14: Номер частей, глав, таблиц, процентов, параграфов и пунктов указаний к разделу Справочника базовых цен на проектные и изыскательские работы для строительства | D14: Расчет стоимости: (a+bx)*Ki, или (объем строительно-монтажных работ) * проц./100 или количество x цена | E14: Стоимость, руб.
A15: 1 | B15: 2 | C15: 3 | D15: 4 | E15: 5
A17: Этап №3 ГРП 2А
A18: 1 | B18: Система автоматического газового пожаротушения помещени технологического корпуса №1 (4 напр.) | C18: СБЦ "Системы противопожарной и охранной защиты" т.2 п.2 | D18: 3814x55,26x1,3x1,3x0,9x1 | E18: =3814*55.26*1.3*1.3*0.9*1 -> 320568.45
C19: k=55,26
C20: к=1.3 п.2.5
C21: к=1.3 п.3
C22: е=0,9 ст.РП
C23: к=1 объем
A24: 2 | B24: Система автоматического газового пожаротушения помещени технологического корпуса №2 (4 напр.) | C24: СБЦ "Системы противопожарной и охранной защиты" т.2 п.2 | D24: 3814x55,26x1,3x1,3x0,9x1 | E24: =3814*55.26*1.3*1.3*0.9*1 -> 320568.45
C25: k=55,26
C26: к=1.3 п.2.5
C27: к=1.3 п.3
C28: е=0,9 ст.РП
C29: к=1 объем
A30: 3 | B30: Система автоматического газового пожаротушения помещени технологической насосной поз.8 | C30: СБЦ "Системы противопожарной и охранной защиты" т.2 п.1 | D30: 2560x55,26x1,3x1,3x0,9x1 | E30: =2560*55.26*1.3*1.3*0.9*1 -> 215169.18
C31: k=55,26
C32: к=1.3 п.2.5
C33: к=1.3 п.3
C34: е=0,9 ст.РП
C35: к=1 объем
A36: 4 | B36: Система автоматического газового пожаротушения помещений операторной поз.19 | C36: СБЦ "Системы противопожарной и охранной защиты" т.2 п.1 | D36: 2560x55,26x1,3x0,75x0,7 | E36: =2560*55.26*1.3*0.75*0.7 -> 96550.272
C37: k=55,26
C38: к=1.3 п.3
C39: к=0,75 ст.Р
C40: к=0,7 объем
A41: 5 | B41: Насосная станция противопожарного водоснабжения поз.9 Q= 200 м3/час | C41: Спр. баз. цен "ВиК" 2015 г. т.5 п.3 | D41: (179590+353530x0,2)x7,22x1,1x0,4x0,7 | E41: =(179590+353530*0.2)*7.22*1.1*0.4*0.7 -> 556598.23
C42: k=7,22 инфл.
C43: к=1,1 микропроцесс.
C44: к=0,4 ст.Р
C45: к=0,7 объем
A46: 6 | B46: Резервуары для противопожарного запаса воды поз.10, 11 емк. 200 куб.м. 2 шт. | C46: Спр. баз. цен "ВиК" 2015 г. т.5 п.10 | D46: (21960+79880x0,2)x7,22x2x0,4x0,7 | E46: =(21960+79880*0.2)*7.22*2*0.4*0.7 -> 153382.84
...

Sheet 1.13 ЛЧ+
A1: Адепт: Проект v 2026.4.2 © ООО"Адепт" | E1: форма 2П, 707/пр
A3: Смета №1.13
A4: на проектные (изыскательские) работы
A6: Наименование предприятия, здания, сооружения, стадии проектирования, этапа, вида проектных или изыскательских работ | F6: =СВОД!B34 -> Линейная часть
A8: Наименование проектной (изыскательской) организации | F8: =СВОД!D14 -> ОАО «СИБНЕФТЕТРАНСПРОЕКТ»
A10: Наименование организации заказчика | F10: =СВОД!D16 -> ООО «Газпром проектирование»
A12: № пп | B12: Наименование объекта проектирования или вида проектных работ | G12: Наименование, номера глав, таблиц, параграфов и пунктов МНЗ на проектные работы | K12: Расчет стоимости | O12: Стоимость, руб.
A13: 1 | B13: 2 | G13: 3 | K13: 4 | O13: 5
A14: Шг.2А - Сеть газосборная ГРП 2А
A15: 4212.00.Р.04.Шг.2А.000.Л.000 Инв номер 763390
A16: 1 | B16: Трубопроводы (межцеховые и шлейфы) диаметром до 300 мм. Протяженность от 1 км до 5 км включительно. | G16: НЗ №849/пр Объекты газовой промышленности. 2023 г. Таблица 3.6. Объекты сбора газа (шлейфы, коллекторы и межцеховые трубопроводы), п.1 A = 61.9 тыс.руб; B = 15.484 тыс.руб; Xзад = 1.0125 (км); Количество = 1 | K16: (A + B * Xзад) * Количество * Ктек * Кст (61 900 руб. + 15 484 руб. * 1.0125) * 1 * 1,56 * 0.6 | O16: =ROUND((61900 + 15484 * 1.0125) * 1 * 1.56 * 0.6, 2) -> 72612.59
B17: Коэффициенты
B18: Стадия: Рабочая документация | G18: Кст = 0.6
B19: инд.3кв.2026г.к 01.01.2022 на пр.раб. | G19: Ктек = 1,56 Письмо Минстроя России от 22.07.2026 №45358-ИФ/09
A20: 2 | B20: Трубопроводы (межцеховые и шлейфы) диаметром до 300 мм. Протяженность от 1 км до 5 км включительно. | G20: НЗ №849/пр Объекты газовой промышленности. 2023 г. Таблица 3.6. Объекты сбора газа (шлейфы, коллекторы и межцеховые трубопроводы), п.1 A = 61.9 тыс.руб; B = 15.484 тыс.руб; Xзад = 2.33152 (км); Количество = 1 | K20: (A + B * Xзад) * Количество * Ктек * Кст (61 900 руб. + 15 484 руб. * 2.33152) * 1 * 1,56 * 0.6 | O20: =ROUND((61900 + 15484 * 2.33152) * 1 * 1.56 * 0.6, 2) -> 91729.18
B21: Коэффициенты
B22: Стадия: Рабочая документация | G22: Кст = 0.6
B23: инд.3кв.2026г.к 01.01.2022 на пр.раб. | G23: Ктек = 1,56 Письмо Минстроя России от 22.07.2026 №45358-ИФ/09
A24: 4212.00.Р.04.Шг.2А.000.Л1.000 Инв номер 763400
A25: 3 | B25: Трубопроводы (межцеховые и шлейфы) диаметром до 300 мм. Протяженность от 1 км до 5 км включительно. | G25: НЗ №849/пр Объекты газовой промышленности. 2023 г. Таблица 3.6. Объекты сбора газа (шлейфы, коллекторы и межцеховые трубопроводы), п.1 A = 61.9 тыс.руб; B = 15.484 тыс.руб; Xзад = 2.73962 (км); Количество = 1 | K25: (A + B * Xзад) * Количество * Ктек * Кст (61 900 руб. + 15 484 руб. * 2.73962) * 1 * 1,56 * 0.6 | O25: =ROUND((61900 + 15484 * 2.73962) * 1 * 1.56 * 0.6, 2) -> 97643.78
B26: Коэффициенты
B27: Стадия: Рабочая документация | G27: Кст = 0.6
B28: инд.3кв.2026г.к 01.01.2022 на пр.раб. | G28: Ктек = 1,56 Письмо Минстроя России от 22.07.2026 №45358-ИФ/09
A29: 4 | B29: Трубопроводы (межцеховые и шлейфы) диаметром до 300 мм. Протяженность от 1 км до 5 км включительно. | G29: НЗ №849/пр Объекты газовой промышленности. 2023 г. Таблица 3.6. Объекты сбора газа (шлейфы, коллекторы и межцеховые трубопроводы), п.1 A = 61.9 тыс.руб; B = 15.484 тыс.руб; Xмин = 1; Xзад = 0.5418 (км); Количество = 1 | K29: (A + B * (0.4 * Xмин + 0.6 * Xзад)) * Количество * Ктек * Кст (61 900 руб. + 15 484 руб. * (0.4 * 1 + 0.6 * 0.5418)) * 1 * 1,56 * 0.6 | O29: =ROUND((61900 + 15484 * (0.4 * 1 + 0.6 * 0.5418)) * 1 * 1.56 * 0.6, 2) -> 68447
B30: Коэффициенты
B31: Стадия: Рабочая документация | G31: Кст = 0.6
B32: инд.3кв.2026г.к 01.01.2022 на пр.раб. | G32: Ктек = 1,56 Письмо Минстроя России от 22.07.2026 №45358-ИФ/09
A33: 4212.00.Р.04.Шг.2А.000.Л2.000 Инв номер 763405
