Workbook

Sheet Лист1
C1: Форма для заполнения по тендерной процедуре №ТП.....
A2: Разработка проектной и рабочей документации объекта "Перевод установки получения масляных альдегидов методом оксосинтеза на Rh катализатор с наращением мощности по 2-ЭГ и 2-ЭГК на АО «Сибур-Химпром»
A4: № п/п | B4: Наименование показателей | C4: Претендент
A6: Соответствие техническому заданию.
A7: п. 4.10 Смета на строительство объектов капитального строительства
A8: 1. | B8: Разработка сметной документации в 2-х форматах: - ресурсным методом -базисно индексным методом
A9: 2. | B9: Базисно-индексный метод:
A10: 2.1 | B10: По основным (ценообразующим) материалам и вспомогательному оборудованию провести мониторинг рынка поставщиков
A11: 2.2 | B11: Предоставить ведомости объемов работ к каждому расчету за подписью разработчика марки проекта.
A12: 2.3 | B12: Предоставить ведомости материалов с построчной стоимостью ресурсов
A13: 2.4 | B13: Предоставить ведомости оборудования с построчной стоимостью ресурсов
A14: 2.5 | B14: В локальных сметных расчетах учесть разделение ТМЦ поставки Заказчик / Подрядчик.
A15: 2.6 | B15: Базисно-индексным методом: локальные сметные расчеты выполнить в сметно-нормативной базе ФЕР-2001 в ред.2017 (с изм.1-4) в программном комплексе «Гранд-Смета» с применением индексов пересчета по статьям затрат Пермского Регионального Центра Ценообразования (ПРЦЦС).
A16: 2.7 | B16: Сметную документацию (для БИМ) сформировать в составе: - сводный сметный расчет; - объектные сметные расчеты; - локальные сметные расчеты ; - ведомости объемов работ; - ведомости ресурсов; - ведомости оборудования
A17: 3. | B17: Ресурсный метод:
A18: 3.1 | B18: Ресурсные ведомости под каждую единичную расценку (ЕР) и титул
A19: 3.2 | B19: Для определения стоимости ресурсов использовать текущие цены на ресурсы, согласованные с Заказчиком.
... A26: 6. | B26: Предоставить пояснительную записку по формированию стоимости с указанием перечня затрат, возможных к реализации, но не учтенных в стоимости строительства

Sheet КП
G1: Форма для заполнения по тендерной процедуре №…….
A3: Разработка ТЭО, ОТР, FEED, проектной и рабочей документации объекта "Выполнение проектно-изыскательских работ по проектам "Техническое перевооружение сети водопроводов, трубопроводов пенного пожаротушения ООО "Томскнефтехим" » Календарный план
A5: Этапы № п/п | B5: Наименование Этапа | C5: Отчетная документация | D5: Дата начала | E5: Дата окончания* | F5: Перечень пунктов из формы ТКП входящих в этап | G5: Стоимость, руб. без НДС
D6: Перечень пунктов из | E6: Перечень пунктов из | F6: Перечень пунктов из
A7: 1 | B7: Стадия ТЭО (ТЭО_ФО+ЛС+ССР) | G7: =SUM(G8:H22) -> 0
A8: 1.1 | B8: ='ТЭО_ФО+ЛС+ССР'!B67 -> Инженерные Изыскания | C8: Отчеты | F8: 2.1 - 2.9 | G8: ='ТЭО_ФО+ЛС+ССР'!C67 -> 0
A9: =A8+0.1 -> 1.2 | B9: ='ТЭО_ФО+ЛС+ССР'!B131 -> Сбор исходных данных | C9: Отчеты | F9: 3.1 - 3.2 | G9: ='ТЭО_ФО+ЛС+ССР'!C131 -> 0
A10: =A9+0.1 -> 1.3 | B10: ='ТЭО_ФО+ЛС+ССР'!B153 -> Обследование существующих строительных конструкций, трубопроводов, оборудования | C10: Отчеты | F10: 4.1 - 4.2 | G10: ='ТЭО_ФО+ЛС+ССР'!C153 -> 0
A11: =A10+0.1 -> 1.4 | B11: ='ТЭО_ФО+ЛС+ССР'!B168 -> Проектное технологическое обследование объекта | C11: Отчеты | F11: 5.1 - 5.2 | G11: ='ТЭО_ФО+ЛС+ССР'!C168 -> 0
A12: =A11+0.1 -> 1.5 | B12: ='ТЭО_ФО+ЛС+ССР'!B183 -> Разработка разделов ТЭО | C12: Документация | F12: 6.1 - 6.35 | G12: ='ТЭО_ФО+ЛС+ССР'!C183 -> 0
A13: =A12+0.1 -> 1.6 | B13: ='ТЭО_ФО+ЛС+ССР'!B429 -> Сессии VE (Value Engineering) | C13: Отчеты | F13: 7.1. - 7.2 | G13: ='ТЭО_ФО+ЛС+ССР'!C429 -> 0
A14: =A13+0.1 -> 1.7 | B14: ='ТЭО_ФО+ЛС+ССР'!B444 -> 3D модель | C14: Модель | F14: 8.1. | G14: ='ТЭО_ФО+ЛС+ССР'!C444 -> 0
A15: =A14+0.1 -> 1.8 | B15: ='ТЭО_ФО+ЛС+ССР'!B452 -> Смежные работы (при необходимости) | C15: Отчеты | F15: 9.1. - 9.26 | G15: ='ТЭО_ФО+ЛС+ССР'!C452 -> 0
A16: =A15+0.1 -> 1.9 | B16: ='ТЭО_ФО+ЛС+ССР'!B635 -> Электронный документооборот | C16: Акт | F16: 10.1. | G16: ='ТЭО_ФО+ЛС+ССР'!C635 -> 0
A17: =A16+0.1 -> 2 | B17: ='ТЭО_ФО+ЛС+ССР'!B643 -> Отчетная документация по проекту | C17: Отчеты | F17: 11.1. | G17: ='ТЭО_ФО+ЛС+ССР'!C643 -> 0
A18: =A17+0.1 -> 2.1 | B18: ='ТЭО_ФО+ЛС+ССР'!B651 -> Согласование с собственниками существующих сооружений пересечение с проектируемыми сооружениями | C18: Утвержд. Согласования | F18: 12.1. | G18: ='ТЭО_ФО+ЛС+ССР'!C651 -> 0
A19: =A18+0.1 -> 2.2 | B19: ='ТЭО_ФО+ЛС+ССР'!B659 -> Расчет зон поражения аварийных химически опасных веществ | C19: Расчеты | F19: 13.1. | G19: ='ТЭО_ФО+ЛС+ССР'!C659 -> 0
A20: =A19+0.1 -> 2.3 | B20: ='ТЭО_ФО+ЛС+ССР'!B667 -> Разработка СТУ | C20: Сметы | F20: 14.1. - 14.2 | G20: ='ТЭО_ФО+ЛС+ССР'!C667 -> 0
A21: =A20+0.1 -> 2.4 | B21: ='ТЭО_ФО+ЛС+ССР'!B682 -> Выполнение работ связанных с земельным участком под строительство | C21: Сметы | F21: 15.1. - 15.2. | G21: ='ТЭО_ФО+ЛС+ССР'!C682 -> 0
A22: =A21+0.1 -> 2.5 | B22: ='ТЭО_ФО+ЛС+ССР'!B10 -> Смета на строительство объектов капитального строительства | C22: Сметы | F22: 1.1. - 1.8 | G22: ='ТЭО_ФО+ЛС+ССР'!C10 -> 0
A24: 2 | B24: Стадия ОТР (ОТР_BOQ) | G24: =SUM(G25:H31) -> 0
A25: =A24+0.1 -> 2.1 | B25: ='ОТР_BOQ '!B67 -> Документация ОТР | C25: Документация | F25: 2.1 - 2.17 | G25: ='ОТР_BOQ '!C67 -> 0
A26: =A25+0.1 -> 2.2 | B26: ='ОТР_BOQ '!B187 -> Сбор исходных данных. | C26: Отчеты | F26: 3.1 - 3.2 | G26: ='ОТР_BOQ '!C187 -> 0
A27: =A26+0.1 -> 2.3 | B27: ='ОТР_BOQ '!B202 -> Проектное технологическое обследование объекта | C27: Отчеты | F27: 4.1 - 4.2 | G27: ='ОТР_BOQ '!C202 -> 0
A28: =A27+0.1 -> 2.4 | B28: ='ОТР_BOQ '!B217 -> Сессии VE (Value Engineering) | C28: Отчеты | F28: 5.1 - 5.2 | G28: ='ОТР_BOQ '!C217 -> 0
A29: =A28+0.1 -> 2.5 | B29: ='ОТР_BOQ '!B232 -> Смежные работы (при необходимости) | C29: Документация | F29: 6.1 - 6.8 | G29: ='ОТР_BOQ '!C232 -> 0
A30: =A29+0.1 -> 2.6 | B30: ='ОТР_BOQ '!B289 -> Отчетная документация по проекту | C30: Отчеты | F30: 7.1. | G30: ='ОТР_BOQ '!C289 -> 0
A31: =A30+0.1 -> 2.7 | B31: ='ОТР_BOQ '!B10 -> Смета на строительство объектов капитального строительства | C31: Сметы | F31: 1.1. - 1.8 | G31: ='ОТР_BOQ '!C10 -> 0
A33: 3 | B33: Стадия FEED (FEED_BOQ тит1) | G33: =SUM(G34:H36) -> 0
A34: =A33+0.1 -> 3.1 | B34: ='FEED_BOQ тит1'!B60 -> FEED (все разделы) | C34: Документация | F34: 2.1 - 2.22 | G34: ='FEED_BOQ тит1'!C60 -> 0
A35: =A34+0.1 -> 3.2 | B35: ='FEED_BOQ тит1'!B258 -> Смежные работы (при необходимости) | C35: Отчеты | F35: 3.1 - 3.50 | G35: ='FEED_BOQ тит1'!C258 -> 0
A36: =A35+0.1 -> 3.3 | B36: ='FEED_BOQ тит1'!B10 -> Смета на строительство объектов капитального строительства | C36: Отчеты | F36: 1.1 - 1.7 | G36: ='FEED_BOQ тит1'!C10 -> 0
A38: 4 | B38: Стадия FEED (FEED_BOQ тит2) | G38: =SUM(G39:H41) -> 0
A39: =A38+0.1 -> 4.1 | B39: ='FEED_BOQ тит2'!B60 -> FEED (все разделы) | C39: Документация | F39: 2.1 - 2.22 | G39: ='FEED_BOQ тит2'!C60 -> 0
A40: =A39+0.1 -> 4.2 | B40: ='FEED_BOQ тит2'!B258 -> Смежные работы (при необходимости) | C40: Отчеты | F40: 3.1 - 3.50 | G40: ='FEED_BOQ тит2'!C258 -> 0
A41: =A40+0.1 -> 4.3 | B41: ='FEED_BOQ тит2'!B10 -> Смета на строительство объектов капитального строительства | C41: Отчеты | F41: 1.1 - 1.7 | G41: ='FEED_BOQ тит2'!C10 -> 0
A43: 5 | B43: Стадия ПД (ПД_BOQ тит1) | G43: =SUM(G44:H46) -> 0
A44: =A43+0.1 -> 5.1 | B44: ='ПД_BOQ тит1.'!B60 -> Проектная документация (все разделы) | C44: Документация | F44: 2.1 - 2.23 | G44: ='ПД_BOQ тит1.'!C60 -> 0
A45: =A44+0.1 -> 5.2 | B45: ='ПД_BOQ тит1.'!B272 -> Смежные работы (при необходимости) | C45: Отчеты | F45: 3.1 - 3.64 | G45: ='ПД_BOQ тит1.'!C272 -> 0
A46: =A45+0.1 -> 5.3 | B46: ='ПД_BOQ тит1.'!B10 -> Смета на строительство объектов капитального строительства | C46: Отчеты | F46: 1.1 - 1.7 | G46: ='ПД_BOQ тит1.'!C10 -> 0
...

Sheet СВОД
C1: Форма для заполнения по тендерной процедуре №…….
A3: Разработка ТЭО, ОТР, FEED, проектной и рабочей документации объекта "Выполнение проектно-изыскательских работ по проектам "Техническое перевооружение сети водопроводов, трубопроводов пенного пожаротушения ООО "Томскнефтехим" »
A5: № п/п | B5: Наименование показателей | C5: Стоимость, руб. без НДС
A7: 1 | B7: Итого стоимость предложения на ТЭО | C7: ='ТЭО_ФО+ЛС+ССР'!C697 -> 0
A8: =A7+1 -> 2 | B8: Итого стоимость предложения на ОТР | C8: ='ОТР_BOQ '!C298 -> 0
A9: =A8+1 -> 3 | B9: Итого стоимость предложения на FEED. титул1 | C9: ='FEED_BOQ тит1'!C618 -> 0
A10: =A9+1 -> 4 | B10: Итого стоимость предложения на FEED. Титул2 | C10: ='FEED_BOQ тит2'!C618 -> 0
A11: =A10+1 -> 5 | B11: Итого стоимость предложения на ПД. титул1 | C11: ='ПД_BOQ тит1.'!C746 -> 0
A12: =A11+1 -> 6 | B12: Итого стоимость предложения на ПД. титул2 | C12: ='ПД_BOQ тит2'!C746 -> 0
A13: =A12+1 -> 7 | B13: Итого стоимость предложения на РД. Титул1 | C13: ='РД_BOQ тит.1'!C1609 -> 0
A14: =A13+1 -> 8 | B14: Итого стоимость предложения на РД. Титул2 | C14: ='РД_BOQ тит.2'!C1609 -> 0
B15: Итого стоимость предложения | C15: =SUM(C7:D14) -> 0
B18: Наименование организации
B20: Должность подписавшего
B21: Фамилия, Имя, Отчество подписавшего
B22: Дата: | D22: ( подпись, M.П.)

Sheet ТЭО_ФО+ЛС+ССР
C1: Форма для заполнения по тендерной процедуре №ТП.....
A2: Разработка ТЭО по объекту "Выполнение проектно-изыскательских работ по проектам "Техническое перевооружение сети водопроводов, трубопроводов пенного пожаротушения ООО "Томскнефтехим" »
C4: (заполняется участником)
A5: № п/п | B5: Наименование показателей | C5: Стоимость, руб. без НДС | D5: Трудозатраты чел.час | E5: Трудозатраты чел.дни | F5: Наименование подрядчика | G5: Обоснование расчета*
G7: Должность | H7: Оценка количества листов документации | J7: чел. | K7: Дней | L7: Часов | M7: Ст-ть чел. часа (руб.) без НДС | N7: Итого Ст-ть (руб.) без НДС | O7: Итого кол. чел.час
H8: (текст.) ф.А4 | I8: (граф.) ф.А1
A9: Соответствие техническому заданию стадии ТЭО
A10: 1. | B10: Смета на строительство объектов капитального строительства | C10: =SUM(C11:C66) -> 0 | D10: =SUM(D12:D66) -> 0 | E10: =SUM(E12:E66) -> 0
A11: 1.1. | B11: Провести мониторинг рынка для определения стоимости ценообразующих материалов | C11: =SUM(N11:N17) -> 0 | D11: =SUM(O11:O17) -> 0 | E11: =D11/8 -> 0 | G11: ГИП | N11: =M11*J11*K11*L11 -> 0 | O11: =J11*K11*L11 -> 0
G12: Нач. отдела | N12: =M12*J12*K12*L12 -> 0 | O12: =J12*K12*L12 -> 0
G13: Гл. специалист | N13: =M13*J13*K13*L13 -> 0 | O13: =J13*K13*L13 -> 0
G14: Рук. Группы | N14: =M14*J14*K14*L14 -> 0 | O14: =J14*K14*L14 -> 0
G15: Вед. инженер | N15: =M15*J15*K15*L15 -> 0 | O15: =J15*K15*L15 -> 0
G16: Старший инженер | N16: =M16*J16*K16*L16 -> 0 | O16: =J16*K16*L16 -> 0
G17: Инженер | N17: =M17*J17*K17*L17 -> 0 | O17: =J17*K17*L17 -> 0
A18: 1.2. | B18: Предоставить ведомости объемов работ в формате BOQ (Описание выполняемых работ/объемы) (с точностью +50% минус 30%) | C18: =SUM(N18:N24) -> 0 | D18: =SUM(O18:O24) -> 0 | E18: =D18/8 -> 0 | G18: ГИП | N18: =M18*J18*K18*L18 -> 0 | O18: =J18*K18*L18 -> 0
G19: Нач. отдела | N19: =M19*J19*K19*L19 -> 0 | O19: =J19*K19*L19 -> 0
G20: Гл. специалист | N20: =M20*J20*K20*L20 -> 0 | O20: =J20*K20*L20 -> 0
G21: Рук. Группы | N21: =M21*J21*K21*L21 -> 0 | O21: =J21*K21*L21 -> 0
G22: Вед. инженер | N22: =M22*J22*K22*L22 -> 0 | O22: =J22*K22*L22 -> 0
G23: Старший инженер | N23: =M23*J23*K23*L23 -> 0 | O23: =J23*K23*L23 -> 0
G24: Инженер | N24: =M24*J24*K24*L24 -> 0 | O24: =J24*K24*L24 -> 0
A25: 1.3. | B25: Предоставить таблицу физических объемов сводную / по титульно (с точностью +50% минус 30%) | C25: =SUM(N25:N31) -> 0 | D25: =SUM(O25:O31) -> 0 | E25: =D25/8 -> 0 | G25: ГИП | N25: =M25*J25*K25*L25 -> 0 | O25: =J25*K25*L25 -> 0
G26: Нач. отдела | N26: =M26*J26*K26*L26 -> 0 | O26: =J26*K26*L26 -> 0
G27: Гл. специалист | N27: =M27*J27*K27*L27 -> 0 | O27: =J27*K27*L27 -> 0
G28: Рук. Группы | N28: =M28*J28*K28*L28 -> 0 | O28: =J28*K28*L28 -> 0
G29: Вед. инженер | N29: =M29*J29*K29*L29 -> 0 | O29: =J29*K29*L29 -> 0
G30: Старший инженер | N30: =M30*J30*K30*L30 -> 0 | O30: =J30*K30*L30 -> 0
G31: Инженер | N31: =M31*J31*K31*L31 -> 0 | O31: =J31*K31*L31 -> 0
A32: 1.4. | B32: Предоставить ведомости материалов с построчной стоимостью ресурсов (BOM) (с точностью +50% минус 30%) | C32: =SUM(N32:N38) -> 0 | D32: =SUM(O32:O38) -> 0 | E32: =D32/8 -> 0 | G32: ГИП | N32: =M32*J32*K32*L32 -> 0 | O32: =J32*K32*L32 -> 0
G33: Нач. отдела | N33: =M33*J33*K33*L33 -> 0 | O33: =J33*K33*L33 -> 0
G34: Гл. специалист | N34: =M34*J34*K34*L34 -> 0 | O34: =J34*K34*L34 -> 0
G35: Рук. Группы | N35: =M35*J35*K35*L35 -> 0 | O35: =J35*K35*L35 -> 0
G36: Вед. инженер | N36: =M36*J36*K36*L36 -> 0 | O36: =J36*K36*L36 -> 0
G37: Старший инженер | N37: =M37*J37*K37*L37 -> 0 | O37: =J37*K37*L37 -> 0
G38: Инженер | N38: =M38*J38*K38*L38 -> 0 | O38: =J38*K38*L38 -> 0
A39: 1.5. | B39: Предоставить ведомости оборудования с построчной стоимостью ресурсов (BOE) (с точностью +50% минус 30%) | C39: =SUM(N39:N45) -> 0 | D39: =SUM(O39:O45) -> 0 | E39: =D39/8 -> 0 | G39: ГИП | N39: =M39*J39*K39*L39 -> 0 | O39: =J39*K39*L39 -> 0
G40: Нач. отдела | N40: =M40*J40*K40*L40 -> 0 | O40: =J40*K40*L40 -> 0
G41: Гл. специалист | N41: =M41*J41*K41*L41 -> 0 | O41: =J41*K41*L41 -> 0
G42: Рук. Группы | N42: =M42*J42*K42*L42 -> 0 | O42: =J42*K42*L42 -> 0
...

Sheet ОТР_BOQ 
C1: Форма для заполнения по тендерной процедуре №ТП.....
A2: Разработка ОТР (Основные технические решения) по объекту "Выполнение проектно-изыскательских работ по проектам "Техническое перевооружение сети водопроводов, трубопроводов пенного пожаротушения ООО "Томскнефтехим" »
C4: (заполняется участником)
A5: № п/п | B5: Наименование показателей | C5: Стоимость, руб. без НДС | D5: Трудозатраты чел.час | E5: Трудозатраты чел.дни | F5: Наименование подрядчика | G5: Обоснование расчета*
G7: Должность | H7: Оценка количества листов документации | J7: чел. | K7: Дней | L7: Часов | M7: Ст-ть чел. часа (руб.) без НДС | N7: Итого Ст-ть (руб.) без НДС | O7: Итого кол. чел.час
H8: (текст.) ф.А4 | I8: (граф.) ф.А1
A9: Соответствие техническому заданию стадии ПД
A10: 1. | B10: Смета на строительство объектов капитального строительства | C10: =SUM(C11:C66) -> 0 | D10: =SUM(D11:D66) -> 0 | E10: =SUM(E11:E66) -> 0
A11: 1.1. | B11: Выполнить мониторинг рынка поставщиков и предоставить данные с учетом доставки до г. ……….: - по основным (ценообразующим) материалам - по вспомогательному оборудованию | C11: =SUM(N11:N17) -> 0 | D11: =SUM(O11:O17) -> 0 | E11: =D11/8 -> 0 | G11: ГИП | N11: =M11*J11*K11*L11 -> 0 | O11: =J11*K11*L11 -> 0
G12: Нач. отдела | N12: =M12*J12*K12*L12 -> 0 | O12: =J12*K12*L12 -> 0
G13: Гл. специалист | N13: =M13*J13*K13*L13 -> 0 | O13: =J13*K13*L13 -> 0
G14: Рук. Группы | N14: =M14*J14*K14*L14 -> 0 | O14: =J14*K14*L14 -> 0
G15: Вед. инженер | N15: =M15*J15*K15*L15 -> 0 | O15: =J15*K15*L15 -> 0
G16: Старший инженер | N16: =M16*J16*K16*L16 -> 0 | O16: =J16*K16*L16 -> 0
G17: Инженер | N17: =M17*J17*K17*L17 -> 0 | O17: =J17*K17*L17 -> 0
A18: 1.2. | B18: Предоставить ведомости объемов работ в формате BOQ (Описание выполняемых работ/объемы) точность +50% минус 30% | C18: =SUM(N18:N24) -> 0 | D18: =SUM(O18:O24) -> 0 | E18: =D18/8 -> 0 | G18: ГИП | N18: =M18*J18*K18*L18 -> 0 | O18: =J18*K18*L18 -> 0
G19: Нач. отдела | N19: =M19*J19*K19*L19 -> 0 | O19: =J19*K19*L19 -> 0
G20: Гл. специалист | N20: =M20*J20*K20*L20 -> 0 | O20: =J20*K20*L20 -> 0
G21: Рук. Группы | N21: =M21*J21*K21*L21 -> 0 | O21: =J21*K21*L21 -> 0
G22: Вед. инженер | N22: =M22*J22*K22*L22 -> 0 | O22: =J22*K22*L22 -> 0
G23: Старший инженер | N23: =M23*J23*K23*L23 -> 0 | O23: =J23*K23*L23 -> 0
G24: Инженер | N24: =M24*J24*K24*L24 -> 0 | O24: =J24*K24*L24 -> 0
A25: 1.3. | B25: Предоставить таблицу физических объемов сводную / по титульно точность +50% минус 30% | C25: =SUM(N25:N31) -> 0 | D25: =SUM(O25:O31) -> 0 | E25: =D25/8 -> 0 | G25: ГИП | N25: =M25*J25*K25*L25 -> 0 | O25: =J25*K25*L25 -> 0
G26: Нач. отдела | N26: =M26*J26*K26*L26 -> 0 | O26: =J26*K26*L26 -> 0
G27: Гл. специалист | N27: =M27*J27*K27*L27 -> 0 | O27: =J27*K27*L27 -> 0
G28: Рук. Группы | N28: =M28*J28*K28*L28 -> 0 | O28: =J28*K28*L28 -> 0
G29: Вед. инженер | N29: =M29*J29*K29*L29 -> 0 | O29: =J29*K29*L29 -> 0
G30: Старший инженер | N30: =M30*J30*K30*L30 -> 0 | O30: =J30*K30*L30 -> 0
G31: Инженер | N31: =M31*J31*K31*L31 -> 0 | O31: =J31*K31*L31 -> 0
A32: 1.4. | B32: Предоставить ведомости материалов с построчной стоимостью ресурсов (BOM) точность +50% минус 30% | C32: =SUM(N32:N38) -> 0 | D32: =SUM(O32:O38) -> 0 | E32: =D32/8 -> 0 | G32: ГИП | N32: =M32*J32*K32*L32 -> 0 | O32: =J32*K32*L32 -> 0
G33: Нач. отдела | N33: =M33*J33*K33*L33 -> 0 | O33: =J33*K33*L33 -> 0
G34: Гл. специалист | N34: =M34*J34*K34*L34 -> 0 | O34: =J34*K34*L34 -> 0
G35: Рук. Группы | N35: =M35*J35*K35*L35 -> 0 | O35: =J35*K35*L35 -> 0
G36: Вед. инженер | N36: =M36*J36*K36*L36 -> 0 | O36: =J36*K36*L36 -> 0
G37: Старший инженер | N37: =M37*J37*K37*L37 -> 0 | O37: =J37*K37*L37 -> 0
G38: Инженер | N38: =M38*J38*K38*L38 -> 0 | O38: =J38*K38*L38 -> 0
A39: 1.5. | B39: Предоставить ведомости оборудования с построчной стоимостью ресурсов (BOE) точность +50% минус 30% | C39: =SUM(N39:N45) -> 0 | D39: =SUM(O39:O45) -> 0 | E39: =D39/8 -> 0 | G39: ГИП | N39: =M39*J39*K39*L39 -> 0 | O39: =J39*K39*L39 -> 0
G40: Нач. отдела | N40: =M40*J40*K40*L40 -> 0 | O40: =J40*K40*L40 -> 0
G41: Гл. специалист | N41: =M41*J41*K41*L41 -> 0 | O41: =J41*K41*L41 -> 0
G42: Рук. Группы | N42: =M42*J42*K42*L42 -> 0 | O42: =J42*K42*L42 -> 0
...

Sheet FEED_BOQ тит1
C1: Форма для заполнения по тендерной процедуре №ТП.....
A2: Разработка FEED по объекту "Выполнение проектно-изыскательских работ по проектам "Техническое перевооружение сети водопроводов, трубопроводов пенного пожаротушения ООО "Томскнефтехим" »
C4: (заполняется участником)
A5: № п/п | B5: Наименование показателей | C5: Стоимость, руб. без НДС | D5: Трудозатраты чел.час | E5: Трудозатраты чел.день | F5: Наименование подрядчика | G5: Обоснование расчета*
G7: Должность | H7: Оценка количества листов документации | J7: чел. | K7: Дней | L7: Часов | M7: Ст-ть чел. часа (руб.) без НДС | N7: Итого Ст-ть (руб.) без НДС | O7: Итого кол. чел.часов
H8: (текст.) ф.А4 | I8: (граф.) ф.А1
A9: Соответствие техническому заданию стадии ПД
A10: 1. | B10: Смета на строительство объектов капитального строительства | C10: =SUM(C11:C59) -> 0 | D10: =SUM(D11:D59) -> 0 | E10: =SUM(E11:E59) -> 0 | O10: =SUM(O11:O59) -> 0
A11: 1.1. | B11: Выполнить мониторинг рынка поставщиков и предоставить данные с учетом доставки до г. ……….: - по основным (ценообразующим) материалам - по вспомогательному оборудованию | C11: =SUM(N11:N17) -> 0 | D11: =SUM(O11:O17) -> 0 | E11: =D11/8 -> 0 | G11: ГИП | N11: =M11*J11*K11*L11 -> 0 | O11: =J11*K11*L11 -> 0
G12: Нач. отдела | N12: =M12*J12*K12*L12 -> 0 | O12: =J12*K12*L12 -> 0
G13: Гл. специалист | N13: =M13*J13*K13*L13 -> 0 | O13: =J13*K13*L13 -> 0
G14: Рук. Группы | N14: =M14*J14*K14*L14 -> 0 | O14: =J14*K14*L14 -> 0
G15: Вед. инженер | N15: =M15*J15*K15*L15 -> 0 | O15: =J15*K15*L15 -> 0
G16: Старший инженер | N16: =M16*J16*K16*L16 -> 0 | O16: =J16*K16*L16 -> 0
G17: Инженер | N17: =M17*J17*K17*L17 -> 0 | O17: =J17*K17*L17 -> 0
A18: 1.2. | B18: Предоставить ведомости объемов работ в формате BOQ | C18: =SUM(N18:N24) -> 0 | D18: =SUM(O18:O24) -> 0 | E18: =D18/8 -> 0 | G18: ГИП | N18: =M18*J18*K18*L18 -> 0 | O18: =J18*K18*L18 -> 0
G19: Нач. отдела | N19: =M19*J19*K19*L19 -> 0 | O19: =J19*K19*L19 -> 0
G20: Гл. специалист | N20: =M20*J20*K20*L20 -> 0 | O20: =J20*K20*L20 -> 0
G21: Рук. Группы | N21: =M21*J21*K21*L21 -> 0 | O21: =J21*K21*L21 -> 0
G22: Вед. инженер | N22: =M22*J22*K22*L22 -> 0 | O22: =J22*K22*L22 -> 0
G23: Старший инженер | N23: =M23*J23*K23*L23 -> 0 | O23: =J23*K23*L23 -> 0
G24: Инженер | N24: =M24*J24*K24*L24 -> 0 | O24: =J24*K24*L24 -> 0
A25: 1.3. | B25: Предоставить таблицу физических объемов сводную / по титульно | C25: =SUM(N25:N31) -> 0 | D25: =SUM(O25:O31) -> 0 | E25: =D25/8 -> 0 | G25: ГИП | N25: =M25*J25*K25*L25 -> 0 | O25: =J25*K25*L25 -> 0
G26: Нач. отдела | N26: =M26*J26*K26*L26 -> 0 | O26: =J26*K26*L26 -> 0
G27: Гл. специалист | N27: =M27*J27*K27*L27 -> 0 | O27: =J27*K27*L27 -> 0
G28: Рук. Группы | N28: =M28*J28*K28*L28 -> 0 | O28: =J28*K28*L28 -> 0
G29: Вед. инженер | N29: =M29*J29*K29*L29 -> 0 | O29: =J29*K29*L29 -> 0
G30: Старший инженер | N30: =M30*J30*K30*L30 -> 0 | O30: =J30*K30*L30 -> 0
G31: Инженер | N31: =M31*J31*K31*L31 -> 0 | O31: =J31*K31*L31 -> 0
A32: 1.4. | B32: Предоставить ведомости материалов с построчной стоимостью ресурсов (BOM) | C32: =SUM(N32:N38) -> 0 | D32: =SUM(O32:O38) -> 0 | E32: =D32/8 -> 0 | G32: ГИП | N32: =M32*J32*K32*L32 -> 0 | O32: =J32*K32*L32 -> 0
G33: Нач. отдела | N33: =M33*J33*K33*L33 -> 0 | O33: =J33*K33*L33 -> 0
G34: Гл. специалист | N34: =M34*J34*K34*L34 -> 0 | O34: =J34*K34*L34 -> 0
G35: Рук. Группы | N35: =M35*J35*K35*L35 -> 0 | O35: =J35*K35*L35 -> 0
G36: Вед. инженер | N36: =M36*J36*K36*L36 -> 0 | O36: =J36*K36*L36 -> 0
G37: Старший инженер | N37: =M37*J37*K37*L37 -> 0 | O37: =J37*K37*L37 -> 0
G38: Инженер | N38: =M38*J38*K38*L38 -> 0 | O38: =J38*K38*L38 -> 0
A39: 1.5. | B39: Предоставить ведомости оборудования с построчной стоимостью ресурсов (BOE) | C39: =SUM(N39:N45) -> 0 | D39: =SUM(O39:O45) -> 0 | E39: =D39/8 -> 0 | G39: ГИП | N39: =M39*J39*K39*L39 -> 0 | O39: =J39*K39*L39 -> 0
G40: Нач. отдела | N40: =M40*J40*K40*L40 -> 0 | O40: =J40*K40*L40 -> 0
G41: Гл. специалист | N41: =M41*J41*K41*L41 -> 0 | O41: =J41*K41*L41 -> 0
G42: Рук. Группы | N42: =M42*J42*K42*L42 -> 0 | O42: =J42*K42*L42 -> 0
...

Sheet FEED_BOQ тит2
C1: Форма для заполнения по тендерной процедуре №ТП.....
A2: Разработка FEED по объекту "Выполнение проектно-изыскательских работ по проектам "Техническое перевооружение сети водопроводов, трубопроводов пенного пожаротушения ООО "Томскнефтехим" .»
C4: (заполняется участником)
A5: № п/п | B5: Наименование показателей | C5: Стоимость, руб. без НДС | D5: Трудозатраты чел.час | E5: Трудозатраты чел.день | F5: Наименование подрядчика | G5: Обоснование расчета*
G7: Должность | H7: Оценка количества листов документации | J7: чел. | K7: Дней | L7: Часов | M7: Ст-ть чел. часа (руб.) без НДС | N7: Итого Ст-ть (руб.) без НДС | O7: Итого кол. чел.часов
H8: (текст.) ф.А4 | I8: (граф.) ф.А1
A9: Соответствие техническому заданию стадии ПД
A10: 1. | B10: Смета на строительство объектов капитального строительства | C10: =SUM(C11:C59) -> 0 | D10: =SUM(D11:D59) -> 0 | E10: =SUM(E11:E59) -> 0 | O10: =SUM(O11:O59) -> 0
A11: 1.1. | B11: Выполнить мониторинг рынка поставщиков и предоставить данные с учетом доставки до г. ……….: - по основным (ценообразующим) материалам - по вспомогательному оборудованию | C11: =SUM(N11:N17) -> 0 | D11: =SUM(O11:O17) -> 0 | E11: =D11/8 -> 0 | G11: ГИП | N11: =M11*J11*K11*L11 -> 0 | O11: =J11*K11*L11 -> 0
G12: Нач. отдела | N12: =M12*J12*K12*L12 -> 0 | O12: =J12*K12*L12 -> 0
G13: Гл. специалист | N13: =M13*J13*K13*L13 -> 0 | O13: =J13*K13*L13 -> 0
G14: Рук. Группы | N14: =M14*J14*K14*L14 -> 0 | O14: =J14*K14*L14 -> 0
G15: Вед. инженер | N15: =M15*J15*K15*L15 -> 0 | O15: =J15*K15*L15 -> 0
G16: Старший инженер | N16: =M16*J16*K16*L16 -> 0 | O16: =J16*K16*L16 -> 0
G17: Инженер | N17: =M17*J17*K17*L17 -> 0 | O17: =J17*K17*L17 -> 0
A18: 1.2. | B18: Предоставить ведомости объемов работ в формате BOQ | C18: =SUM(N18:N24) -> 0 | D18: =SUM(O18:O24) -> 0 | E18: =D18/8 -> 0 | G18: ГИП | N18: =M18*J18*K18*L18 -> 0 | O18: =J18*K18*L18 -> 0
G19: Нач. отдела | N19: =M19*J19*K19*L19 -> 0 | O19: =J19*K19*L19 -> 0
G20: Гл. специалист | N20: =M20*J20*K20*L20 -> 0 | O20: =J20*K20*L20 -> 0
G21: Рук. Группы | N21: =M21*J21*K21*L21 -> 0 | O21: =J21*K21*L21 -> 0
G22: Вед. инженер | N22: =M22*J22*K22*L22 -> 0 | O22: =J22*K22*L22 -> 0
G23: Старший инженер | N23: =M23*J23*K23*L23 -> 0 | O23: =J23*K23*L23 -> 0
G24: Инженер | N24: =M24*J24*K24*L24 -> 0 | O24: =J24*K24*L24 -> 0
A25: 1.3. | B25: Предоставить таблицу физических объемов сводную / по титульно | C25: =SUM(N25:N31) -> 0 | D25: =SUM(O25:O31) -> 0 | E25: =D25/8 -> 0 | G25: ГИП | N25: =M25*J25*K25*L25 -> 0 | O25: =J25*K25*L25 -> 0
G26: Нач. отдела | N26: =M26*J26*K26*L26 -> 0 | O26: =J26*K26*L26 -> 0
G27: Гл. специалист | N27: =M27*J27*K27*L27 -> 0 | O27: =J27*K27*L27 -> 0
G28: Рук. Группы | N28: =M28*J28*K28*L28 -> 0 | O28: =J28*K28*L28 -> 0
G29: Вед. инженер | N29: =M29*J29*K29*L29 -> 0 | O29: =J29*K29*L29 -> 0
G30: Старший инженер | N30: =M30*J30*K30*L30 -> 0 | O30: =J30*K30*L30 -> 0
G31: Инженер | N31: =M31*J31*K31*L31 -> 0 | O31: =J31*K31*L31 -> 0
A32: 1.4. | B32: Предоставить ведомости материалов с построчной стоимостью ресурсов (BOM) | C32: =SUM(N32:N38) -> 0 | D32: =SUM(O32:O38) -> 0 | E32: =D32/8 -> 0 | G32: ГИП | N32: =M32*J32*K32*L32 -> 0 | O32: =J32*K32*L32 -> 0
G33: Нач. отдела | N33: =M33*J33*K33*L33 -> 0 | O33: =J33*K33*L33 -> 0
G34: Гл. специалист | N34: =M34*J34*K34*L34 -> 0 | O34: =J34*K34*L34 -> 0
G35: Рук. Группы | N35: =M35*J35*K35*L35 -> 0 | O35: =J35*K35*L35 -> 0
G36: Вед. инженер | N36: =M36*J36*K36*L36 -> 0 | O36: =J36*K36*L36 -> 0
G37: Старший инженер | N37: =M37*J37*K37*L37 -> 0 | O37: =J37*K37*L37 -> 0
G38: Инженер | N38: =M38*J38*K38*L38 -> 0 | O38: =J38*K38*L38 -> 0
A39: 1.5. | B39: Предоставить ведомости оборудования с построчной стоимостью ресурсов (BOE) | C39: =SUM(N39:N45) -> 0 | D39: =SUM(O39:O45) -> 0 | E39: =D39/8 -> 0 | G39: ГИП | N39: =M39*J39*K39*L39 -> 0 | O39: =J39*K39*L39 -> 0
G40: Нач. отдела | N40: =M40*J40*K40*L40 -> 0 | O40: =J40*K40*L40 -> 0
G41: Гл. специалист | N41: =M41*J41*K41*L41 -> 0 | O41: =J41*K41*L41 -> 0
G42: Рук. Группы | N42: =M42*J42*K42*L42 -> 0 | O42: =J42*K42*L42 -> 0
...

Sheet ПД_BOQ тит1.
C1: Форма для заполнения по тендерной процедуре №ТП.....
A2: Разработка проектной документации по объекту "Выполнение проектно-изыскательских работ по проектам "Техническое перевооружение сети водопроводов, трубопроводов пенного пожаротушения ООО "Томскнефтехим" »
C4: (заполняется участником)
A5: № п/п | B5: Наименование показателей | C5: Стоимость, руб. без НДС | D5: Трудозатраты чел.час | E5: Трудозатраты чел.день | F5: Наименование подрядчика | G5: Обоснование расчета*
G7: Должность | H7: Оценка количества листов документации | J7: чел. | K7: Дней | L7: Часов | M7: Ст-ть чел. часа (руб.) без НДС | N7: Итого Ст-ть (руб.) без НДС | O7: Итого кол. чел.часов
H8: (текст.) ф.А4 | I8: (граф.) ф.А1
A9: Соответствие техническому заданию стадии ПД
A10: 1. | B10: Смета на строительство объектов капитального строительства | C10: =SUM(C11:C59) -> 0 | D10: =SUM(D11:D59) -> 0 | E10: =SUM(E11:E59) -> 0 | O10: =SUM(O11:O59) -> 0
A11: 1.1. | B11: Выполнить мониторинг рынка поставщиков и предоставить данные с учетом доставки до г. ……….: - по основным (ценообразующим) материалам - по вспомогательному оборудованию | C11: =SUM(N11:N17) -> 0 | D11: =SUM(O11:O17) -> 0 | E11: =D11/8 -> 0 | G11: ГИП | N11: =M11*J11*K11*L11 -> 0 | O11: =J11*K11*L11 -> 0
G12: Нач. отдела | N12: =M12*J12*K12*L12 -> 0 | O12: =J12*K12*L12 -> 0
G13: Гл. специалист | N13: =M13*J13*K13*L13 -> 0 | O13: =J13*K13*L13 -> 0
G14: Рук. Группы | N14: =M14*J14*K14*L14 -> 0 | O14: =J14*K14*L14 -> 0
G15: Вед. инженер | N15: =M15*J15*K15*L15 -> 0 | O15: =J15*K15*L15 -> 0
G16: Старший инженер | N16: =M16*J16*K16*L16 -> 0 | O16: =J16*K16*L16 -> 0
G17: Инженер | N17: =M17*J17*K17*L17 -> 0 | O17: =J17*K17*L17 -> 0
A18: 1.2. | B18: Предоставить ведомости объемов работ в формате BOQ | C18: =SUM(N18:N24) -> 0 | D18: =SUM(O18:O24) -> 0 | E18: =D18/8 -> 0 | G18: ГИП | N18: =M18*J18*K18*L18 -> 0 | O18: =J18*K18*L18 -> 0
G19: Нач. отдела | N19: =M19*J19*K19*L19 -> 0 | O19: =J19*K19*L19 -> 0
G20: Гл. специалист | N20: =M20*J20*K20*L20 -> 0 | O20: =J20*K20*L20 -> 0
G21: Рук. Группы | N21: =M21*J21*K21*L21 -> 0 | O21: =J21*K21*L21 -> 0
G22: Вед. инженер | N22: =M22*J22*K22*L22 -> 0 | O22: =J22*K22*L22 -> 0
G23: Старший инженер | N23: =M23*J23*K23*L23 -> 0 | O23: =J23*K23*L23 -> 0
G24: Инженер | N24: =M24*J24*K24*L24 -> 0 | O24: =J24*K24*L24 -> 0
A25: 1.3. | B25: Предоставить таблицу физических объемов сводную / по титульно | C25: =SUM(N25:N31) -> 0 | D25: =SUM(O25:O31) -> 0 | E25: =D25/8 -> 0 | G25: ГИП | N25: =M25*J25*K25*L25 -> 0 | O25: =J25*K25*L25 -> 0
G26: Нач. отдела | N26: =M26*J26*K26*L26 -> 0 | O26: =J26*K26*L26 -> 0
G27: Гл. специалист | N27: =M27*J27*K27*L27 -> 0 | O27: =J27*K27*L27 -> 0
G28: Рук. Группы | N28: =M28*J28*K28*L28 -> 0 | O28: =J28*K28*L28 -> 0
G29: Вед. инженер | N29: =M29*J29*K29*L29 -> 0 | O29: =J29*K29*L29 -> 0
G30: Старший инженер | N30: =M30*J30*K30*L30 -> 0 | O30: =J30*K30*L30 -> 0
G31: Инженер | N31: =M31*J31*K31*L31 -> 0 | O31: =J31*K31*L31 -> 0
A32: 1.4. | B32: Предоставить ведомости материалов с построчной стоимостью ресурсов (BOM) | C32: =SUM(N32:N38) -> 0 | D32: =SUM(O32:O38) -> 0 | E32: =D32/8 -> 0 | G32: ГИП | N32: =M32*J32*K32*L32 -> 0 | O32: =J32*K32*L32 -> 0
G33: Нач. отдела | N33: =M33*J33*K33*L33 -> 0 | O33: =J33*K33*L33 -> 0
G34: Гл. специалист | N34: =M34*J34*K34*L34 -> 0 | O34: =J34*K34*L34 -> 0
G35: Рук. Группы | N35: =M35*J35*K35*L35 -> 0 | O35: =J35*K35*L35 -> 0
G36: Вед. инженер | N36: =M36*J36*K36*L36 -> 0 | O36: =J36*K36*L36 -> 0
G37: Старший инженер | N37: =M37*J37*K37*L37 -> 0 | O37: =J37*K37*L37 -> 0
G38: Инженер | N38: =M38*J38*K38*L38 -> 0 | O38: =J38*K38*L38 -> 0
A39: 1.5. | B39: Предоставить ведомости оборудования с построчной стоимостью ресурсов (BOE) | C39: =SUM(N39:N45) -> 0 | D39: =SUM(O39:O45) -> 0 | E39: =D39/8 -> 0 | G39: ГИП | N39: =M39*J39*K39*L39 -> 0 | O39: =J39*K39*L39 -> 0
G40: Нач. отдела | N40: =M40*J40*K40*L40 -> 0 | O40: =J40*K40*L40 -> 0
G41: Гл. специалист | N41: =M41*J41*K41*L41 -> 0 | O41: =J41*K41*L41 -> 0
G42: Рук. Группы | N42: =M42*J42*K42*L42 -> 0 | O42: =J42*K42*L42 -> 0
...

Sheet ПД_BOQ тит2
C1: Форма для заполнения по тендерной процедуре №ТП.....
A2: Разработка проектной документации по объекту "Выполнение проектно-изыскательских работ по проектам "Техническое перевооружение сети водопроводов, трубопроводов пенного пожаротушения ООО "Томскнефтехим" »
C4: (заполняется участником)
A5: № п/п | B5: Наименование показателей | C5: Стоимость, руб. без НДС | D5: Трудозатраты чел.час | E5: Трудозатраты чел.дни | F5: Наименование подрядчика | G5: Обоснование расчета*
G7: Должность | H7: Оценка количества листов документации | J7: чел. | K7: Дней | L7: Часов | M7: Ст-ть чел. часа (руб.) без НДС | N7: Итого Ст-ть (руб.) без НДС | O7: Итого кол. Чел.час
H8: (текст.) ф.А4 | I8: (граф.) ф.А1
A9: Соответствие техническому заданию стадии ПД
A10: 1. | B10: Смета на строительство объектов капитального строительства | C10: =SUM(C11:C59) -> 0 | D10: =SUM(D11:D59) -> 0 | E10: =SUM(E11:E59) -> 0
A11: 1.1. | B11: Выполнить мониторинг рынка поставщиков и предоставить данные с учетом доставки до г. ……….: - по основным (ценообразующим) материалам - по вспомогательному оборудованию | C11: =SUM(N11:N17) -> 0 | D11: =SUM(O11:O17) -> 0 | E11: =D11/8 -> 0 | G11: ГИП | N11: =M11*J11*K11*L11 -> 0 | O11: =J11*K11*L11 -> 0
G12: Нач. отдела | N12: =M12*J12*K12*L12 -> 0 | O12: =J12*K12*L12 -> 0
G13: Гл. специалист | N13: =M13*J13*K13*L13 -> 0 | O13: =J13*K13*L13 -> 0
G14: Рук. Группы | N14: =M14*J14*K14*L14 -> 0 | O14: =J14*K14*L14 -> 0
G15: Вед. инженер | N15: =M15*J15*K15*L15 -> 0 | O15: =J15*K15*L15 -> 0
G16: Старший инженер | N16: =M16*J16*K16*L16 -> 0 | O16: =J16*K16*L16 -> 0
G17: Инженер | N17: =M17*J17*K17*L17 -> 0 | O17: =J17*K17*L17 -> 0
A18: 1.2. | B18: Предоставить ведомости объемов работ в формате BOQ | C18: =SUM(N18:N24) -> 0 | D18: =SUM(O18:O24) -> 0 | E18: =D18/8 -> 0 | G18: ГИП | N18: =M18*J18*K18*L18 -> 0 | O18: =J18*K18*L18 -> 0
G19: Нач. отдела | N19: =M19*J19*K19*L19 -> 0 | O19: =J19*K19*L19 -> 0
G20: Гл. специалист | N20: =M20*J20*K20*L20 -> 0 | O20: =J20*K20*L20 -> 0
G21: Рук. Группы | N21: =M21*J21*K21*L21 -> 0 | O21: =J21*K21*L21 -> 0
G22: Вед. инженер | N22: =M22*J22*K22*L22 -> 0 | O22: =J22*K22*L22 -> 0
G23: Старший инженер | N23: =M23*J23*K23*L23 -> 0 | O23: =J23*K23*L23 -> 0
G24: Инженер | N24: =M24*J24*K24*L24 -> 0 | O24: =J24*K24*L24 -> 0
A25: 1.3. | B25: Предоставить таблицу физических объемов сводную / по титульно | C25: =SUM(N25:N31) -> 0 | D25: =SUM(O25:O31) -> 0 | E25: =D25/8 -> 0 | G25: ГИП | N25: =M25*J25*K25*L25 -> 0 | O25: =J25*K25*L25 -> 0
G26: Нач. отдела | N26: =M26*J26*K26*L26 -> 0 | O26: =J26*K26*L26 -> 0
G27: Гл. специалист | N27: =M27*J27*K27*L27 -> 0 | O27: =J27*K27*L27 -> 0
G28: Рук. Группы | N28: =M28*J28*K28*L28 -> 0 | O28: =J28*K28*L28 -> 0
G29: Вед. инженер | N29: =M29*J29*K29*L29 -> 0 | O29: =J29*K29*L29 -> 0
G30: Старший инженер | N30: =M30*J30*K30*L30 -> 0 | O30: =J30*K30*L30 -> 0
G31: Инженер | N31: =M31*J31*K31*L31 -> 0 | O31: =J31*K31*L31 -> 0
A32: 1.4. | B32: Предоставить ведомости материалов с построчной стоимостью ресурсов (BOM) | C32: =SUM(N32:N38) -> 0 | D32: =SUM(O32:O38) -> 0 | E32: =D32/8 -> 0 | G32: ГИП | N32: =M32*J32*K32*L32 -> 0 | O32: =J32*K32*L32 -> 0
G33: Нач. отдела | N33: =M33*J33*K33*L33 -> 0 | O33: =J33*K33*L33 -> 0
G34: Гл. специалист | N34: =M34*J34*K34*L34 -> 0 | O34: =J34*K34*L34 -> 0
G35: Рук. Группы | N35: =M35*J35*K35*L35 -> 0 | O35: =J35*K35*L35 -> 0
G36: Вед. инженер | N36: =M36*J36*K36*L36 -> 0 | O36: =J36*K36*L36 -> 0
G37: Старший инженер | N37: =M37*J37*K37*L37 -> 0 | O37: =J37*K37*L37 -> 0
G38: Инженер | N38: =M38*J38*K38*L38 -> 0 | O38: =J38*K38*L38 -> 0
A39: 1.5. | B39: Предоставить ведомости оборудования с построчной стоимостью ресурсов (BOE) | C39: =SUM(N39:N45) -> 0 | D39: =SUM(O39:O45) -> 0 | E39: =D39/8 -> 0 | G39: ГИП | N39: =M39*J39*K39*L39 -> 0 | O39: =J39*K39*L39 -> 0
G40: Нач. отдела | N40: =M40*J40*K40*L40 -> 0 | O40: =J40*K40*L40 -> 0
G41: Гл. специалист | N41: =M41*J41*K41*L41 -> 0 | O41: =J41*K41*L41 -> 0
G42: Рук. Группы | N42: =M42*J42*K42*L42 -> 0 | O42: =J42*K42*L42 -> 0
...

Sheet РД_BOQ тит.1
C1: Форма для заполнения по тендерной процедуре №ТП.....
A2: Разработка рабочей документации по объекту "Выполнение проектно-изыскательских работ по проектам "Техническое перевооружение сети водопроводов, трубопроводов пенного пожаротушения ООО "Томскнефтехим" »
C4: (заполняется участником)
A5: № п/п | B5: Наименование показателей | C5: Стоимость, руб. без НДС | D5: Трудозатраты чел.час | E5: Трудозатраты чел.дни | F5: Наименование подрядчика | G5: Обоснование расчета*
G7: Должность | H7: Оценка количества листов документации | J7: чел. | K7: Дней | L7: Дней | M7: Часов | N7: Ст-ть чел. часа (руб.) без НДС | O7: Итого Ст-ть (руб.) без НДС | P7: Итого кол. чел.час
H8: (текст.) ф.А4 | I8: (граф.) ф.А1
A9: Соответствие техническому заданию стадии ПД
A10: 1. | B10: Смета на строительство объектов капитального строительства | C10: =SUM(C11:C73) -> 0 | D10: =SUM(D11:D73) -> 0 | E10: =SUM(E11:E73) -> 0
A11: 1.1. | B11: Выполнить мониторинг рынка поставщиков и предоставить данные с учетом доставки до г. ……….: - по основным (ценообразующим) материалам - по вспомогательному оборудованию | C11: =SUM(O11:O17) -> 0 | D11: =SUM(P11:P17) -> 0 | E11: =D11/8 -> 0 | G11: ГИП | O11: =N11*J11*K11*M11 -> 0 | P11: =J11*K11*M11 -> 0
G12: Нач. отдела | O12: =N12*J12*K12*M12 -> 0 | P12: =J12*K12*M12 -> 0
G13: Гл. специалист | O13: =N13*J13*K13*M13 -> 0 | P13: =J13*K13*M13 -> 0
G14: Рук. Группы | O14: =N14*J14*K14*M14 -> 0 | P14: =J14*K14*M14 -> 0
G15: Вед. инженер | O15: =N15*J15*K15*M15 -> 0 | P15: =J15*K15*M15 -> 0
G16: Старший инженер | O16: =N16*J16*K16*M16 -> 0 | P16: =J16*K16*M16 -> 0
G17: Инженер | O17: =N17*J17*K17*M17 -> 0 | P17: =J17*K17*M17 -> 0
A18: 1.2. | B18: Предоставить ведомости объемов работ в формате BOQ (Описание выполняемых работ/объемы) | C18: =SUM(O18:O24) -> 0 | D18: =SUM(P18:P24) -> 0 | E18: =D18/8 -> 0 | G18: ГИП | O18: =N18*J18*K18*M18 -> 0 | P18: =J18*K18*M18 -> 0
G19: Нач. отдела | O19: =N19*J19*K19*M19 -> 0 | P19: =J19*K19*M19 -> 0
G20: Гл. специалист | O20: =N20*J20*K20*M20 -> 0 | P20: =J20*K20*M20 -> 0
G21: Рук. Группы | O21: =N21*J21*K21*M21 -> 0 | P21: =J21*K21*M21 -> 0
G22: Вед. инженер | O22: =N22*J22*K22*M22 -> 0 | P22: =J22*K22*M22 -> 0
G23: Старший инженер | O23: =N23*J23*K23*M23 -> 0 | P23: =J23*K23*M23 -> 0
G24: Инженер | O24: =N24*J24*K24*M24 -> 0 | P24: =J24*K24*M24 -> 0
A25: 1.3. | B25: Предоставить таблицу физических объемов сводную / по титульно | C25: =SUM(O25:O31) -> 0 | D25: =SUM(P25:P31) -> 0 | E25: =D25/8 -> 0 | G25: ГИП | O25: =N25*J25*K25*M25 -> 0 | P25: =J25*K25*M25 -> 0
G26: Нач. отдела | O26: =N26*J26*K26*M26 -> 0 | P26: =J26*K26*M26 -> 0
G27: Гл. специалист | O27: =N27*J27*K27*M27 -> 0 | P27: =J27*K27*M27 -> 0
G28: Рук. Группы | O28: =N28*J28*K28*M28 -> 0 | P28: =J28*K28*M28 -> 0
G29: Вед. инженер | O29: =N29*J29*K29*M29 -> 0 | P29: =J29*K29*M29 -> 0
G30: Старший инженер | O30: =N30*J30*K30*M30 -> 0 | P30: =J30*K30*M30 -> 0
G31: Инженер | O31: =N31*J31*K31*M31 -> 0 | P31: =J31*K31*M31 -> 0
A32: 1.4. | B32: Предоставить ведомости материалов с построчной стоимостью ресурсов (BOM) | C32: =SUM(O32:O38) -> 0 | D32: =SUM(P32:P38) -> 0 | E32: =D32/8 -> 0 | G32: ГИП | O32: =N32*J32*K32*M32 -> 0 | P32: =J32*K32*M32 -> 0
G33: Нач. отдела | O33: =N33*J33*K33*M33 -> 0 | P33: =J33*K33*M33 -> 0
G34: Гл. специалист | O34: =N34*J34*K34*M34 -> 0 | P34: =J34*K34*M34 -> 0
G35: Рук. Группы | O35: =N35*J35*K35*M35 -> 0 | P35: =J35*K35*M35 -> 0
G36: Вед. инженер | O36: =N36*J36*K36*M36 -> 0 | P36: =J36*K36*M36 -> 0
G37: Старший инженер | O37: =N37*J37*K37*M37 -> 0 | P37: =J37*K37*M37 -> 0
G38: Инженер | O38: =N38*J38*K38*M38 -> 0 | P38: =J38*K38*M38 -> 0
A39: 1.5. | B39: Предоставить ведомости оборудования с построчной стоимостью ресурсов (BOE) | C39: =SUM(O39:O45) -> 0 | D39: =SUM(P39:P45) -> 0 | E39: =D39/8 -> 0 | G39: ГИП | O39: =N39*J39*K39*M39 -> 0 | P39: =J39*K39*M39 -> 0
G40: Нач. отдела | O40: =N40*J40*K40*M40 -> 0 | P40: =J40*K40*M40 -> 0
G41: Гл. специалист | O41: =N41*J41*K41*M41 -> 0 | P41: =J41*K41*M41 -> 0
G42: Рук. Группы | O42: =N42*J42*K42*M42 -> 0 | P42: =J42*K42*M42 -> 0
...

Sheet РД_BOQ тит.2
C1: Форма для заполнения по тендерной процедуре №ТП.....
A2: Разработка рабочей документации по объекту "Выполнение проектно-изыскательских работ по проектам "Техническое перевооружение сети водопроводов, трубопроводов пенного пожаротушения ООО "Томскнефтехим" »
C4: (заполняется участником)
A5: № п/п | B5: Наименование показателей | C5: Стоимость, руб. без НДС | D5: Трудозатраты чел.час | E5: Трудозатраты чел.дни | F5: Наименование подрядчика | G5: Обоснование расчета*
G7: Должность | H7: Оценка количества листов документации | J7: чел. | K7: Дней | L7: Часов | M7: Ст-ть чел. часа (руб.) без НДС | N7: Итого Ст-ть (руб.) без НДС | O7: Итого кол. чел.час
H8: (текст.) ф.А4 | I8: (граф.) ф.А1
A9: Соответствие техническому заданию стадии ПД
A10: 1. | B10: Смета на строительство объектов капитального строительства | C10: =SUM(C11:C73) -> 0 | D10: =SUM(D11:D73) -> 0 | E10: =SUM(E11:E73) -> 0
A11: 1.1. | B11: Выполнить мониторинг рынка поставщиков и предоставить данные с учетом доставки до г. ……….: - по основным (ценообразующим) материалам - по вспомогательному оборудованию | C11: =SUM(N11:N17) -> 0 | D11: =SUM(O11:O17) -> 0 | E11: =D11/8 -> 0 | G11: ГИП | N11: =M11*J11*K11*L11 -> 0 | O11: =J11*K11*L11 -> 0
G12: Нач. отдела | N12: =M12*J12*K12*L12 -> 0 | O12: =J12*K12*L12 -> 0
G13: Гл. специалист | N13: =M13*J13*K13*L13 -> 0 | O13: =J13*K13*L13 -> 0
G14: Рук. Группы | N14: =M14*J14*K14*L14 -> 0 | O14: =J14*K14*L14 -> 0
G15: Вед. инженер | N15: =M15*J15*K15*L15 -> 0 | O15: =J15*K15*L15 -> 0
G16: Старший инженер | N16: =M16*J16*K16*L16 -> 0 | O16: =J16*K16*L16 -> 0
G17: Инженер | N17: =M17*J17*K17*L17 -> 0 | O17: =J17*K17*L17 -> 0
A18: 1.2. | B18: Предоставить ведомости объемов работ в формате BOQ (Описание выполняемых работ/объемы) | C18: =SUM(N18:N24) -> 0 | D18: =SUM(O18:O24) -> 0 | E18: =D18/8 -> 0 | G18: ГИП | N18: =M18*J18*K18*L18 -> 0 | O18: =J18*K18*L18 -> 0
G19: Нач. отдела | N19: =M19*J19*K19*L19 -> 0 | O19: =J19*K19*L19 -> 0
G20: Гл. специалист | N20: =M20*J20*K20*L20 -> 0 | O20: =J20*K20*L20 -> 0
G21: Рук. Группы | N21: =M21*J21*K21*L21 -> 0 | O21: =J21*K21*L21 -> 0
G22: Вед. инженер | N22: =M22*J22*K22*L22 -> 0 | O22: =J22*K22*L22 -> 0
G23: Старший инженер | N23: =M23*J23*K23*L23 -> 0 | O23: =J23*K23*L23 -> 0
G24: Инженер | N24: =M24*J24*K24*L24 -> 0 | O24: =J24*K24*L24 -> 0
A25: 1.3. | B25: Предоставить таблицу физических объемов сводную / по титульно | C25: =SUM(N25:N31) -> 0 | D25: =SUM(O25:O31) -> 0 | E25: =D25/8 -> 0 | G25: ГИП | N25: =M25*J25*K25*L25 -> 0 | O25: =J25*K25*L25 -> 0
G26: Нач. отдела | N26: =M26*J26*K26*L26 -> 0 | O26: =J26*K26*L26 -> 0
G27: Гл. специалист | N27: =M27*J27*K27*L27 -> 0 | O27: =J27*K27*L27 -> 0
G28: Рук. Группы | N28: =M28*J28*K28*L28 -> 0 | O28: =J28*K28*L28 -> 0
G29: Вед. инженер | N29: =M29*J29*K29*L29 -> 0 | O29: =J29*K29*L29 -> 0
G30: Старший инженер | N30: =M30*J30*K30*L30 -> 0 | O30: =J30*K30*L30 -> 0
G31: Инженер | N31: =M31*J31*K31*L31 -> 0 | O31: =J31*K31*L31 -> 0
A32: 1.4. | B32: Предоставить ведомости материалов с построчной стоимостью ресурсов (BOM) | C32: =SUM(N32:N38) -> 0 | D32: =SUM(O32:O38) -> 0 | E32: =D32/8 -> 0 | G32: ГИП | N32: =M32*J32*K32*L32 -> 0 | O32: =J32*K32*L32 -> 0
G33: Нач. отдела | N33: =M33*J33*K33*L33 -> 0 | O33: =J33*K33*L33 -> 0
G34: Гл. специалист | N34: =M34*J34*K34*L34 -> 0 | O34: =J34*K34*L34 -> 0
G35: Рук. Группы | N35: =M35*J35*K35*L35 -> 0 | O35: =J35*K35*L35 -> 0
G36: Вед. инженер | N36: =M36*J36*K36*L36 -> 0 | O36: =J36*K36*L36 -> 0
G37: Старший инженер | N37: =M37*J37*K37*L37 -> 0 | O37: =J37*K37*L37 -> 0
G38: Инженер | N38: =M38*J38*K38*L38 -> 0 | O38: =J38*K38*L38 -> 0
A39: 1.5. | B39: Предоставить ведомости оборудования с построчной стоимостью ресурсов (BOE) | C39: =SUM(N39:N45) -> 0 | D39: =SUM(O39:O45) -> 0 | E39: =D39/8 -> 0 | G39: ГИП | N39: =M39*J39*K39*L39 -> 0 | O39: =J39*K39*L39 -> 0
G40: Нач. отдела | N40: =M40*J40*K40*L40 -> 0 | O40: =J40*K40*L40 -> 0
G41: Гл. специалист | N41: =M41*J41*K41*L41 -> 0 | O41: =J41*K41*L41 -> 0
G42: Рук. Группы | N42: =M42*J42*K42*L42 -> 0 | O42: =J42*K42*L42 -> 0
...

Sheet РД_Ресурс.метод тит.1
C1: Форма для заполнения по тендерной процедуре №ТП.....
A2: Разработка рабочей документации по объекту "Выполнение проектно-изыскательских работ по проектам "Техническое перевооружение сети водопроводов, трубопроводов пенного пожаротушения ООО "Томскнефтехим" »
C4: (заполняется участником)
A5: № п/п | B5: Наименование показателей | C5: Стоимость, руб. без НДС | D5: Трудозатраты чел.час | E5: Трудозатраты чел.дни | F5: Наименование подрядчика | G5: Обоснование расчета*
G7: Должность | H7: Оценка количества листов документации | J7: чел. | K7: Дней | L7: Часов | M7: Ст-ть чел. часа (руб.) без НДС | N7: Итого Ст-ть (руб.) без НДС | O7: Итого кол. чел.час
H8: (текст.) ф.А4 | I8: (граф.) ф.А1
A9: Соответствие техническому заданию стадии ПД
A10: 1. | B10: Смета на строительство объектов капитального строительства | C10: =SUM(C11:C73) -> 0 | D10: =SUM(D11:D73) -> 0 | E10: =SUM(E11:E73) -> 0
A11: 1.1. | B11: Выполнить мониторинг рынка поставщиков и предоставить данные с учетом доставки до г. ……….: - по основным (ценообразующим) материалам - по вспомогательному оборудованию | C11: =SUM(N11:N17) -> 0 | D11: =SUM(O11:O17) -> 0 | E11: =D11/8 -> 0 | G11: ГИП | N11: =M11*J11*K11*L11 -> 0 | O11: =J11*K11*L11 -> 0
G12: Нач. отдела | N12: =M12*J12*K12*L12 -> 0 | O12: =J12*K12*L12 -> 0
G13: Гл. специалист | N13: =M13*J13*K13*L13 -> 0 | O13: =J13*K13*L13 -> 0
G14: Рук. Группы | N14: =M14*J14*K14*L14 -> 0 | O14: =J14*K14*L14 -> 0
G15: Вед. инженер | N15: =M15*J15*K15*L15 -> 0 | O15: =J15*K15*L15 -> 0
G16: Старший инженер | N16: =M16*J16*K16*L16 -> 0 | O16: =J16*K16*L16 -> 0
G17: Инженер | N17: =M17*J17*K17*L17 -> 0 | O17: =J17*K17*L17 -> 0
A18: 1.2. | B18: Предоставить таблицу физических объемов сводная / по титульно | C18: =SUM(N18:N24) -> 0 | D18: =SUM(O18:O24) -> 0 | E18: =D18/8 -> 0 | G18: ГИП | N18: =M18*J18*K18*L18 -> 0 | O18: =J18*K18*L18 -> 0
G19: Нач. отдела | N19: =M19*J19*K19*L19 -> 0 | O19: =J19*K19*L19 -> 0
G20: Гл. специалист | N20: =M20*J20*K20*L20 -> 0 | O20: =J20*K20*L20 -> 0
G21: Рук. Группы | N21: =M21*J21*K21*L21 -> 0 | O21: =J21*K21*L21 -> 0
G22: Вед. инженер | N22: =M22*J22*K22*L22 -> 0 | O22: =J22*K22*L22 -> 0
G23: Старший инженер | N23: =M23*J23*K23*L23 -> 0 | O23: =J23*K23*L23 -> 0
G24: Инженер | N24: =M24*J24*K24*L24 -> 0 | O24: =J24*K24*L24 -> 0
A25: 1.3. | B25: Предоставить ведомости материалов с построчной стоимостью ресурсов | C25: =SUM(N25:N31) -> 0 | D25: =SUM(O25:O31) -> 0 | E25: =D25/8 -> 0 | G25: ГИП | N25: =M25*J25*K25*L25 -> 0 | O25: =J25*K25*L25 -> 0
G26: Нач. отдела | N26: =M26*J26*K26*L26 -> 0 | O26: =J26*K26*L26 -> 0
G27: Гл. специалист | N27: =M27*J27*K27*L27 -> 0 | O27: =J27*K27*L27 -> 0
G28: Рук. Группы | N28: =M28*J28*K28*L28 -> 0 | O28: =J28*K28*L28 -> 0
G29: Вед. инженер | N29: =M29*J29*K29*L29 -> 0 | O29: =J29*K29*L29 -> 0
G30: Старший инженер | N30: =M30*J30*K30*L30 -> 0 | O30: =J30*K30*L30 -> 0
G31: Инженер | N31: =M31*J31*K31*L31 -> 0 | O31: =J31*K31*L31 -> 0
A32: 1.4. | B32: Предоставить ведомости оборудования с построчной стоимостью ресурсов | C32: =SUM(N32:N38) -> 0 | D32: =SUM(O32:O38) -> 0 | E32: =D32/8 -> 0 | G32: ГИП | N32: =M32*J32*K32*L32 -> 0 | O32: =J32*K32*L32 -> 0
G33: Нач. отдела | N33: =M33*J33*K33*L33 -> 0 | O33: =J33*K33*L33 -> 0
G34: Гл. специалист | N34: =M34*J34*K34*L34 -> 0 | O34: =J34*K34*L34 -> 0
G35: Рук. Группы | N35: =M35*J35*K35*L35 -> 0 | O35: =J35*K35*L35 -> 0
G36: Вед. инженер | N36: =M36*J36*K36*L36 -> 0 | O36: =J36*K36*L36 -> 0
G37: Старший инженер | N37: =M37*J37*K37*L37 -> 0 | O37: =J37*K37*L37 -> 0
G38: Инженер | N38: =M38*J38*K38*L38 -> 0 | O38: =J38*K38*L38 -> 0
A39: 1.5. | B39: Расчитать количество стыков / дюйм диаметров по проекту | C39: =SUM(N39:N45) -> 0 | D39: =SUM(O39:O45) -> 0 | E39: =D39/8 -> 0 | G39: ГИП | N39: =M39*J39*K39*L39 -> 0 | O39: =J39*K39*L39 -> 0
G40: Нач. отдела | N40: =M40*J40*K40*L40 -> 0 | O40: =J40*K40*L40 -> 0
G41: Гл. специалист | N41: =M41*J41*K41*L41 -> 0 | O41: =J41*K41*L41 -> 0
G42: Рук. Группы | N42: =M42*J42*K42*L42 -> 0 | O42: =J42*K42*L42 -> 0
...

Sheet Лист2

Sheet Лист3
