Workbook
Name \: Лист1!#REF!
Name \: Лист1!#REF!
Name \: Лист1!#REF!
Name \: [1]Лист1!#REF!
Name \: [2]Лист1!#REF!
Name \: Лист1!#REF!
Name KD: #REF!
Name KD: #REF!
Name KD: #REF!
Name KD: #REF!
Name KD: #REF!
Name KD: #REF!
Name KD: #REF!
Name KD: #REF!
Name KD: #REF!
Name Print_Area: '4.1 КД'!$A$1:$H$40
Name АВТОМОБИЛЬНЫЕ_ДОРОГИ: Лист1!$J$3:$J$4
Name город: #REF!
Name город: #REF!
Name город: #REF!
Name город: #REF!
Name город: #REF!
Name город: #REF!
Name город: #REF!
Name город: #REF!
Name город: #REF!
Name ЖЕЛЕЗНЫЕ_ДОРОГИ: Лист1!$AI$3:$AI$11
Name ЗАЩИТНЫЕ_СООРУЖЕНИЯ_ГРАЖДАНСКОЙ_ОБОРОНЫ: Лист1!$AO$3
Name ИСКУСТВЕННЫЕ: Лист1!$A$3:$A$12
Name ИСКУСТВЕННЫЕ_СООРУЖЕНИЯ: Лист1!$A$3:$A$12
Name ИССКУСТВЕННЫЕ: Лист1!$A$3:$A$12
Name ИССКУСТВЕННЫЕ_СООРУЖЕНИЯ_МОСТЫ_ПЕРЕХОДЫ_ПУТЕПРОВОДЫ: Лист1!$A$3:$A$12
Name КОММУНАЛЬНЫЕ_ИНЖЕНЕРНЫЕ_СЕТИ_И_СООРУЖЕНИЯ: Лист1!$S$3:$S$8
Name Конф: #REF!
Name Конф: #REF!
Name Конф: #REF!
Name Конф: #REF!
Name Конф: #REF!
Name Конф: #REF!
Name Конф: #REF!
Name Конф: #REF!
Name Конф: #REF!
Name конфл: #REF!
Name конфл: #REF!
Name конфл: #REF!
Name конфл: #REF!
Name конфл: #REF!
Name конфл: #REF!
Name конфл: #REF!
Name конфл: #REF!
Name конфл: #REF!
Name конфл2: #REF!
Name конфл2: #REF!
Name конфл2: #REF!
Name конфл2: #REF!
Name конфл2: #REF!
Name конфл2: #REF!
Name конфл2: #REF!
Name конфл2: #REF!
Name конфл2: #REF!

Sheet Форма сводной сметы 
B1: 1 | D1: 1 | G1: 1 | H1: 1 | I1: 1 | J1: 1
J2: Форма 1пс
B4: Приложение к
D5: (договору, дополнительному соглашению)
B7: СМЕТА на проектные и изыскательские работы
B9: Наименование строительства и стадии проектирования | F9: «Модернизация существующей инфраструктуры транспортировки и налива фракции С5, с целью обеспечения налива дополнительного объема фракции С5, в количестве 6 000 т/мес.» | N9: =F9 -> «Модернизация существующей инфраструктуры транспортировки и налива фракции С5, с целью обеспечения налива дополнительного объема фракции С5, в количестве 6 000 т/мес.»
B12: Наименование проектной организации - генерального проектировщика | F12: ОАО "СибНефтеТрансПроект"
B15: Наименование организации заказчика | F15: ПАО «Нижнекамскнефтехим»
B18: N п.п. | C18: Перечень выполняемых работ | E18: Характеристика проектируемого объекта | F18: Трудозатраты определенные участников, ч.ч. | G18: Ссылка на N смет по формам N 2п и 3п | H18: Стоимость работ
H19: изыскательских | I19: проектных | J19: всего, без НДС, руб. | K19: всего, с НДС, руб.
B20: =IF($B$1=1,SUBTOTAL(2,$B$1:B1),"") -> 1 | C20: =IF($B$1=1,SUBTOTAL(2,$B$1:D1),"") -> 2 | E20: =IF($B$1=1,SUBTOTAL(2,$B$1:E1),"") -> 2 | G20: =IF($B$1=1,SUBTOTAL(2,$B$1:G1),"") -> 3 | H20: =IF($B$1=1,SUBTOTAL(2,$B$1:H1),"") -> 4 | I20: =IF($B$1=1,SUBTOTAL(2,$B$1:I1),"") -> 5 | J20: =IF($B$1=1,SUBTOTAL(2,$B$1:J1),"") -> 6 | K20: 7
B21: 1 | C21: Сбор исходных данных и выполнение работ по обследованию существующих зданий и сооружений | G21: Сводная смета №1 | H21: 0 | I21: =СВОД!F18 -> 9272148.2 | J21: =SUM(H21:I21) -> 9272148.2 | K21: =J21*1.2 -> 11126578 | L21: 1.1 По калькуляции затрат по форме 3П 1.2 СБЦП 81-02-25-2001 «Справочник базовых цен на обмерные работы и обследования зданий и сооружений» (Приказ Минстроя России от 25.04.2016 № 270/пр).
B22: 2 | C22: Выполнение инженерных изысканий | G22: Сводная смета №1 | H22: =СВОД!F13 -> 20111633 | I22: 0 | J22: =SUM(H22:I22) -> 20111633 | K22: =J22*1.2 -> 24133960 | L22: СБЦ-ИИ-2006 "Инженерно-геодезические изыскания при строительстве и эксплуатации зданий и сооружений" (Рекомендован Росстроем Министерства регионального развития РФ письмом от 24.05.2006 г. N СК-1976/02). СБЦ-ИИ-1998 СБЦ на инженерно-геологические и инженерно-экологические изыскания для строительства (Одобрен письмом Госстроя от 22 июня 1998 г. N 9-4/84). СБЦ-ИИ-2000 "Инженерно-гидрографические работы. Инженерно-гидрометеорологические изыскания на реках" (Утвержден письмом Госстроя России от 26.09.2000 N 5-11/91). Приказ № 317, от 02.07.2010 г. Министерства регионального развития Российской Федерации. об утверждении методики определения стоимости работ по очистке местности от взрывоопасных предметов в сфере градостроительной деятельности. СЦНПР-91 Сборник цен на научно-проектные работы по памятникам истории и культуры.
B23: 3 | C23: Землеустроительная (градостроительная) документация (ППТ, ПМТ, градплан) | J23: =SUM(H23:I23) -> 0 | K23: =J23*1.2 -> 0 | L23: Сборник цен на проектные работы в строительстве "Территориальное планирование и планировка территории", утвержденный Приказом Министерства регионального развития Российской Федерации от 28.05.2010 г.№ 260. Сборник цен и общественно необходимых затрат труда (ОНЗТ) на изготовление проектной и изыскательской продукции землеустройства, земельного кадастра и мониторинга земель, утвержденный Приказом Роскомзема от 28.12.1995 г. № 70.
B24: 4 | C24: Корректировка проектной документации, в т.ч.: | J24: =SUM(H24:I24) -> 0 | K24: =J24*1.2 -> 0
B25: 4.1 | C25: - | D25: Формирование пакета исходно-разрешительной документации | J25: =SUM(H25:I25) -> 0 | K25: =J25*1.2 -> 0 | L25: По калькуляции затрат по форме 3П
B26: 4.2 | C26: - | D26: Подготовка проектов ТУ на подключение к инженерным сетям и на пересечение с инженерными сетями | J26: =SUM(H26:I26) -> 0 | K26: =J26*1.2 -> 0 | L26: По калькуляции затрат по форме 3П
B27: 4.3 | C27: - | D27: Разделы ПД по Постановлениюот 16.02.2008 №87 | J27: =SUM(H27:I27) -> 0 | K27: =J27*1.2 -> 0 | L27: Справочники базовых цен приведенные в «Федеральном реестре сметных нормативов, подлежащих применению при определении сметной стоимости объектов капитального строительства» размещенного на официальном сайте Минстроя России (www.minstroyrf.ru) методические указания по применению справочников базовых цен на проектные работы в строительстве, 2009 (Приказ Министерства регионального развития РФ от 29 декабря 2009 г. №620); разъяснения ОАО «ЦИНТРИНВЕСТпроект»; коэффициенты изменения сметной стоимости проектных работ публикуемые ежеквартально Минстроем РФ, за исключением случаев особо оговоренных в конкурсной документации | N27: ТЧ ПД
B28: 4.4 | C28: - | D28: Разработка КД, ОЛ и ИТТ на основное и вспомогательное энергетическое оборудование | J28: =SUM(H28:I28) -> 0 | K28: =J28*1.2 -> 0 | L28: СБЦ приведенные в «Федеральном реестре сметных нормативов, подлежащих применению при определении сметной стоимости объектов капитального строительства» размещенного на официальном сайте Минстроя России (www.minstroyrf.ru)
B29: 4.5 | C29: - | D29: Разработка ОВОС, проведение общественных слушаний, разработка ПМООС | J29: =SUM(H29:I29) -> 0 | K29: =J29*1.2 -> 0 | L29: 1. Ориентировочно стоимость разработки ОВОС может составлять дополнительно до 4% от общей стоимости разработки проектной и рабочей документации (П + Р). (Для объектов с привлечением средств ПАО "Газпром" - до 2%) 2. По калькуляции затрат по форме 3П, с предоставлением обоснования. 3. Затраты на разработку раздела ПД «Перечень мероприятий по охране окружающей среды» (ООС) учтены комплексными ценами, содержащимися в СБЦ изд. 1995-1999 гг., 2003 г., 2004 г., 2006-2008 гг., а также ценами, введенными в 2009 г. в статусе государственных стоимостных нормативов. Исключение составляют СБЦ в которых указан другой порядок определения этих затрат
B30: 4.6 | C30: - | D30: Разработка СЗЗ | J30: =SUM(H30:I30) -> 0 | K30: =J30*1.2 -> 0 | L30: СБЦ "Территориальное планирование и планировка территорий. 2010 г. Раздел 2, Таблица 5.
B31: 4.7 | C31: - | D31: Проведение процедур P&ID review, HAZOP/HAZID и SIL | J31: =SUM(H31:I31) -> 0 | K31: =J31*1.2 -> 0 | L31: По калькуляции затрат по форме 3П
B32: 5 | C32: Разработка рабочей документации, в т.ч.: | J32: =SUM(H32:I32) -> 0 | K32: =J32*1.2 -> 0
B33: 5.1 | C33: - | D33: Подготовка сводной заказной спецификации, разработка ведомости объемов работ по форме Заказчика, разработка спецификации аварийного запаса ЗИП | G33: Сводная смета №1 | H33: 0 | I33: =СВОД!H21*0.02 -> 819349.08 | J33: =SUM(H33:I33) -> 819349.08 | K33: =J33*1.2 -> 983218.89 | L33: Выполненнение отдельным томом (в том числе в формате Excel) в размере до 2% от стоимости проектирования соответствующих разделов. Затраты на разработку Разработка ведомости объемов работ учтены комплексными ценами, содержащимися в СБЦ. Затраты на разработку спецификации аварийного запаса ЗИП работ учтены комплексными ценами, содержащимися в СБЦ.
B34: 5.2 | C34: - | D34: Разработка комплектов по титулам | G34: Сводная смета №1 | H34: 0 | I34: =СВОД!E30-СВОД!E29 -> 44464376 | J34: =SUM(H34:I34) -> 44464376 | K34: =J34*1.2 -> 53357251 | L34: СБЦ приведенные в «Федеральном реестре сметных нормативов, подлежащих применению при определении сметной стоимости объектов капитального строительства» размещенного на официальном сайте Минстроя России (www.minstroyrf.ru)
B35: 6 | C35: Разработка эксплуатационной документации, в т.ч.: | J35: =SUM(H35:I35) -> 0 | K35: =J35*1.2 -> 0
B36: 6.1 | C36: - | D36: Разработка технологического регламента | J36: =SUM(H36:I36) -> 0 | K36: =J36*1.2 -> 0 | L36: По калькуляции затрат по форме 3П
B37: 6.2 | C37: - | D37: Разработка ПЛАС | J37: =SUM(H37:I37) -> 0 | K37: =J37*1.2 -> 0 | L37: Справочники базовых цен приведенные в «Федеральном реестре сметных нормативов, подлежащих применению при определении сметной стоимости объектов капитального строительства» размещенного на официальном сайте Минстроя России (www.minstroyrf.ru)
B38: 7 | C38: Прочие затраты, в т.ч.: | J38: =SUM(H38:I38) -> 0 | K38: =J38*1.2 -> 0
B39: 7.1 | C39: - | D39: Рассмотрение и согласование ТКП и РКД поставщиков оборудования и материалов | H39: 0 | I39: =СВОД!F36 -> 2009356.3 | J39: =SUM(H39:I39) -> 2009356.3 | K39: =J39*1.2 -> 2411227.6 | L39: По калькуляции затрат по форме 3П
B40: 8 | C40: Инжиниринговые услуги | J40: =SUM(H40:I40) -> 0 | K40: =J40*1.2 -> 0
B41: 8.1 | C41: - | D41: Авторский надзор Корректировка рабочей документации по результатам СМР.Стадия As build | H41: 0 | I41: =СВОД!E40 -> 6829577.3 | J41: =SUM(H41:I41) -> 6829577.3 | K41: =J41*1.2 -> 8195492.7
B42: 9 | C42: Эксплуатационная документация | J42: =SUM(H42:I42) -> 0 | K42: =J42*1.2 -> 0
B43: 9.1 | C43: - | D43: Корректировка технологического регламента,паспорта взрывобезопасности ОПО, декларации ПБ, план действий по предупреждению и ликвидации ЧС | H43: 0 | I43: =СВОД!E46 -> 3425610 | J43: =SUM(H43:I43) -> 3425610 | K43: =J43*1.2 -> 4110732
B44: 8 | C44: Итого: | H44: =ROUND(SUM(H21:H39),2) -> 20111633 | I44: =ROUND(SUM(I21:I43),2) -> 66820417 | J44: =SUM(H44:I44) -> 86932050
B45: 9 | C45: НДС 20 % | J45: =ROUND(J44*0.2,2) -> 17386410
B46: 10 | C46: Всего с учетом НДС: | J46: =J45+J44 -> 1.0431846e+08 | K46: =SUM(K21:K39) -> 92012236 | N46: =СВОД!F50 -> 1.0431846e+08
N47: =N46-K46 -> 12306225
D49: Итого по смете | F49: =K46 -> 92012236
E50: (сумма прописью)
...

Sheet СВОД
A1: Сводная смета №1
A2: на проектные и изыскательские работы
A4: По объекту: | B4: ='Форма сводной сметы '!N9 -> «Модернизация существующей инфраструктуры транспортировки и налива фракции С5, с целью обеспечения налива дополнительного объема фракции С5, в количестве 6 000 т/мес.»
C6: Стадия проектирования: Рабочая документация
A7: № пп | B7: Перечень выполняемых работ | C7: Ссылка на № смет по формам 2П, 3П | D7: Полная стоимость работ, руб.
D8: изыскательских | E8: проектных | F8: Всего
A9: 1 | B9: 2 | C9: 4 | D9: 5 | E9: 6 | F9: 7
A10: 1 | B10: Инженерные изыскания
A11: 1.1 | B11: Инженерно-геодезические изыскания | C11: =CONCATENATE("Смета №",A11) -> Смета №1.1 | D11: ='1.1_ИГДИ'!O59 -> 5290473.2 | E11: 0 | F11: =ROUND(SUM(D11+E11),2) -> 5290473.2
A12: 1.2 | B12: Инженерно-геологические изыскания | C12: Смета №1.2.1 Смета №1.2.2 | D12: ='1.2.1 ИГИ'!G61+'1.2.2 ИГИ'!G60 -> 14821160 | E12: 0 | F12: =ROUND(SUM(D12+E12),2) -> 14821160
A13: 1.3 | B13: Итого : | D13: =ROUND(ROUND(SUM(D11:D12),2),2) -> 20111633 | E13: =ROUND(ROUND(SUM(E11:E12),2),2) -> 0 | F13: =E13+D13 -> 20111633
A15: 2 | B15: Обследование, СИД
A16: 2.1 | B16: Обследование существующих зданий и сооружений | C16: =CONCATENATE("Смета №",A16) -> Смета №2.1 | D16: 0 | E16: ='2.1 Обслед'!I53 -> 8939487 | F16: =ROUND(SUM(D16+E16),2) -> 8939487
A17: 2.2 | B17: Сбор исходных данных | C17: Смета №01 | D17: 0 | E17: ='РД_BOQ '!Q112 -> 332661.2 | F17: =ROUND(SUM(D17+E17),2) -> 332661.2
A18: 2.3 | B18: Итого : | D18: =ROUND(SUM(D16:D17),2) -> 0 | E18: =ROUND(SUM(E16:E17),2) -> 9272148.2 | F18: =E18+D18 -> 9272148.2
A20: 3 | B20: Рабочая документация | H20: ТЧ РД
A21: 3.1 | B21: Технология | C21: =CONCATENATE("Смета №",A21) -> Смета №3.1 | D21: 0 | E21: ='3.1 ТХ'!I56 -> 32951458 | F21: =ROUND(SUM(D21+E21),2) -> 32951458 | H21: =SUM(F21:F23) -> 40967454
A22: 3.2 | B22: Сети электроснабжения | C22: =CONCATENATE("Смета №",A22) -> Смета №3.2 | D22: 0 | E22: ='3.2 ЭС'!I52 -> 2711725.4 | F22: =ROUND(SUM(D22+E22),2) -> 2711725.4
A23: 3.3 | B23: Автоматизированная система управления технологическим процессом (АСУ ТП) | C23: =CONCATENATE("Смета №",A23) -> Смета №3.3 | D23: 0 | E23: ='3.3 АСУТП'!Y173 -> 5304270.9 | F23: =ROUND(SUM(D23+E23),2) -> 5304270.9
A24: 3.4 | B24: Промышленная безопасность | C24: =CONCATENATE("Смета №",A24) -> Смета №3.4 | D24: 0 | E24: =ПромБез!I23 -> 900000 | F24: =ROUND(SUM(D24+E24),2) -> 900000
A25: 3.5 | B25: Гидравлические расчеты | C25: =CONCATENATE("Смета №",A25) -> Смета №3.5 | D25: 0 | E25: =Расч!H36 -> 393032.72 | F25: =ROUND(SUM(D25+E25),2) -> 393032.72
A26: 3.6 | B26: Смежные работы | C26: =C17 -> Смета №01 | D26: 0 | E26: ='РД_BOQ '!Q157+'РД_BOQ '!Q178+'РД_BOQ '!Q199 -> 1213411.7 | F26: =ROUND(SUM(D26+E26),2) -> 1213411.7
A27: 3.7 | B27: Отчетная документация по проекту | C27: =C17 -> Смета №01 | D27: 0 | E27: ='РД_BOQ '!Q214 -> 240477.92 | F27: =ROUND(SUM(D27+E27),2) -> 240477.92
A28: 3.8 | B28: Оплата экспертизы Промышленной безопасности | C28: По факту | D28: 0 | E28: 750000 | F28: =ROUND(SUM(D28+E28),2) -> 750000
A29: 3.9 | B29: Подготовка сводной заказной спецификации, разработка ведомости объемов работ по форме Заказчика, разработка спецификации аварийного запаса ЗИП | C29: 2% от ТЧ РД | D29: 0 | E29: =(E21+E22+E23)*0.02 -> 819349.08 | F29: =ROUND(SUM(D29+E29),2) -> 819349.08
A30: 3.10 | B30: Итого : | D30: =SUM(D21:D29) -> 0 | E30: =ROUND(SUM(E21:E29),2) -> 45283725 | F30: =ROUND(SUM(D30+E30),2) -> 45283725
A32: 4 | B32: Прочие затраты
A33: 4.1 | B33: ='РД_BOQ '!B192 -> Формирование механических ОЛ | C33: =$C$27 -> Смета №01 | D33: 0 | E33: ='РД_BOQ '!C192 -> 1133002.4 | F33: =ROUND(SUM(D33+E33),2) -> 1133002.4
A34: 4.1 | B34: ='Форма сводной сметы '!D39 -> Рассмотрение и согласование ТКП и РКД поставщиков оборудования и материалов | C34: =CONCATENATE("Смета №",A34) -> Смета №4.1 | D34: 0 | E34: ='4.1 КД'!H36 -> 563231.44 | F34: =ROUND(SUM(D34+E34),2) -> 563231.44
A35: 4.2 | B35: Согласование с собственниками существующих сооружений пересечение с проектируемыми сооружениями | C35: =$C$27 -> Смета №01 | D35: 0 | E35: ='РД_BOQ '!C185 -> 313122.48 | F35: =ROUND(SUM(D35+E35),2) -> 313122.48
A36: 4.2 | B36: Итого : | D36: =ROUND(SUM(D34),2) -> 0 | E36: =ROUND(SUM(E33:E35),2) -> 2009356.3 | F36: =E36+D36 -> 2009356.3
A37: 5 | B37: Инжиниринговые услуги
A38: 5.1 | B38: Авторский надзор | C38: =$C$27 -> Смета №01 | D38: 0 | E38: ='РД_BOQ '!C224 -> 4236422.1 | F38: =ROUND(SUM(D38+E38),2) -> 4236422.1
A39: 5.2 | B39: Корректировка рабочей документации по результатам СМР.Стадия As build | C39: =$C$27 -> Смета №01 | D39: 0 | E39: ='РД_BOQ '!C231 -> 2593155.2 | F39: =ROUND(SUM(D39+E39),2) -> 2593155.2
A40: 5.3 | B40: Итого : | D40: =SUM(D30:D39) -> 0 | E40: =ROUND(SUM(E37:E39),2) -> 6829577.3 | F40: =ROUND(SUM(F37:F39),2) -> 6829577.3
A41: 6 | B41: Эксплуатационная документация
A42: 6.1 | B42: ='РД_BOQ '!B239 -> Корректировка технологического регламента (при необходимости) 5-ти регламентов (ЭП-616, ЭП-600, ИП-10, Т-8/2, Т-6) | C42: =$C$27 -> Смета №01 | D42: 0 | E42: ='РД_BOQ '!C239 -> 1283752.1 | F42: =ROUND(SUM(D42+E42),2) -> 1283752.1
A43: 6.2 | B43: ='РД_BOQ '!B246 -> Паспорт взрывобезопасности опасного производственного объекта (при необходимости) | C43: =$C$27 -> Смета №01 | D43: 0 | E43: ='РД_BOQ '!C246 -> 829849.7 | F43: =ROUND(SUM(D43+E43),2) -> 829849.7
A44: 6.3 | B44: ='РД_BOQ '!B253 -> Декларация пожарной безопасности (при необходимости) | C44: =$C$27 -> Смета №01 | D44: 0 | E44: ='РД_BOQ '!C253 -> 709610.66 | F44: =ROUND(SUM(D44+E44),2) -> 709610.66
A45: 6.4 | B45: ='РД_BOQ '!B260 -> План действий по предупреждению и ликвидации чрезвычайных ситуаций природного и техногенного характера (при необходимости) | C45: =$C$27 -> Смета №01 | D45: 0 | E45: ='РД_BOQ '!C260 -> 602397.54 | F45: =ROUND(SUM(D45+E45),2) -> 602397.54
...

Sheet 1.1_ИГДИ
A1: Смета № | F1: 1.1
A2: Инженерно - геодезические изыскания
B3: Наименование объекта: | D3: ='Форма сводной сметы '!N9 -> «Модернизация существующей инфраструктуры транспортировки и налива фракции С5, с целью обеспечения налива дополнительного объема фракции С5, в количестве 6 000 т/мес.»
B5: Наименование организации: | D5: ='Форма сводной сметы '!F12 -> ОАО "СибНефтеТрансПроект"
A7: № п/п | B7: Наименование работ и затрат | D7: Обоснование стоимости | E7: Ед. изм. | F7: Кол- во | G7: Расчет стоимости | O7: Стоимость, руб
A9: 1 | B9: 2 | D9: 3 | E9: 4 | F9: 5 | G9: 6 | O9: 7
B10: Сметный расчет составлен по Справочнику базовых цен на инженерные изыскания для строительства. Инженерно-геодезические изыскания. ПНИИИС, 2004 г.
A11: 1 | B11: Создание инженерно-топографического плана. Эстакада (3 яруса). | D11: Ч. I, гл.2, табл.9.
D12: 1,25п - территория со специальным режимом - ОУ, п.8, в);
B13: [ P ] = | C13: 19.58 | D13: 1,75пк - съемка подз. коммуникаций - Ч. I, гл.2, табл.9, прим.4.
B14: - масштаб: | C14: 1:500 | D14: 1,2к - применение комп. технологий - ОУ, п.15, д).
B15: - высота сеч. рельефа: | C15: 0.5м.
B16: - В. Территории действ. пром. предприятий.
D17: 1,3пк - детальное обследование колодцев подземных коммуникаций и надземных коммуникаций, с составлением эскизов и разрезов опор и узлов - Ч. I, гл.2, табл.9, прим.5;
B18: Категория сложности II | C18: полевые работы: | D18: Ч. I, гл.2, табл.9, § 5 | E18: 1 га. | F18: 19.58 | G18: 4632 | H18: 1.75 | J18: 1.3 | M18: 1.25 | N18: 19.58*4 632*1.75*1.3*1.25 | O18: 257912.66
C19: камеральные работы: | D19: Ч. I, гл.2, табл.9, § 5 | E19: 1 га. | F19: 19.58 | G19: 1938 | H19: 1.75 | I19: 1.2 | J19: 1.3 | N19: 19.58*1 938*1.75*1.2*1.3 | O19: 103592.69
A20: 2 | B20: Создание инженерно-топографического плана. Насосная. | D20: Ч. I, гл.2, табл.9.
D21: 1,25п - территория со специальным режимом - ОУ, п.8, в);
B22: [ P ] = | C22: 0.9 | D22: 1,75пк - съемка подз. коммуникаций - Ч. I, гл.2, табл.9, прим.4.
B23: - масштаб: | C23: 1:500 | D23: 1,2к - применение комп. технологий - ОУ, п.15, д).
B24: - высота сеч. рельефа: | C24: 0.5м.
B25: - В. Территории действ. пром. предприятий.
D26: 1,4п - съёмка участков 1:500 до 1 га. - Ч. I, гл.2, табл.10, § 1.
B27: Категория сложности II | C27: полевые работы: | D27: Ч. I, гл.2, табл.9, § 5 | E27: 1 га. | F27: 0.9 | G27: 4632 | H27: 1.75 | J27: 1.4 | M27: 1.25 | N27: 0.9*4 632*1.75*1.4*1.25 | O27: 12766.95
C28: камеральные работы: | D28: Ч. I, гл.2, табл.9, § 5 | E28: 1 га. | F28: 0.9 | G28: 1938 | H28: 1.75 | I28: 1.2 | N28: 0.9*1 938*1.75*1.2 | O28: 3662.82
A29: 3 | B29: Создание плановой опорной сети. | D29: Ч. I, гл.1, табл.8.
B30: с закладкой - | C30: 4
B31: - 2 разряд | D31: 1,3пк - использование спутниковых геодезических систем - Ч. I, гл.1, табл.8, прим.2.
B32: Категория И-II, З-II Категория II | C32: полевые работы: | D32: Ч. I, гл.1, табл.8, § 3 | E32: 1 пт. | F32: 4 | G32: 6426 | H32: 1.3 | N32: 4.0*6 426*1.3 | O32: 33415.2
C33: камеральные работы: | D33: Ч. I, гл.1, табл.8, § 3 | E33: 1 пт. | F33: 4 | G33: 2538 | H33: 1.3 | N33: 4.0*2 538*1.3 | O33: 13197.6
A34: 4 | B34: Создание высотной опорной сети. | D34: Ч. I, гл.1, табл.8.
B35: - IV класс
B36: Категория И-II, З-II Категория II | C36: полевые работы: | D36: Ч. I, гл.1, табл.8, § 4 | E36: 1 пт. | F36: 4 | G36: 1897 | N36: 4.0*1 897 | O36: 7588
C37: камеральные работы: | D37: Ч. I, гл.1, табл.8, § 4 | E37: 1 пт. | F37: 4 | G37: 428 | N37: 4.0*428 | O37: 1712
A38: 5 | B38: Плановая и высотная привязка геологических скважин, точек статического зондирования и пр. | D38: Ч. II, гл.7, табл.48.
B39: - скв. геологические | C39: 20
B40: [ ] = | C40: 20
B41: При расстоянии между точками:
B42: - св. 200 м. до 350 м. | D42: 0,5п - предварительная разбивка местоположения точек
B43: Категория сложности I | C43: полевые работы: | D43: Ч. II, гл.7, табл.48, § 4 | E43: 1 т. | F43: 20 | G43: 180 | H43: 0.5 | N43: 20.0*180*0.5 | O43: 1800
...

Sheet 1.2.1 ИГИ
A1: Смета №1.2.1
B2: на инженерно-геологические изыскания
A4: Наименование объекта: | C4: ='Форма сводной сметы '!N9 -> «Модернизация существующей инфраструктуры транспортировки и налива фракции С5, с целью обеспечения налива дополнительного объема фракции С5, в количестве 6 000 т/мес.»
C5: 56209 Нижнекамск. Насосная Т-8/2
A6: Наименование организации-подрядчика | C6: ОАО "Сибнефтетранспроект"
A8: № п/п | B8: Наименование видов работ | C8: Обоснование стоимости | D8: Единица измерения | E8: Объем | F8: Расценка | G8: Стоимость
A9: Справочник базовых цен на инженерно-геологические и инженерно-экологические изыскания для строительства, ГОССТРОЙ РФ, 1999г.
A10: Раздел I, БУРОВЫЕ И ГОРНОПРОХОДЧЕСКИЕ РАБОТЫ
A11: 1 | B11: Инженерно-геологическая рекогносцировка при удовлетворительной проходимости | C11: Таб.9 §2 | D11: 1км | E11: 0.4 | F11: =ROUND(E11,0)&"*27.0" -> 0*27.0 | G11: =ROUND(E11*27,1) -> 10.8
A12: 2 | B12: Колонковое бурение скважин диаметром до 160 мм глубиной до 15 м (8скв.х15п.м.) в породах | C12: Таб.17 §1
B13: I категории | D13: 1 м | E13: 15 | F13: =E13&"*36.0*0.9" -> 15*36.0*0.9 | G13: =ROUND(E13*36*0.9,0) -> 486
B14: II категории | D14: 1 м | E14: 45 | F14: =E14&"*38.4*0.9" -> 45*38.4*0.9 | G14: =ROUND(E14*38.4*0.9,1) -> 1555.2
B15: III категории | D15: 1 м | E15: 45 | F15: =E15&"*42.6*0.9" -> 45*42.6*0.9 | G15: =ROUND(E15*42.6*0.9,1) -> 1725.3
B16: IV категории | D16: 1 м | E16: 15 | F16: =E16&"*45.6*0.9" -> 15*45.6*0.9 | G16: =ROUND(E16*45.6*0.9,1) -> 615.6
B17: Итого по пункту 2 | E17: =SUM(E13:E16) -> 120 | G17: =SUM(G13:G16) -> 4382.1
A18: 3 | B18: Отбор монолитов | C18: Таб.57
B19: из скважин с глубины до 10м | C19: §1 | D19: 1 мон | E19: 40 | F19: =E19&"*22.9" -> 40*22.9 | G19: =ROUND(E19*22.9,1) -> 916
B20: из скважин с глубины св.10 до 20м | C20: §2 | D20: 1 мон | E20: 20 | F20: =E20&"*30.6" -> 20*30.6 | G20: =ROUND(E20*30.6,1) -> 612
A21: 4 | B21: Гидрогеологические наблюдения при бурении скважин диаметром до 160 мм | C21: Таб.18 §1 гл.4 п.8 | D21: 1 м | E21: =E17*0.6 -> 72 | F21: =E21&"*1.6*0.6" -> 72*1.6*0.6 | G21: =ROUND(E21*1.6*0.6,1) -> 69.1
A22: 5 | B22: Бурение скважин для штамповых испытаний площадью 600см2 до 10м в породах II категории | C22: глава 6 п.4 Таб.21 §4 | D22: 1 м | E22: 32 | F22: =E22&"*10.8*0.4" -> 32*10.8*0.4 | G22: =ROUND(E22*10.8*0.4,1) -> 138.2
A23: 6 | B23: Испытание грунтов в буровых скважинах на глубине до 10м вертикальной статической нагрузкой штампом площадью 600см2 удельным давлением до 0.3МПа-III категории сложности | C23: Таб.54 §15 | D23: 1 исп. | E23: 8 | F23: =E23&"*570" -> 8*570 | G23: =ROUND(E23*570,1) -> 4560
A24: 7 | B24: Статическое зондирование глубиной св.10 до 15 м | C24: Таб.45 §5 | D24: 1 испыт. | E24: 8 | F24: =E24&"*172.5" -> 8*172.5 | G24: =ROUND(E24*172.5,1) -> 1380
A25: 8 | B25: Плановая и высотная привязка выработок II категории сложности при расстоянии между выработками | C25: Таб.93
B26: до 50 м | C26: §1 | D26: 1т | E26: 8 | F26: =E26&"*8.5" -> 8*8.5 | G26: =ROUND(E26*8.5,1) -> 68
A27: 9 | B27: Предварительная разбивка II категории сложности при расстоянии между точками | C27: Таб.93
B28: до 50 м | C28: §1 | D28: 1т | E28: =E26 -> 8 | F28: =E28&"*8.5" -> 8*8.5 | G28: =ROUND(E28*8.5,1) -> 68
A29: 10 | B29: Итого по пунктам 1-9 с учетом неблагоприятного периода | C29: Таб.2 §3 | F29: =G11+ROUND(SUM(G17:G28),1)&"*1.3" -> 12204,2*1.3 | G29: =(G11+SUM(G17:G28))*1.3 -> 15865.46
A30: 11 | B30: Внутренний транспорт | C30: Таб.4 §5 | F30: =ROUND(G29,1)&"*0.1625" -> 15865,5*0.1625 | G30: =ROUND(G29*0.1625,1) -> 2578.1
A31: 12 | B31: Внешний транспорт | C31: Таб.5 §5 | F31: =ROUND((G29+G30),1)&"*0.364" -> 18443,6*0.364 | G31: =(G29+G30)*0.364 -> 6713.4558
A32: 13 | B32: Организация и ликвидация работ | C32: ОУ п.13 | F32: =ROUND((G29+G30),1)&"*0.06" -> 18443,6*0.06 | G32: =(G29+G30)*0.06 -> 1106.6136
A33: 14 | B33: ВСЕГО по разделу I с учетом спецрежима территории | C33: ОУ п.8в | F33: =ROUND((SUM(G29:G32)),1)&"*1.25" -> 26263,6*1.25 | G33: =ROUND(G29+G30+G31+G32,1)*1.25 -> 32829.5
A34: Раздел II, ЛАБОРАТОРНЫЕ РАБОТЫ
A35: =A33+1 -> 15 | B35: Полный комплекс определений физических свойств | C35: Таб.63 §8 | D35: 1обр | E35: =SUM(E19:E20)-SUM(E36:E38) -> 6 | F35: =E35&"*47.1" -> 6*47.1 | G35: =ROUND(E35*47.1,1) -> 282.6
A36: =A35+1 -> 16 | B36: Сокращенный комплекс физико-механических свойств грунтов при консолидированном срезе с нагрузкой до 0,6 МПа | C36: Таб.63 §11 | D36: 1обр | E36: 24 | F36: =E36&"*135.0" -> 24*135.0 | G36: =ROUND(E36*135,1) -> 3240
A37: =A36+1 -> 17 | B37: Сокращенный комплекс физико-механических свойств грунтов. Показатели сжимаемости и сопутствующие определения при компрессионных испытаниях с двумя ветвями нагрузки до 0,6 МПа | C37: Таб.63 §18 | D37: 1обр | E37: 6 | F37: =E37&"*147.5" -> 6*147.5 | G37: =ROUND(E37*147.5,1) -> 885
A38: =A37+1 -> 18 | B38: Определение характеристик прочности и деформируемости грунтов при трехосном сжатии. Дренированное испытание с предварительным уплотнением образца и отжатием воды из него только в процессе уплотнения) для определения характеристик прочности и деформируемости глинистых и биогенных грунтов в стабилизированном состоянии | C38: Таб.66 §4 | E38: 24 | F38: =E38&"*741.4" -> 24*741.4 | G38: =ROUND(E38*741.4,1) -> 17793.6
A39: =A38+1 -> 19 | B39: Относительная деформация пучения | C39: Табл.63 аналог §32 | D39: 1обр | E39: 12 | F39: =E39&"*186.4" -> 12*186.4 | G39: =ROUND(E39*186.4,1) -> 2236.8
A40: =A39+1 -> 20 | B40: Стандартный анализ воды | C40: Таб.73 §2 | D40: 1обр | E40: 3 | F40: =E40&"*67.3" -> 3*67.3 | G40: =ROUND(E40*67.3,1) -> 201.9
A41: =A40+1 -> 21 | B41: Коррозия грунтов к стали | C41: Таб.75 §4 | D41: 1обр | E41: 6 | F41: =E41&"*18.2" -> 6*18.2 | G41: =ROUND(E41*18.2,1) -> 109.2
A42: =A41+1 -> 22 | B42: Водная вытяжка | C42: Таб.71 §1 | D42: 1обр | E42: 6 | F42: =E42&"*48.8" -> 6*48.8 | G42: =ROUND(E42*48.8,1) -> 292.8
...

Sheet 1.2.2 ИГИ
A1: Смета №1.2.2
B2: на инженерно-геологические изыскания
A4: Наименование объекта: | C4: ='Форма сводной сметы '!N9 -> «Модернизация существующей инфраструктуры транспортировки и налива фракции С5, с целью обеспечения налива дополнительного объема фракции С5, в количестве 6 000 т/мес.»
C5: 56209 Нижнекамск. Эстакада
A6: Наименование организации-подрядчика | C6: ОАО "Сибнефтетранспроект"
A8: № п/п | B8: Наименование видов работ | C8: Обоснование стоимости | D8: Единица измерения | E8: Объем | F8: Расценка | G8: Стоимость
A9: Справочник базовых цен на инженерно-геологические и инженерно-экологические изыскания для строительства, ГОССТРОЙ РФ, 1999г.
A10: Раздел I, БУРОВЫЕ И ГОРНОПРОХОДЧЕСКИЕ РАБОТЫ
A11: 1 | B11: Инженерно-геологическая рекогносцировка при удовлетворительной проходимости | C11: Таб.9 §2 | D11: 1км | E11: 4.9 | F11: =ROUND(E11,0)&"*27.0" -> 5*27.0 | G11: =ROUND(E11*27,1) -> 132.3
A12: 2 | B12: Колонковое бурение скважин диаметром до 160 мм глубиной до 15 м (8скв.х15п.м.) в породах | C12: Таб.17 §1
B13: I категории | D13: 1 м | E13: 70 | F13: =E13&"*36.0*0.9" -> 70*36.0*0.9 | G13: =ROUND(E13*36*0.9,0) -> 2268
B14: II категории | D14: 1 м | E14: 200 | F14: =E14&"*38.4*0.9" -> 200*38.4*0.9 | G14: =ROUND(E14*38.4*0.9,1) -> 6912
B15: III категории | D15: 1 м | E15: 200 | F15: =E15&"*42.6*0.9" -> 200*42.6*0.9 | G15: =ROUND(E15*42.6*0.9,1) -> 7668
B16: IV категории | D16: 1 м | E16: 40 | F16: =E16&"*45.6*0.9" -> 40*45.6*0.9 | G16: =ROUND(E16*45.6*0.9,1) -> 1641.6
B17: Итого по пункту 2 | E17: =SUM(E13:E16) -> 510 | G17: =SUM(G13:G16) -> 18489.6
A18: 3 | B18: Отбор монолитов | C18: Таб.57
B19: из скважин с глубины до 10м | C19: §1 | D19: 1 мон | E19: 90 | F19: =E19&"*22.9" -> 90*22.9 | G19: =ROUND(E19*22.9,1) -> 2061
B20: из скважин с глубины св.10 до 20м | C20: §2 | D20: 1 мон | E20: 60 | F20: =E20&"*30.6" -> 60*30.6 | G20: =ROUND(E20*30.6,1) -> 1836
A21: 4 | B21: Гидрогеологические наблюдения при бурении скважин диаметром до 160 мм | C21: Таб.18 §1 гл.4 п.8 | D21: 1 м | E21: =E17*0.6 -> 306 | F21: =E21&"*1.6*0.6" -> 306*1.6*0.6 | G21: =ROUND(E21*1.6*0.6,1) -> 293.8
A22: 5 | B22: Статическое зондирование глубиной св.10 до 15 м | C22: Таб.45 §5 | D22: 1 испыт. | E22: 34 | F22: =E22&"*172.5" -> 34*172.5 | G22: =ROUND(E22*172.5,1) -> 5865
A23: 6 | B23: Проходка шурфов сечением 1,25 м2 глубиной до 10 м в породах III категории | C23: Таб.27§2 прим.2, 3 | D23: 1 м | E23: 24 | F23: =E23&"*70.7*0.75*1.3" -> 24*70.7*0.75*1.3 | G23: =ROUND(E23*70.7*0.75*1.3,0) -> 1654
A24: 7 | B24: Крепление шурфов в неусточивых породах глубиной св. 2.5 до 5 м | C24: Таб.32§2 | D24: 1 шурф | E24: 6 | F24: =E24&"*102.6" -> 6*102.6 | G24: =ROUND(E24*102.6,0) -> 616
A25: =A24+1 -> 8 | B25: Плановая и высотная привязка выработок II категории сложности при расстоянии между выработками | C25: Таб.93
B26: св. 100 до 200 м | C26: §3 | D26: 1т | E26: 34 | F26: =E26&"*14.4" -> 34*14.4 | G26: =ROUND(E26*14.4,1) -> 489.6
A27: =A25+1 -> 9 | B27: Предварительная разбивка II категории сложности при расстоянии между точками | C27: Таб.93
B28: св. 100 до 200 м | C28: §3 | D28: 1т | E28: =E26 -> 34 | F28: =E28&"*14.4" -> 34*14.4 | G28: =ROUND(E28*14.4,1) -> 489.6
A29: =A27+1 -> 10 | B29: Итого по пунктам 1-9 с учетом неблагоприятного периода | C29: Таб.2 §3 | F29: =G11+ROUND(SUM(G17:G28),1)&"*1.3" -> 31926,9*1.3 | G29: =(G11+SUM(G17:G28))*1.3 -> 41504.97
A30: =A29+1 -> 11 | B30: Внутренний транспорт | C30: Таб.4 §5 | F30: =ROUND(G29,1)&"*0.15" -> 41505*0.15 | G30: =ROUND(G29*0.15,1) -> 6225.7
A31: =A30+1 -> 12 | B31: Внешний транспорт | C31: Таб.5 §5 | F31: =ROUND((G29+G30),1)&"*0.364" -> 47730,7*0.364 | G31: =(G29+G30)*0.364 -> 17373.964
A32: =A31+1 -> 13 | B32: Организация и ликвидация работ | C32: ОУ п.13 | F32: =ROUND((G29+G30),1)&"*0.06" -> 47730,7*0.06 | G32: =(G29+G30)*0.06 -> 2863.8402
A33: =A32+1 -> 14 | B33: ВСЕГО по разделу I с учетом спецрежима территории | C33: ОУ п.8в | F33: =ROUND((SUM(G29:G32)),1)&"*1.25" -> 67968,5*1.25 | G33: =ROUND(G29+G30+G31+G32,1)*1.25 -> 84960.625
A34: Раздел II, ЛАБОРАТОРНЫЕ РАБОТЫ
A35: =A33+1 -> 15 | B35: Полный комплекс определений физических свойств | C35: Таб.63 §8 | D35: 1обр | E35: =SUM(E19:E20)-SUM(E36:E38) -> 72 | F35: =E35&"*47.1" -> 72*47.1 | G35: =ROUND(E35*47.1,1) -> 3391.2
A36: =A35+1 -> 16 | B36: Сокращенный комплекс физико-механических свойств грунтов при консолидированном срезе с нагрузкой до 0,6 МПа | C36: Таб.63 §11 | D36: 1обр | E36: 36 | F36: =E36&"*135.0" -> 36*135.0 | G36: =ROUND(E36*135,1) -> 4860
A37: =A36+1 -> 17 | B37: Сокращенный комплекс физико-механических свойств грунтов. Показатели сжимаемости и сопутствующие определения при компрессионных испытаниях с двумя ветвями нагрузки до 0,6 МПа | C37: Таб.63 §18 | D37: 1обр | E37: 6 | F37: =E37&"*147.5" -> 6*147.5 | G37: =ROUND(E37*147.5,1) -> 885
A38: =A37+1 -> 18 | B38: Определение характеристик прочности и деформируемости грунтов при трехосном сжатии. Дренированное испытание с предварительным уплотнением образца и отжатием воды из него только в процессе уплотнения) для определения характеристик прочности и деформируемости глинистых и биогенных грунтов в стабилизированном состоянии | C38: Таб.66 §4 | E38: 36 | F38: =E38&"*741.4" -> 36*741.4 | G38: =ROUND(E38*741.4,1) -> 26690.4
A39: =A38+1 -> 19 | B39: Относительная деформация пучения | C39: Табл.63 аналог §32 | D39: 1обр | E39: 18 | F39: =E39&"*186.4" -> 18*186.4 | G39: =ROUND(E39*186.4,1) -> 3355.2
A40: =A39+1 -> 20 | B40: Стандартный анализ воды | C40: Таб.73 §2 | D40: 1обр | E40: 6 | F40: =E40&"*67.3" -> 6*67.3 | G40: =ROUND(E40*67.3,1) -> 403.8
A41: =A40+1 -> 21 | B41: Коррозия грунтов к стали | C41: Таб.75 §4 | D41: 1обр | E41: 12 | F41: =E41&"*18.2" -> 12*18.2 | G41: =ROUND(E41*18.2,1) -> 218.4
A42: =A41+1 -> 22 | B42: Водная вытяжка | C42: Таб.71 §1 | D42: 1обр | E42: 12 | F42: =E42&"*48.8" -> 12*48.8 | G42: =ROUND(E42*48.8,1) -> 585.6
...

Sheet 2.1 Обслед
I1: Форма 2П
A3: =СВОД!C16 -> Смета №2.1
A4: на проектные работы
B6: Наименование объекта, стадии, | E6: ='Форма сводной сметы '!N9 -> «Модернизация существующей инфраструктуры транспортировки и налива фракции С5, с целью обеспечения налива дополнительного объема фракции С5, в количестве 6 000 т/мес.»
B7: этапа проектных работ
E8: =СВОД!B16 -> Обследование существующих зданий и сооружений
B10: Наименование проектной | E10: ='Форма сводной сметы '!F12 -> ОАО "СибНефтеТрансПроект"
B11: (изыскательской) организации
B13: Наименование организации | E13: ='Форма сводной сметы '!F15 -> ПАО «Нижнекамскнефтехим»
B14: заказчика
A16: № пп | B16: Характеристика предприятия, здания, сооружения или виды работ | D16: Номер частей, глав, таблиц, процентов, параграфов и пунктов указаний к разделу Справочника базовых цен на проектные и изыскательские работы для строительства | H16: Расчет стоимости: (a+bx)*Ki, или (объем строительно-монтажных работ) * проц./100 или количество x цена | I16: Стоимость, руб.
A17: 1 | B17: 2 | D17: 3 | H17: 4 | I17: 5
A18: Эстакады трубны
A19: 1 | B19: Выполнение инженерных обследований строительных конструкций каркасных одноэтажных зданий. II категория сложности работ. II категория сложности здания. Высота здания до 14 м. | D19: Справочник базовых цен на обмерные работы и обследования зданий и сооружений. 2016 г. Глава 3. Базовые цены на выполнение обмерных работ и обследований. Таблица 3. Базовые цены на выполнение инженерных обследований строительных конструкций одноэтажных зданий, п.12 B=0.4756 тыс.руб; Осн. показ. Х=916 (100 м3) Количество = 1 | H19: (A + B * Xзад) * Количество * Ктек * K1 (0 руб + 475.6 руб * 916) * 1 * 6.25 * 0.8 | I19: =ROUND((0 + 475.6 * 916) * 1 * 6.25 * 0.8,2) -> 2178248
B20: Коэффициенты
B21: инд.4кв.2024г.к 01.01.2001 на пр.раб. | D21: Ктек = 6.25 Письмо Минстроя России от 18.10.2024 №61327-ИФ/09
B22: Базовая цена для зданий и сооружений промышленного назначения (при пролетах более 12 м и высоте этажей более 6 м) определяется с применением коэффициента | D22: K1 = 0.8 Глава 2.1, п.2.1.2 (Ценообразующий)
A23: 2 | B23: Выполнение обмерных работ для каркасных одноэтажных зданий. II категория сложности работ. II категория сложности здания. Высота здания до 14 м. | D23: Справочник базовых цен на обмерные работы и обследования зданий и сооружений. 2016 г. Глава 3. Базовые цены на выполнение обмерных работ и обследований. Таблица 1. Базовые цены на выполнение обмерных работ для одноэтажных зданий, п.12 B=0.4136 тыс.руб; Осн. показ. Х=916 (100 м3) Количество = 1 | H23: (A + B * Xзад) * Количество * Ктек * K1 (0 руб + 413.6 руб * 916) * 1 * 6.25 * 0.8 | I23: =ROUND((0 + 413.6 * 916) * 1 * 6.25 * 0.8,2) -> 1894288
B24: Коэффициенты
B25: инд.4кв.2024г.к 01.01.2001 на пр.раб. | D25: Ктек = 6.25 Письмо Минстроя России от 18.10.2024 №61327-ИФ/09
B26: Базовая цена для зданий и сооружений промышленного назначения (при пролетах более 12 м и высоте этажей более 6 м) определяется с применением коэффициента | D26: K1 = 0.8 Глава 2.1, п.2.1.2 (Ценообразующий)
A27: 3 | B27: Выполнение инженерных обследований строительных конструкций каркасных одноэтажных зданий. II категория сложности работ. II категория сложности здания. Высота здания до 13 м. | D27: Справочник базовых цен на обмерные работы и обследования зданий и сооружений. 2016 г. Глава 3. Базовые цены на выполнение обмерных работ и обследований. Таблица 3. Базовые цены на выполнение инженерных обследований строительных конструкций одноэтажных зданий, п.11 B=0.4926 тыс.руб; Осн. показ. Х=455 (100 м3) Количество = 1 | H27: (A + B * Xзад) * Количество * Ктек * K1 (0 руб + 492.6 руб * 455) * 1 * 6.25 * 0.8 | I27: =ROUND((0 + 492.6 * 455) * 1 * 6.25 * 0.8,2) -> 1120665
B28: Коэффициенты
B29: инд.4кв.2024г.к 01.01.2001 на пр.раб. | D29: Ктек = 6.25 Письмо Минстроя России от 18.10.2024 №61327-ИФ/09
B30: Базовая цена для зданий и сооружений промышленного назначения (при пролетах более 12 м и высоте этажей более 6 м) определяется с применением коэффициента | D30: K1 = 0.8 Глава 2.1, п.2.1.2 (Ценообразующий)
A31: 4 | B31: Выполнение обмерных работ для каркасных одноэтажных зданий. II категория сложности работ. II категория сложности здания. Высота здания до 13 м. | D31: Справочник базовых цен на обмерные работы и обследования зданий и сооружений. 2016 г. Глава 3. Базовые цены на выполнение обмерных работ и обследований. Таблица 1. Базовые цены на выполнение обмерных работ для одноэтажных зданий, п.11 B=0.4444 тыс.руб; Осн. показ. Х=455 (100 м3) Количество = 1 | H31: (A + B * Xзад) * Количество * Ктек * K1 (0 руб + 444.4 руб * 455) * 1 * 6.25 * 0.8 | I31: =ROUND((0 + 444.4 * 455) * 1 * 6.25 * 0.8,2) -> 1011010
B32: Коэффициенты
B33: инд.4кв.2024г.к 01.01.2001 на пр.раб. | D33: Ктек = 6.25 Письмо Минстроя России от 18.10.2024 №61327-ИФ/09
B34: Базовая цена для зданий и сооружений промышленного назначения (при пролетах более 12 м и высоте этажей более 6 м) определяется с применением коэффициента | D34: K1 = 0.8 Глава 2.1, п.2.1.2 (Ценообразующий)
A35: 5 | B35: Выполнение инженерных обследований строительных конструкций каркасных одноэтажных зданий. II категория сложности работ. II категория сложности здания. Высота здания до 4 м. | D35: Справочник базовых цен на обмерные работы и обследования зданий и сооружений. 2016 г. Глава 3. Базовые цены на выполнение обмерных работ и обследований. Таблица 3. Базовые цены на выполнение инженерных обследований строительных конструкций одноэтажных зданий, п.2 B=0.6432 тыс.руб; Осн. показ. Х=307 (100 м3) Количество = 1 | H35: (A + B * Xзад) * Количество * Ктек * K1 (0 руб + 643.2 руб * 307) * 1 * 6.25 * 0.8 | I35: =ROUND((0 + 643.2 * 307) * 1 * 6.25 * 0.8,2) -> 987312
B36: Коэффициенты
B37: инд.4кв.2024г.к 01.01.2001 на пр.раб. | D37: Ктек = 6.25 Письмо Минстроя России от 18.10.2024 №61327-ИФ/09
B38: Базовая цена для зданий и сооружений промышленного назначения (при пролетах более 12 м и высоте этажей более 6 м) определяется с применением коэффициента | D38: K1 = 0.8 Глава 2.1, п.2.1.2 (Ценообразующий)
A39: 6 | B39: Выполнение обмерных работ для каркасных одноэтажных зданий. II категория сложности работ. II категория сложности здания. Высота здания до 4 м. | D39: Справочник базовых цен на обмерные работы и обследования зданий и сооружений. 2016 г. Глава 3. Базовые цены на выполнение обмерных работ и обследований. Таблица 1. Базовые цены на выполнение обмерных работ для одноэтажных зданий, п.2 B=0.7186 тыс.руб; Осн. показ. Х=307 (100 м3) Количество = 1 | H39: (A + B * Xзад) * Количество * Ктек * K1 (0 руб + 718.6 руб * 307) * 1 * 6.25 * 0.8 | I39: =ROUND((0 + 718.6 * 307) * 1 * 6.25 * 0.8,2) -> 1103051
B40: Коэффициенты
B41: инд.4кв.2024г.к 01.01.2001 на пр.раб. | D41: Ктек = 6.25 Письмо Минстроя России от 18.10.2024 №61327-ИФ/09
B42: Базовая цена для зданий и сооружений промышленного назначения (при пролетах более 12 м и высоте этажей более 6 м) определяется с применением коэффициента | D42: K1 = 0.8 Глава 2.1, п.2.1.2 (Ценообразующий)
A43: Насосная Т-8/2
A44: 7 | B44: Выполнение инженерных обследований строительных конструкций каркасных одноэтажных зданий. II категория сложности работ. II категория сложности здания. Высота здания до 12 м. | D44: Справочник базовых цен на обмерные работы и обследования зданий и сооружений. 2016 г. Глава 3. Базовые цены на выполнение обмерных работ и обследований. Таблица 3. Базовые цены на выполнение инженерных обследований строительных конструкций одноэтажных зданий, п.10 B=0.509 тыс.руб; Осн. показ. Х=131 (100 м3) Количество = 1 | H44: (A + B * Xзад) * Количество * Ктек * K1 (0 руб + 509 руб * 131) * 1 * 6.25 * 0.8 | I44: =ROUND((0 + 509 * 131) * 1 * 6.25 * 0.8,2) -> 333395
B45: Коэффициенты
...

Sheet 3.1 ТХ
I1: Форма 2П
A3: =СВОД!C21 -> Смета №3.1
A4: на проектные работы
B6: Наименование объекта, стадии, | E6: ='Форма сводной сметы '!N9 -> «Модернизация существующей инфраструктуры транспортировки и налива фракции С5, с целью обеспечения налива дополнительного объема фракции С5, в количестве 6 000 т/мес.»
B7: этапа проектных работ
E8: =СВОД!B21 -> Технология
B10: Наименование проектной | E10: ='Форма сводной сметы '!F12 -> ОАО "СибНефтеТрансПроект"
B11: (изыскательской) организации
B13: Наименование организации | E13: ='Форма сводной сметы '!F15 -> ПАО «Нижнекамскнефтехим»
B14: заказчика
A16: № пп | B16: Характеристика предприятия, здания, сооружения или виды работ | D16: Номер частей, глав, таблиц, процентов, параграфов и пунктов указаний к разделу Справочника базовых цен на проектные и изыскательские работы для строительства | H16: Расчет стоимости: (a+bx)*Ki, или (объем строительно-монтажных работ) * проц./100 или количество x цена | I16: Стоимость, руб.
A17: 1 | B17: 2 | D17: 3 | H17: 4 | I17: 5
A18: Замена запорной арматуры - узел из 2 ед. для насосов Н-5, Н-6 в насосной ЭП-616
A19: 1 | B19: Здания и сооружения. Электрифицированные задвижки на сетях МЦК, сосредоточенные в одном месте | D19: Объекты нефтеперерабатывающей и нефтехимической промышленности. 2015 г. Таблица 8. Объекты подсобно-производственного, вспомогательного и общезаводского назначения, внутриплощадочные инженерные сети, схема планировочной организации земельного участка, п.1.93 A=16.5 тыс.руб.; B=7.7 тыс.руб.; Осн. показ. Х=2 (задвижка) Количество = 1 | H19: (A + B * Xзад) * Количество * Кст * Ктек * K1 (16500 руб + 7700 руб * 2) * 1 * 0.6 * 6.25 * 1.2 | I19: 143550
B20: Коэффициенты
B21: Стадия: Рабочая документация | D21: Кст = 0.6
B22: инд.4кв.2024г.к 01.01.2001 на пр.раб. | D22: Ктек = 6.25 Письмо Минстроя России от 18.10.2024 №61327-ИФ/09
B23: Цена разработки проектной и рабочей документации на реконструкцию действующих предприятий, цехов, зданий и сооружений определяется по ценам Справочников базовых цен на проектные работы для строительства. При этом при определении стоимости проектных работ от стоимости реконструкции применяется коэффициент | D23: K1 = 1.2 МУ 2009 г. Часть III п.3.4 (Ценообразующий)
A24: Замена участка трубопровода рег. № 2112х длиной 352 м. от ЭП-616 до ИП-10
A25: 2 | B25: Внутриплощадочные инженерные сети. Тепло-, газо-, материалопроводы на эстакадах. Длина трассы свыше 0.3 до 0.5 км. | D25: Объекты нефтеперерабатывающей и нефтехимической промышленности. 2015 г. Таблица 8. Объекты подсобно-производственного, вспомогательного и общезаводского назначения, внутриплощадочные инженерные сети, схема планировочной организации земельного участка, п.2.5 A=1712.5 тыс.руб.; B=1007.8 тыс.руб.; Осн. показ. Х=0.352 (км) Количество = 1 | H25: (A + B * Xзад) * Количество * Кст * Ктек * K1 (1712500 руб + 1007800 руб * 0.352) * 1 * 0.6 * 6.25 * 1.2 | I25: =9302605.2*0.8 -> 7442084.2
B26: Коэффициенты
B27: Стадия: Рабочая документация | D27: Кст = 0.6
B28: инд.4кв.2024г.к 01.01.2001 на пр.раб. | D28: Ктек = 6.25 Письмо Минстроя России от 18.10.2024 №61327-ИФ/09
B29: Цена разработки проектной и рабочей документации на реконструкцию действующих предприятий, цехов, зданий и сооружений определяется по ценам Справочников базовых цен на проектные работы для строительства. При этом при определении стоимости проектных работ от стоимости реконструкции применяется коэффициент | D29: K1 = 1.2 МУ 2009 г. Часть III п.3.4 (Ценообразующий)
A30: Замена расходомера с обвязкой на ИП-10
A31: 3 | B31: Здания и сооружения. Узлы коммерческого учета | D31: Объекты нефтеперерабатывающей и нефтехимической промышленности. 2015 г. Таблица 8. Объекты подсобно-производственного, вспомогательного и общезаводского назначения, внутриплощадочные инженерные сети, схема планировочной организации земельного участка, п.1.95 A=385 тыс.руб.; Количество = 1 (узел) | H31: A * Количество * Кст * Ктек * K1 385000 руб * 1 * 0.6 * 6.25 * 1.2 | I31: =1732500*0.3 -> 519750
B32: Коэффициенты
B33: Стадия: Рабочая документация | D33: Кст = 0.6
B34: инд.4кв.2024г.к 01.01.2001 на пр.раб. | D34: Ктек = 6.25 Письмо Минстроя России от 18.10.2024 №61327-ИФ/09
B35: Цена разработки проектной и рабочей документации на реконструкцию действующих предприятий, цехов, зданий и сооружений определяется по ценам Справочников базовых цен на проектные работы для строительства. При этом при определении стоимости проектных работ от стоимости реконструкции применяется коэффициент | D35: K1 = 1.2 МУ 2009 г. Часть III п.3.4 (Ценообразующий)
A36: Замена насосов - 2 ед. в насосной Т-8/2
A37: 4 | B37: Здания и сооружения. Насосная перекачки нефтепродуктов. Производительность свыше 100 до 1000 м3/час. | D37: Объекты нефтеперерабатывающей и нефтехимической промышленности. 2015 г. Таблица 8. Объекты подсобно-производственного, вспомогательного и общезаводского назначения, внутриплощадочные инженерные сети, схема планировочной организации земельного участка, п.1.45 A=609.6 тыс.руб.; B=0.54 тыс.руб.; Осн. показ. Х=280 (м3/час) Количество = 1 | H37: (A + B * Xзад) * Количество * Кст * Ктек * K1 (609600 руб + 540 руб * 280) * 1 * 0.6 * 6.25 * 1.2 | I37: =3423600 -> 3423600
B38: Коэффициенты
B39: Стадия: Рабочая документация | D39: Кст = 0.6
B40: инд.4кв.2024г.к 01.01.2001 на пр.раб. | D40: Ктек = 6.25 Письмо Минстроя России от 18.10.2024 №61327-ИФ/09
B41: Цена разработки проектной и рабочей документации на реконструкцию действующих предприятий, цехов, зданий и сооружений определяется по ценам Справочников базовых цен на проектные работы для строительства. При этом при определении стоимости проектных работ от стоимости реконструкции применяется коэффициент | D41: K1 = 1.2 МУ 2009 г. Часть III п.3.4 (Ценообразующий)
A42: Трубопроводы подключения к емкостям Е-16/1,2, емкости Е-2/1 длиной 409 м.
A43: 5 | B43: Внутриплощадочные инженерные сети. Тепло-, газо-, материалопроводы на эстакадах. Длина трассы свыше 0.3 до 0.5 км. | D43: Объекты нефтеперерабатывающей и нефтехимической промышленности. 2015 г. Таблица 8. Объекты подсобно-производственного, вспомогательного и общезаводского назначения, внутриплощадочные инженерные сети, схема планировочной организации земельного участка, п.2.5 A=1712.5 тыс.руб.; B=1007.8 тыс.руб.; Осн. показ. Х=0.409 (км) Количество = 1 | H43: (A + B * Xзад) * Количество * Кст * Ктек * K1 (1712500 руб + 1007800 руб * 0.409) * 1 * 0.6 * 6.25 * 1.2 | I43: =9561105.9*0.8 -> 7648884.7
B44: Коэффициенты
B45: Стадия: Рабочая документация | D45: Кст = 0.6
...

Sheet 3.2 ЭС
I1: Форма 2П
A3: =СВОД!C22 -> Смета №3.2
A4: на проектные работы
B6: Наименование объекта, стадии, | E6: ='Форма сводной сметы '!N9 -> «Модернизация существующей инфраструктуры транспортировки и налива фракции С5, с целью обеспечения налива дополнительного объема фракции С5, в количестве 6 000 т/мес.»
B7: этапа проектных работ
E8: =СВОД!B22 -> Сети электроснабжения
B10: Наименование проектной | E10: ='Форма сводной сметы '!F12 -> ОАО "СибНефтеТрансПроект"
B11: (изыскательской) организации
B13: Наименование организации | E13: ='Форма сводной сметы '!F15 -> ПАО «Нижнекамскнефтехим»
B14: заказчика
A16: № пп | B16: Характеристика предприятия, здания, сооружения или виды работ | D16: Номер частей, глав, таблиц, процентов, параграфов и пунктов указаний к разделу Справочника базовых цен на проектные и изыскательские работы для строительства | H16: Расчет стоимости: (a+bx)*Ki, или (объем строительно-монтажных работ) * проц./100 или количество x цена | I16: Стоимость, руб.
A17: 1 | B17: 2 | D17: 3 | H17: 4 | I17: 5
A18: Проектирование системы бесперебойного питания
A19: 1 | B19: Электропитание приборов в газовых объектах | D19: Газооборудование и газоснабжение промышленных предприятий, зданий и сооружений. 2015 г. Таблица 19. Электроснабжение и молниезащита, п.1 A=11.083 тыс.руб; Количество = 6 (панель) | H19: A * Количество * Кст * Ктек 11083 руб * 6 * 0.6 * 6.25 | I19: =ROUND(11083 * 6 * 0.6 * 6.25,2) -> 249367.5
B20: Коэффициенты
B21: Стадия: Рабочая документация | D21: Кст = 0.6
B22: инд.4кв.2024г.к 01.01.2001 на пр.раб. | D22: Ктек = 6.25 Письмо Минстроя России от 18.10.2024 №61327-ИФ/09
A23: Установка низковольтных щитов управления (НКУ-0,4 кВ)
A24: 2 | B24: Установка щитов станции управления в здании. Размер свыше 25 до 30 м2. | D24: Объекты магистрального трубопроводного транспорта нефти. 2012 г. Таблица 4. Отдельные сооружения объектов магистрального трубопроводного транспорта нефти, п.24.4 A=42.24 тыс.руб; Количество = 1 (1 установка) | H24: A * Количество * Кст * Ктек 42240 руб * 1 * 0.6 * 6.25 | I24: =ROUND(42240 * 1 * 0.6 * 6.25,2) -> 158400
B25: Коэффициенты
B26: Стадия: Рабочая документация | D26: Кст = 0.6
B27: инд.4кв.2024г.к 01.01.2001 на пр.раб. | D27: Ктек = 6.25 Письмо Минстроя России от 18.10.2024 №61327-ИФ/09
A28: ЧРП
A29: 3 | B29: Частотно-регулируемый привод, расположенный в отдельном здании | D29: Объекты магистрального трубопроводного транспорта нефти. 2012 г. Таблица 4. Отдельные сооружения объектов магистрального трубопроводного транспорта нефти п.47 A=400.91 тыс.руб; Количество = 2 (1 сооружение) | H29: A * Количество * Кст * Ктек * K1 400910 руб * 2 * 0.6 * 6.25 * 0.5 | I29: =ROUND(400910 * 2 * 0.6 * 6.25 * 0.5,2) -> 1503412.5
B30: Коэффициенты
B31: Стадия: Рабочая документация | D31: Кст = 0.6
B32: инд.4кв.2024г.к 01.01.2001 на пр.раб. | D32: Ктек = 6.25 Письмо Минстроя России от 18.10.2024 №61327-ИФ/09
B33: Цена привязки типовой или повторно применяемой проектной документации с внесением в нее изменений в подземную и надземную часть определяется по ценам Справочников с применением коэффициента | D33: K1 = 0.5 МУ 2009 г. Часть III п.3.2 (Ценообразующий)
A34: Прокладка кабельных линий 0,4/0,23 кВ до потребителей
A35: 4 | B35: Внутриплощадочные инженерные сети. Электрокабельные сети, сети КиА, сети связи. В том числе: по непроходным кабельным эстакадам. | D35: Объекты нефтеперерабатывающей и нефтехимической промышленности. 2015 г. Таблица 8. Объекты подсобно-производственного, вспомогательного и общезаводского назначения, внутриплощадочные инженерные сети, схема планировочной организации земельного участка, п.2.10 B=433.69 тыс.руб.; Осн. показ. Х=0.5 (км) Количество = 1 | H35: (A + B * Xзад) * Количество * Кст * Ктек (0 руб + 433690 руб * 0.5) * 1 * 0.6 * 6.25 * 0.666 | I35: =ROUND((0 + 433690 * 0.5) * 1 * 0.6 * 6.25 * 0.666,2) -> 541570.39
B36: Коэффициенты
B37: Стадия: Рабочая документация | D37: Кст = 0.6
B38: инд.4кв.2024г.к 01.01.2001 на пр.раб. | D38: Ктек = 6.25 Письмо Минстроя России от 18.10.2024 №61327-ИФ/09
B39: Разделы документации
B40: 1. Инженерное оборудование. Технологические решения: система электроснабжения | D40: 0.666
A41: Проектирование заземляющего устройства зданий и сооружений
A42: 5 | B42: Объединенные заземляющие устройства нефтеперекачивающей станции и подстанции напряжением 110 кВ и выше с установкой выравнивающих и защитных контуров. Значения удельных сопротивлений грунта от 1 до 50000 Ом/см. | D42: Объекты магистрального трубопроводного транспорта нефти. 2012 г. Таблица 4. Отдельные сооружения объектов магистрального трубопроводного транспорта нефти, п.22.1 A=8.87 тыс.руб; Количество = 6 (1 объект) | H42: A * Количество * Кст * Ктек 8870 руб * 6 * 0.6 * 6.25 | I42: =ROUND(8870 * 6 * 0.6 * 6.25,2) -> 199575
B43: Коэффициенты
B44: Стадия: Рабочая документация | D44: Кст = 0.6
B45: инд.4кв.2024г.к 01.01.2001 на пр.раб. | D45: Ктек = 6.25 Письмо Минстроя России от 18.10.2024 №61327-ИФ/09
...

Sheet 3.3 АСУТП
B1: 5
B4: =СВОД!C23 -> Смета №3.3
B5: =СВОД!B23 -> Автоматизированная система управления технологическим процессом (АСУ ТП)
B6: Наименование объекта | G6: ='Форма сводной сметы '!N9 -> «Модернизация существующей инфраструктуры транспортировки и налива фракции С5, с целью обеспечения налива дополнительного объема фракции С5, в количестве 6 000 т/мес.»
B8: Стадия | G8: Рабочая документация
B10: Наименование организации Заказчика | G10: ='Форма сводной сметы '!F15 -> ПАО «Нижнекамскнефтехим»
B11: Наименование проектной организации | G11: ='Форма сводной сметы '!F12 -> ОАО "СибНефтеТрансПроект"
B13: Смета составлена на основании "СБЦ на проектные работы в строительстве "Автоматизированные системы управления технологическими процессами (АСУТП)" (2016г.)
B15: 1. Краткая характеристика объекта автоматизации:
B16: Новое строительство
B17: Новое строительство
B18: Реконструкция, модернизация, тех. перевооружение
B19: Требование на разработку ТЗ к созданию АСУ ТП: | H19: Нет
H20: Да
H21: Нет
B22: Требуемые части документации АСУ ТП:
D23: ОР | E23: ОО | F23: ИО | G23: ТО | H23: МО | I23: ПО
D24: Да | E24: Нет | F24: Да | G24: Да | H24: Да | I24: Да
D25: Да | E25: Да | F25: Да | G25: Да | H25: Да | I25: Да
D26: Нет | E26: Нет | F26: Нет | G26: Нет | H26: Нет | I26: Нет
B27: 2. Исходные данные:
B28: Трудоемкость разработки ТЗ на создание АСУ ТП
B29: Основные факторы, определяющие трудоемкость разработки | M29: Количество баллов
B30: № пп | C30: Фактор | E30: Наименование | H30: Определение | M30: ТЗ
B31: 1 | C31: Ф1 | E31: Степень научно-технической новизны (ТОУ) | H31: I степень - ТОУ имеет действующие аналоги в России и, возможно за рубежом | M31: =IF(H19="Да",SUMIF($H32:$L35,$H31,M32:N35),0) -> 0
B32: 1.1 | H32: I степень - ТОУ имеет действующие аналоги в России и, возможно за рубежом | M32: 1
B33: 1.2 | H33: II степень - ТОУ имеет действующие аналоги только за рубежом | M33: 2
B34: 1.3 | H34: III степень - ни с конструкторской, ни с технологической точек зрения ТОУ не является принципиально новым объектом, но действующих аналогов не имеет | M34: 4
B35: 1.4 | H35: IV степень - с конструкторской и (или) технологической точек зрения ТОУ является принципиально новым объектом | M35: 8
B36: 2 | C36: Ф2 | E36: Характер протекания управляемого технологического процесса во времени | H36: Непрерывный (с длительным поддержанием режимов, близких к установившимся, и практически безостановочной подачей сырья и реагентов) | M36: =IF(H19="Да",SUMIF($H37:$L42,$H36,M37:N42),0) -> 0
B37: 2.1 | H37: Непрерывный (с длительным поддержанием режимов, близких к установившимся, и практически безостановочной подачей сырья и реагентов) | M37: 1
B38: 2.2 | H38: Полунепрерывный (непрерывный, с существенными для управления переходными режимами, вызванными либо добавками (заменами) сырья или реагентов, либо выдачей продукции) | M38: 2
B39: 2.3 | H39: Непрерывно-дискретный - I (сочетающий непрерывные и прерывистые режимы на различных стадиях процесса) | M39: 4
B40: 2.4 | H40: Непрерывно-дискретный - II (сочетающий непрерывные и прерывистые режимы с малой длительностью непрерывных режимов в аварийных условиях) | M40: 5
B41: 2.5 | H41: Циклический (прерывистый, с существенной для управления длительностью интервалов непрерывного функционирования и циклическим следованием интервалов с различными режимами) | M41: 4
B42: 2.6 | H42: Дискретный (прерывистый, с малой, несущественной для управления, длительностью непрерывных технологических операций) | M42: 3
B43: 3 | C43: Ф3 | E43: Количество технологических операций, выполняемых на ТОУ | H43: свыше 5 до 10 | M43: =IF(H19="Да",SUMIF($H44:$L51,$H43,M44:N51),0) -> 0
B44: 3.1 | H44: до 5 | M44: 1
B45: 3.2 | H45: свыше 5 до 10 | M45: 2
B46: 3.3 | H46: свыше 10 до 20 | M46: 4
...

Sheet ПромБез
I1: Форма 2П
A3: =СВОД!C24 -> Смета №3.4
A4: на проектные работы
B6: Наименование объекта, стадии, | E6: ='Форма сводной сметы '!N9 -> «Модернизация существующей инфраструктуры транспортировки и налива фракции С5, с целью обеспечения налива дополнительного объема фракции С5, в количестве 6 000 т/мес.»
B7: этапа проектных работ
E8: =СВОД!B24 -> Промышленная безопасность
B10: Наименование проектной | E10: ='Форма сводной сметы '!F12 -> ОАО "СибНефтеТрансПроект"
B11: (изыскательской) организации
B13: Наименование организации | E13: ='Форма сводной сметы '!F15 -> ПАО «Нижнекамскнефтехим»
B14: заказчика
A16: № пп | B16: Характеристика предприятия, здания, сооружения или виды работ | D16: Номер частей, глав, таблиц, процентов, параграфов и пунктов указаний к разделу Справочника базовых цен на проектные и изыскательские работы для строительства | H16: Расчет стоимости: (a+bx)*Ki, или (объем строительно-монтажных работ) * проц./100 или количество x цена | I16: Стоимость, руб.
A17: 1 | B17: 2 | D17: 3 | H17: 4 | I17: 5
A18: 1 | B18: Подраздел «Промышленная безопасность» | D18: Объекты магистрального трубопроводного транспорта нефти. 2012 г. Таблица 5. Раздел "Промышленная безопасность". Раздел "Мероприятия по гражданской обороне. Мероприятия по предупреждению чрезвычайных ситуаций природного и техногенного характера" (стадия "Проектная документация") п.3 A=144 тыс.руб; Количество = 1 (декларируемый объект) | H18: Полный комплекс работ (100%): A * Количество * Кст * Ктек 144000 руб * 1 * 1 * 6.25 | I18: =ROUND(144000 * 1 * 1 * 6.25,2) -> 900000
B19: Коэффициенты
B20: Стадия: Проектная документация | D20: Кст = 1
B21: инд.4кв.2024г.к 01.01.2001 на пр.раб. | D21: Ктек = 6.25 Письмо Минстроя России от 18.10.2024 №61327-ИФ/09
A22: 2 | B22: Итого по смете: | I22: =ROUND(($I$18),2) -> 900000
B23: Всего по смете: | I23: =I22 -> 900000

Sheet Расч
H1: Форма 3П
H2: Приложение № ___
H3: к договору №______________________
C4: СМЕТА на проектные работы № | D4: =СВОД!A25 -> 3.5
B6: Наименование предприятия, здания, сооружения:
B9: Стадия: | C9: этап:
B10: Проектная документация | C10: =СВОД!B25 -> Гидравлические расчеты
B11: Наименование организации исполнителя:
B12: ='Форма сводной сметы '!F12 -> ОАО "СибНефтеТрансПроект"
B13: Наименование организации заказчика:
B14: ='Форма сводной сметы '!F15 -> ПАО «Нижнекамскнефтехим»
B16: Раздел 1. Определение трудоемкости (трудозатрат) выполняемой работы
A18: № п/п | B18: Перечень выполняемых работ | C18: Исполнители | F18: Количество человеко-дней (гр.4 * гр.5) | G18: Средняя зарплата за 1 день | H18: Оплата труда (всего) (гр.6 * гр.7)
C19: должность | D19: Количество
D20: чел | E20: дн
A21: 1 | B21: 2 | C21: 3 | D21: 4 | E21: 5 | F21: 6 | G21: 7 | H21: 8
A22: Разработка документации (вид работ/сооружение) | K22: среднечасов. ЗП
A23: 1 | B23: =C10 -> Гидравлические расчеты | C23: Начальник отдела | D23: 1 | E23: 1 | F23: =E23*D23 -> 1 | G23: =K23*8 -> 40079.68 | H23: =F23*G23 -> 40079.68 | J23: Начальник отдела | K23: 5009.96
C24: Главный специалист | D24: 1 | E24: 1 | F24: =E24*D24 -> 1 | G24: =K24*8 -> 30059.76 | H24: =F24*G24 -> 30059.76 | J24: Главный специалист | K24: 3757.47
C25: Руководитель группы | D25: 1 | E25: 0 | F25: =E25*D25 -> 0 | G25: =K25*8 -> 27053.76 | H25: =F25*G25 -> 0 | J25: Руководитель группы | K25: 3381.72
C26: Ведущий инженер | D26: 1 | E26: 8 | F26: =E26*D26 -> 8 | G26: =K26*8 -> 20039.84 | H26: =F26*G26 -> 160318.72 | J26: Ведущий инженер | K26: 2504.98
C27: Инженер 1-й категории | D27: 1 | E27: 9 | F27: =E27*D27 -> 9 | G27: =K27*8 -> 18063.84 | H27: =F27*G27 -> 162574.56 | J27: Инженер 1-й категории | K27: 2257.98
C28: Инженер 2-й категории | D28: 1 | E28: 0 | F28: =E28*D28 -> 0 | G28: =K28*8 -> 17033.84 | H28: =F28*G28 -> 0 | J28: Инженер 2-й категории | K28: 2129.23
C29: Инженер 3-й категории | D29: 1 | E29: 0 | F29: =E29*D29 -> 0 | G29: =K29*8 -> 16031.84 | H29: =F29*G29 -> 0 | J29: Инженер 3-й категории | K29: 2003.98
C30: Инженер | D30: 1 | E30: 0 | F30: =E30*D30 -> 0 | G30: =K30*8 -> 14528.84 | H30: =F30*G30 -> 0 | J30: Инженер | K30: 1816.105
B31: Итого з/п непосредственных исполнителей | H31: =SUM(H23:H30) -> 393032.72
B32: Раздел 2. Определение стоимости работ, перечисленных в разделе 1
A33: № п/п | B33: Наименование показателей | G33: Единица измерения | H33: Сумма
A34: 1 | B34: 2 | G34: 3 | H34: 4
A35: .1 | B35: Итого заработная плата непосредственных исполнителей (итог по гр.8 раздела 1) | G35: руб. | H35: =H31 -> 393032.72
A36: .2 | B36: Общая стоимость работы (стр.1) | G36: руб. | H36: =H35 -> 393032.72
A37: .3 | B37: НДС 20% | G37: руб. | H37: =H36*0.2 -> 78606.544
A38: .4 | B38: Всего с НДС | G38: руб. | H38: =H36+H37 -> 471639.26
B39: Средняя стоимость ч.ч. | G39: руб. | H39: =H31/SUM(F23:F30)/8 -> 2585.7416

Sheet РД_BOQ 
