Workbook

Sheet Лист1
C1: Форма для заполнения по тендерной процедуре №ТП.....
A2: Разработка проектной и рабочей документации объекта "Перевод установки получения масляных альдегидов методом оксосинтеза на Rh катализатор с наращением мощности по 2-ЭГ и 2-ЭГК на АО «Сибур-Химпром»
A4: № п/п | B4: Наименование показателей | C4: Претендент
A6: Соответствие техническому заданию.
A7: п. 4.10 Смета на строительство объектов капитального строительства
A8: 1. | B8: Разработка сметной документации в 2-х форматах: - ресурсным методом -базисно индексным методом
A9: 2. | B9: Базисно-индексный метод:
A10: 2.1 | B10: По основным (ценообразующим) материалам и вспомогательному оборудованию провести мониторинг рынка поставщиков
A11: 2.2 | B11: Предоставить ведомости объемов работ к каждому расчету за подписью разработчика марки проекта.
A12: 2.3 | B12: Предоставить ведомости материалов с построчной стоимостью ресурсов
A13: 2.4 | B13: Предоставить ведомости оборудования с построчной стоимостью ресурсов
A14: 2.5 | B14: В локальных сметных расчетах учесть разделение ТМЦ поставки Заказчик / Подрядчик.
A15: 2.6 | B15: Базисно-индексным методом: локальные сметные расчеты выполнить в сметно-нормативной базе ФЕР-2001 в ред.2017 (с изм.1-4) в программном комплексе «Гранд-Смета» с применением индексов пересчета по статьям затрат Пермского Регионального Центра Ценообразования (ПРЦЦС).
A16: 2.7 | B16: Сметную документацию (для БИМ) сформировать в составе: - сводный сметный расчет; - объектные сметные расчеты; - локальные сметные расчеты ; - ведомости объемов работ; - ведомости ресурсов; - ведомости оборудования
A17: 3. | B17: Ресурсный метод:
A18: 3.1 | B18: Ресурсные ведомости под каждую единичную расценку (ЕР) и титул
A19: 3.2 | B19: Для определения стоимости ресурсов использовать текущие цены на ресурсы, согласованные с Заказчиком.
... A26: 6. | B26: Предоставить пояснительную записку по формированию стоимости с указанием перечня затрат, возможных к реализации, но не учтенных в стоимости строительства

Sheet СВОД
C1: Форма для заполнения по тендерной процедуре № __________
A3: Разработка рабочей документации по проекту «Техническое перевооружение узла очистки, осушки и регазификации этилена на площадке Казанской компрессорной станции магистрального продуктопровода (этилен) Нижнекамск-Казань Татарстанского линейно-производственного управления ООО «УЭТП-НКНХ»
A5: № п/п | B5: Наименование показателей | C5: Стоимость, руб. без НДС
A7: 1 | B7: Итого стоимость предложения | C7: =КП!G20 -> 82828575
B8: Итого стоимость предложения | C8: =C7 -> 82828575
B11: ОАО "Сибнефтетранспроект"
B13: Главный инженер
B14: Крупников Антон Владимирович
B15: 45825 | D15: ( подпись, M.П.)

Sheet КП
G1: Форма для заполнения по тендерной процедуре №…….
A3: Разработка рабочей документации по проекту «Техническое перевооружение узла очистки, осушки и регазификации этилена на площадке Казанской компрессорной станции магистрального продуктопровода (этилен) Нижнекамск-Казань Татарстанского линейно-производственного управления ООО «УЭТП-НКНХ». Календарный план.
A5: Этапы № п/п | B5: Наименование Этапа | C5: Отчетная документация | D5: Дата начала | E5: Дата окончания* | F5: Перечень пунктов из формы ТКП входящих в этап | G5: Стоимость, руб. без НДС
D6: Перечень пунктов из | E6: Перечень пунктов из | F6: Перечень пунктов из
A7: 1 | B7: =РД!B182 -> Сбор исходных данных. | C7: Отчеты | D7: 45839 | E7: =E9 -> 45912 | F7: 4.1. | G7: =РД!C182 -> 2466021.5
A8: 2 | B8: =РД!B160 -> Инженерные Изыскания | C8: Отчеты | D8: =D7+14 -> 45853 | E8: =E7 -> 45912 | F8: 3.1.-3.3. | G8: =РД!C160 -> 8533475.6
A9: 3 | B9: =РД!B190 -> Обследование существующих строительных конструкций | C9: Отчеты | D9: =D7+14 -> 45853 | E9: =D9+45+14 -> 45912 | F9: 5.1.-5.3. | G9: =РД!C190 -> 6258438.2
A10: 4 | B10: =РД!B212 -> Проектное технологическое обследование объекта | C10: Отчеты | D10: =D9 -> 45853 | E10: =E9 -> 45912 | F10: 6.1.-6.2. | G10: =РД!C212 -> 5138011.9
A11: 5 | B11: =РД!B220 -> Разработка рабочей документации | C11: Документация | D11: =E8-18 -> 45894 | E11: =D11+46+14 -> 45954 | F11: 7.1.-7.8. | G11: =РД!C220 -> 25983500
A12: 6 | B12: =РД!B53 -> Пояснительная записка для ЭПБ на техническое перевооружение | C12: Документация | D12: =D11 -> 45894 | E12: =E11 -> 45954 | F12: 2.1.-2.9 | G12: =РД!C53 -> 6422003.9
A13: 7 | B13: =РД!B373 -> Выполнение проектных расчетов. Оформление передача заказчику. | C13: Расчеты | D13: =D14 -> 45894 | E13: =E14 -> 45954 | F13: 13.1.-13.7. | G13: =РД!C373 -> 5919023.3
A14: 8 | B14: =РД!B329 -> Смежные работы | C14: Отчеты | D14: =D11 -> 45894 | E14: =E11 -> 45954 | F14: 11.1.-11.5. | G14: =РД!C329 -> 12971781
A15: 9 | B15: =РД!B10 -> Расчет ключевых физических объемов | C15: Отчеты | D15: =D14+14 -> 45908 | E15: =E14-14+7 -> 45947 | F15: 1.1.-1.6. | G15: =РД!C10 -> 4567418.2
A16: 10 | B16: =РД!B292 -> Сессии VE (Value Engineering) | C16: Отчеты | D16: =D11+30 -> 45924 | E16: =D16+14 -> 45938 | F16: 9.1.-9.2. | G16: =РД!C292 -> 224446.08
A17: 11 | B17: =РД!B284 -> Отчетная документация по проекту | C17: Отчеты | D17: =D8 -> 45853 | E17: =E18 -> 45978 | F17: 8.1. | G17: =РД!C284 -> 565123.2
A18: 12 | B18: =РД!B307 -> Эксплуатационная документация | C18: Документация | D18: =E16+7 -> 45945 | E18: =D18+19+14 -> 45978 | F18: 10.1.-10.5. | G18: =РД!C307 -> 3052887.5
A19: 13 | B19: =РД!B365 -> Электронный документооборот | C19: Акт | D19: =D18 -> 45945 | E19: =E18 -> 45978 | F19: 12.1 | G19: =РД!C365 -> 726443.76
B20: Итого стоимость предложения | G20: =SUM(G7:H19) -> 82828575
B21: * - Датой окончания является дата подписания Заказчиком акта приемки выполненных работ
B23: Наименование организации
B25: ОАО "Сибнефтетранспроект"
B26: Главный инженер
B27: Крупников Антон Владимирович
B28: 45825 | G28: ( подпись, M.П.)

Sheet РД
C1: Форма для заполнения по тендерной процедуре №ТП.....
A2: Разработка рабочей документации по проекту «Техническое перевооружение узла очистки, осушки и регазификации этилена на площадке Казанской компрессорной станции магистрального продуктопровода (этилен) Нижнекамск-Казань Татарстанского линейно-производственного управления ООО «УЭТП-НКНХ»
C4: (заполняется участником)
A5: № п/п | B5: Наименование показателей | C5: Стоимость, руб. без НДС | D5: Трудозатраты чел.час | E5: Трудозатраты чел.дни | F5: Наименование подрядчика | G5: Обоснование расчета*
G7: Должность | H7: Оценка количества листов документации | J7: чел. | K7: Дней | L7: Дней | M7: Часов | N7: Ст-ть чел. часа (руб.) без НДС | O7: Итого Ст-ть (руб.) без НДС | P7: Итого кол. чел.час
H8: (текст.) ф.А4 | I8: (граф.) ф.А1 | R8: K= | S8: 1
A9: Соответствие техническому заданию стадии ОТР
A10: 1. | B10: Расчет ключевых физических объемов | C10: =SUBTOTAL(9,C11:C52) -> 4567418.2 | D10: =SUBTOTAL(9,D11:D52) -> 1653.28 | E10: =SUBTOTAL(9,E11:E52) -> 206.66
A11: 1.1. | B11: Формирование перечня Ключевых физических объемов изделий, материалов, работ | C11: =SUM(,O11:O17) -> 2064002.6 | D11: =SUM(,P11:P17) -> 780.16 | E11: =D11/8 -> 97.52 | G11: ГИП | J11: 1 | K11: =L11*$S$8 -> 0.42 | L11: 0.42 | M11: 8 | N11: =DATA!$D$2 -> 5009.96 | O11: =N11*J11*K11*M11 -> 16833.466 | P11: =J11*K11*M11 -> 3.36
G12: Нач. отдела | J12: 5 | K12: =L12*$S$8 -> 0.42 | L12: 0.42 | M12: 8 | N12: =DATA!$D$3 -> 4508.96 | O12: =N12*J12*K12*M12 -> 75750.528 | P12: =J12*K12*M12 -> 16.8
G13: Гл. специалист | J13: 5 | K13: =L13*$S$8 -> 1.5 | L13: 1.5 | M13: 8 | N13: =DATA!$D$4 -> 3757.47 | O13: =N13*J13*K13*M13 -> 225448.2 | P13: =J13*K13*M13 -> 60
G14: Рук. Группы | J14: 5 | K14: =L14*$S$8 -> 1.5 | L14: 1.5 | M14: 8 | N14: =DATA!$D$5 -> 3381.72 | O14: =N14*J14*K14*M14 -> 202903.2 | P14: =J14*K14*M14 -> 60
G15: Вед. инженер | J15: 5 | K15: =L15*$S$8 -> 10 | L15: 10 | M15: 8 | N15: =DATA!$D$6 -> 2504.98 | O15: =N15*J15*K15*M15 -> 1001992 | P15: =J15*K15*M15 -> 400
G16: Старший инженер | J16: 3 | K16: =L16*$S$8 -> 10 | L16: 10 | M16: 8 | N16: =DATA!$D$7 -> 2254.48 | O16: =N16*J16*K16*M16 -> 541075.2 | P16: =J16*K16*M16 -> 240
G17: Инженер
A18: 1.2. | B18: Предоставить ведомости объемов работ в формате BOQ (Описание выполняемых работ/объемы) | C18: =SUM(,O18:O24) -> 929748.03 | D18: =SUM(,P18:P24) -> 308.16 | E18: =D18/8 -> 38.52 | G18: ГИП | J18: 1 | K18: =L18*$S$8 -> 0.42 | L18: 0.42 | M18: 8 | N18: =DATA!$D$2 -> 5009.96 | O18: =N18*J18*K18*M18 -> 16833.466 | P18: =J18*K18*M18 -> 3.36
G19: Нач. отдела | J19: 5 | K19: =L19*$S$8 -> 0.42 | L19: 0.42 | M19: 8 | N19: =DATA!$D$3 -> 4508.96 | O19: =N19*J19*K19*M19 -> 75750.528 | P19: =J19*K19*M19 -> 16.8
G20: Гл. специалист | J20: 5 | K20: =L20*$S$8 -> 1.5 | L20: 1.5 | M20: 8 | N20: =DATA!$D$4 -> 3757.47 | O20: =N20*J20*K20*M20 -> 225448.2 | P20: =J20*K20*M20 -> 60
G21: Рук. Группы | J21: 5 | K21: =L21*$S$8 -> 1.5 | L21: 1.5 | M21: 8 | N21: =DATA!$D$5 -> 3381.72 | O21: =N21*J21*K21*M21 -> 202903.2 | P21: =J21*K21*M21 -> 60
G22: Вед. инженер | J22: 5 | K22: =L22*$S$8 -> 3 | L22: 3 | M22: 8 | N22: =DATA!$D$6 -> 2504.98 | O22: =N22*J22*K22*M22 -> 300597.6 | P22: =J22*K22*M22 -> 120
G23: Старший инженер | J23: 2 | K23: =L23*$S$8 -> 3 | L23: 3 | M23: 8 | N23: =DATA!$D$7 -> 2254.48 | O23: =N23*J23*K23*M23 -> 108215.04 | P23: =J23*K23*M23 -> 48
G24: Инженер
A25: 1.3. | B25: Предоставление ведомостей материалов с построчной стоимостью ресурсов (BOM) | C25: =SUM(,O25:O31) -> 604240.88 | D25: =SUM(,P25:P31) -> 226.08 | E25: =D25/8 -> 28.26 | G25: ГИП | J25: 1 | K25: =L25*$S$8 -> 0.42 | L25: 0.42 | M25: 8 | N25: =DATA!$D$2 -> 5009.96 | O25: =N25*J25*K25*M25 -> 16833.466 | P25: =J25*K25*M25 -> 3.36
G26: Нач. отдела | J26: 2 | K26: =L26*$S$8 -> 0.42 | L26: 0.42 | M26: 8 | N26: =DATA!$D$3 -> 4508.96 | O26: =N26*J26*K26*M26 -> 30300.211 | P26: =J26*K26*M26 -> 6.72
G27: Гл. специалист | J27: 2 | K27: =L27*$S$8 -> 1.5 | L27: 1.5 | M27: 8 | N27: =DATA!$D$4 -> 3757.47 | O27: =N27*J27*K27*M27 -> 90179.28 | P27: =J27*K27*M27 -> 24
G28: Рук. Группы | J28: 2 | K28: =L28*$S$8 -> 1.5 | L28: 1.5 | M28: 8 | N28: =DATA!$D$5 -> 3381.72 | O28: =N28*J28*K28*M28 -> 81161.28 | P28: =J28*K28*M28 -> 24
G29: Вед. инженер | J29: 1 | K29: =L29*$S$8 -> 7 | L29: 7 | M29: 8 | N29: =DATA!$D$6 -> 2504.98 | O29: =N29*J29*K29*M29 -> 140278.88 | P29: =J29*K29*M29 -> 56
G30: Старший инженер | J30: 1 | K30: =L30*$S$8 -> 7 | L30: 7 | M30: 8 | N30: =DATA!$D$7 -> 2254.48 | O30: =N30*J30*K30*M30 -> 126250.88 | P30: =J30*K30*M30 -> 56
G31: Инженер | J31: 1 | K31: =L31*$S$8 -> 7 | L31: 7 | M31: 8 | N31: =DATA!$D$8 -> 2129.23 | O31: =N31*J31*K31*M31 -> 119236.88 | P31: =J31*K31*M31 -> 56
A32: 1.4. | B32: Предоставление ведомостей оборудования с построчной стоимостью ресурсов (BOE) | C32: =SUM(,O32:O38) -> 343222.16 | D32: =SUM(,P32:P38) -> 118.08 | E32: =D32/8 -> 14.76 | G32: ГИП | J32: 1 | K32: =L32*$S$8 -> 0.42 | L32: 0.42 | M32: 8 | N32: =DATA!$D$2 -> 5009.96 | O32: =N32*J32*K32*M32 -> 16833.466 | P32: =J32*K32*M32 -> 3.36
G33: Нач. отдела | J33: 2 | K33: =L33*$S$8 -> 0.42 | L33: 0.42 | M33: 8 | N33: =DATA!$D$3 -> 4508.96 | O33: =N33*J33*K33*M33 -> 30300.211 | P33: =J33*K33*M33 -> 6.72
G34: Гл. специалист | J34: 2 | K34: =L34*$S$8 -> 1.5 | L34: 1.5 | M34: 8 | N34: =DATA!$D$4 -> 3757.47 | O34: =N34*J34*K34*M34 -> 90179.28 | P34: =J34*K34*M34 -> 24
G35: Рук. Группы | J35: 1 | K35: =L35*$S$8 -> 1.5 | L35: 1.5 | M35: 8 | N35: =DATA!$D$5 -> 3381.72 | O35: =N35*J35*K35*M35 -> 40580.64 | P35: =J35*K35*M35 -> 12
G36: Вед. инженер | J36: 1 | K36: =L36*$S$8 -> 3 | L36: 3 | M36: 8 | N36: =DATA!$D$6 -> 2504.98 | O36: =N36*J36*K36*M36 -> 60119.52 | P36: =J36*K36*M36 -> 24
G37: Старший инженер | J37: 1 | K37: =L37*$S$8 -> 3 | L37: 3 | M37: 8 | N37: =DATA!$D$7 -> 2254.48 | O37: =N37*J37*K37*M37 -> 54107.52 | P37: =J37*K37*M37 -> 24
G38: Инженер | J38: 1 | K38: =L38*$S$8 -> 3 | L38: 3 | M38: 8 | N38: =DATA!$D$8 -> 2129.23 | O38: =N38*J38*K38*M38 -> 51101.52 | P38: =J38*K38*M38 -> 24
A39: 1.5. | B39: Предоставление ведомостей дефектов (BOD) | C39: =SUM(,O39:O45) -> 343222.16 | D39: =SUM(,P39:P45) -> 118.08 | E39: =D39/8 -> 14.76 | G39: ГИП | J39: 1 | K39: =L39*$S$8 -> 0.42 | L39: 0.42 | M39: 8 | N39: =DATA!$D$2 -> 5009.96 | O39: =N39*J39*K39*M39 -> 16833.466 | P39: =J39*K39*M39 -> 3.36
G40: Нач. отдела | J40: 2 | K40: =L40*$S$8 -> 0.42 | L40: 0.42 | M40: 8 | N40: =DATA!$D$3 -> 4508.96 | O40: =N40*J40*K40*M40 -> 30300.211 | P40: =J40*K40*M40 -> 6.72
G41: Гл. специалист | J41: 2 | K41: =L41*$S$8 -> 1.5 | L41: 1.5 | M41: 8 | N41: =DATA!$D$4 -> 3757.47 | O41: =N41*J41*K41*M41 -> 90179.28 | P41: =J41*K41*M41 -> 24
G42: Рук. Группы | J42: 1 | K42: =L42*$S$8 -> 1.5 | L42: 1.5 | M42: 8 | N42: =DATA!$D$5 -> 3381.72 | O42: =N42*J42*K42*M42 -> 40580.64 | P42: =J42*K42*M42 -> 12
...

Sheet DATA
D1: ПД, РД | E1: АН | F1: ИИ
C2: ГИП | D2: =P4 -> 5009.96 | F2: =D2/0.6 -> 8349.9333 | H2: 20454 | I2: =H2*(30-4) -> 531804 | J2: =I2*0.25 -> 132951 | M2: Среднеотраслевая шкала индексов средневзвешенных ставок непосредственных исполнителей устанавливается с учетом положений п. 5.3 МУ о разработке СБЦ (приказ Минстроя России от 04.06.2015) | Q2: Рамка Сибур ЭТО | R2: Рамка НИПИГАЗ | S2: ГПП ставки для формы 3П (0,45; 8%) | T2: ГПП | U2: С5 | V2: Сибур Рамка ЭТО | W2: ГПП | X2: Рамка НИПИГАЗ
C3: Нач. отдела | D3: =P5 -> 4508.96 | F3: =D3/0.6 -> 7514.9333 | H3: 20454 | I3: =H3*(30-4) -> 531804 | J3: =I3*0.25 -> 132951 | M3: наименование должностей | O3: Индекс ср. взв.ставок
C4: Гл. специалист | D4: =P7 -> 3757.47 | F4: =D4/0.6 -> 6262.45 | H4: 16290 | I4: =H4*(30-4) -> 423540 | J4: =I4*0.25 -> 105885 | M4: Главный инженер проекта | O4: 2 | P4: 5009.96 | Q4: =$Q$9*O4 -> 5000 | R4: =$R$9*O4 -> 3242 | S4: =20454 -> 20454 | T4: =S4*1.08/0.45/8 -> 6136.2 | U4: =P4*160*0.25 -> 200398.4 | V4: =Q4*160*0.25 -> 200000 | W4: =T4*160*0.25 -> 245448 | X4: =R4*160*0.25 -> 129680 | Y4: =T4/Q4 -> 1.22724
C5: Рук. Группы | D5: =P8 -> 3381.72 | F5: =D5/0.6 -> 5636.2 | M5: Начальник отдела | O5: 1.8 | P5: 4508.96 | Q5: =$Q$9*O5 -> 4500 | R5: =$R$9*O5 -> 2917.8 | S5: =20454 -> 20454 | T5: =S5/0.45*1.08/8 -> 6136.2 | U5: =P5*160*0.25 -> 180358.4 | V5: =Q5*160*0.25 -> 180000 | W5: =T5*160*0.25 -> 245448 | X5: =R5*160*0.25 -> 116712 | Y5: =T5/Q5 -> 1.3636
C6: Вед. инженер | D6: =P9 -> 2504.98 | F6: =D6/0.6 -> 4174.9667 | M6: Заместитель нач. отдела | O6: 1.7 | P6: 4258.47 | Q6: =$Q$9*O6 -> 4250 | R6: =$R$9*O6 -> 2755.7 | S6: 18278 | T6: =S6/0.45*1.08/8 -> 5483.4 | U6: =P6*160*0.25 -> 170338.8 | V6: =Q6*160*0.25 -> 170000 | W6: =T6*160*0.25 -> 219336 | X6: =R6*160*0.25 -> 110228 | Y6: =T6/Q6 -> 1.2902118
C7: Старший инженер | D7: =P10 -> 2254.48 | F7: =D7/0.6 -> 3757.4667 | M7: Главный специалист | O7: 1.5 | P7: 3757.47 | Q7: =$Q$9*O7 -> 3750 | R7: =$R$9*O7 -> 2431.5 | S7: 16290 | T7: =S7/0.45*1.08/8 -> 4887 | U7: =P7*160*0.25 -> 150298.8 | V7: =Q7*160*0.25 -> 150000 | W7: =T7*160*0.25 -> 195480 | X7: =R7*160*0.25 -> 97260 | Y7: =T7/Q7 -> 1.3032
C8: Инженер | D8: =P11 -> 2129.23 | F8: =D8/0.6 -> 3548.7167 | M8: Руководитель группы | O8: 1.35 | P8: 3381.72 | Q8: =$Q$9*O8 -> 3375 | R8: =$R$9*O8 -> 2188.35 | S8: 14574 | T8: =S8/0.45*1.08/8 -> 4372.2 | U8: =P8*160*0.25 -> 135268.8 | V8: =Q8*160*0.25 -> 135000 | W8: =T8*160*0.25 -> 174888 | X8: =R8*160*0.25 -> 87534 | Y8: =T8/Q8 -> 1.2954667
D9: =SUM(D2:D8)*160*5 -> 18837440 | M9: Ведущий специалист | O9: 1 | P9: 2504.98 | Q9: 2500 | R9: 1621 | S9: 12984 | T9: =S9/0.45*1.08/8 -> 3895.2 | U9: =P9*160*0.25 -> 100199.2 | V9: =Q9*160*0.25 -> 100000 | W9: =T9*160*0.25 -> 155808 | X9: =R9*160*0.25 -> 64840 | Y9: =T9/Q9 -> 1.55808 | Z9: =Q9/R9 -> 1.5422579
M10: Инженер 1 категории | O10: 0.9 | P10: 2254.48 | Q10: =$Q$9*O10 -> 2250 | R10: =$R$9*O10 -> 1458.9 | S10: 10605 | T10: =S10/0.45*1.08/8 -> 3181.5 | U10: =P10*160*0.25 -> 90179.2 | V10: =Q10*160*0.25 -> 90000 | W10: =T10*160*0.25 -> 127260 | X10: =R10*160*0.25 -> 58356 | Y10: =T10/Q10 -> 1.414
M11: Инженер 2 категории | O11: 0.85 | P11: 2129.23 | Q11: =$Q$9*O11 -> 2125 | R11: =$R$9*O11 -> 1377.85 | S11: 9784 | T11: =S11/0.45*1.08/8 -> 2935.2 | U11: =P11*160*0.25 -> 85169.2 | V11: =Q11*160*0.25 -> 85000 | W11: =T11*160*0.25 -> 117408 | X11: =R11*160*0.25 -> 55114 | Y11: =T11/Q11 -> 1.3812706
M12: Инженер 3 категории | O12: 0.8 | P12: 2003.98 | Q12: =$Q$9*O12 -> 2000 | R12: =$R$9*O12 -> 1296.8 | S12: 8300 | T12: =S12/0.45*1.08/8 -> 2490 | U12: =P12*160*0.25 -> 80159.2 | V12: =Q12*160*0.25 -> 80000 | W12: =T12*160*0.25 -> 99600 | X12: =R12*160*0.25 -> 51872 | Y12: =T12/Q12 -> 1.245
C13: Офис в нижнекамске, средняя | D13: =(D7*4+D2)*1.5/5 -> 4208.364 | M13: Техник 1 категории | O13: 0.6 | P13: 1502.99 | Q13: =$Q$9*O13 -> 1500 | R13: =$R$9*O13 -> 972.6 | S13: 8300 | T13: =S13/0.45*1.08/8 -> 2490 | U13: =P13*160*0.25 -> 60119.6 | V13: =Q13*160*0.25 -> 60000 | W13: =T13*160*0.25 -> 99600 | X13: =R13*160*0.25 -> 38904 | Y13: =T13/Q13 -> 1.66
C14: Стоимость 5 чел | D14: =D13*260*5*2 -> 10941746 | M14: Техник 2 категории | O14: 0.55 | P14: 1377.74 | Q14: =$Q$9*O14 -> 1375 | R14: =$R$9*O14 -> 891.55 | S14: 7406 | T14: =S14/0.45*1.08/8 -> 2221.8 | U14: =P14*160*0.25 -> 55109.6 | V14: =Q14*160*0.25 -> 55000 | W14: =T14*160*0.25 -> 88872 | X14: =R14*160*0.25 -> 35662 | Y14: =T14/Q14 -> 1.6158545
C15: Билеты | D15: =18000*5*2*2 -> 360000 | M15: Техник 3 категории | O15: 0.5 | P15: 1252.49 | Q15: =$Q$9*O15 -> 1250 | R15: =$R$9*O15 -> 810.5 | S15: 6689 | T15: =S15/0.45*1.08/8 -> 2006.7 | U15: =P15*160*0.25 -> 50099.6 | V15: =Q15*160*0.25 -> 50000 | W15: =T15*160*0.25 -> 80268 | X15: =R15*160*0.25 -> 32420 | Y15: =T15/Q15 -> 1.60536
C16: Суточные/питание | D16: =700*5*60 -> 210000
C17: Проживание | D17: =3500*5*60 -> 1050000
C18: Ежедневный проезд до места работы | D18: =500*5*60 -> 150000
C19: Аренда офиса | D19: =90000*2 -> 180000
C20: Аттестация специалистов/обучение | D20: =50000/6*5 -> 41666.667
C21: Лицензии для ПО | D21: =69000*5 -> 345000
C22: Медосмотры | D22: =7000*5 -> 35000
C23: Covid - мероприятия/прививочный сертификат | D23: =3000*5 -> 15000
C24: ИТОГО | D24: =SUM(D13:D23)*0.5 -> 6666310.7

Sheet  ТРУДОЕМКОСТЬ
E1: Приложение №1.1 к Форме КП
B2: ФИКСИРОВАННАЯ ТРУДОЕМКОСТЬ НА ГРАФИЧЕСКИЙ И ТЕКСТОВОЙ ЛИСТ (единица измерения) ПРОЕКТНОЙ И РАБОЧЕЙ ДОКУМЕНТАЦИИ.
B4: № п/п | C4: Наименование | D4: Марка чертежа | E4: Формат листа | F4: Норматив трудозатрат, (чел./час). ПД | G4: Норматив трудозатрат, (чел./час). РД.
B5: 1. | C5: МОНТАЖНО - ТЕХНОЛОГИЧЕСКИЙ ОТДЕЛ
B6: 1.1 | C6: Технология производства. Текстовая часть | D6: ТХ | E6: А4 | F6: 4 | G6: 4
B7: 1.2 | C7: Технология производства. Графическая часть | D7: ТХ | E7: А1 | F7: 36 | G7: 36
B8: 1.3 | C8: Технологические коммуникации. Текстовая часть | D8: ТК | E8: А4 | F8: 4 | G8: 4
B9: 1.4 | C9: Технологические коммуникации. Графическая часть. | D9: ТК | E9: А1 | F9: 28 | G9: 28
B10: 1.5 | C10: Тепловая изоляция. Текстовая часть | D10: ТИ | E10: А4 | F10: 4 | G10: 4
B11: 1.6 | C11: Антикоррозионная защита. Текстовая часть. | D11: АЗ, АЗО | E11: А4 | F11: 4 | G11: 4
B12: 1.7 | C12: Антикоррозионная защита. Графическая часть. | D12: АЗ, АЗО | E12: А1 | F12: 18 | G12: 18
B13: 1.8 | C13: Расчет Материального баланса. Тестовая чать. | D13: РР | E13: А4 | F13: 12 | G13: 12
B14: 1.9 | C14: Расчет Материального баланса. Графическая чать. | D14: РР | E14: А1 | F14: 36 | G14: 36
B15: 1.10 | C15: Тепловая изоляция. Графическая часть | D15: ТИ | E15: А1 | F15: 28 | G15: 28
B16: 1.11 | C16: Сборочные и монтажны чертежи | D16: СБ | E16: А4 | F16: 4 | G16: 4
B17: 1.12 | C17: Сборочные и монтажные чертежи | D17: СБ | E17: А1 | F17: 36 | G17: 36
B18: 2. | C18: КИПиА
B19: 2.1 | C19: Автоматизация технологически процессов. Текстовая часть. | D19: АК, АТХ | E19: А4 | F19: а | G19: 4
B20: 2.2 | C20: Автоматизация технологически процессов. Графическая часть. | D20: АК, АТХ | E20: А1 | F20: 28 | G20: 28
B21: 2.3 | C21: Разработка ТЗ на ВУ АСУТП. Текстовая часть. | D21: ТЗ | E21: А4 | F21: 5 | G21: 5
B22: 2.4 | C22: Разработка ТЗ на ВУ АСУТП. Графическая часть. | D22: ТЗ | E22: А1 | F22: 16 | G22: 16
B23: 3. | C23: ЭЛЕКТРОТЕХНИЧЕСКИЙ ОТДЕЛ
B24: 3.1 | C24: Силовое электрооборудование. Текстовая часть. | D24: ЭМ | E24: А4 | F24: 4 | G24: 4
B25: 3.2 | C25: Силовое электрооборудование. Графическая часть. | D25: ЭМ | E25: А1 | F25: 25 | G25: 25
B26: 3.3 | C26: Электрическое освещение. Текстовая часть. | D26: ЭО, ЭН | E26: А4 | F26: 4 | G26: 4
B27: 3.4 | C27: Электрическое освещение. Графическая часть. | D27: ЭО, ЭН | E27: А1 | F27: 18 | G27: 18
B28: 3.5 | C28: Электроснабжение. Текстовая часть | D28: ЭС | E28: А4 | F28: 4 | G28: 4
B29: 3.6 | C29: Электроснабжение. Графическая часть | D29: ЭС | E29: А1 | F29: 25 | G29: 25
B30: 3.7 | C30: Воздушние, кабельные линии электро передач. Текстовая часть. | D30: ЭВ, ЭК | E30: А4 | F30: 4 | G30: 4
B31: 3.8 | C31: Воздушние, кабельные линии электро передач. Графическая часть. | D31: ЭВ, ЭК | E31: А1 | F31: 18 | G31: 18
B32: 3.9 | C32: Электрообогрев. Текстовая часть. | D32: ЭОГ | E32: А4 | F32: 4 | G32: 4
B33: 3.10 | C33: Электрообогрев. Графическая часть. | D33: ЭОГ | E33: А1 | F33: 18 | G33: 18
B34: 3.11 | C34: Молниезащита, Заземление. Тестовая часть | D34: ЭГ | E34: А4 | F34: 4 | G34: 4
B35: 3.12 | C35: Молниезащита, Заземление. Графическая часть | D35: МЗ, ЗЗ, ЭГ | E35: А1 | F35: 18 | G35: 18
B36: 4. | C36: СЕТИ СВЯЗИ
B37: 4.1 | C37: Сети связи. Охранная и пожарная сигнализации. Текстовая часть | D37: СС, ОС, ПС, СОУЭ, | E37: А4 | F37: 4 | G37: 4
B38: 4.2 | C38: Сети связи. Охранная и пожарная сигнализации. Графическая часть | D38: СС, ОС, ПС,СОУЭ, | E38: А1 | F38: 19 | G38: 19
B39: 4.3 | C39: Радиосвязь, радиовещание и телевидение. Текстовая часть | D39: РТ | E39: А4 | F39: 4 | G39: 4
B40: 4.4 | C40: Радиосвязь, радиовещание и телевидение. Графическая часть | D40: РТ | E40: А1 | F40: 20 | G40: 20
B41: 5. | C41: СТРОИТЕЛЬНО - КОНСТРУКТОРСКИЙ ОТДЕЛ
...

Sheet Лист2

Sheet Лист3
