Workbook
Name Print_Titles: '1.1.4 ИГДИ+'!$6:$6
Name Print_Titles: '3.15.1 Бурение+ '!$16:$16
Name Print_Titles: '3.15.2 ПроектБур+ '!$16:$16

Sheet РНМЦ
A1: Расчет начальной максимальной цены
A2: на выполнение работ по объекту:
A3: Реконструкция газопромысловых сооружений Степновской станции подземного хранения газа
A5: Наименование предприятия, здания, сооружения, стадии проектирования, этапа, вида проектных или изыскательских работ | C5: Выполнение работ по корректировке рабочей и сметной документации объекта «Реконструкция газопромысловых сооружений Степновской СПХГ» , Выполнение диагностического обследования существующих зданий и сооружений, Выполнение комплексных инженерных изысканий.
C6: Рабочая документация
A7: Наименование проектной (изыскательской) организации | C7: Определяется по итогам конкурентных процедур
A8: Наименование организации заказчика | C8: ООО "Газпром проектирование"
A10: № п/п | B10: Наименование видов работ | C10: Ссылка на номер локального расчета | D10: Стоимость, руб.
A11: 1 | B11: 2 | C11: 3 | D11: 4
A12: =СВОД!A21 -> 1 | B12: =СВОД!B21 -> Инженерные изыскания
A13: =СВОД!A22 -> 1.1 | B13: =СВОД!B22 -> Инженерно-геодезические изыскания | C13: =СВОД!E22 -> Сметы №1.1.1-№1.1.4 | D13: =СВОД!H22 -> 13435089
A14: =СВОД!A23 -> 1.2 | B14: =СВОД!B23 -> Инженерно-геологические изыскания | C14: =СВОД!E23 -> Сметы №1.2.1-№1.2.2 | D14: =СВОД!H23 -> 21969334
A15: =СВОД!A24 -> 1.3 | B15: =СВОД!B24 -> Мобильное лазерное сканирование (МЛС) | C15: =СВОД!E24 -> Смета №1.3 | D15: =СВОД!H24 -> 0
A16: =СВОД!A25 -> 1.4 | B16: =СВОД!B25 -> Итого Инженерные изыскания: | D16: =СВОД!H25 -> 39964618
A18: =СВОД!A27 -> 2 | B18: =СВОД!B27 -> Обследование, сбор исходных данных
A19: =СВОД!A28 -> 2.1 | B19: =СВОД!B28 -> Обследование и оценка технического состяния строительных конструкций | C19: =СВОД!E28 -> Смета №2.1 | D19: =СВОД!H28 -> 13673881
A20: =СВОД!A29 -> 2.2 | B20: =СВОД!B29 -> Внесение изменений в техническую документацию | C20: =СВОД!E29 -> Смета №2.2 | D20: =СВОД!H29 -> 5079636
A21: =СВОД!A30 -> 2.3 | B21: =СВОД!B30 -> Сбор исходных данных | C21: =СВОД!E30 -> Смета №2.3 | D21: =СВОД!H30 -> 5721868.2
A22: =СВОД!A31 -> 2.4 | B22: =СВОД!B31 -> Итого Обследование, сбор исходных данных: | D22: =СВОД!H31 -> 24475386
A24: =СВОД!A33 -> 3 | B24: =СВОД!B33 -> Рабочая документация
A25: =СВОД!A34 -> 3.1 | B25: =СВОД!B34 -> Генеральный план | C25: =СВОД!E34 -> Смета №3.1 | D25: =СВОД!H34 -> 3276535.2
A26: =СВОД!A35 -> 3.2 | B26: =СВОД!B35 -> Автомобильные дороги | C26: =СВОД!E35 -> Смета №3.2 | D26: =СВОД!H35 -> 4828808.6
A27: =СВОД!A36 -> 3.3 | B27: =СВОД!B36 -> Технология производства | C27: =СВОД!E36 -> Смета №3.3 | D27: =СВОД!H36 -> 58732646
A28: =СВОД!A37 -> 3.4 | B28: =СВОД!B37 -> Отопление, вентиляция и кондиционирование | C28: =СВОД!E37 -> Смета №3.4 | D28: =СВОД!H37 -> 30320631
A29: =СВОД!A38 -> 3.5 | B29: =СВОД!B38 -> Автоматизированная система управления технологическим процессом (АСУ ТП) | C29: =СВОД!E38 -> Сметы №3.5.1-№3.5.6 | D29: =СВОД!H38 -> 14529311
A30: =СВОД!A39 -> 3.6 | B30: =СВОД!B39 -> Автоматизированная система управления энергоснабжением (АСУ Э) | C30: =СВОД!E39 -> Сметы №3.6.1-№3.6.5 | D30: =СВОД!H39 -> 5811572
A31: =СВОД!A40 -> 3.7 | B31: =СВОД!B40 -> Автоматизация электрического освещения (АЭО) | C31: =СВОД!E40 -> Сметы №3.7.1-№3.7.3 | D31: =СВОД!H40 -> 1690386
A32: =СВОД!A41 -> 3.8 | B32: =СВОД!B41 -> Система противопожарной безопасности и автоматики (СПБА) | C32: =СВОД!E41 -> Сметы №3.8.1-№3.8.6 | D32: =СВОД!H41 -> 11368057
A33: =СВОД!A42 -> 3.9 | B33: =СВОД!B42 -> Сети связи и сигнализации | C33: =СВОД!E42 -> Сметы №3.9.1-№3.9.7 | D33: =СВОД!H42 -> 14311185
A34: =СВОД!A43 -> 3.10 | B34: =СВОД!B43 -> Электроснабжение | C34: =СВОД!E43 -> Смета №3.10 | D34: =СВОД!H43 -> 45652932
A35: =СВОД!A44 -> 3.11 | B35: =СВОД!B44 -> Электрохимическая защита | C35: =СВОД!E44 -> Смета №3.11 | D35: =СВОД!H44 -> 18342242
A36: =СВОД!A45 -> 3.12 | B36: =СВОД!B45 -> Сети водоснабжения и канализации | C36: =СВОД!E45 -> Смета №3.12 | D36: =СВОД!H45 -> 7763728.1
... A39: =СВОД!A48 -> 3.15 | B39: =СВОД!B48 -> Проект бурения скважин | C39: =СВОД!E48 -> Сметы №3.15.1-№3.15.2 | D39: =СВОД!H48 -> 1309609.4
A40: =СВОД!A49 -> 3.16 | B40: =СВОД!B49 -> Итого Рабочая документация: | D40: =СВОД!H49 -> 2.1926073e+08
A42: =СВОД!A51 -> 4 | B42: Итого | D42: =СВОД!H51 -> 2.8370073e+08
A43: =СВОД!A52 -> 5 | B43: Кроме того, НДС 22% | C43: 22% от п.4 | D43: =СВОД!H52 -> 62414161
A44: =СВОД!A53 -> 6 | B44: Всего с НДС | C44: Сумма от п.4-5 | D44: =СВОД!H53 -> 3.4611489e+08
A47: Главный инженер проекта
A48: ООО «Газпром проектирование»
A49: Саратовский филиал | C49: ___________________ | D49: А.Г. Гордеев

Sheet СВОД
D1: Форма 1пс
A3: СВОДНАЯ СМЕТА
A4: на проектные работы и инженерные изыскания
A6: По объекту: | D6: Реконструкция газопромысловых сооружений Степновской станции подземного хранения газа
A9: Наименование строительства и стадии проектирования | D9: Рабочая документация
A14: Наименование проектной организации-генерального проектировщика | D14: Определяется по итогам конкурентных процедур
A16: Наименование организации заказчика | D16: ООО «Газпром проектирование»
A18: №пп | B18: Перечень выполняемых работ | E18: Ссылка на № смет по формам 2П, 3П | F18: Полная стоимость работ, руб.
F19: изыскательских | G19: проектных | H19: Всего
A20: 1 | B20: 2 | E20: 4 | F20: 5 | G20: 6 | H20: 7
A21: 1 | B21: Инженерные изыскания
A22: 1.1 | B22: Инженерно-геодезические изыскания | E22: =CONCATENATE("Сметы №",A22,".1","-№",A22,".4") -> Сметы №1.1.1-№1.1.4 | F22: ='1.1.1 ИГДИ'!G102+'1.1.2 ИГДИ'!O21+'1.1.3 ИГДИ'!G102+'1.1.4 ИГДИ+'!G105 -> 13435089 | H22: =G22+F22 -> 13435089
A23: 1.2 | B23: Инженерно-геологические изыскания | E23: =CONCATENATE("Сметы №",A23,".1","-№",A23,".2") -> Сметы №1.2.1-№1.2.2 | F23: ='1.2.1 ИГИ'!E87+'1.2.2 ИГИ+'!E86 -> 21969334 | H23: =G23+F23 -> 21969334
A24: 1.3 | B24: Мобильное лазерное сканирование (МЛС) | E24: =CONCATENATE("Смета №",A24) -> Смета №1.3 | F24: ='1.3 МЛС'!G96 -> 4560194.1
A25: 1.4 | B25: =CONCATENATE("Итого ",B21,":") -> Итого Инженерные изыскания: | F25: =ROUND(SUM(F22:F24),2) -> 39964618 | G25: =ROUND(SUM(G22:G23),2) -> 0 | H25: =G25+F25 -> 39964618
A27: 2 | B27: Обследование, сбор исходных данных
A28: 2.1 | B28: Обследование и оценка технического состяния строительных конструкций | E28: =CONCATENATE("Смета №",A28) -> Смета №2.1 | G28: =Смета_№2.1_Обслед!R239 -> 13673881 | H28: =G28+F28 -> 13673881
A29: 2.2 | B29: Внесение изменений в техническую документацию | E29: =CONCATENATE("Смета №",A29) -> Смета №2.2 | G29: ='2.2 ТехДок+ '!K32 -> 5079636 | H29: =G29+F29 -> 5079636
A30: 2.3 | B30: Сбор исходных данных | E30: =CONCATENATE("Смета №",A30) -> Смета №2.3 | G30: ='2.3 СИД '!G58 -> 5721868.2 | H30: =G30+F30 -> 5721868.2
A31: 2.4 | B31: =CONCATENATE("Итого ",B27,":") -> Итого Обследование, сбор исходных данных: | F31: =ROUND(SUM(F26:F28),2) -> 0 | G31: =ROUND(SUM(G28:G30),2) -> 24475386 | H31: =G31+F31 -> 24475386
A33: 3 | B33: Рабочая документация
A34: 3.1 | B34: Генеральный план | E34: =CONCATENATE("Смета №",A34) -> Смета №3.1 | G34: ='РД 3.1 ГП++'!R70 -> 3276535.2 | H34: =G34+F34 -> 3276535.2
A35: 3.2 | B35: Автомобильные дороги | E35: =CONCATENATE("Смета №",A35) -> Смета №3.2 | G35: ='3.2 Автодороги++'!R96 -> 4828808.6 | H35: =G35+F35 -> 4828808.6
A36: 3.3 | B36: Технология производства | E36: =CONCATENATE("Смета №",A36) -> Смета №3.3 | G36: ='3.3 ТХ++'!R478 -> 58732646 | H36: =G36+F36 -> 58732646
A37: 3.4 | B37: Отопление, вентиляция и кондиционирование | E37: =CONCATENATE("Смета №",A37) -> Смета №3.4 | G37: ='3.4 ОВ++'!R185 -> 30320631 | H37: =G37+F37 -> 30320631
A38: 3.5 | B38: Автоматизированная система управления технологическим процессом (АСУ ТП) | E38: =CONCATENATE("Сметы №",A38,".1","-№",A38,".6") -> Сметы №3.5.1-№3.5.6 | G38: ='3.5.1 АСУТП этап12'!Y173+'3.5.2 АСУТП этап15'!Y173+'3.5.3 АСУТП этап16'!Y173+'3.5.4 АСУТП этап27'!Y173+'3.5.5 АСУТП этап2+'!Y173+'3.5.6 АСУТП этап3++'!Y173 -> 14529311 | H38: =G38+F38 -> 14529311
A39: 3.6 | B39: Автоматизированная система управления энергоснабжением (АСУ Э) | E39: =CONCATENATE("Сметы №",A39,".1","-№",A39,".5") -> Сметы №3.6.1-№3.6.5 | G39: ='3.6.1 АСУЭ этап2'!Y173+'3.6.2 АСУЭ этап15'!Y173+'3.6.3 АСУЭ этап16'!Y173+'3.6.4 АСУЭ этап27'!Y173+'3.6.5 АСУЭ этап3++'!Y173 -> 5811572 | H39: =G39+F39 -> 5811572
A40: 3.7 | B40: Автоматизация электрического освещения (АЭО) | E40: =CONCATENATE("Сметы №",A40,".1","-№",A40,".3") -> Сметы №3.7.1-№3.7.3 | G40: ='3.7.1 АЭО этап15'!Y173+'3.7.2 АЭО этап16'!Y173+'3.7.3 АЭО этап3++'!Y173 -> 1690386 | H40: =G40+F40 -> 1690386
A41: 3.8 | B41: Система противопожарной безопасности и автоматики (СПБА) | E41: =CONCATENATE("Сметы №",A41,".1","-№",A41,".6") -> Сметы №3.8.1-№3.8.6 | G41: ='3.8.1 СПБА этап12'!Y173+'3.8.2 СПБА этап15'!Y173+'3.8.3 СПБА этап16'!Y173+'3.8.4 СПБА этап27'!Y173+'3.8.5 СПБА этап2+'!Y173+'3.8.6 СПБА этап3++'!Y173 -> 11368057 | H41: =G41+F41 -> 11368057
A42: 3.9 | B42: Сети связи и сигнализации | E42: =CONCATENATE("Сметы №",A42,".1","-№",A42,".7") -> Сметы №3.9.1-№3.9.7 | G42: ='3.9.1 этап12 СС'!E116+'3.9.2 этап13 СС'!E25+'3.9.3 этап 15 СС'!E121+'3.9.4 этап16 СС'!E48+'3.9.5 этап17 СС'!E34+'3.9.6 этап27 СС'!E162+'3.9.7 СС ЭТАП3++'!E244 -> 14311185 | H42: =G42+F42 -> 14311185
A43: 3.10 | B43: Электроснабжение | E43: =CONCATENATE("Смета №",A43) -> Смета №3.10 | G43: ='3.10 ЭС++'!E915 -> 45652932 | H43: =G43+F43 -> 45652932
A44: 3.11 | B44: Электрохимическая защита | E44: =CONCATENATE("Смета №",A44) -> Смета №3.11 | G44: ='3.11 ЭХЗ+'!E384 -> 18342242 | H44: =G44+F44 -> 18342242
A45: 3.12 | B45: Сети водоснабжения и канализации | E45: =CONCATENATE("Смета №",A45) -> Смета №3.12 | G45: ='3.12 ВК++'!E213 -> 7763728.1 | H45: =G45+F45 -> 7763728.1
A46: 3.13 | B46: Архитектурно-строительные решения | E46: =CONCATENATE("Смета №",A46) -> Смета №3.13 | G46: ='3.13 АС'!R29 -> 606480 | H46: =G46+F46 -> 606480
A47: 3.14 | B47: Линейная часть | E47: =CONCATENATE("Смета №",A47) -> Смета №3.14 | G47: ='3.14 ЛЧ++'!R94 -> 716607.12 | H47: =G47+F47 -> 716607.12
A48: 3.15 | B48: Проект бурения скважин | E48: =CONCATENATE("Сметы №",A48,".1","-№",A48,".2") -> Сметы №3.15.1-№3.15.2 | G48: ='3.15.1 Бурение+ '!G38+'3.15.2 ПроектБур+ '!G38 -> 1309609.4 | H48: =G48+F48 -> 1309609.4
A49: 3.16 | B49: =CONCATENATE("Итого ",B33,":") -> Итого Рабочая документация: | F49: =ROUND(SUM(F44:F46),2) -> 0 | G49: =ROUND(SUM(G34:G48),2) -> 2.1926073e+08 | H49: =G49+F49 -> 2.1926073e+08
A51: 4 | B51: Итого по сводной смете: | F51: =F49+F31+F25 -> 39964618 | G51: =G49+G31+G25 -> 2.4373611e+08 | H51: =G51+F51 -> 2.8370073e+08
A52: 5 | B52: Кроме того, НДС | E52: 0.22 | F52: =ROUND(($F$51) * (22/100),2) -> 8792215.9 | G52: =ROUND(G51*0.22,2) -> 53621945 | H52: =G52+F52 -> 62414161
A53: 6 | B53: Всего по сводной смете: | F53: =ROUND((SUM($F$51:$F$52)) * 1,2) -> 48756834 | G53: =ROUND((SUM($G$51:$G$52)) * 1,2) -> 2.9735806e+08 | H53: =G53+F53 -> 3.4611489e+08

Sheet 1.1.1 ИГДИ
B2: Смета №1.1.1
B3: =СВОД!B22 -> Инженерно-геодезические изыскания
A5: № пп | B5: Наименование работ и затрат | C5: Единица измерения | D5: Кол-во | E5: Обоснование стоимости | F5: Расчет стоимости, руб. | G5: Стоимость, руб.
A6: 1 | B6: 2 | C6: 3 | D6: 4 | E6: 5 | F6: 6 | G6: 7
A7: Раздел 1. Полевые работы
A8: III. Работы по созданию опорной геодезической сети (ПИИ Таблица 4.1.1)
A9: 1 | B9: Создание пунктов плановой опорной геодезической сети без закладки центров методом спутниковых геодезических определений, 2-го разряда в условиях выполнения полевых работ: II категории | C9: 1 пункт | D9: 4 | E9: НЗ_ИГДИ-7-8 | F9: 35837*4 A** | G9: 143348
E10: Кинф = 1.2700 (1) Письмо Минстроя России N 45358-ИФ/09 от 22.07.2026г (2026г. III квартал)
A11: 2 | B11: Создание пунктов плановой опорной геодезической сети без закладки центров методом спутниковых геодезических определений, 2-го разряда в условиях выполнения полевых работ: II категории | C11: 1 пункт | D11: 4 | E11: НЗ_ИГДИ-7-8 | F11: (35837*4)*0.5 (A**)*К1 | G11: 71674
E12: К1 = 0.5 (ТЧ_п.44_т.7_прим._п.1) При выполнении полевых работ по созданию пунктов плановой опорной геодезической сети без закладки центров методом спутниковых геодезических определений, совмещённых с пунктами высотной опорной сети IV класса, созданных без закладки центров методом спутниковых геодезических определений, (К3)
E13: Кинф = 1.2700 (1) Письмо Минстроя России N 45358-ИФ/09 от 22.07.2026г (2026г. III квартал)
A14: IV. Работы по топографической съёмке в масштабах 1:500 - 1:2000 (ПИИ Таблица 4.1.2)
A15: Незастроенная территория
A16: Застроенная территория (ПИИ Таблица 4.1.2)
A17: 3 | B17: Топографическая съемка тахеометрическим методом и сочетанием тахеометрического метода с методом спутниковых геодезических определений с высотой сечения рельефа через 0,5 метров, застроенной территории в масштабе 1:1000 в условиях выполнения полевых работ: IV категории | C17: 1 гектар | D17: 2 | E17: НЗ_ИГДИ-18-17 | F17: 57593*2 A** | G17: 115186
E18: Кинф = 1.2700 (1) Письмо Минстроя России N 45358-ИФ/09 от 22.07.2026г (2026г. III квартал)
A19: V. Работы по съёмке подземных инженерных коммуникаций и сооружений (ПИИ Таблица 4.1.2)
A20: 4 | B20: Полевые работы по поиску и съемке подземных инженерных коммуникаций при помощи трубокабелеискателя при количестве точек подземных инженерных коммуникаций на 1 гектар снимаемого участка: от 7 до 14 включительно | C20: 1 гектар | D20: 2 | E20: НЗ_ИГДИ-46-2 | F20: 24772*2 A** | G20: 49544
E21: Кинф = 1.2700 (1) Письмо Минстроя России N 45358-ИФ/09 от 22.07.2026г (2026г. III квартал)
A22: VII. Работы по привязке инженерно-геологических выработок, геофизических и гидрогеологических точек наблюдения (ПИИ Таблица 4.1.3)
A23: Работы по перенесению в натуру проектного положения инженерно-геологических, геофизических, гидрогеологических точек наблюдения (ПИИ Таблица 4.1.3).
A24: 5 | B24: Привязка инженерно-геологических выработок, геофизических и гидрогеологических точек наблюдения при расстоянии между точками от 200 (двухсот) до 350 (трехсот пятидесяти) метров включительно, в условиях выполнения полевых работ: III категории | C24: 1 точка | D24: 31 | E24: НЗ_ИГДИ-55-12 | F24: (13975*31)*0.5 (A**)*К1 | G24: 216612.5
E25: К1 = 0.5 (ТЧ_п.126_т.55_прим._п.1) При работах по перенесению в натуру инженерно-геологических выработок, геофизических, гидрогеологических точек наблюдений, (К8)
E26: Кинф = 1.2700 (1) Письмо Минстроя России N 45358-ИФ/09 от 22.07.2026г (2026г. III квартал)
A27: Работы по привязке фактического положения инженерно-геологических, геофизических, гидрогеологических точек наблюдения после завершения работ (ПИИ Таблица 4.1.3).
A28: 6 | B28: Привязка инженерно-геологических выработок, геофизических и гидрогеологических точек наблюдения при расстоянии между точками от 200 (двухсот) до 350 (трехсот пятидесяти) метров включительно, в условиях выполнения полевых работ: III категории | C28: 1 точка | D28: 31 | E28: НЗ_ИГДИ-55-12 | F28: 13975*31 A** | G28: 433225
E29: Кинф = 1.2700 (1) Письмо Минстроя России N 45358-ИФ/09 от 22.07.2026г (2026г. III квартал)
B30: Итоги по разделу 1 Полевые работы:
B31: Итого Поз. 1-6 | G31: 1 029 589.50
B32: Всего c учетом "Письмо Минстроя России N 45358-ИФ/09 от 22.07.2026г (2026г. III квартал) 1.2700" | G32: 1 286 986.88
B33: Итого по разделу 1 Полевые работы | G33: 1 286 986.88
A34: Раздел 2. Дополнительные затраты на производство полевых работ
A35: 7 | B35: Дополнительные затраты на неизбежные перерывы - 25% | C35: руб. | D35: 1029589.6 | E35: НЗ_ИГДИ п.25 | F35: 0.25*1029589.63 B** | G35: 257397.41
E36: Кинф = 1.2700 (1) Письмо Минстроя России N 45358-ИФ/09 от 22.07.2026г (2026г. III квартал)
A37: 8 | B37: Показатели дополнительных затрат на внешний транспорт (ПДЗвнеш) автомобильного транспорта, расстояние от места постоянной работы работников до участка проведения полевых работ от 2000 до 4000 км включительно при стоимости полевых работ от 1000 до 3000 тыс. руб. | C37: руб. | D37: 1029589.6 | E37: НЗ_ИГДИ-3-4-4 | F37: 0.2343*1029589.63 B** | G37: 241232.85
E38: Кинф = 1.2700 (1) Письмо Минстроя России N 45358-ИФ/09 от 22.07.2026г (2026г. III квартал)
A39: 9 | B39: Показатели дополнительных затрат на организацию полевых работ (ПДЗорг), расстояние от места постоянной работы работников до участка проведения полевых работ от 1000 до 2000 км включительно: при стоимости полевых работ свыше/до 3000 тыс. руб. - 7,7 % | C39: руб. | D39: 1029589.6 | E39: НЗ_ИГДИ-4-4-4 | F39: 0.3038*1029589.63 B** | G39: 312789.33
E40: Кинф = 1.2700 (1) Письмо Минстроя России N 45358-ИФ/09 от 22.07.2026г (2026г. III квартал)
B41: Итоги по разделу 2 Дополнительные затраты на производство полевых работ:
B42: Итого Поз. 7-9 | G42: 811 419.59
...

Sheet 1.1.2 ИГДИ
A1: Смета №1.1.2
A2: Инженерно - геодезические изыскания
A4: № п/п | B4: Наименование работ и затрат | D4: Обоснование стоимости | E4: Ед. изм. | F4: Кол- во | G4: Расчет стоимости | O4: Стоимость, руб
A5: 1 | B5: 2 | D5: 3 | E5: 4 | F5: 5 | G5: 6 | O5: 7
B6: Сметный расчет составлен по Справочнику базовых цен на инженерные изыскания для строительства. Инженерно-геодезические изыскания. ПНИИИС, 2004 г.
A7: 1 | B7: Картографическое вычерчивание топографических планов и карт. Создание ситуационного плана. | D7: Ч. II, гл.8, табл.65.
D8: 1,2к - применение комп. технологий - ОУ, п.15, д).
B9: Категория К-II, Р-II Категория II | C9: 1:5000 0,5м
C11: камеральные работы: | D11: Ч. II, гл.8, табл.65, § 10 | E11: 1 дм2 | F11: 40 | G11: 110 | H11: 1.2 | N11: 40.0*110*1.2 | O11: 5280
B12: Категория К-II, Р-II Категория II | C12: 1:10000 0,5м
C14: камеральные работы: | D14: Ч. II, гл.8, табл.65, § 14 | E14: 1 дм2 | F14: 10 | G14: 154 | H14: 1.2 | N14: 10.0*154*1.2 | O14: 1848
A15: 2 | B15: Итого камеральных работ | F15: 1 | N15: 1*7 128.00 | O15: 7128
A16: 3 | B16: Итого с районным коэффициентом | C16: камеральные работы: | D16: 1,08к - районный коэффициент 1,15 - ОУ, п.8, д), табл.3, §2 | F16: 1.08 | H16: 7128 | N16: 7 128.00*1.08 | O16: 7698.24
A17: 4 | B17: итого: | O17: 7698.24
A18: 5 | B18: Итого с учетом индекса изменения стоимости к уровню базовых цен по состоянию на 1 января 2001 года | D18: Письмо Минстроя России N 45358-ИФ/09 от 22.07.2026г (2026г. III квартал) | F18: 7.229 | H18: 7698.24 | N18: 7 698.24*7.07 | O18: =(54426.56/7.07)*7.229 -> 55650.58
A19: 6 | B19: Итого | O19: =O18 -> 55650.58
A20: 7 | B20: Итого с коэффициентом оптимизации ПАО Газпром | O20: =O19*0.8 -> 44520.464
A21: 8 | B21: Всего по смете | O21: =O20 -> 44520.464

Sheet 1.1.3 ИГДИ
G2: Форма 2п
B3: СМЕТА №1.1.3
B4: Реконструкция ГПС - Объёмы к изм ТЗ (ИГДИ.2)
B5: =СВОД!B22 -> Инженерно-геодезические изыскания
A7: № пп | B7: Наименование работ и затрат | C7: Единица измерения | D7: Кол-во | E7: Обоснование стоимости | F7: Расчет стоимости, руб. | G7: Стоимость, руб.
A8: 1 | B8: 2 | C8: 3 | D8: 4 | E8: 5 | F8: 6 | G8: 7
A9: Раздел 1. Полевые работы
A10: III. Работы по созданию опорной геодезической сети
A11: Этап 16; 4212.012.Р.16/0.0004.Г3.001.40203.000-ГСН; Межпоселковый газопровод высокого давления II категории от ПППГ до коллектора КС3-ГРП5; ПОГС - 1шт; 4212.012.Р.3/0.0004.КЛС.02А.41403.001-КЛС; Трассы кабельных линий связи; ГРП-2А Операторная - КС-3 СЭБ (поз. 225); ПОГС - 2шт; Этап 3; 4212.00.Р.04.МПВ.2.000.НВ.000; Водовод межплощадочный КС3-ГРП2А подземной прокладки; ПОГС – 1шт; Этап 16; 4212.00.Р.04.КК.10.000.НК.000; Коллектор межплощадочный канализационный ПППГ-КОС; ПОГС – 1шт; Этап 16; 4212.00.Р.04.МПВ.9.000.НВ.000; Водовод межплощадочный ПППГ-КОС; ПОГС – 1шт; Этап 27; 4212.00.Р.04.МПВ.8.000.НВ.000; Водовод межплощадочный КОС-КС5; ПОГС – 1шт; Этап 27; 4212.СРТ.00.Р.04.МПВ.5.1.НВ.000; Водовод межплощадочный к точке подключения ГРП.5; ПОГС – 2шт; Этап 27; 4212.00.Р.04.МПВ.5.000.НВ.000; Водовод межплощадочный от КС5 до РЛВЖ; ПОГС – 1шт; 4212.012.Р.3/0.0004.ВЭЛ.000.41501.000-ЭВ - ВЛЗ 6 кВ (в габаритах 35 кВ) от ПС 110/35/6 кВ «Степная-газовая» до КСПХГ №5; ПОГС – 3шт; 4212.012.Р.3/0.0004.ВЭЛ.000.41501.000-ЭВ1 - ВЛЗ 6 кВ к ГРП 2А 253м; ПОГС – 1шт; 4212.012.Р.3/0.0004.ВЭЛ.000.41501.000-ЭВ2 - ВЛЗ 6 кВ к ГРП 1А 920м ПОГС – 1шт.
A12: 1 | B12: Создание пунктов плановой опорной геодезической сети без закладки центров методом спутниковых геодезических определений, 2-го разряда в условиях выполнения полевых работ: II категории | C12: 1 пункт | D12: 15 | E12: НЗ_ИГДИ-7-8 | F12: (35837*15)*1.27 (A**)*К1 | G12: 671943.75
E13: К1 = 1.27 Письмо Минстроя России N 45358-ИФ/09 от 22.07.2026г (2026г. III квартал)
E14: Кинф = 1.2700 (1) Письмо Минстроя России N 45358-ИФ/09 от 22.07.2026г (2026г. III квартал)
A15: 2 | B15: Создание пунктов плановой опорной геодезической сети без закладки центров методом спутниковых геодезических определений, 2-го разряда в условиях выполнения полевых работ: II категории | C15: 1 пункт | D15: 15 | E15: НЗ_ИГДИ-7-8 | F15: (35837*15)*0.5*1.27 (A**)*К1*К2 | G15: 335971.88
E16: К1 = 0.5 (ТЧ_п.44_т.7_прим._п.1) При выполнении полевых работ по созданию пунктов плановой опорной геодезической сети без закладки центров методом спутниковых геодезических определений, совмещённых с пунктами высотной опорной сети IV класса, созданных без закладки центров методом спутниковых геодезических определений, (К3)
E17: К2 = 1.27 Письмо Минстроя России N 45358-ИФ/09 от 22.07.2026г (2026г. III квартал)
E18: Кинф = 1.2700 (1) Письмо Минстроя России N 45358-ИФ/09 от 22.07.2026г (2026г. III квартал)
A19: IV. Работы по топографической съёмке в масштабах 1:500 - 1:2000
A20: Незастроенная территория
A21: Застроенная территория
A22: Этап 16; 4212.012.Р.16/0.0004.Г3.001.40203.000-ГСН; Межпоселковый газопровод высокого давления II категории от ПППГ до коллектора КС3-ГРП5; P=154,55м*6м=0.08га; 4212.012.Р.3/0.0004.КЛС.02А.41403.001-КЛС; Трассы кабельных линий связи; ГРП-2А Операторная - КС-3 СЭБ (поз. 225); P=4500м*6м=2.7га; Этап 3; 4212.00.Р.04.МПВ.2.000.НВ.000; Водовод межплощадочный КС3-ГРП2А подземной прокладки; P=1900м*6м=1.14а; Этап 16; 4212.00.Р.04.КК.10.000.НК.000; Коллектор межплощадочный канализационный ПППГ-КОС; P=214м*6м=0.13га; Этап 16; 4212.00.Р.04.МПВ.9.000.НВ.000; Водовод межплощадочный ПППГ-КОС; P=257м*6м=0.15га; Этап 27; 4212.00.Р.04.МПВ.8.000.НВ.000; Водовод межплощадочный КОС-КС5; P=665м*6м=0.40га; Этап 27; 4212.СРТ.00.Р.04.МПВ.5.1.НВ.000; Водовод межплощадочный к точке подключения ГРП.5; P=1370м*6м=0.82га; Этап 27; 4212.00.Р.04.МПВ.5.000.НВ.000; Водовод межплощадочный от КС5 до РЛВЖ; P=210м*6м=0.13га; 4212.012.Р.3/0.0004.ВЭЛ.000.41501.000-ЭВ - ВЛЗ 6 кВ (в габаритах 35 кВ) от ПС 110/35/6 кВ «Степная-газовая» до КСПХГ №5; P=3927м*6м=2.36га; 4212.012.Р.3/0.0004.ВЭЛ.000.41501.000-ЭВ1 - ВЛЗ 6 кВ к ГРП 2А; P=253м*6м=0.15га; 4212.012.Р.3/0.0004.ВЭЛ.000.41501.000-ЭВ2 - ВЛЗ 6 кВ к ГРП 1А; P=920м*6м=0.55га
A23: 3 | B23: Топографическая съемка тахеометрическим методом и сочетанием тахеометрического метода с методом спутниковых геодезических определений с высотой сечения рельефа через 0,5 метров, застроенной территории в масштабе 1:500 в условиях выполнения полевых работ: II категории | C23: 1 гектар | D23: 8.62233 | E23: НЗ_ИГДИ-18-11 | F23: (38848*8.62233)*1.27*0.5 (A**)*К2*К3 | G23: 209350.17
E24: К2 = 1.27 Письмо Минстроя России N 45358-ИФ/09 от 22.07.2026г (2026г. III квартал)
E25: К3 = 0.5 Обновление ИИ
E26: Кинф = 1.2700 (1) Письмо Минстроя России N 45358-ИФ/09 от 22.07.2026г (2026г. III квартал)
A27: V. Работы по съёмке подземных инженерных коммуникаций и сооружений
A28: 4 | B28: Полевые работы по поиску и съемке подземных инженерных коммуникаций при помощи трубокабелеискателя при количестве точек подземных инженерных коммуникаций на 1 гектар снимаемого участка: от 7 до 14 включительно | C28: 1 гектар | D28: 8.622335 | E28: НЗ_ИГДИ-46-2 | F28: (24772*8.622335)*1.27*0.5 (A**)*К1*К2 | G28: 133495.3
E29: К1 = 1.27 Письмо Минстроя России N 45358-ИФ/09 от 22.07.2026г (2026г. III квартал)
E30: К2 = 0.5 Обновление ИИ
E31: Кинф = 1.2700 (1) Письмо Минстроя России N 45358-ИФ/09 от 22.07.2026г (2026г. III квартал)
A32: VII. Работы по привязке инженерно-геологических выработок, геофизических и гидрогеологических точек наблюдения
A33: Работы по перенесению в натуру проектного положения инженерно-геологических, геофизических, гидрогеологических точек наблюдения.
A34: Работы по привязке фактического положения инженерно-геологических, геофизических, гидрогеологических точек наблюдения после завершения работ.
B35: Итоги по разделу 1 Полевые работы:
B36: Итого Поз. 1-4 | G36: 1 350 761.10
B37: Итого по разделу 1 Полевые работы | G37: 1 350 761.10
A38: Раздел 2. Дополнительные затраты на производство полевых работ
A39: 5 | B39: Показатели дополнительных затрат на внешний транспорт (ПДЗвнеш) автомобильного транспорта, расстояние от места постоянной работы работников до участка проведения полевых работ от 1000 до 2000 км включительно при стоимости полевых работ свыше/до 3000 тыс. руб. - 8,2 % | C39: руб. | D39: 1350761.2 | E39: НЗ_ИГДИ-3-4-4 | F39: (0.1175*1350761.24)*1.27 (B**)*Кинф | G39: 198393.06
E40: Кинф = 1.2700 (1) Письмо Минстроя России N 45358-ИФ/09 от 22.07.2026г (2026г. III квартал)
A41: 6 | B41: Показатели дополнительных затрат на организацию полевых работ (ПДЗорг), расстояние от места постоянной работы работников до участка проведения полевых работ от 1000 до 2000 км включительно: при стоимости полевых работ свыше/до 3000 тыс. руб. - 7,7 % | C41: руб. | D41: 1350761.2 | E41: НЗ_ИГДИ-4-4-4 | F41: (0.2345*1350761.24)*1.27 (B**)*Кинф | G41: 395941.89
E42: Кинф = 1.2700 (1) Письмо Минстроя России N 45358-ИФ/09 от 22.07.2026г (2026г. III квартал)
...

Sheet 1.1.4 ИГДИ+
G2: Форма 2п
B3: СМЕТА № 1.1.4 2026-07-29 Реконструкция ГПС - Убежище + ГС ГРП-2А
A5: № пп | B5: Наименование работ и затрат | C5: Единица измерения | D5: Кол-во | E5: Обоснование стоимости | F5: Расчет стоимости, руб. | G5: Стоимость, руб.
A6: 1 | B6: 2 | C6: 3 | D6: 4 | E6: 5 | F6: 6 | G6: 7
A7: Раздел 1. Полевые работы
A8: III. Работы по созданию опорной геодезической сети
A9: 1 | B9: Создание пунктов плановой опорной геодезической сети без закладки центров методом спутниковых геодезических определений, 2-го разряда в условиях выполнения полевых работ: II категории | C9: 1 пункт | D9: 10 | E9: НЗ_ИГДИ-7-8 | F9: (35837*10)*1.27 (A**)*К1 | G9: 447962.5
E10: К1 = 1.27 Письмо Минстроя России N 45358-ИФ/09 от 22.07.2026г (2026г. III квартал)
E11: Кинф = 1.2700 (1) Письмо Минстроя России N 45358-ИФ/09 от 22.07.2026г (2026г. III квартал)
A12: 2 | B12: Создание пунктов плановой опорной геодезической сети без закладки центров методом спутниковых геодезических определений, 2-го разряда в условиях выполнения полевых работ: II категории | C12: 1 пункт | D12: 10 | E12: НЗ_ИГДИ-7-8 | F12: (35837*10)*0.5*1.27 (A**)*К1*К2 | G12: 223981.25
E13: К1 = 0.5 (ТЧ_п.44_т.7_прим._п.1) При выполнении полевых работ по созданию пунктов плановой опорной геодезической сети без закладки центров методом спутниковых геодезических определений, совмещённых с пунктами высотной опорной сети IV класса, созданных без закладки центров методом спутниковых геодезических определений, (К3)
E14: К2 = 1.27 Письмо Минстроя России N 45358-ИФ/09 от 22.07.2026г (2026г. III квартал)
E15: Кинф = 1.2700 (1) Письмо Минстроя России N 45358-ИФ/09 от 22.07.2026г (2026г. III квартал)
A16: IV. Работы по топографической съёмке в масштабах 1:500 - 1:2000
A17: Незастроенная территория
A18: Застроенная территория
A19: 3 | B19: Топографическая съемка тахеометрическим методом и сочетанием тахеометрического метода с методом спутниковых геодезических определений с высотой сечения рельефа через 0,5 метров, застроенной территории в масштабе 1:1000 в условиях выполнения полевых работ: II категории | C19: 1 гектар | D19: 52 | E19: НЗ_ИГДИ-18-15 | F19: (25899*52)*1.27 (A**)*К2 | G19: 1683435
E20: К2 = 1.27 Письмо Минстроя России N 45358-ИФ/09 от 22.07.2026г (2026г. III квартал)
E21: Кинф = 1.2700 (1) Письмо Минстроя России N 45358-ИФ/09 от 22.07.2026г (2026г. III квартал)
A22: V. Работы по съёмке подземных инженерных коммуникаций и сооружений
A23: 4 | B23: Полевые работы по поиску и съемке подземных инженерных коммуникаций при помощи трубокабелеискателя при количестве точек подземных инженерных коммуникаций на 1 гектар снимаемого участка: от 7 до 14 включительно | C23: 1 гектар | D23: 52 | E23: НЗ_ИГДИ-46-2 | F23: (24772*52)*1.27 (A**)*К1 | G23: 1610180
E24: К1 = 1.27 Письмо Минстроя России N 45358-ИФ/09 от 22.07.2026г (2026г. III квартал)
E25: Кинф = 1.2700 (1) Письмо Минстроя России N 45358-ИФ/09 от 22.07.2026г (2026г. III квартал)
A26: VII. Работы по привязке инженерно-геологических выработок, геофизических и гидрогеологических точек наблюдения
A27: Работы по перенесению в натуру проектного положения инженерно-геологических, геофизических, гидрогеологических точек наблюдения.
A28: Работы по привязке фактического положения инженерно-геологических, геофизических, гидрогеологических точек наблюдения после завершения работ.
B29: Итоги по разделу 1 Полевые работы:
B30: Итого Поз. 1-4 | G30: 3 965 558.75
B31: Итого по разделу 1 Полевые работы | G31: 3 965 558.75
A32: Раздел 2. Дополнительные затраты на производство полевых работ
A33: 5 | B33: Дополнительные затраты на неизбежные перерывы - 25% | C33: руб. | D33: 3965558.9 | E33: НЗ_ИГДИ п.25 | F33: (0.25*3965558.86)*1.27 (B**)*Кинф | G33: 1239237.2
E34: Кинф = 1.2700 (1) Письмо Минстроя России N 45358-ИФ/09 от 22.07.2026г (2026г. III квартал)
A35: 6 | B35: Показатели дополнительных затрат на внешний транспорт (ПДЗвнеш) автомобильного транспорта, расстояние от места постоянной работы работников до участка проведения полевых работ от 1000 до 2000 км включительно при стоимости полевых работ свыше/до 3000 тыс. руб. - 8,2 % | C35: руб. | D35: 3965558.9 | E35: НЗ_ИГДИ-3-4-4 | F35: (0.119*3965558.86)*1.27 (B**)*Кинф | G35: 589876.88
E36: Кинф = 1.2700 (1) Письмо Минстроя России N 45358-ИФ/09 от 22.07.2026г (2026г. III квартал)
A37: 7 | B37: Показатели дополнительных затрат на организацию полевых работ (ПДЗорг), расстояние от места постоянной работы работников до участка проведения полевых работ от 1000 до 2000 км включительно: при стоимости полевых работ свыше/до 3000 тыс. руб. - 7,7 % | C37: руб. | D37: 3965558.9 | E37: НЗ_ИГДИ-4-4-4 | F37: (0.088*3965558.86)*1.27 (B**)*Кинф | G37: 436211.47
E38: Кинф = 1.2700 (1) Письмо Минстроя России N 45358-ИФ/09 от 22.07.2026г (2026г. III квартал)
B39: Итоги по разделу 2 Дополнительные затраты на производство полевых работ:
B40: Итого Поз. 5-7 | G40: 2 265 325.49
B41: Итого по разделу 2 Дополнительные затраты на производство полевых работ | G41: 2 265 325.49
A42: Раздел 3. Камеральные работы
...

Sheet 1.2.1 ИГИ
A1: Смета №1.2.1
A2: на работы по инженерным изысканиям
A4: инженерно-геологические
A5: (наименование вида инженерных изысканий)
A6: Реконструкция газопромысловых сооружений Степновской СПХГ
A7: (наименование объекта капитального строительства)
A10: № | B10: Наименование работ или затрат | C10: Обоснование | D10: Расчет стоимости | E10: Сметная стоимость в уровне цен, сложившемся на день составления сметной документации, рублей | F10: объем
A11: 1 | B11: 2 | C11: 3 | D11: 4 | E11: 5
B12: I. Полевые работы
A13: 1 | B13: Рекогносцировочное обследование II категории сложности | C13: Нормативные затраты на работы по инженерно-геологическим изысканиям Табл.12, п.7 | D13: ="(15264+3608*"&F13&"га)*1.27" -> (15264+3608*13га)*1.27 | E13: =(15264+(3608*F13))*1.27 -> 78953.36 | F13: 13
A14: =A13+1 -> 2 | B14: Проходка инженерно-геологических скважин колонковым способом бурения: | C14: Нормативные затраты на работы по инженерно-геологическим изысканиям
B15: диаметром до 160 (ста шестидесяти) миллиметров включительно при глубине скважины до 15 (пятнадцати) метров включительно в грунтах категории:
B16: I | C16: Табл.14, п.1; Табл.2, п.1 | D16: ="2858*"&F16&"п.м.*1.04*1.27" -> 2858*57п.м.*1.04*1.27 | E16: =2858*F16*1.04*1.27 -> 215166.24 | F16: 57
B17: II | C17: Табл.14, п.2; Табл.2, п.1 | D17: ="3237*"&F17&"п.м.*1.04*1.27" -> 3237*204п.м.*1.04*1.27 | E17: =3237*F17*1.04*1.27 -> 872187.64 | F17: 204
B18: III | C18: Табл.14, п.3; Табл.2, п.1 | D18: ="3300*"&F18&"п.м.*1.04*1.27" -> 3300*74п.м.*1.04*1.27 | E18: =3300*F18*1.04*1.27 -> 322539.36 | F18: 74
B19: IV | C19: Табл.14, п.4; Табл.2, п.1 | D19: ="4125*"&F19&"п.м.*1.04*1.27" -> 4125*0п.м.*1.04*1.27 | E19: =4125*F19*1.04*1.27 -> 0 | F19: 0
A20: =A14+1 -> 3 | B20: Крепление инженерно-геологических скважин обсадными трубами | C20: Нормативные затраты на работы по инженерно-геологическим изысканиям Табл.25, п.1 | D20: ="1536*"&F20&"п.м.*1.27" -> 1536*67п.м.*1.27 | E20: =1536*F20*1.27 -> 130698.24 | F20: 67
A21: =A20+1 -> 4 | B21: Проведение гидрогеологических исследований первого от поверхности земли подземного водоносного горизонта в инженерно-геологических скважинах | C21: Нормативные затраты на работы по инженерно-геологическим изысканиям Табл.26, п.1 | D21: ="983*"&F21&"скв*1.27" -> 983*31скв*1.27 | E21: =983*F21*1.27 -> 38700.71 | F21: 31
A22: =A21+1 -> 5 | B22: Проходка шурфов при глубине шурфа, метров: | C22: Нормативные затраты на работы по инженерно-геологическим изысканиям
B23: от 2,5 до 5 включительно в грунтах категории:
B24: III | C24: Табл.30, п.7 | D24: ="23558*"&F24&"м3*1.27" -> 23558*60м3*1.27 | E24: =23558*F24*1.02*1.27 -> 1831022 | F24: =24*2.5 -> 60
B25: IV | C25: Табл.30, п.8 | D25: ="37562*"&F25&"м3*1.27" -> 37562*60м3*1.27 | E25: =37562*F25*1.02*1.27 -> 2919468.9 | F25: =24*2.5 -> 60
A26: =A22+1 -> 6 | B26: Предварительная проходка методом разбуривания асфальта, бетона, древесины, крупнообломочных грунтов, техногенных грунтов с поверхности земли для последующего проведения полевых испытаний грунтов методом статического зондирования | C26: Нормативные затраты на работы по инженерно-геологическим изысканиям Табл.43, п.1; Табл.2, п.5 | D26: ="902*"&F26&"п.м.*1.02*1.27" -> 902*10п.м.*1.02*1.27 | E26: =902*F26*1.02*1.27 -> 11684.508 | F26: 10
A27: =A26+1 -> 7 | B27: Полевые испытания грунтов методом статического зондирования непрерывным вдавливанием на глубину, метров: | C27: Нормативные затраты на работы по инженерно-геологическим изысканиям
B28: от 10 до 15 включительно | C28: Табл.43, п.3; Табл.2, п.5 | D28: ="3138*"&F28&"п.м.*1.1*1.27" -> 3138*150п.м.*1.1*1.27 | E28: =3138*F28*1.1*1.27 -> 657567.9 | F28: 150
A29: =A27+1 -> 8 | B29: Дополнительные затраты на производство полевых работ в неблагоприятный период года | C29: Нормативные затраты на работы по инженерно-геологическим изысканиям Табл.3, п.3 | D29: =ROUND(SUM(E13:E28),0)&"*0.19" -> 7077989*0.19 | E29: =SUM(E13:E28)*0.19 -> 1344817.9
A30: =A29+1 -> 9 | B30: Дополнительных затрат на неизбежные перерывы | C30: Нормативные затраты на работы по инженерно-геологическим изысканиям п.27 | D30: =ROUND(SUM(E13:E28),0)&"*0.25" -> 7077989*0.25 | E30: =SUM(E13:E28)*0.25 -> 1769497.2
A31: =A30+1 -> 10 | B31: Дополнительные затраты на проезд | C31: Нормативные затраты на работы по инженерно-геологическим изысканиям Табл.5, п.5 | D31: =ROUND(SUM(E13:E28),0)&"*(28.1%+(48.2%-28.1%)/(10млн.руб-5млн.руб)*(10млн.руб-"&ROUND(SUM(E13:E28),0)&"))" -> 7077989*(28.1%+(48.2%-28.1%)/(10млн.руб-5млн.руб)*(10млн.руб-7077989)) | E31: =SUM(E13:E28)*(28.1%+(48.2%-28.1%)/(10000000-5000000)*(10000000-SUM(E13:E28))) -> 2820329.8
A32: =A31+1 -> 11 | B32: Дополнительные затраты на организацию полевых работ | C32: Нормативные затраты на работы по инженерно-геологическим изысканиям Табл.8, п.5. | D32: =ROUND(SUM(E13:E28),0)&"*7.4%" -> 7077989*7.4% | E32: =SUM(E13:E28)*7.4% -> 523771.17
A33: =A32+1 -> 12 | B33: Дополнительные затраты на районные выплаты | C33: Нормативные затраты на работы по инженерно-геологическим изысканиям п.40 | D33: ="("&ROUND(SUM(E13:E28),0)&"+"&ROUND(E29,0)&"+"&ROUND(E30,0)&"+"&ROUND(E32,0)&")*(0.41*"&ROUND(F33,2)&"+0.59-1)" -> (7077989+1344818+1769497+523771)*(0.41*1+0.59-1) | E33: =(SUM(E13:E30)+E32)*(0.41*F33+0.59-1) -> 0 | F33: 1
B34: Итого по разделу I | E34: =SUM(E13:E33) -> 13536405
B35: II. Лабораторные работы
A36: =A33+1 -> 13 | B36: Определение влажности грунта методом высушивания до постоянной массы | C36: Нормативные затраты на работы по инженерно-геологическим изысканиям Табл.56, п.1-3; Табл.57, п.1 | D36: ="((459+335+141)*"&F36&"обр+229*"&F36&"опр)*1.27" -> ((459+335+141)*167обр+229*167опр)*1.27 | E36: =((459+335+141)*F36+229*F36)*1.27 -> 246872.76 | F36: 167
A37: =A36+1 -> 14 | B37: Определение плотности частиц грунта пикнометрическим методом | C37: Нормативные затраты на работы по инженерно-геологическим изысканиям Табл.56, п.1-3; Табл.57, п.4 | D37: ="((459+335+141)*"&F37&"обр+600*"&F37&"опр)*1.27" -> ((459+335+141)*122обр+600*122опр)*1.27 | E37: =((459+335+141)*F37+600*F37)*1.27 -> 237832.9 | F37: =90+32 -> 122
A38: =A37+1 -> 15 | B38: Определение содержания органических веществ в грунте методом прокаливания до постоянной массы | C38: Нормативные затраты на работы по инженерно-геологическим изысканиям Табл.56, п.1-3; Табл.57, п.8 | D38: ="((459+335+141)*"&F38&"обр+370*"&F38&"опр)*1.27" -> ((459+335+141)*18обр+370*18опр)*1.27 | E38: =((459+335+141)*F38+370*F38)*1.27 -> 29832.3 | F38: 18
A39: =A38+1 -> 16 | B39: Определение гранулометрического (зернового) состава грунта ситовым методом с промывкой водой с разделением грунта по фракциям размерами: свыше 0,5 миллиметра, от 0,25 до 0,5 миллиметра, от 0,1 до 0,25 миллиметра и до 0,1 миллиметра | C39: Нормативные затраты на работы по инженерно-геологическим изысканиям Табл.56, п.1-3; Табл.57, п.10 | D39: ="((459+335+141)*"&F39&"обр+917*"&F39&"опр)*1.27" -> ((459+335+141)*60обр+917*60опр)*1.27 | E39: =((459+335+141)*F39+917*F39)*1.27 -> 141122.4 | F39: 60
A40: =A39+1 -> 17 | B40: Определение гранулометрического (микроагрегатного) состава грунта ареометрическим методом с разделением грунта на фракции размерами: от 0,05 до 0,1 миллиметра, от 0,01 до 0,05 миллиметра, от 0,005 до 0,01 миллиметра, от 0,001 до 0,002 миллиметра и до 0,001 миллиметра | C40: Нормативные затраты на работы по инженерно-геологическим изысканиям Табл.56, п.1-3; Табл.57, п.14 | D40: ="((459+335+141)*"&F40&"обр+1852*"&F40&"опр)*1.27" -> ((459+335+141)*60обр+1852*60опр)*1.27 | E40: =((459+335+141)*F40+1852*F40)*1.27 -> 212369.4 | F40: 60
A41: =A40+1 -> 18 | B41: Определение относительной деформации морозного пучения | C41: Нормативные затраты на работы по инженерно-геологическим изысканиям Табл.56, п.1-3; Табл.57, п.16 | D41: ="((459+335+141)*"&F41&"обр+4546*"&F41&"опр)*1.27" -> ((459+335+141)*6обр+4546*6опр)*1.27 | E41: =((459+335+141)*F41+4546*F41)*1.27 -> 41765.22 | F41: 6
A42: =A41+1 -> 19 | B42: Определение плотности глинистого грунта методом режущего кольца | C42: Нормативные затраты на работы по инженерно-геологическим изысканиям Табл.56, п.1-3; Табл.57, п.17 | D42: ="((459+335+141)*"&F42&"обр+529*"&F42&"опр)*1.27" -> ((459+335+141)*122обр+529*122опр)*1.27 | E42: =((459+335+141)*F42+529*F42)*1.27 -> 226832.16 | F42: =90+32 -> 122
A43: =A42+1 -> 20 | B43: Определение верхнего предела пластичности глинистого грунта - влажности грунта на границе текучести и нижнего предела пластичности глинистого грунта - влажности грунта на границе раскатывания при проведении испытания с использованием образца грунта природной влажности | C43: Нормативные затраты на работы по инженерно-геологическим изысканиям Табл.56, п.1-3; Табл.57, п.18 | D43: ="((459+335+141)*"&F43&"обр+1676*"&F43&"опр)*1.27" -> ((459+335+141)*139обр+1676*139опр)*1.27 | E43: =((459+335+141)*F43+1676*F43)*1.27 -> 460919.83 | F43: =107+32 -> 139
...

Sheet 1.2.2 ИГИ+
A1: Смета №1.2.2
A2: на работы по инженерным изысканиям
A4: инженерно-геологические
A5: (наименование вида инженерных изысканий)
A6: Реконструкция газопромысловых сооружений Степновской СПХГ
A7: (наименование объекта капитального строительства)
A10: № | B10: Наименование работ или затрат | C10: Обоснование | D10: Расчет стоимости | E10: Сметная стоимость в уровне цен, сложившемся на день составления сметной документации, рублей | F10: объем
A11: 1 | B11: 2 | C11: 3 | D11: 4 | E11: 5
B12: I. Полевые работы
A13: 1 | B13: Рекогносцировочное обследование II категории сложности | C13: Нормативные затраты на работы по инженерно-геологическим изысканиям Табл.12, п.7 | D13: ="(15264+3608*"&F13&"га)*1,27" -> (15264+3608*0,3га)*1,27 | E13: =(15264+(3608*F13))*1.27 -> 20759.928 | F13: 0.3
A14: =A13+1 -> 2 | B14: Проходка инженерно-геологических скважин колонковым способом бурения: | C14: Нормативные затраты на работы по инженерно-геологическим изысканиям
B15: диаметром до 160 (ста шестидесяти) миллиметров включительно при глубине скважины до 15 (пятнадцати) метров включительно в грунтах категории:
B16: I | C16: Табл.14, п.1; Табл.2, п.1 | D16: ="2858*"&F16&"п.м.*1.04*1,27" -> 2858*7п.м.*1.04*1,27 | E16: =2858*F16*1.04*1.27 -> 26423.925 | F16: 7
B17: II | C17: Табл.14, п.2; Табл.2, п.1 | D17: ="3237*"&F17&"п.м.*1.04*1,27" -> 3237*7п.м.*1.04*1,27 | E17: =3237*F17*1.04*1.27 -> 29928.007 | F17: 7
B18: III | C18: Табл.14, п.3; Табл.2, п.1 | D18: ="3300*"&F18&"п.м.*1.04*1,27" -> 3300*8п.м.*1.04*1,27 | E18: =3300*F18*1.04*1.27 -> 34869.12 | F18: 8
B19: IV | C19: Табл.14, п.4; Табл.2, п.1 | D19: ="4125*"&F19&"п.м.*1.04*1,27" -> 4125*0п.м.*1.04*1,27 | E19: =4125*F19*1.04*1.27 -> 0 | F19: 0
A20: =A14+1 -> 3 | B20: Крепление инженерно-геологических скважин обсадными трубами | C20: Нормативные затраты на работы по инженерно-геологическим изысканиям Табл.25, п.1 | D20: ="1536*"&F20&"п.м.*1,27" -> 1536*6п.м.*1,27 | E20: =1536*F20*1.27 -> 11704.32 | F20: 6
A21: =A20+1 -> 4 | B21: Проведение гидрогеологических исследований первого от поверхности земли подземного водоносного горизонта в инженерно-геологических скважинах | C21: Нормативные затраты на работы по инженерно-геологическим изысканиям Табл.26, п.1 | D21: ="983*"&F21&"скв*1,27" -> 983*2скв*1,27 | E21: =983*F21*1.27 -> 2496.82 | F21: 2
A22: =A21+1 -> 5 | B22: Проходка шурфов при глубине шурфа, метров: | C22: Нормативные затраты на работы по инженерно-геологическим изысканиям
B23: от 2,5 до 5 включительно в грунтах категории:
B24: III | C24: Табл.30, п.7 | D24: ="23558*"&F24&"м3*1,27" -> 23558*0м3*1,27 | E24: =23558*F24*1.02*1.27 -> 0 | F24: 0
B25: IV | C25: Табл.30, п.8 | D25: ="37562*"&F25&"м3*1,27" -> 37562*0м3*1,27 | E25: =37562*F25*1.02*1.27 -> 0 | F25: 0
A26: =A22+1 -> 6 | B26: Предварительная проходка методом разбуривания асфальта, бетона, древесины, крупнообломочных грунтов, техногенных грунтов с поверхности земли для последующего проведения полевых испытаний грунтов методом статического зондирования | C26: Нормативные затраты на работы по инженерно-геологическим изысканиям Табл.43, п.1; Табл.2, п.5 | D26: ="902*"&F26&"п.м.*1.02*1,27" -> 902*0п.м.*1.02*1,27 | E26: =902*F26*1.02*1.27 -> 0 | F26: 0
A27: =A26+1 -> 7 | B27: Полевые испытания грунтов методом статического зондирования непрерывным вдавливанием на глубину, метров: | C27: Нормативные затраты на работы по инженерно-геологическим изысканиям
B28: от 10 до 15 включительно | C28: Табл.43, п.3; Табл.2, п.5 | D28: ="3138*"&F28&"п.м.*1.1*1,27" -> 3138*0п.м.*1.1*1,27 | E28: =3138*F28*1.1*1.27 -> 0 | F28: 0
A29: =A27+1 -> 8 | B29: Дополнительные затраты на производство полевых работ в неблагоприятный период года | C29: Нормативные затраты на работы по инженерно-геологическим изысканиям Табл.3, п.3 | D29: =ROUND(SUM(E13:E28),0)&"*0.19" -> 126182*0.19 | E29: =SUM(E13:E28)*0.19 -> 23974.603
A30: =A29+1 -> 9 | B30: Дополнительных затрат на неизбежные перерывы | C30: Нормативные затраты на работы по инженерно-геологическим изысканиям п.27 | D30: =ROUND(SUM(E13:E28),0)&"*0.25" -> 126182*0.25 | E30: =SUM(E13:E28)*0.25 -> 31545.53
A31: =A30+1 -> 10 | B31: Дополнительные затраты на проезд | C31: Нормативные затраты на работы по инженерно-геологическим изысканиям Табл.5, п.5 | D31: =ROUND(SUM(E13:E28),0)&"*(28.1%+(48.2%-28.1%)/(10млн.руб-5млн.руб)*(10млн.руб-"&ROUND(SUM(E13:E28),0)&"))" -> 126182*(28.1%+(48.2%-28.1%)/(10млн.руб-5млн.руб)*(10млн.руб-126182)) | E31: =SUM(E13:E28)*(28.1%+(48.2%-28.1%)/(10000000-5000000)*(10000000-SUM(E13:E28))) -> 85542.326
A32: =A31+1 -> 11 | B32: Дополнительные затраты на организацию полевых работ | C32: Нормативные затраты на работы по инженерно-геологическим изысканиям Табл.8, п.5. | D32: =ROUND(SUM(E13:E28),0)&"*7.4%" -> 126182*7.4% | E32: =SUM(E13:E28)*7.4% -> 9337.4769
A33: =A32+1 -> 12 | B33: Дополнительные затраты на районные выплаты | C33: Нормативные затраты на работы по инженерно-геологическим изысканиям п.40 | D33: ="("&ROUND(SUM(E13:E28),0)&"+"&ROUND(E29,0)&"+"&ROUND(E30,0)&"+"&ROUND(E32,0)&")*(0.41*"&ROUND(F33,2)&"+0.59-1)" -> (126182+23975+31546+9337)*(0.41*1+0.59-1) | E33: =(SUM(E13:E30)+E32)*(0.41*F33+0.59-1) -> 0 | F33: 1
B34: Итого по разделу I | E34: =SUM(E13:E33) -> 276582.06
B35: II. Лабораторные работы
A36: =A33+1 -> 13 | B36: Определение влажности грунта методом высушивания до постоянной массы | C36: Нормативные затраты на работы по инженерно-геологическим изысканиям Табл.56, п.1-3; Табл.57, п.1 | D36: ="((459+335+141)*"&F36&"обр+229*"&F36&"опр)*1,27" -> ((459+335+141)*12обр+229*12опр)*1,27 | E36: =((459+335+141)*F36+229*F36)*1.27 -> 17739.36 | F36: 12
A37: =A36+1 -> 14 | B37: Определение плотности частиц грунта пикнометрическим методом | C37: Нормативные затраты на работы по инженерно-геологическим изысканиям Табл.56, п.1-3; Табл.57, п.4 | D37: ="((459+335+141)*"&F37&"обр+600*"&F37&"опр)*1,27" -> ((459+335+141)*6обр+600*6опр)*1,27 | E37: =((459+335+141)*F37+600*F37)*1.27 -> 11696.7 | F37: 6
A38: =A37+1 -> 15 | B38: Определение содержания органических веществ в грунте методом прокаливания до постоянной массы | C38: Нормативные затраты на работы по инженерно-геологическим изысканиям Табл.56, п.1-3; Табл.57, п.8 | D38: ="((459+335+141)*"&F38&"обр+370*"&F38&"опр)*1,27" -> ((459+335+141)*3обр+370*3опр)*1,27 | E38: =((459+335+141)*F38+370*F38)*1.27 -> 4972.05 | F38: 3
A39: =A38+1 -> 16 | B39: Определение гранулометрического (зернового) состава грунта ситовым методом с промывкой водой с разделением грунта по фракциям размерами: свыше 0,5 миллиметра, от 0,25 до 0,5 миллиметра, от 0,1 до 0,25 миллиметра и до 0,1 миллиметра | C39: Нормативные затраты на работы по инженерно-геологическим изысканиям Табл.56, п.1-3; Табл.57, п.10 | D39: ="((459+335+141)*"&F39&"обр+917*"&F39&"опр)*1,27" -> ((459+335+141)*3обр+917*3опр)*1,27 | E39: =((459+335+141)*F39+917*F39)*1.27 -> 7056.12 | F39: 3
A40: =A39+1 -> 17 | B40: Определение гранулометрического (микроагрегатного) состава грунта ареометрическим методом с разделением грунта на фракции размерами: от 0,05 до 0,1 миллиметра, от 0,01 до 0,05 миллиметра, от 0,005 до 0,01 миллиметра, от 0,001 до 0,002 миллиметра и до 0,001 миллиметра | C40: Нормативные затраты на работы по инженерно-геологическим изысканиям Табл.56, п.1-3; Табл.57, п.14 | D40: ="((459+335+141)*"&F40&"обр+1852*"&F40&"опр)*1,27" -> ((459+335+141)*2обр+1852*2опр)*1,27 | E40: =((459+335+141)*F40+1852*F40)*1.27 -> 7078.98 | F40: 2
A41: =A40+1 -> 18 | B41: Определение относительной деформации морозного пучения | C41: Нормативные затраты на работы по инженерно-геологическим изысканиям Табл.56, п.1-3; Табл.57, п.16 | D41: ="((459+335+141)*"&F41&"обр+4546*"&F41&"опр)*1,27" -> ((459+335+141)*1обр+4546*1опр)*1,27 | E41: =((459+335+141)*F41+4546*F41)*1.27 -> 6960.87 | F41: 1
A42: =A41+1 -> 19 | B42: Определение плотности глинистого грунта методом режущего кольца | C42: Нормативные затраты на работы по инженерно-геологическим изысканиям Табл.56, п.1-3; Табл.57, п.17 | D42: ="((459+335+141)*"&F42&"обр+529*"&F42&"опр)*1,27" -> ((459+335+141)*3обр+529*3опр)*1,27 | E42: =((459+335+141)*F42+529*F42)*1.27 -> 5577.84 | F42: 3
A43: =A42+1 -> 20 | B43: Определение верхнего предела пластичности глинистого грунта - влажности грунта на границе текучести и нижнего предела пластичности глинистого грунта - влажности грунта на границе раскатывания при проведении испытания с использованием образца грунта природной влажности | C43: Нормативные затраты на работы по инженерно-геологическим изысканиям Табл.56, п.1-3; Табл.57, п.18 | D43: ="((459+335+141)*"&F43&"обр+1676*"&F43&"опр)*1,27" -> ((459+335+141)*6обр+1676*6опр)*1,27 | E43: =((459+335+141)*F43+1676*F43)*1.27 -> 19895.82 | F43: 6
...

Sheet 1.3 МЛС
G2: Форма 2п
B3: =СВОД!E24 -> Смета №1.3
B4: Реконструкция ГПС - Объёмы к изм ТЗ (МЛС)
B5: =СВОД!B24 -> Мобильное лазерное сканирование (МЛС)
A7: № пп | B7: Наименование работ и затрат | C7: Единица измерения | D7: Кол-во | E7: Обоснование стоимости | F7: Расчет стоимости, руб. | G7: Стоимость, руб.
A8: 1 | B8: 2 | C8: 3 | D8: 4 | E8: 5 | F8: 6 | G8: 7
A9: Раздел 1. Полевые работы
A10: III. Работы по созданию опорной геодезической сети
A11: 1 | B11: Создание пунктов плановой опорной геодезической сети без закладки центров методом спутниковых геодезических определений, 2-го разряда в условиях выполнения полевых работ: II категории | C11: 1 пункт | D11: 6 | E11: НЗ_ИГДИ-7-8 | F11: (35837*6)*1,27 (A**)*Кинф | G11: 268777.5
E12: Кинф = 1,2700 (1) Письмо Минстроя России N 45358-ИФ/09 от 22.07.2026г (2026г. III квартал)
A13: 2 | B13: Создание пунктов плановой опорной геодезической сети без закладки центров методом спутниковых геодезических определений, 2-го разряда в условиях выполнения полевых работ: II категории | C13: 1 пункт | D13: 6 | E13: НЗ_ИГДИ-7-8 | F13: (35837*6)*0.5*1,27 (A**)*К1*Кинф | G13: 134388.75
E14: К1 = 0.5 (ТЧ_п.44_т.7_прим._п.1) При выполнении полевых работ по созданию пунктов плановой опорной геодезической сети без закладки центров методом спутниковых геодезических определений, совмещённых с пунктами высотной опорной сети IV класса, созданных без закладки центров методом спутниковых геодезических определений, (К3)
E15: Кинф = 1,2700 (1) Письмо Минстроя России N 45358-ИФ/09 от 22.07.2026г (2026г. III квартал)
A16: IV. Работы по топографической съёмке в масштабах 1:500 - 1:2000
A17: Топографическая съёмка методом МЛС ПППГ - КС-3 СЭБ (поз. 225) КС-3 СЭБ (поз. 225) - РЛВЖ КПП КС-3 СЭБ (поз. 225) - КС-5 ПЭБ
A18: 3 | B18: Создание пунктов съемочной геодезической сети для топографической съемки методами ВЛС ЦАФС, ЦАФС, МЛС и НЛС в условиях выполнения полевых работ: II категории | C18: 1 пункт | D18: 90 | E18: НЗ_ИГДИ-19-2 | F18: (16439*90)*1,27 (A**)*Кинф | G18: 1849387.5
E19: Кинф = 1,2700 (1) Письмо Минстроя России N 45358-ИФ/09 от 22.07.2026г (2026г. III квартал)
A20: В границах нас пункта
A21: 4 | B21: Топографическая съемка полосы местности вдоль оси (участка оси) линейного объекта шириной до 100 (ста) метров методом МЛС в масштабах 1:500 - 1:2000 расположенного в границах населенных пунктов в условиях выполнения полевых работ при протяженности участка:до 20 км включительно | C21: 1 км | D21: 9 | E21: НЗ_ИГДИ-41-1 | F21: (92160+21504*9)*1,27 (A+B**)*Кинф | G21: 357120
E22: Кинф = 1,2700 (1) Письмо Минстроя России N 45358-ИФ/09 от 22.07.2026г (2026г. III квартал)
A23: За границами населенного пункта
A24: V. Работы по съёмке подземных инженерных коммуникаций и сооружений
A25: VII. Работы по привязке инженерно-геологических выработок, геофизических и гидрогеологических точек наблюдения
A26: Работы по перенесению в натуру проектного положения инженерно-геологических, геофизических, гидрогеологических точек наблюдения.
A27: Работы по привязке фактического положения инженерно-геологических, геофизических, гидрогеологических точек наблюдения после завершения работ.
B28: Итоги по разделу 1 Полевые работы:
B29: Итого Поз. 1-4 | G29: 2 609 673.75
B30: Итого по разделу 1 Полевые работы | G30: 2 609 673.75
A31: Раздел 2. Дополнительные затраты на производство полевых работ
A32: 5 | B32: Дополнительные затраты на неизбежные перерывы - 25% | C32: руб. | D32: 2609674 | E32: НЗ_ИГДИ п.25 | F32: (0.25*2609674.02)*1,27 (B**)*Кинф | G32: 815523.13
E33: Кинф = 1,2700 (1) Письмо Минстроя России N 45358-ИФ/09 от 22.07.2026г (2026г. III квартал)
A34: 6 | B34: Показатели дополнительных затрат на внешний транспорт (ПДЗвнеш) автомобильного транспорта, расстояние от места постоянной работы работников до участка проведения полевых работ от 1000 до 2000 км включительно при стоимости полевых работ свыше/до 3000 тыс. руб. - 8,2 % | C34: руб. | D34: 2609674 | E34: НЗ_ИГДИ-3-4-4 | F34: (0.082*2609674.02)*1,27 (B**)*Кинф | G34: 267491.59
E35: Кинф = 1,2700 (1) Письмо Минстроя России N 45358-ИФ/09 от 22.07.2026г (2026г. III квартал)
A36: 7 | B36: Показатели дополнительных затрат на организацию полевых работ (ПДЗорг), расстояние от места постоянной работы работников до участка проведения полевых работ от 1000 до 2000 км включительно: при стоимости полевых работ свыше/до 3000 тыс. руб. - 7,7 % | C36: руб. | D36: 2609674 | E36: НЗ_ИГДИ-4-4-4 | F36: (0.077*2609674.02)*1,27 (B**)*Кинф | G36: 251181.12
E37: Кинф = 1,2700 (1) Письмо Минстроя России N 45358-ИФ/09 от 22.07.2026г (2026г. III квартал)
B38: Итоги по разделу 2 Дополнительные затраты на производство полевых работ:
B39: Итого Поз. 5-7 | G39: 1 334 195.84
B40: Итого по разделу 2 Дополнительные затраты на производство полевых работ | G40: 1 334 195.84
A41: Раздел 3. Камеральные работы
A42: III. Работы по созданию опорной геодезической сети
...

Sheet Смета_№2.1_Обслед
A1: Адепт: Проект v 2026.4.2 © ООО"Адепт" | E1: форма 2П, 707/пр
A3: Смета №2.1
A4: на проектные (изыскательские) работы
A6: Наименование предприятия, здания, сооружения, стадии проектирования, этапа, вида проектных или изыскательских работ | F6: Степн.ПХГ - Обследование
A8: Наименование проектной (изыскательской) организации
A10: Наименование организации заказчика
A12: № пп | B12: Наименование объекта проектирования или вида проектных работ | G12: Наименование, номера глав, таблиц, параграфов и пунктов МНЗ на проектные работы | K12: Расчет стоимости | O12: Стоимость, руб.
A13: 1 | B13: 2 | G13: 3 | K13: 4 | O13: 5
A14: Выполнение обмерных работ и обследований
A15: 1. КС-3. Производственно-энергетический блок (поз. 103)
A16: 1 | B16: Выполнение обмерных работ для каркасных многоэтажных зданий. III категория сложности работ. III категория сложности здания. Высота здания до 7 м. | G16: Справочник базовых цен на обмерные работы и обследования зданий и сооружений. 2016 г. Глава 3. Базовые цены на выполнение обмерных работ и обследований. Таблица 2. Базовые цены на выполнение обмерных работ для многоэтажных зданий, п.5 A = 0.9296 тыс.руб; Xзад = 45.97 (100 м3); Количество = 1 (100 м3) | K16: A * Xзад * Количество * Ктек * K1 * K2 * K3 * K4 929.6 руб. * 45.97 * 1 * 7.22 * 1.2 * 1.15 * 1.15 * 1.3 | O16: =ROUND(929.6 * 45.97 * 1 * 7.22 * 1.2 * 1.15 * 1.15 * 1.3, 2) -> 636543.51
B17: Коэффициенты
B18: инд.3кв.2026г.к 01.01.2001 на пр.раб. | G18: Ктек = 7.22 Письмо Минстроя России от 23.07.2026 №45358-ИФ/09
B19: Здания, возведенные на просадочных, набухающих грунтах, над горными выработками, в подтапливаемых районах с карстовыми и оползневыми явлениями | G19: K1 = 1.2 Таблица 10, п.1 (Ценообразующий)
B20: Насыщенность оборудованием более 50% площади помещений, затрудняющая производство обмерных и обследовательских работ или выполнение обмеров и обследований в затрудненных условиях (захламленность, стесненность, частично разобраны полы и др.) | G20: K2 = 1.15 Таблица 10, п.2 (Ценообразующий)
B21: Выполнение работ в условиях, требующих обеспечение безопасности (использование дополнительных лестниц и различных приспособлений) | G21: K3 = 1.15 Таблица 10, п.6 (Ценообразующий)
B22: Корректирующий коэффициент, учитывающий строительный объем зданий и сооружений до 5000 м3 | G22: K4 = 1.3 Таблица 11, п.5 (Ценообразующий)
A23: 2 | B23: Выполнение инженерных обследований строительных конструкций каркасных многоэтажных зданий. III категория сложности работ. III категория сложности здания. Высота здания до 7 м. | G23: Справочник базовых цен на обмерные работы и обследования зданий и сооружений. 2016 г. Глава 3. Базовые цены на выполнение обмерных работ и обследований. Таблица 4. Цены на выполнение инженерных обследований строительных конструкций многоэтажных зданий, п.5 A = 0.9044 тыс.руб; Xзад = 45.97 (100 м3); Количество = 1 (100 м3) | K23: A * Xзад * Количество * Ктек * K1 * K2 * K3 * K4 904.4 руб. * 45.97 * 1 * 7.22 * 1.2 * 1.15 * 1.15 * 1.3 | O23: =ROUND(904.4 * 45.97 * 1 * 7.22 * 1.2 * 1.15 * 1.15 * 1.3, 2) -> 619287.81
B24: Коэффициенты
B25: инд.3кв.2026г.к 01.01.2001 на пр.раб. | G25: Ктек = 7.22 Письмо Минстроя России от 23.07.2026 №45358-ИФ/09
B26: Здания, возведенные на просадочных, набухающих грунтах, над горными выработками, в подтапливаемых районах с карстовыми и оползневыми явлениями | G26: K1 = 1.2 Таблица 10, п.1 (Ценообразующий)
B27: Насыщенность оборудованием более 50% площади помещений, затрудняющая производство обмерных и обследовательских работ или выполнение обмеров и обследований в затрудненных условиях (захламленность, стесненность, частично разобраны полы и др.) | G27: K2 = 1.15 Таблица 10, п.2 (Ценообразующий)
B28: Выполнение работ в условиях, требующих обеспечение безопасности (использование дополнительных лестниц и различных приспособлений) | G28: K3 = 1.15 Таблица 10, п.6 (Ценообразующий)
B29: Корректирующий коэффициент, учитывающий строительный объем зданий и сооружений до 5000 м3 | G29: K4 = 1.3 Таблица 11, п.5 (Ценообразующий)
A30: 2. КС-3. Здание закрытого распределительного устройства 6кВ (поз.104)
A31: 3 | B31: Выполнение обмерных работ для каркасных одноэтажных зданий. III категория сложности работ. III категория сложности здания. Высота здания до 4 м. | G31: Справочник базовых цен на обмерные работы и обследования зданий и сооружений. 2016 г. Глава 3. Базовые цены на выполнение обмерных работ и обследований. Таблица 1. Базовые цены на выполнение обмерных работ для одноэтажных зданий, п.2 A = 0.9468 тыс.руб; Xзад = 8.045 (100 м3); Количество = 1 (100 м3) | K31: A * Xзад * Количество * Ктек * K1 * K2 * K3 * K4 946.8 руб. * 8.045 * 1 * 7.22 * 1.2 * 1.15 * 1.15 * 2.2 | O31: =ROUND(946.8 * 8.045 * 1 * 7.22 * 1.2 * 1.15 * 1.15 * 2.2, 2) -> 192008.79
B32: Коэффициенты
B33: инд.3кв.2026г.к 01.01.2001 на пр.раб. | G33: Ктек = 7.22 Письмо Минстроя России от 23.07.2026 №45358-ИФ/09
B34: Здания, возведенные на просадочных, набухающих грунтах, над горными выработками, в подтапливаемых районах с карстовыми и оползневыми явлениями | G34: K1 = 1.2 Таблица 10, п.1 (Ценообразующий)
B35: Насыщенность оборудованием более 50% площади помещений, затрудняющая производство обмерных и обследовательских работ или выполнение обмеров и обследований в затрудненных условиях (захламленность, стесненность, частично разобраны полы и др.) | G35: K2 = 1.15 Таблица 10, п.2 (Ценообразующий)
B36: Выполнение работ в условиях, требующих обеспечение безопасности (использование дополнительных лестниц и различных приспособлений) | G36: K3 = 1.15 Таблица 10, п.6 (Ценообразующий)
B37: Корректирующий коэффициент, учитывающий строительный объем зданий и сооружений до 3000 м3 | G37: K4 = 2.2 Таблица 11, п.3 (Ценообразующий)
A38: 4 | B38: Выполнение инженерных обследований строительных конструкций каркасных одноэтажных зданий. III категория сложности работ. III категория сложности здания. Высота здания до 4 м. | G38: Справочник базовых цен на обмерные работы и обследования зданий и сооружений. 2016 г. Глава 3. Базовые цены на выполнение обмерных работ и обследований. Таблица 3. Базовые цены на выполнение инженерных обследований строительных конструкций одноэтажных зданий, п.2 A = 0.9102 тыс.руб; Xзад = 8.045 (100 м3); Количество = 1 (100 м3) | K38: A * Xзад * Количество * Ктек * K1 * K2 * K3 * K4 910.2 руб. * 8.045 * 1 * 7.22 * 1.2 * 1.15 * 1.15 * 2.2 | O38: =ROUND(910.2 * 8.045 * 1 * 7.22 * 1.2 * 1.15 * 1.15 * 2.2, 2) -> 184586.39
B39: Коэффициенты
B40: инд.3кв.2026г.к 01.01.2001 на пр.раб. | G40: Ктек = 7.22 Письмо Минстроя России от 23.07.2026 №45358-ИФ/09
B41: Здания, возведенные на просадочных, набухающих грунтах, над горными выработками, в подтапливаемых районах с карстовыми и оползневыми явлениями | G41: K1 = 1.2 Таблица 10, п.1 (Ценообразующий)
B42: Насыщенность оборудованием более 50% площади помещений, затрудняющая производство обмерных и обследовательских работ или выполнение обмеров и обследований в затрудненных условиях (захламленность, стесненность, частично разобраны полы и др.) | G42: K2 = 1.15 Таблица 10, п.2 (Ценообразующий)
