Workbook

Sheet КП
A5: КАЛЕНДАРНЫЙ ПЛАН РАБОТ
A6: Разработка раздела проектной документации «Автомобильные дороги» по объекту «Магистральный газопровод «Мурманск-Волхов». Этап 1.2. Линейная часть. Участок УП ГРС Костомукша – УП ГРС Кемь, Этап 1.3. Линейная часть. Участок УП ГРС Кемь – УП ГРС Лоухи, Этап 1.9. Линейная часть. Участок УП ГРС Мончегорск – УП КС Мурманская
A8: № этапа | B8: Наименование работ (этапа работ) | C8: Сроки выполнения работ | E8: Стоимость, руб. | F8: НДС** ___%, руб | G8: Стоимость работ с учетом НДС (руб.) | H8: НМЦ (лимитная стоимость) работ (руб), без НДС*** | I8: НМЦ (лимитная стоимость) работ (руб), с НДС***
C9: Начало выполнения работ | D9: Окончание выполнения работ
A10: 1 | B10: Этап 1.2. Линейная часть. Участок УП ГРС Костомукша - УП ГРС Кемь. Автомобильные дороги (Сметы 1.1 - 1.8 - 100%) | C10: С даты заключения договора | D10: 2 месяца с даты заключения договора | E10: ='Форма 1.1'!D14 -> 10469983 | F10: ='Форма 1.1'!E14 -> 523499.14 | G10: ='Форма 1.1'!F14 -> 10993482 | H10: 10472704 | I10: =ROUND(H10*1.22,2) -> 12776699 | K10: =H10-E10 -> 2721.24
A11: 2 | B11: Этап 1.3. Линейная часть. Участок УП ГРС Кемь - УП ГРС Лоухи. Автомобильные дороги (Сметы 2.1-2.16 - 100%) | C11: С даты заключения договора | D11: 3 месяца с даты заключения договора | E11: ='Форма 1.1'!D23 -> 6654622.6 | F11: ='Форма 1.1'!E23 -> 332731.13 | G11: ='Форма 1.1'!F23 -> 6987353.8 | H11: 6659924.9 | I11: =ROUND(H11*1.22,2) -> 8125108.4 | K11: =H11-E11 -> 5302.3
A12: 3 | B12: Этап 1.9. Линейная часть. Участок УП ГРС Оленегорск - УП ГРС Мурманск. Автомобильные дороги (Сметы 3.1-3.4 - 100%) | C12: С даты заключения договора | D12: 46387 | E12: ='Форма 1.1'!D40 -> 2118163.7 | F12: ='Форма 1.1'!E40 -> 105908.19 | G12: ='Форма 1.1'!F40 -> 2224071.9 | H12: 2119841.2 | I12: =ROUND(H12*1.22,2) -> 2586206.3 | K12: =H12-E12 -> 1677.51
A13: Итого: | E13: =E12+E11+E10 -> 19242769 | F13: =F12+F11+F10 -> 962138.46 | G13: =G12+G11+G10 -> 20204908 | H13: =SUM(H10:H12) -> 19252470 | I13: =SUM(I10:I12) -> 23488014 | K13: =H13-E13 -> 9701.05 | L13: ='Форма 1.1'!F45 -> 20204908 | M13: =L13-G13 -> 0
B15: * при составлении сводной сметы в обязательном порядке приложить локальные сметные расчеты по видам выполняемых работ
B16: ** участник должен указать ставку НДС в соответствии с его системой налогообложения и уровнем доходов.
B17: *** стоимость по каждому этапу не должна превышать начальную (максимальную) цену договора (НМЦ) по каждому этапу

Sheet Форма 1.1
A1: ОБЩЕСТВО С ОГРАНИЧЕННОЙ ОТВЕТСТВЕННОСТЬЮ «СПЕЦИАЛЬНОЕ ПРОЕКТИРОВАНИЕ СТРОИТЕЛЬСТВА» ООО «СПЕЦПРОЕКТСТРОЙ»
A4: Коммерческое предложение (Форма 1.1)
B6: Наименование участника: ООО "СПЕЦПРОЕКТСТРОЙ"
B7: Наименование и номер маркетинговых исследований: Разработка раздела проектной документации «Автомобильные дороги» по объекту «Магистральный газопровод «Мурманск-Волхов». Этап 1.2. Линейная часть. Участок УП ГРС Костомукша – УП ГРС Кемь, Этап 1.3. Линейная часть. Участок УП ГРС Кемь – УП ГРС Лоухи, Этап 1.9. Линейная часть. Участок УП ГРС Мончегорск – УП КС Мурманская для нужд ООО "Газпром проектирование", №0080/26/2.3/00083983/ГППроект/ПР/ГОС/Э/29.07.2026
B8: Наименование объекта проектирования:
A10: Разработка раздела проектной документации «Автомобильные дороги» по объекту «Магистральный газопровод «Мурманск-Волхов». Этап 1.2. Линейная часть. Участок УП ГРС Костомукша – УП ГРС КемьЭтап 1.3. Линейная часть. Участок УП ГРС Кемь – УП ГРС Лоухи Этап 1.9. Линейная часть. Участок УП ГРС Мончегорск – УП КС Мурманская
A12: №№ п/п | B12: Наименование видов инженерных изысканий, работ и затрат | C12: Ссылка на №№ смет по формам 2п и 3п | D12: Сметная стоимость проектно -изыскательских работ, руб. без НДС | E12: НДС** 5% , руб | F12: Сметная стоимость проектно -изыскательских работ, руб. с НДС | G12: НМЦ (лимитная стоимость) работ (руб), без НДС*** | H12: НМЦ (лимитная стоимость) работ (руб), с НДС***
E13: НДС 20%, руб | F13: Сметная стоимость проектно -изыскательских работ, руб. с НДС
A14: 1 | B14: Этап 1.2. Линейная часть. Участок УП ГРС Костомукша - УП ГРС Кемь. Автомобильные дороги | D14: =ROUND(SUM(D15:D22),2) -> 10469983 | E14: =ROUND(D14*0.05,2) -> 523499.14 | F14: =E14+D14 -> 10993482 | G14: =SUM(G15,G16,G17,G18,G19,G20,G21,G22) -> 10472704 | H14: =ROUND(G14*1.22,2) -> 12776699 | J14: =G14-D14 -> 2721.24 | K14: =СВОД!I25 -> 10469983 | L14: =K14-D14 -> 0
A15: 1.1 | B15: Подъездная автодорога км 598 | C15: Смета №1.1 | D15: =СВОД!I16 -> 1653152.9 | E15: =ROUND(D15*0.05,2) -> 82657.64 | F15: =E15+D15 -> 1735810.5 | G15: 1653397.8 | H15: =ROUND(G15*1.22,2) -> 2017145.4 | J15: =G15-D15 -> 244.95
A16: 1.2 | B16: Подъездная автодорога к УРС Беломорская (км 599,2) | C16: Смета №1.2 | D16: =СВОД!I17 -> 287215.22 | E16: =ROUND(D16*0.05,2) -> 14360.76 | F16: =E16+D16 -> 301575.98 | G16: 287260.47 | H16: =ROUND(G16*1.22,2) -> 350457.77 | J16: =G16-D16 -> 45.25
A17: 1.3 | B17: Подъездная автодорога к ПРС Ноттоворакка (км 622,1) | C17: Смета №1.3 | D17: =СВОД!I18 -> 538654.03 | E17: =ROUND(D17*0.05,2) -> 26932.7 | F17: =E17+D17 -> 565586.73 | G17: 539055.67 | H17: =ROUND(G17*1.22,2) -> 657647.92 | J17: =G17-D17 -> 401.64
A18: 1.4 | B18: Подъездная автодорога км 627,6 | C18: Смета №1.4 | D18: =СВОД!I19 -> 538654.03 | E18: =ROUND(D18*0.05,2) -> 26932.7 | F18: =E18+D18 -> 565586.73 | G18: 539055.67 | H18: =ROUND(G18*1.22,2) -> 657647.92 | J18: =G18-D18 -> 401.64
A19: 1.5 | B19: Подъездная автодорога к УРС Половина (км 658,8) | C19: Смета №1.5 | D19: =СВОД!I20 -> 538654.03 | E19: =ROUND(D19*0.05,2) -> 26932.7 | F19: =E19+D19 -> 565586.73 | G19: 539055.67 | H19: =ROUND(G19*1.22,2) -> 657647.92 | J19: =G19-D19 -> 401.64
A20: 1.6 | B20: Подъездная автодорога км 681,4 | C20: Смета №1.6 | D20: =СВОД!I21 -> 4886820.3 | E20: =ROUND(D20*0.05,2) -> 244341.01 | F20: =E20+D20 -> 5131161.3 | G20: 4887089.6 | H20: =ROUND(G20*1.22,2) -> 5962249.3 | J20: =G20-D20 -> 269.33
A21: 1.7 | B21: Подъездная автодорога км 683,2 | C21: Смета №1.7 | D21: =СВОД!I22 -> 538654.03 | E21: =ROUND(D21*0.05,2) -> 26932.7 | F21: =E21+D21 -> 565586.73 | G21: 539055.67 | H21: =ROUND(G21*1.22,2) -> 657647.92 | J21: =G21-D21 -> 401.64
A22: 1.8 | B22: Подъездная автодорога км 686,8 | C22: Смета №1.8 | D22: =СВОД!I23 -> 1488178.4 | E22: =ROUND(D22*0.05,2) -> 74408.92 | F22: =E22+D22 -> 1562587.3 | G22: 1488733.5 | H22: =ROUND(G22*1.22,2) -> 1816254.9 | J22: =G22-D22 -> 555.15
A23: 2 | B23: Этап 1.3. Линейная часть. Участок УП ГРС Кемь - УП ГРС Лоухи. Автомобильные дороги | D23: =ROUND(SUM(D24:D39),2) -> 6654622.6 | E23: =ROUND(D23*0.05,2) -> 332731.13 | F23: =E23+D23 -> 6987353.8 | G23: =SUM(G24:G39) -> 6659924.9 | H23: =ROUND(G23*1.22,2) -> 8125108.4 | J23: =G23-D23 -> 5302.3 | K23: =СВОД!I43 -> 6654622.6 | L23: =K23-D23 -> 0
A24: 2.1 | B24: Подъездная автодорога к УП КС Кемская км 689,8 | C24: Смета №2.1 | D24: =СВОД!I27 -> 490399.9 | E24: =ROUND(D24*0.05,2) -> 24520 | F24: =E24+D24 -> 514919.9 | G24: 490501.95 | H24: =ROUND(G24*1.22,2) -> 598412.38 | J24: =G24-D24 -> 102.05
A25: 2.2 | B25: Подъездная автодорога к площадке артсквжин | C25: Смета №2.2 | D25: =СВОД!I28 -> 520328.13 | E25: =ROUND(D25*0.05,2) -> 26016.41 | F25: =E25+D25 -> 546344.54 | G25: 520336.49 | H25: =ROUND(G25*1.22,2) -> 634810.52 | J25: =G25-D25 -> 8.36
A26: 2.3 | B26: Подъездная автодорога к УРС КС Кемская, км 690,9 | C26: Смета №2.3 | D26: =СВОД!I29 -> 261011.37 | E26: =ROUND(D26*0.05,2) -> 13050.57 | F26: =E26+D26 -> 274061.94 | G26: 261225.27 | H26: =ROUND(G26*1.22,2) -> 318694.83 | J26: =G26-D26 -> 213.9
A27: 2.4 | B27: Подъездная автодорога к к площадке кранового узла и площадке БТМА, км 691,7 | C27: Смета №2.4 | D27: =СВОД!I30 -> 335046.28 | E27: =ROUND(D27*0.05,2) -> 16752.31 | F27: =E27+D27 -> 351798.59 | G27: 335246.38 | H27: =ROUND(G27*1.22,2) -> 409000.58 | J27: =G27-D27 -> 200.1
A28: 2.5 | B28: Подъездная автодорога к ПРС Егутварака, км 715,6 | C28: Смета №2.5 | D28: =СВОД!I31 -> 184179.32 | E28: =ROUND(D28*0.05,2) -> 9208.97 | F28: =E28+D28 -> 193388.29 | G28: 184360.23 | H28: =ROUND(G28*1.22,2) -> 224919.48 | J28: =G28-D28 -> 180.91
A29: 2.6 | B29: Подъездная автодорога к ПРС Кумозеро, км 750,9 | C29: Смета №2.6 | D29: =СВОД!I32 -> 225088.86 | E29: =ROUND(D29*0.05,2) -> 11254.44 | F29: =E29+D29 -> 236343.3 | G29: 225204.65 | H29: =ROUND(G29*1.22,2) -> 274749.67 | J29: =G29-D29 -> 115.79
A30: 2.7 | B30: Подъездная автодорога к площадке кранового узла и площадке БТМА, км 751,0 | C30: Смета №2.7 | D30: =СВОД!I33 -> 502632.89 | E30: =ROUND(D30*0.05,2) -> 25131.64 | F30: =E30+D30 -> 527764.53 | G30: 502878.61 | H30: =ROUND(G30*1.22,2) -> 613511.9 | J30: =G30-D30 -> 245.72
A31: 2.8 | B31: Подъездная автодорога к площадке кранового узла и площадке БТМА, 752,1 | C31: Смета №2.8 | D31: =СВОД!I34 -> 537323.7 | E31: =ROUND(D31*0.05,2) -> 26866.19 | F31: =E31+D31 -> 564189.89 | G31: 537794.39 | H31: =ROUND(G31*1.22,2) -> 656109.16 | J31: =G31-D31 -> 470.69
A32: 2.9 | B32: Подъездная автодорога к площадке кранового узла и площадке БТМА, км 765,4 | C32: Смета №2.9 | D32: =СВОД!I35 -> 920293.14 | E32: =ROUND(D32*0.05,2) -> 46014.66 | F32: =E32+D32 -> 966307.8 | G32: 920460.75 | H32: =ROUND(G32*1.22,2) -> 1122962.1 | J32: =G32-D32 -> 167.61
A33: 2.10 | B33: Подъездная автодорога к площадке кранового узла и площадке БТМА, 766,8 | C33: Смета №2.10 | D33: =СВОД!I36 -> 502632.89 | E33: =ROUND(D33*0.05,2) -> 25131.64 | F33: =E33+D33 -> 527764.53 | G33: 502878.61 | H33: =ROUND(G33*1.22,2) -> 613511.9 | J33: =G33-D33 -> 245.72
A34: 2.11 | B34: Подъездная автодорога к площадке кранового узла и площадке БТМА, 784,5 | C34: Смета №2.11 | D34: =СВОД!I37 -> 436468.86 | E34: =ROUND(D34*0.05,2) -> 21823.44 | F34: =E34+D34 -> 458292.3 | G34: 436538.63 | H34: =ROUND(G34*1.22,2) -> 532577.13 | J34: =G34-D34 -> 69.77
A35: 2.12 | B35: Подъездная автодорога к площадке кранового узла и площадке БТМА, 785,2 | C35: Смета №2.12 | D35: =СВОД!I38 -> 677142.73 | E35: =ROUND(D35*0.05,2) -> 33857.14 | F35: =E35+D35 -> 710999.87 | G35: 677292.39 | H35: =ROUND(G35*1.22,2) -> 826296.72 | J35: =G35-D35 -> 149.66
... A39: 2.16 | B39: Подъездная автодорога к ПРС Лоухи, км 829,1 | C39: Смета №2.16 | D39: =СВОД!I42 -> 192786.09 | E39: =ROUND(D39*0.05,2) -> 9639.3 | F39: =E39+D39 -> 202425.39 | G39: 194947.36 | H39: =ROUND(G39*1.22,2) -> 237835.78 | J39: =G39-D39 -> 2161.27
A40: 3 | B40: Этап 1.9. Линейная часть. Участок УП ГРС Оленегорск - УП ГРС Мурманск. Автомобильные дороги | D40: =ROUND(SUM(D41:D44),2) -> 2118163.7 | E40: =ROUND(D40*0.05,2) -> 105908.19 | F40: =E40+D40 -> 2224071.9 | G40: =SUM(G41:G44) -> 2119841.2 | H40: =ROUND(G40*1.22,2) -> 2586206.3 | J40: =G40-D40 -> 1677.51 | K40: =СВОД!I51 -> 2118163.7 | L40: =K40-D40 -> 0
A41: 3.1 | B41: Подъездная автодорога к УРС Кица, км 1226,4 | C41: Смета №3.1 | D41: =СВОД!I46 -> 664498.45 | E41: =ROUND(D41*0.05,2) -> 33224.92 | F41: =E41+D41 -> 697723.37 | G41: 664802.37 | H41: =ROUND(G41*1.22,2) -> 811058.89 | J41: =G41-D41 -> 303.92
A42: 3.2 | B42: Подъездная автодорога к площадке кранового узла и площадке БТМА, км 1245,5 | C42: Смета №3.2 | D42: =СВОД!I47 -> 827073.53 | E42: =ROUND(D42*0.05,2) -> 41353.68 | F42: =E42+D42 -> 868427.21 | G42: 827166.65 | H42: =ROUND(G42*1.22,2) -> 1009143.3 | J42: =G42-D42 -> 93.12
A43: 3.3 | B43: Подъездная автодорога к УП КС Мурманская, км 1246,7 | C43: Смета №3.3 | D43: =СВОД!I48 -> 373294.84 | E43: =ROUND(D43*0.05,2) -> 18664.74 | F43: =E43+D43 -> 391959.58 | G43: 373949.26 | H43: =ROUND(G43*1.22,2) -> 456218.1 | J43: =G43-D43 -> 654.42
A44: 3.4 | B44: Подъездная автодорога к ОРС КС Мурманская, км 1247,5 | C44: Смета №3.4 | D44: =СВОД!I49 -> 253296.91 | E44: =ROUND(D44*0.05,2) -> 12664.85 | F44: =E44+D44 -> 265961.76 | G44: 253922.96 | H44: =ROUND(G44*1.22,2) -> 309786.01 | J44: =G44-D44 -> 626.05
A45: 11 | B45: Итого | D45: =D40+D23+D14 -> 19242769 | E45: =ROUND(D45*0.05,2) -> 962138.46 | F45: =E45+D45 -> 20204908 | G45: =G40+G23+G14 -> 19252470 | H45: =H40+H23+H14 -> 23488014 | J45: =G45-D45 -> 9701.05 | K45: =СВОД!I52 -> 19242769 | L45: =K45-D45 -> 0
B47: * при составлении сводной сметы в обязательном порядке приложить локальные сметные расчеты по видам выполняемых работ
B48: ** участник должен указать ставку НДС в соответствии с его системой налогообложения и уровнем доходов.
B49: *** стоимость по каждому этапу не должна превышать начальную (максимальную) цену договора (НМЦ) по каждому этапу
...

Sheet СВОД
D1: Форма 1пс
A3: СВОДНАЯ СМЕТА №1
A4: на проектные работы и инженерные изыскания
A7: Наименование строительства и стадии проектирования | D7: Разработка раздела проектной документации «Автомобильные дороги» по объекту «Магистральный газопровод «Мурманск-Волхов». Этап 1.2. Линейная часть. Участок УП ГРС Костомукша – УП ГРС КемьЭтап 1.3. Линейная часть. Участок УП ГРС Кемь – УП ГРС ЛоухиЭтап 1.9. Линейная часть. Участок УП ГРС Мончегорск – УП КС Мурманская
A10: Наименование участника | D10: ООО "Спецпроектстрой"
A12: №пп | B12: Перечень выполняемых работ | E12: Характеристика проектируемого объекта | G12: Ссылка на № смет по формам 2П, 3П | H12: Полная стоимость работ, руб.
H13: изыскательских | I13: проектных | J13: Всего
A14: 1 | B14: 2 | E14: 3 | G14: 4 | H14: 5 | I14: 6 | J14: 7
A15: 1 | B15: Этап 1.2. Линейная часть. Участок УП ГРС Костомукша - УП ГРС Кемь. Автомобильные дороги
A16: 1.1 | B16: Подъездная автодорога км 598 | E16: Проектная документация | G16: 1.1 | H16: 0 | I16: 1653152.9 | J16: 1653152.9
A17: 1.2 | B17: Подъездная автодорога к УРС Беломорская (км 599,2) | E17: Проектная документация | G17: 1.2 | H17: 0 | I17: 287215.22 | J17: 287215.22
A18: 1.3 | B18: Подъездная автодорога к ПРС Ноттоворакка (км 622,1) | E18: Проектная документация | G18: 1.3 | H18: 0 | I18: 538654.03 | J18: 538654.03
A19: 1.4 | B19: Подъездная автодорога км 627,6 | E19: Проектная документация | G19: 1.4 | H19: 0 | I19: 538654.03 | J19: 538654.03
A20: 1.5 | B20: Подъездная автодорога к УРС Половина (км 658,8) | E20: Проектная документация | G20: 1.5 | H20: 0 | I20: 538654.03 | J20: 538654.03
A21: 1.6 | B21: Подъездная автодорога км 681,4 | E21: Проектная документация | G21: 1.6 | H21: 0 | I21: 4886820.3 | J21: 4886820.3
A22: 1.7 | B22: Подъездная автодорога км 683,2 | E22: Проектная документация | G22: 1.7 | H22: 0 | I22: 538654.03 | J22: 538654.03
A23: 1.8 | B23: Подъездная автодорога км 686,8 | E23: Проектная документация | G23: 1.8 | H23: 0 | I23: 1488178.4 | J23: 1488178.4
A24: 1.9 | B24: Итого Этап 1.2. Линейная часть. Участок УП ГРС Костомукша - УП ГРС Кемь. Автомобильные дороги: | H24: =ROUND(SUM($H$16:$H$23),2) -> 0 | I24: =ROUND(SUM($I$16:$I$23),2) -> 10469983 | J24: =ROUND(SUM($J$16:$J$23),2) -> 10469983
A25: 1.10 | B25: Всего Этап 1.2. Линейная часть. Участок УП ГРС Костомукша - УП ГРС Кемь. Автомобильные дороги: | G25: Сумма от п.1.9 | H25: =ROUND($H$24,2) -> 0 | I25: =ROUND($I$24,2) -> 10469983 | J25: =ROUND($J$24,2) -> 10469983
A26: 2 | B26: Этап 1.3. Линейная часть. Участок УП ГРС Кемь - УП ГРС Лоухи. Автомобильные дороги
A27: 2.1 | B27: Подъездная автодорога к УП КС Кемская км 689,8 | E27: Проектная документация | G27: 2.1 | H27: 0 | I27: 490399.9 | J27: 490399.9
A28: 2.2 | B28: Подъездная автодорога к площадке артсквжин | E28: Проектная документация | G28: 2.2 | H28: 0 | I28: 520328.13 | J28: 520328.13
A29: 2.3 | B29: Подъездная автодорога к УРС КС Кемская, км 690,9 | E29: Проектная документация | G29: 2.3 | H29: 0 | I29: 261011.37 | J29: 261011.37
A30: 2.4 | B30: Подъездная автодорога к к площадке кранового узла и площадке БТМА, км 691,7 | E30: Проектная документация | G30: 2.4 | H30: 0 | I30: 335046.28 | J30: 335046.28
A31: 2.5 | B31: Подъездная автодорога к ПРС Егутварака, км 715,6 | E31: Проектная документация | G31: 2.5 | H31: 0 | I31: 184179.32 | J31: 184179.32
A32: 2.6 | B32: Подъездная автодорога к ПРС Кумозеро, км 750,9 | E32: Проектная документация | G32: 2.6 | H32: 0 | I32: 225088.86 | J32: 225088.86
A33: 2.7 | B33: Подъездная автодорога к площадке кранового узла и площадке БТМА, км 751,0 | E33: Проектная документация | G33: 2.7 | H33: 0 | I33: 502632.89 | J33: 502632.89
A34: 2.8 | B34: Подъездная автодорога к площадке кранового узла и площадке БТМА, 752,1 | E34: Проектная документация | G34: 2.8 | H34: 0 | I34: 537323.7 | J34: 537323.7
A35: 2.9 | B35: Подъездная автодорога к площадке кранового узла и площадке БТМА, км 765,4 | E35: Проектная документация | G35: 2.9 | H35: 0 | I35: 920293.14 | J35: 920293.14
A36: 2.10 | B36: Подъездная автодорога к площадке кранового узла и площадке БТМА, 766,8 | E36: Проектная документация | G36: 2.10 | H36: 0 | I36: 502632.89 | J36: 502632.89
A37: 2.11 | B37: Подъездная автодорога к площадке кранового узла и площадке БТМА, 784,5 | E37: Проектная документация | G37: 2.11 | H37: 0 | I37: 436468.86 | J37: 436468.86
A38: 2.12 | B38: Подъездная автодорога к площадке кранового узла и площадке БТМА, 785,2 | E38: Проектная документация | G38: 2.12 | H38: 0 | I38: 677142.73 | J38: 677142.73
... A42: 2.16 | B42: Подъездная автодорога к ПРС Лоухи, км 829,1 | E42: Проектная документация | G42: 2.16 | H42: 0 | I42: 192786.09 | J42: 192786.09
A43: 2.17 | B43: Итого Этап 1.3. Линейная часть. Участок УП ГРС Кемь - УП ГРС Лоухи. Автомобильные дороги: | H43: =ROUND(SUM($H$27:$H$42),2) -> 0 | I43: =ROUND(SUM($I$27:$I$42),2) -> 6654622.6 | J43: =ROUND(SUM($J$27:$J$42),2) -> 6654622.6
A44: 2.18 | B44: Всего Этап 1.3. Линейная часть. Участок УП ГРС Кемь - УП ГРС Лоухи. Автомобильные дороги: | G44: Сумма от п.2.17 | H44: =ROUND($H$43,2) -> 0 | I44: =ROUND($I$43,2) -> 6654622.6 | J44: =ROUND($J$43,2) -> 6654622.6
A45: 3 | B45: Этап 1.9. Линейная часть. Участок УП ГРС Оленегорск - УП ГРС Мурманск. Автомобильные дороги
A46: 3.1 | B46: Подъездная автодорога к УРС Кица, км 1226,4 | E46: Проектная документация | G46: 3.1 | H46: 0 | I46: 664498.45 | J46: 664498.45
A47: 3.2 | B47: Подъездная автодорога к площадке кранового узла и площадке БТМА, км 1245,5 | E47: Проектная документация | G47: 3.2 | H47: 0 | I47: 827073.53 | J47: 827073.53
A48: 3.3 | B48: Подъездная автодорога к УП КС Мурманская, км 1246,7 | E48: Проектная документация | G48: 3.3 | H48: 0 | I48: 373294.84 | J48: 373294.84
A49: 3.4 | B49: Подъездная автодорога к ОРС КС Мурманская, км 1247,5 | E49: Проектная документация | G49: 3.4 | H49: 0 | I49: 253296.91 | J49: 253296.91
...

Sheet Смета_№1.1_Подъездная автодоро
A1: Адепт: Проект v 2026.4.0 © ООО"Адепт" | E1: форма 2П
A3: Смета №1.1
A4: на проектные (изыскательские) работы
A6: Наименование предприятия, здания, сооружения, стадии проектирования, этапа, вида проектных или изыскательских работ | F6: Подъездная автодорога км 598
A8: Наименование проектной (изыскательской) организации | F8: ООО "Спецпроектстрой"
A10: Наименование организации заказчика | F10: ООО "Газпром проектирование"
A12: № пп | B12: Характеристика предприятия, здания, сооружения или виды работ | G12: Номер частей, глав, таблиц, процентов, параграфов и пунктов указаний к разделу Справочника базовых цен на проектные и изыскательские работы для строительства | K12: Расчет стоимости: (a+bx)*Ki, или (объем строительно-монтажных работ) * проц./100 или количество x цена | O12: Стоимость, руб.
A13: 1 | B13: 2 | G13: 3 | K13: 4 | O13: 5
A14: 1 | B14: Примыкание автомобильных дорог в одном уровне с устройством переходно-скоростных полос движения, островков безопасности. Категория сложности проектирования: 2. | G14: НЗ №51/пр Строительство, реконструкция и капитальный ремонт автомобильных дорог, их конструктивных элементов и сооружений на них. 2025 г. Таблица 3.7. Развязки, п.2.2 A = 1 440.8 тыс.руб; Количество = 2 (объект) | K14: A * Количество * Ктек * Кст * K1 1 440 800 руб. * 2 * 1.38 * 0.4 * 0.47 * 1.1155 | O14: =ROUND(1440800 * 2 * 1.38 * 0.4 * 0.47 * 1.1155, 2) -> 833950.37
B15: Коэффициенты
B16: Стадия: Проектная документация | G16: Кст = 0.4
B17: инд.2кв.2026г.к 01.01.2023 на пр.раб. | G17: Ктек = 1.38 Письмо Минстроя России от 08.04.2026 №20212-ИФ/09
B18: Пересечение (примыкание) автомобильных дорог в одном уровне определяется с корректирующим коэффициентом для примыканий без устройства переходно-скоростных полос | G18: K1 = 0.47 Табл.4, п.9 (Ценообразующий)
B19: Коэффициент, учитывающий природные факторы, усложняющие проектирование: опасные гидрологические и геологические явления (заболоченная территория). Коэффициент применяется к стоимости проектирования следующих разделов П+Р: ПЗУ (ППО в части вертикальной планировки и организации рельефа, транспорта); в полном объеме АР и КР (ТКР, ИЛО); в части монтажных элементов ИОС; доля СМ на выполняемый объем | G19: K2 = 1.15 (РПД 2,3.1-3.5,7) Методика, 707/пр. Приложение 5, табл.5.1, п.1.1 (Усложняющий)
B20: Разделы документации | K20: (2% + 8% * (1 + 0.15) + 4% * (1 + 0.15) + 26% * (1 + 0.15) + 4% * (1 + 0.15) + 8% * (1 + 0.15) + 14% * (1 + 0.15) + 11% + 9% + 1% + 13% * (1 + 0.15)) = 111.55%
A21: 2 | B21: Автомобильные дороги технической категории IV. Категория сложности проектирования: 2. Протяженность от 2 до 5 километров включительно. | G21: НЗ №51/пр Строительство, реконструкция и капитальный ремонт автомобильных дорог, их конструктивных элементов и сооружений на них. 2025 г. Таблица 3.5. Автомобильные дороги технической категории IV, п.5.2 A = 545.5 тыс.руб; B = 522.975 тыс.руб; Протяженность дороги L = 2.485 км; Количество = 1; | K21: (A + B * L) * Количество * Ктек * Кст (545 500 руб. + 522 975 руб. * 2.485) * 1 * 1.38 * 0.4 * 1.1245 | O21: =ROUND((545500 + 522975 * 2.485) * 1 * 1.38 * 0.4 * 1.1245, 2) -> 1145293.4
B22: Коэффициенты
B23: Стадия: Проектная документация | G23: Кст = 0.4
B24: инд.2кв.2026г.к 01.01.2023 на пр.раб. | G24: Ктек = 1.38 Письмо Минстроя России от 08.04.2026 №20212-ИФ/09
B25: Коэффициент, учитывающий природные факторы, усложняющие проектирование: опасные гидрологические и геологические явления (заболоченная территория). Коэффициент применяется к стоимости проектирования следующих разделов П+Р: ПЗУ (ППО в части вертикальной планировки и организации рельефа, транспорта); в полном объеме АР и КР (ТКР, ИЛО); в части монтажных элементов ИОС; доля СМ на выполняемый объем | G25: K1 = 1.15 (РПД 2,3.1-3.5,7) Методика, 707/пр. Приложение 5, табл.5.1, п.1.1 (Усложняющий)
B26: Разделы документации | K26: (2% + 7% * (1 + 0.15) + 7% * (1 + 0.15) + 29% * (1 + 0.15) + 8% * (1 + 0.15) + 8% * (1 + 0.15) + 13% * (1 + 0.15) + 9% + 5% + 1% + 11% * (1 + 0.15)) = 112.45%
A27: 3 | B27: Водопропускные трубы на автомобильных дорогах протяженностью, м. Круглые и прямоугольные железобетонные трубы отверстием до 2000 мм. | G27: Искусственные сооружения. 2015 г. Таблица 2. Водопропускные трубы на железных и автомобильных дорогах, п.2.4 A = 5.61 тыс.руб; B = 0.24 тыс.руб; Xзад = 18 (м); Количество = 2 | K27: (A + B * Xзад) * Количество * Ктек * Кст * (1 + дроб. ч. K1) (5 610 руб. + 240 руб. * 18) * 2 * 7.1 * 0.34 * (1 + 0.15) | O27: =ROUND((5610 + 240 * 18) * 2 * 7.1 * 0.34 * (1 + 0.15), 2) -> 55133.35
B28: Коэффициенты
B29: Стадия: Проектная документация | G29: Кст = 0.34
B30: инд.2кв.2026г.к 01.01.2001 на пр.раб. | G30: Ктек = 7.1 Письмо Минстроя России от 08.04.2026 №20212-ИФ/09
B31: Разработка проектной документации на строительство предприятий, зданий и сооружений в сложных условиях:расположение площадки строительства в подтапливаемых зонах и др. | G31: K1 = 1.15 МУ 2009 г. Часть III п.3.7 (Усложняющий)
B32: Разделы документации | K32: (63% + 26% + 11%) = 100%
A33: 4 | B33: Водопропускные трубы на автомобильных дорогах протяженностью, м. Круглые и прямоугольные железобетонные трубы отверстием до 2000 мм трехочковые. | G33: Искусственные сооружения. 2015 г. Таблица 2. Водопропускные трубы на железных и автомобильных дорогах, п.2.6 A = 7.59 тыс.руб; B = 0.33 тыс.руб; Xзад = 12 (м); Количество = 1 | K33: (A + B * Xзад) * Количество * Ктек * Кст * (1 + дроб. ч. K1) (7 590 руб. + 330 руб. * 12) * 1 * 7.1 * 0.34 * (1 + 0.15) | O33: =ROUND((7590 + 330 * 12) * 1 * 7.1 * 0.34 * (1 + 0.15), 2) -> 32063.96
B34: Коэффициенты
B35: Стадия: Проектная документация | G35: Кст = 0.34
B36: инд.2кв.2026г.к 01.01.2001 на пр.раб. | G36: Ктек = 7.1 Письмо Минстроя России от 08.04.2026 №20212-ИФ/09
B37: Разработка проектной документации на строительство предприятий, зданий и сооружений в сложных условиях:расположение площадки строительства в подтапливаемых зонах и др. | G37: K1 = 1.15 МУ 2009 г. Часть III п.3.7 (Усложняющий)
B38: Разделы документации | K38: (63% + 26% + 11%) = 100%
A39: 5 | B39: Итого по смете: | O39: =ROUND(SUM($O$14:$O$33),2) -> 2066441.1
A40: 6 | B40: Новое начисление | G40: К1 = 0.8 Коэффициент оптимизации ПАО "Газпром" («Порядок формирования стоимости проектно-изыскательских работ для строительства и реконструкции объектов ПАО «Газпром» от 28.12.2017г. п.5.41) (Ценообразующий) | K40: Коэф-т 1 от п.5 * 0.8 | O40: =ROUND(($O$39) * 1 * 0.8,2) -> 1653152.9
A41: 7 | B41: Всего по смете: | O41: =ROUND(($O$40),2) -> 1653152.9

Sheet Смета_№1.2_Подъездная автодоро
A1: Адепт: Проект v 2026.4.0 © ООО"Адепт" | E1: форма 2П
A3: Смета №1.2
A4: на проектные (изыскательские) работы
A6: Наименование предприятия, здания, сооружения, стадии проектирования, этапа, вида проектных или изыскательских работ | F6: Подъездная автодорога к УРС Беломорская (км 599,2)
A8: Наименование проектной (изыскательской) организации | F8: ООО "Спецпроектстрой"
A10: Наименование организации заказчика | F10: ООО "Газпром проектирование"
A12: № пп | B12: Характеристика предприятия, здания, сооружения или виды работ | G12: Номер частей, глав, таблиц, процентов, параграфов и пунктов указаний к разделу Справочника базовых цен на проектные и изыскательские работы для строительства | K12: Расчет стоимости: (a+bx)*Ki, или (объем строительно-монтажных работ) * проц./100 или количество x цена | O12: Стоимость, руб.
A13: 1 | B13: 2 | G13: 3 | K13: 4 | O13: 5
A14: 1 | B14: Автомобильные дороги технической категории IV. Категория сложности проектирования: 2. Протяженность от 0.2 до 0.5 километра включительно. | G14: НЗ №51/пр Строительство, реконструкция и капитальный ремонт автомобильных дорог, их конструктивных элементов и сооружений на них. 2025 г. Таблица 3.5. Автомобильные дороги технической категории IV, п.2.2 A = 151.1 тыс.руб; B = 1 030.273 тыс.руб; Протяженность дороги L = 0.333 км; Количество = 1; | K14: (A + B * L) * Количество * Ктек * Кст (151 100 руб. + 1 030 273 руб. * 0.333) * 1 * 1.38 * 0.4 * 1.114 | O14: =ROUND((151100 + 1030273 * 0.333) * 1 * 1.38 * 0.4 * 1.114, 2) -> 303885.68
B15: Коэффициенты
B16: Стадия: Проектная документация | G16: Кст = 0.4
B17: инд.2кв.2026г.к 01.01.2023 на пр.раб. | G17: Ктек = 1.38 Письмо Минстроя России от 08.04.2026 №20212-ИФ/09
B18: Коэффициент, учитывающий природные факторы, усложняющие проектирование: опасные гидрологические и геологические явления (заболоченная территория). Коэффициент применяется к стоимости проектирования следующих разделов П+Р: ПЗУ (ППО в части вертикальной планировки и организации рельефа, транспорта); в полном объеме АР и КР (ТКР, ИЛО); в части монтажных элементов ИОС; доля СМ на выполняемый объем | G18: K1 = 1.15 (РПД 2,3.2-3.5,7) Методика, 707/пр. Приложение 5, табл.5.1, п.1.1 (Усложняющий)
B19: Разделы документации | K19: (2% + 7% * (1 + 0.15) + 7% + 29% * (1 + 0.15) + 8% * (1 + 0.15) + 8% * (1 + 0.15) + 13% * (1 + 0.15) + 9% + 5% + 1% + 11% * (1 + 0.15)) = 111.4%
A20: 2 | B20: Водопропускные трубы на автомобильных дорогах протяженностью, м. Круглые и прямоугольные железобетонные трубы отверстием до 2000 мм. | G20: Искусственные сооружения. 2015 г. Таблица 2. Водопропускные трубы на железных и автомобильных дорогах, п.2.4 A = 5.61 тыс.руб; B = 0.24 тыс.руб; Xзад = 18 (м); Количество = 2 | K20: (A + B * Xзад) * Количество * Ктек * Кст * (1 + дроб. ч. K1) (5 610 руб. + 240 руб. * 18) * 2 * 7.1 * 0.34 * (1 + 0.15) | O20: =ROUND((5610 + 240 * 18) * 2 * 7.1 * 0.34 * (1 + 0.15), 2) -> 55133.35
B21: Коэффициенты
B22: Стадия: Проектная документация | G22: Кст = 0.34
B23: инд.2кв.2026г.к 01.01.2001 на пр.раб. | G23: Ктек = 7.1 Письмо Минстроя России от 08.04.2026 №20212-ИФ/09
B24: Разработка проектной документации на строительство предприятий, зданий и сооружений в сложных условиях:расположение площадки строительства в подтапливаемых зонах и др. | G24: K1 = 1.15 МУ 2009 г. Часть III п.3.7 (Усложняющий)
B25: Разделы документации | K25: (63% + 26% + 11%) = 100%
A26: 3 | B26: Итого по смете: | O26: =ROUND(SUM($O$14:$O$20),2) -> 359019.03
A27: 4 | B27: Новое начисление | G27: К1 = 0.8 Коэффициент оптимизации ПАО "Газпром" («Порядок формирования стоимости проектно-изыскательских работ для строительства и реконструкции объектов ПАО «Газпром» от 28.12.2017г. п.5.41) (Ценообразующий) | K27: Коэф-т 1 от п.3 * 0.8 | O27: =ROUND(($O$26) * 1 * 0.8,2) -> 287215.22
A28: 5 | B28: Всего по смете: | O28: =ROUND(($O$27),2) -> 287215.22

Sheet Смета_№1.3_Подъездная автодоро
A1: Адепт: Проект v 2026.4.0 © ООО"Адепт" | E1: форма 2П
A3: Смета №1.3
A4: на проектные (изыскательские) работы
A6: Наименование предприятия, здания, сооружения, стадии проектирования, этапа, вида проектных или изыскательских работ | F6: Подъездная автодорога к ПРС Ноттоворакка (км 622,1)
A8: Наименование проектной (изыскательской) организации | F8: ООО "Спецпроектстрой"
A10: Наименование организации заказчика | F10: ООО "Газпром проектирование"
A12: № пп | B12: Характеристика предприятия, здания, сооружения или виды работ | G12: Номер частей, глав, таблиц, процентов, параграфов и пунктов указаний к разделу Справочника базовых цен на проектные и изыскательские работы для строительства | K12: Расчет стоимости: (a+bx)*Ki, или (объем строительно-монтажных работ) * проц./100 или количество x цена | O12: Стоимость, руб.
A13: 1 | B13: 2 | G13: 3 | K13: 4 | O13: 5
A14: 1 | B14: Автомобильные дороги технической категории IV. Категория сложности проектирования: 2. Протяженность от 0.5 до 1 километра включительно. | G14: НЗ №51/пр Строительство, реконструкция и капитальный ремонт автомобильных дорог, их конструктивных элементов и сооружений на них. 2025 г. Таблица 3.5. Автомобильные дороги технической категории IV, п.3.2 A = 357.8 тыс.руб; B = 616.816 тыс.руб; Протяженность дороги L = 1 км; Количество = 1; | K14: (A + B * L) * Количество * Ктек * Кст (357 800 руб. + 616 816 руб. * 1) * 1 * 1.38 * 0.4 * 1.1245 | O14: =ROUND((357800 + 616816 * 1) * 1 * 1.38 * 0.4 * 1.1245, 2) -> 604967.54
B15: Коэффициенты
B16: Стадия: Проектная документация | G16: Кст = 0.4
B17: инд.2кв.2026г.к 01.01.2023 на пр.раб. | G17: Ктек = 1.38 Письмо Минстроя России от 08.04.2026 №20212-ИФ/09
B18: Коэффициент, учитывающий природные факторы, усложняющие проектирование: опасные гидрологические и геологические явления (заболоченная территория). Коэффициент применяется к стоимости проектирования следующих разделов П+Р: ПЗУ (ППО в части вертикальной планировки и организации рельефа, транспорта); в полном объеме АР и КР (ТКР, ИЛО); в части монтажных элементов ИОС; доля СМ на выполняемый объем | G18: K1 = 1.15 (РПД 2,3.1-3.5,7) Методика, 707/пр. Приложение 5, табл.5.1, п.1.1 (Усложняющий)
B19: Разделы документации | K19: (2% + 7% * (1 + 0.15) + 7% * (1 + 0.15) + 29% * (1 + 0.15) + 8% * (1 + 0.15) + 8% * (1 + 0.15) + 13% * (1 + 0.15) + 9% + 5% + 1% + 11% * (1 + 0.15)) = 112.45%
A20: 2 | B20: Водопропускные трубы на автомобильных дорогах протяженностью, м. Круглые и прямоугольные железобетонные трубы отверстием до 2000 мм. | G20: Искусственные сооружения. 2015 г. Таблица 2. Водопропускные трубы на железных и автомобильных дорогах, п.2.4 A = 5.61 тыс.руб; B = 0.24 тыс.руб; Xзад = 22 (м); Количество = 2 | K20: (A + B * Xзад) * Количество * Ктек * Кст * (1 + дроб. ч. K1 + дроб. ч. K2) (5 610 руб. + 240 руб. * 22) * 2 * 7.1 * 0.34 * (1 + 0.15 + 0.15) | O20: =ROUND((5610 + 240 * 22) * 2 * 7.1 * 0.34 * (1 + 0.15 + 0.15), 2) -> 68350
B21: Коэффициенты
B22: Стадия: Проектная документация | G22: Кст = 0.34
B23: инд.2кв.2026г.к 01.01.2001 на пр.раб. | G23: Ктек = 7.1 Письмо Минстроя России от 08.04.2026 №20212-ИФ/09
B24: Разработка проектной документации на строительство предприятий, зданий и сооружений в сложных условиях:расположение площадки строительства в подтапливаемых зонах и др. | G24: K1 = 1.15 МУ 2009 г. Часть III п.3.7 (Усложняющий)
B25: Коэффициент. учитывающий природные факторы. усложняющие проектирование: опасные гидрологические и геологические явления (заболоченная территория). Коэффициент применяется к стоимости проектирования следующих разделов П+Р: ПЗУ (ППО в части вертикальной планировки и организации рельефа. транспорта); в полном объеме АР и КР (ТКР. ИЛО); в части монтажных элементов ИОС; доля СМ на выполняемый объем | G25: K2 = 1.15 Методика, 707/пр. Приложение 5, табл.5.1, п.1.1 (Усложняющий)
B26: Разделы документации | K26: (63% + 26% + 11%) = 100%
A27: 3 | B27: Итого по смете: | O27: =ROUND(SUM($O$14:$O$20),2) -> 673317.54
A28: 4 | B28: Новое начисление | G28: К1 = 0.8 Коэффициент оптимизации ПАО "Газпром" («Порядок формирования стоимости проектно-изыскательских работ для строительства и реконструкции объектов ПАО «Газпром» от 28.12.2017г. п.5.41) (Ценообразующий) | K28: Коэф-т 1 от п.3 * 0.8 | O28: =ROUND(($O$27) * 1 * 0.8,2) -> 538654.03
A29: 5 | B29: Всего по смете: | O29: =ROUND(($O$28),2) -> 538654.03

Sheet Смета_№1.4_Подъездная автодоро
A1: Адепт: Проект v 2026.4.0 © ООО"Адепт" | E1: форма 2П
A3: Смета №1.4
A4: на проектные (изыскательские) работы
A6: Наименование предприятия, здания, сооружения, стадии проектирования, этапа, вида проектных или изыскательских работ | F6: Подъездная автодорога км 627,6
A8: Наименование проектной (изыскательской) организации | F8: ООО "Спецпроектстрой"
A10: Наименование организации заказчика | F10: ООО "Газпром проектирование"
A12: № пп | B12: Характеристика предприятия, здания, сооружения или виды работ | G12: Номер частей, глав, таблиц, процентов, параграфов и пунктов указаний к разделу Справочника базовых цен на проектные и изыскательские работы для строительства | K12: Расчет стоимости: (a+bx)*Ki, или (объем строительно-монтажных работ) * проц./100 или количество x цена | O12: Стоимость, руб.
A13: 1 | B13: 2 | G13: 3 | K13: 4 | O13: 5
A14: 1 | B14: Автомобильные дороги технической категории IV. Категория сложности проектирования: 2. Протяженность от 0.5 до 1 километра включительно. | G14: НЗ №51/пр Строительство, реконструкция и капитальный ремонт автомобильных дорог, их конструктивных элементов и сооружений на них. 2025 г. Таблица 3.5. Автомобильные дороги технической категории IV, п.3.2 A = 357.8 тыс.руб; B = 616.816 тыс.руб; Протяженность дороги L = 1 км; Количество = 1; | K14: (A + B * L) * Количество * Ктек * Кст (357 800 руб. + 616 816 руб. * 1) * 1 * 1.38 * 0.4 * 1.1245 | O14: =ROUND((357800 + 616816 * 1) * 1 * 1.38 * 0.4 * 1.1245, 2) -> 604967.54
B15: Коэффициенты
B16: Стадия: Проектная документация | G16: Кст = 0.4
B17: инд.2кв.2026г.к 01.01.2023 на пр.раб. | G17: Ктек = 1.38 Письмо Минстроя России от 08.04.2026 №20212-ИФ/09
B18: Коэффициент, учитывающий природные факторы, усложняющие проектирование: опасные гидрологические и геологические явления (заболоченная территория). Коэффициент применяется к стоимости проектирования следующих разделов П+Р: ПЗУ (ППО в части вертикальной планировки и организации рельефа, транспорта); в полном объеме АР и КР (ТКР, ИЛО); в части монтажных элементов ИОС; доля СМ на выполняемый объем | G18: K1 = 1.15 (РПД 2,3.1-3.5,7) Методика, 707/пр. Приложение 5, табл.5.1, п.1.1 (Усложняющий)
B19: Разделы документации | K19: (2% + 7% * (1 + 0.15) + 7% * (1 + 0.15) + 29% * (1 + 0.15) + 8% * (1 + 0.15) + 8% * (1 + 0.15) + 13% * (1 + 0.15) + 9% + 5% + 1% + 11% * (1 + 0.15)) = 112.45%
A20: 2 | B20: Водопропускные трубы на автомобильных дорогах протяженностью, м. Круглые и прямоугольные железобетонные трубы отверстием до 2000 мм. | G20: Искусственные сооружения. 2015 г. Таблица 2. Водопропускные трубы на железных и автомобильных дорогах, п.2.4 A = 5.61 тыс.руб; B = 0.24 тыс.руб; Xзад = 22 (м); Количество = 2 | K20: (A + B * Xзад) * Количество * Ктек * Кст * (1 + дроб. ч. K1 + дроб. ч. K2) (5 610 руб. + 240 руб. * 22) * 2 * 7.1 * 0.34 * (1 + 0.15 + 0.15) | O20: =ROUND((5610 + 240 * 22) * 2 * 7.1 * 0.34 * (1 + 0.15 + 0.15), 2) -> 68350
B21: Коэффициенты
B22: Стадия: Проектная документация | G22: Кст = 0.34
B23: инд.2кв.2026г.к 01.01.2001 на пр.раб. | G23: Ктек = 7.1 Письмо Минстроя России от 08.04.2026 №20212-ИФ/09
B24: Разработка проектной документации на строительство предприятий, зданий и сооружений в сложных условиях:расположение площадки строительства в подтапливаемых зонах и др. | G24: K1 = 1.15 МУ 2009 г. Часть III п.3.7 (Усложняющий)
B25: Коэффициент. учитывающий природные факторы. усложняющие проектирование: опасные гидрологические и геологические явления (заболоченная территория). Коэффициент применяется к стоимости проектирования следующих разделов П+Р: ПЗУ (ППО в части вертикальной планировки и организации рельефа. транспорта); в полном объеме АР и КР (ТКР. ИЛО); в части монтажных элементов ИОС; доля СМ на выполняемый объем | G25: K2 = 1.15 Методика, 707/пр. Приложение 5, табл.5.1, п.1.1 (Усложняющий)
B26: Разделы документации | K26: (63% + 26% + 11%) = 100%
A27: 3 | B27: Итого по смете: | O27: =ROUND(SUM($O$14:$O$20),2) -> 673317.54
A28: 4 | B28: Новое начисление | G28: К1 = 0.8 Коэффициент оптимизации ПАО "Газпром" («Порядок формирования стоимости проектно-изыскательских работ для строительства и реконструкции объектов ПАО «Газпром» от 28.12.2017г. п.5.41) (Ценообразующий) | K28: Коэф-т 1 от п.3 * 0.8 | O28: =ROUND(($O$27) * 1 * 0.8,2) -> 538654.03
A29: 5 | B29: Всего по смете: | O29: =ROUND(($O$28),2) -> 538654.03

Sheet Смета_№1.5_Подъездная автодоро
A1: Адепт: Проект v 2026.4.0 © ООО"Адепт" | E1: форма 2П
A3: Смета №1.5
A4: на проектные (изыскательские) работы
A6: Наименование предприятия, здания, сооружения, стадии проектирования, этапа, вида проектных или изыскательских работ | F6: Подъездная автодорога к УРС Половина (км 658,8)
A8: Наименование проектной (изыскательской) организации | F8: ООО "Спецпроектстрой"
A10: Наименование организации заказчика | F10: ООО "Газпром проектирование"
A12: № пп | B12: Характеристика предприятия, здания, сооружения или виды работ | G12: Номер частей, глав, таблиц, процентов, параграфов и пунктов указаний к разделу Справочника базовых цен на проектные и изыскательские работы для строительства | K12: Расчет стоимости: (a+bx)*Ki, или (объем строительно-монтажных работ) * проц./100 или количество x цена | O12: Стоимость, руб.
A13: 1 | B13: 2 | G13: 3 | K13: 4 | O13: 5
A14: 1 | B14: Автомобильные дороги технической категории IV. Категория сложности проектирования: 2. Протяженность от 0.5 до 1 километра включительно. | G14: НЗ №51/пр Строительство, реконструкция и капитальный ремонт автомобильных дорог, их конструктивных элементов и сооружений на них. 2025 г. Таблица 3.5. Автомобильные дороги технической категории IV, п.3.2 A = 357.8 тыс.руб; B = 616.816 тыс.руб; Протяженность дороги L = 1 км; Количество = 1; | K14: (A + B * L) * Количество * Ктек * Кст (357 800 руб. + 616 816 руб. * 1) * 1 * 1.38 * 0.4 * 1.1245 | O14: =ROUND((357800 + 616816 * 1) * 1 * 1.38 * 0.4 * 1.1245, 2) -> 604967.54
B15: Коэффициенты
B16: Стадия: Проектная документация | G16: Кст = 0.4
B17: инд.2кв.2026г.к 01.01.2023 на пр.раб. | G17: Ктек = 1.38 Письмо Минстроя России от 08.04.2026 №20212-ИФ/09
B18: Коэффициент, учитывающий природные факторы, усложняющие проектирование: опасные гидрологические и геологические явления (заболоченная территория). Коэффициент применяется к стоимости проектирования следующих разделов П+Р: ПЗУ (ППО в части вертикальной планировки и организации рельефа, транспорта); в полном объеме АР и КР (ТКР, ИЛО); в части монтажных элементов ИОС; доля СМ на выполняемый объем | G18: K1 = 1.15 (РПД 2,3.1-3.5,7) Методика, 707/пр. Приложение 5, табл.5.1, п.1.1 (Усложняющий)
B19: Разделы документации | K19: (2% + 7% * (1 + 0.15) + 7% * (1 + 0.15) + 29% * (1 + 0.15) + 8% * (1 + 0.15) + 8% * (1 + 0.15) + 13% * (1 + 0.15) + 9% + 5% + 1% + 11% * (1 + 0.15)) = 112.45%
A20: 2 | B20: Водопропускные трубы на автомобильных дорогах протяженностью, м. Круглые и прямоугольные железобетонные трубы отверстием до 2000 мм. | G20: Искусственные сооружения. 2015 г. Таблица 2. Водопропускные трубы на железных и автомобильных дорогах, п.2.4 A = 5.61 тыс.руб; B = 0.24 тыс.руб; Xзад = 22 (м); Количество = 2 | K20: (A + B * Xзад) * Количество * Ктек * Кст * (1 + дроб. ч. K1 + дроб. ч. K2) (5 610 руб. + 240 руб. * 22) * 2 * 7.1 * 0.34 * (1 + 0.15 + 0.15) | O20: =ROUND((5610 + 240 * 22) * 2 * 7.1 * 0.34 * (1 + 0.15 + 0.15), 2) -> 68350
B21: Коэффициенты
B22: Стадия: Проектная документация | G22: Кст = 0.34
B23: инд.2кв.2026г.к 01.01.2001 на пр.раб. | G23: Ктек = 7.1 Письмо Минстроя России от 08.04.2026 №20212-ИФ/09
B24: Разработка проектной документации на строительство предприятий, зданий и сооружений в сложных условиях:расположение площадки строительства в подтапливаемых зонах и др. | G24: K1 = 1.15 МУ 2009 г. Часть III п.3.7 (Усложняющий)
B25: Коэффициент. учитывающий природные факторы. усложняющие проектирование: опасные гидрологические и геологические явления (заболоченная территория). Коэффициент применяется к стоимости проектирования следующих разделов П+Р: ПЗУ (ППО в части вертикальной планировки и организации рельефа. транспорта); в полном объеме АР и КР (ТКР. ИЛО); в части монтажных элементов ИОС; доля СМ на выполняемый объем | G25: K2 = 1.15 Методика, 707/пр. Приложение 5, табл.5.1, п.1.1 (Усложняющий)
B26: Разделы документации | K26: (63% + 26% + 11%) = 100%
A27: 3 | B27: Итого по смете: | O27: =ROUND(SUM($O$14:$O$20),2) -> 673317.54
A28: 4 | B28: Новое начисление | G28: К1 = 0.8 Коэффициент оптимизации ПАО "Газпром" («Порядок формирования стоимости проектно-изыскательских работ для строительства и реконструкции объектов ПАО «Газпром» от 28.12.2017г. п.5.41) (Ценообразующий) | K28: Коэф-т 1 от п.3 * 0.8 | O28: =ROUND(($O$27) * 1 * 0.8,2) -> 538654.03
A29: 5 | B29: Всего по смете: | O29: =ROUND(($O$28),2) -> 538654.03

Sheet Смета_№1.6_Подъездная автодоро
A1: Адепт: Проект v 2026.4.0 © ООО"Адепт" | E1: форма 2П
A3: Смета №1.6
A4: на проектные (изыскательские) работы
A6: Наименование предприятия, здания, сооружения, стадии проектирования, этапа, вида проектных или изыскательских работ | F6: Подъездная автодорога км 681,4
A8: Наименование проектной (изыскательской) организации | F8: ООО "Спецпроектстрой"
A10: Наименование организации заказчика | F10: ООО "Газпром проектирование"
A12: № пп | B12: Характеристика предприятия, здания, сооружения или виды работ | G12: Номер частей, глав, таблиц, процентов, параграфов и пунктов указаний к разделу Справочника базовых цен на проектные и изыскательские работы для строительства | K12: Расчет стоимости: (a+bx)*Ki, или (объем строительно-монтажных работ) * проц./100 или количество x цена | O12: Стоимость, руб.
A13: 1 | B13: 2 | G13: 3 | K13: 4 | O13: 5
A14: 1 | B14: Примыкание автомобильных дорог в одном уровне с устройством переходно-скоростных полос движения, островков безопасности. Категория сложности проектирования: 2. | G14: НЗ №51/пр Строительство, реконструкция и капитальный ремонт автомобильных дорог, их конструктивных элементов и сооружений на них. 2025 г. Таблица 3.7. Развязки, п.2.2 A = 1 440.8 тыс.руб; Количество = 2 (объект) | K14: A * Количество * Ктек * Кст * K1 1 440 800 руб. * 2 * 1.38 * 0.4 * 0.47 * 1.1155 | O14: =ROUND(1440800 * 2 * 1.38 * 0.4 * 0.47 * 1.1155, 2) -> 833950.37
B15: Коэффициенты
B16: Стадия: Проектная документация | G16: Кст = 0.4
B17: инд.2кв.2026г.к 01.01.2023 на пр.раб. | G17: Ктек = 1.38 Письмо Минстроя России от 08.04.2026 №20212-ИФ/09
B18: Пересечение (примыкание) автомобильных дорог в одном уровне определяется с корректирующим коэффициентом для примыканий без устройства переходно-скоростных полос | G18: K1 = 0.47 Табл.4, п.9 (Ценообразующий)
B19: Коэффициент, учитывающий природные факторы, усложняющие проектирование: опасные гидрологические и геологические явления (заболоченная территория). Коэффициент применяется к стоимости проектирования следующих разделов П+Р: ПЗУ (ППО в части вертикальной планировки и организации рельефа, транспорта); в полном объеме АР и КР (ТКР, ИЛО); в части монтажных элементов ИОС; доля СМ на выполняемый объем | G19: K2 = 1.15 (РПД 2,3.1-3.5,7) Методика, 707/пр. Приложение 5, табл.5.1, п.1.1 (Усложняющий)
B20: Разделы документации | K20: (2% + 8% * (1 + 0.15) + 4% * (1 + 0.15) + 26% * (1 + 0.15) + 4% * (1 + 0.15) + 8% * (1 + 0.15) + 14% * (1 + 0.15) + 11% + 9% + 1% + 13% * (1 + 0.15)) = 111.55%
A21: 2 | B21: Автомобильные дороги технической категории IV. Категория сложности проектирования: 2. Протяженность от 10 до 20 километров включительно. | G21: НЗ №51/пр Строительство, реконструкция и капитальный ремонт автомобильных дорог, их конструктивных элементов и сооружений на них. 2025 г. Таблица 3.5. Автомобильные дороги технической категории IV, п.7.2 A = 2 032.7 тыс.руб; B = 308.352 тыс.руб; Протяженность дороги L = 16.5 км; Количество = 1; | K21: (A + B * L) * Количество * Ктек * Кст (2 032 700 руб. + 308 352 руб. * 16.5) * 1 * 1.38 * 0.4 * 1.1245 | O21: =ROUND((2032700 + 308352 * 16.5) * 1 * 1.38 * 0.4 * 1.1245, 2) -> 4419870.2
B22: Коэффициенты
B23: Стадия: Проектная документация | G23: Кст = 0.4
B24: инд.2кв.2026г.к 01.01.2023 на пр.раб. | G24: Ктек = 1.38 Письмо Минстроя России от 08.04.2026 №20212-ИФ/09
B25: Коэффициент, учитывающий природные факторы, усложняющие проектирование: опасные гидрологические и геологические явления (заболоченная территория). Коэффициент применяется к стоимости проектирования следующих разделов П+Р: ПЗУ (ППО в части вертикальной планировки и организации рельефа, транспорта); в полном объеме АР и КР (ТКР, ИЛО); в части монтажных элементов ИОС; доля СМ на выполняемый объем | G25: K1 = 1.15 (РПД 2,3.1-3.5,7) Методика, 707/пр. Приложение 5, табл.5.1, п.1.1 (Усложняющий)
B26: Разделы документации | K26: (2% + 7% * (1 + 0.15) + 7% * (1 + 0.15) + 29% * (1 + 0.15) + 8% * (1 + 0.15) + 8% * (1 + 0.15) + 13% * (1 + 0.15) + 9% + 5% + 1% + 11% * (1 + 0.15)) = 112.45%
A27: 3 | B27: Водопропускные трубы на автомобильных дорогах протяженностью, м. Круглые и прямоугольные железобетонные трубы отверстием до 2000 мм. | G27: Искусственные сооружения. 2015 г. Таблица 2. Водопропускные трубы на железных и автомобильных дорогах, п.2.4 A = 5.61 тыс.руб; B = 0.24 тыс.руб; Xзад = 18 (м); Количество = 2 | K27: (A + B * Xзад) * Количество * Ктек * Кст * (1 + дроб. ч. K1) (5 610 руб. + 240 руб. * 18) * 2 * 7.1 * 0.34 * (1 + 0.15) | O27: =ROUND((5610 + 240 * 18) * 2 * 7.1 * 0.34 * (1 + 0.15), 2) -> 55133.35
B28: Коэффициенты
B29: Стадия: Проектная документация | G29: Кст = 0.34
B30: инд.2кв.2026г.к 01.01.2001 на пр.раб. | G30: Ктек = 7.1 Письмо Минстроя России от 08.04.2026 №20212-ИФ/09
B31: Разработка проектной документации на строительство предприятий, зданий и сооружений в сложных условиях:расположение площадки строительства в подтапливаемых зонах и др. | G31: K1 = 1.15 МУ 2009 г. Часть III п.3.7 (Усложняющий)
B32: Разделы документации | K32: (63% + 26% + 11%) = 100%
A33: 4 | B33: Водопропускные трубы на автомобильных дорогах протяженностью, м. Круглые и прямоугольные железобетонные трубы отверстием до 2000 мм трехочковые. | G33: Искусственные сооружения. 2015 г. Таблица 2. Водопропускные трубы на железных и автомобильных дорогах, п.2.6 A = 7.59 тыс.руб; B = 0.33 тыс.руб; Xзад = 12 (м); Количество = 12 | K33: (A + B * Xзад) * Количество * Ктек * Кст * (1 + дроб. ч. K1) (7 590 руб. + 330 руб. * 12) * 12 * 7.1 * 0.34 * (1 + 0.15) | O33: =ROUND((7590 + 330 * 12) * 12 * 7.1 * 0.34 * (1 + 0.15), 2) -> 384767.46
B34: Коэффициенты
B35: Стадия: Проектная документация | G35: Кст = 0.34
B36: инд.2кв.2026г.к 01.01.2001 на пр.раб. | G36: Ктек = 7.1 Письмо Минстроя России от 08.04.2026 №20212-ИФ/09
B37: Разработка проектной документации на строительство предприятий, зданий и сооружений в сложных условиях:расположение площадки строительства в подтапливаемых зонах и др. | G37: K1 = 1.15 МУ 2009 г. Часть III п.3.7 (Усложняющий)
B38: Разделы документации | K38: (63% + 26% + 11%) = 100%
A39: 5 | B39: Заглубленные сооружения и конструкции, водопонижение, противооползневые сооружения и мероприятия. Строительное водопонижение в сложных инженерно-геологических и гидрогеологических условиях. Периметр водопонизительного контура от 100 до 300 м. | G39: Заглубленные сооружения и конструкции, водопонижение, противооползневые сооружения и мероприятия. 2015 г. Таблица 1. Заглубленные сооружения и конструкции, водопонижение, противооползневые сооружения и мероприятия, п.13 A = 69.48 тыс.руб; B = 49.123 тыс.руб; Xзад = 2.55 (100 м); Количество = 1 | K39: (A + B * Xзад) * Количество * Ктек * Кст (69 480 руб. + 49 123 руб. * 2.55) * 1 * 7.1 * 0.3 | O39: =ROUND((69480 + 49123 * 2.55) * 1 * 7.1 * 0.3, 2) -> 414803.97
B40: Коэффициенты
B41: Стадия: Проектная документация | G41: Кст = 0.3
B42: инд.2кв.2026г.к 01.01.2001 на пр.раб. | G42: Ктек = 7.1 Письмо Минстроя России от 08.04.2026 №20212-ИФ/09
B43: Разделы документации | K43: (2% + 4% + 7% + 7% + 49% + 12% + 4% + 8% + 2% + 5%) = 100%
A44: 6 | B44: Итого по смете: | O44: =ROUND(SUM($O$14:$O$39),2) -> 6108525.4
A45: 7 | B45: Новое начисление | G45: К1 = 0.8 Коэффициент оптимизации ПАО "Газпром" («Порядок формирования стоимости проектно-изыскательских работ для строительства и реконструкции объектов ПАО «Газпром» от 28.12.2017г. п.5.41) (Ценообразующий) | K45: Коэф-т 1 от п.6 * 0.8 | O45: =ROUND(($O$44) * 1 * 0.8,2) -> 4886820.3
...

Sheet Смета_№1.7_Подъездная автодоро
A1: Адепт: Проект v 2026.4.0 © ООО"Адепт" | E1: форма 2П
A3: Смета №1.7
A4: на проектные (изыскательские) работы
A6: Наименование предприятия, здания, сооружения, стадии проектирования, этапа, вида проектных или изыскательских работ | F6: Подъездная автодорога км 683,2
A8: Наименование проектной (изыскательской) организации | F8: ООО "Спецпроектстрой"
A10: Наименование организации заказчика | F10: ООО "Газпром проектирование"
A12: № пп | B12: Характеристика предприятия, здания, сооружения или виды работ | G12: Номер частей, глав, таблиц, процентов, параграфов и пунктов указаний к разделу Справочника базовых цен на проектные и изыскательские работы для строительства | K12: Расчет стоимости: (a+bx)*Ki, или (объем строительно-монтажных работ) * проц./100 или количество x цена | O12: Стоимость, руб.
A13: 1 | B13: 2 | G13: 3 | K13: 4 | O13: 5
A14: 1 | B14: Автомобильные дороги технической категории IV. Категория сложности проектирования: 2. Протяженность от 0.5 до 1 километра включительно. | G14: НЗ №51/пр Строительство, реконструкция и капитальный ремонт автомобильных дорог, их конструктивных элементов и сооружений на них. 2025 г. Таблица 3.5. Автомобильные дороги технической категории IV, п.3.2 A = 357.8 тыс.руб; B = 616.816 тыс.руб; Протяженность дороги L = 1 км; Количество = 1; | K14: (A + B * L) * Количество * Ктек * Кст (357 800 руб. + 616 816 руб. * 1) * 1 * 1.38 * 0.4 * 1.1245 | O14: =ROUND((357800 + 616816 * 1) * 1 * 1.38 * 0.4 * 1.1245, 2) -> 604967.54
B15: Коэффициенты
B16: Стадия: Проектная документация | G16: Кст = 0.4
B17: инд.2кв.2026г.к 01.01.2023 на пр.раб. | G17: Ктек = 1.38 Письмо Минстроя России от 08.04.2026 №20212-ИФ/09
B18: Коэффициент, учитывающий природные факторы, усложняющие проектирование: опасные гидрологические и геологические явления (заболоченная территория). Коэффициент применяется к стоимости проектирования следующих разделов П+Р: ПЗУ (ППО в части вертикальной планировки и организации рельефа, транспорта); в полном объеме АР и КР (ТКР, ИЛО); в части монтажных элементов ИОС; доля СМ на выполняемый объем | G18: K1 = 1.15 (РПД 2,3.1-3.5,7) Методика, 707/пр. Приложение 5, табл.5.1, п.1.1 (Усложняющий)
B19: Разделы документации | K19: (2% + 7% * (1 + 0.15) + 7% * (1 + 0.15) + 29% * (1 + 0.15) + 8% * (1 + 0.15) + 8% * (1 + 0.15) + 13% * (1 + 0.15) + 9% + 5% + 1% + 11% * (1 + 0.15)) = 112.45%
A20: 2 | B20: Водопропускные трубы на автомобильных дорогах протяженностью, м. Круглые и прямоугольные железобетонные трубы отверстием до 2000 мм. | G20: Искусственные сооружения. 2015 г. Таблица 2. Водопропускные трубы на железных и автомобильных дорогах, п.2.4 A = 5.61 тыс.руб; B = 0.24 тыс.руб; Xзад = 22 (м); Количество = 2 | K20: (A + B * Xзад) * Количество * Ктек * Кст * (1 + дроб. ч. K1 + дроб. ч. K2) (5 610 руб. + 240 руб. * 22) * 2 * 7.1 * 0.34 * (1 + 0.15 + 0.15) | O20: =ROUND((5610 + 240 * 22) * 2 * 7.1 * 0.34 * (1 + 0.15 + 0.15), 2) -> 68350
B21: Коэффициенты
B22: Стадия: Проектная документация | G22: Кст = 0.34
B23: инд.2кв.2026г.к 01.01.2001 на пр.раб. | G23: Ктек = 7.1 Письмо Минстроя России от 08.04.2026 №20212-ИФ/09
B24: Разработка проектной документации на строительство предприятий, зданий и сооружений в сложных условиях:расположение площадки строительства в подтапливаемых зонах и др. | G24: K1 = 1.15 МУ 2009 г. Часть III п.3.7 (Усложняющий)
B25: Коэффициент. учитывающий природные факторы. усложняющие проектирование: опасные гидрологические и геологические явления (заболоченная территория). Коэффициент применяется к стоимости проектирования следующих разделов П+Р: ПЗУ (ППО в части вертикальной планировки и организации рельефа. транспорта); в полном объеме АР и КР (ТКР. ИЛО); в части монтажных элементов ИОС; доля СМ на выполняемый объем | G25: K2 = 1.15 Методика, 707/пр. Приложение 5, табл.5.1, п.1.1 (Усложняющий)
B26: Разделы документации | K26: (63% + 26% + 11%) = 100%
A27: 3 | B27: Итого по смете: | O27: =ROUND(SUM($O$14:$O$20),2) -> 673317.54
A28: 4 | B28: Новое начисление | G28: К1 = 0.8 Коэффициент оптимизации ПАО "Газпром" («Порядок формирования стоимости проектно-изыскательских работ для строительства и реконструкции объектов ПАО «Газпром» от 28.12.2017г. п.5.41) (Ценообразующий) | K28: Коэф-т 1 от п.3 * 0.8 | O28: =ROUND(($O$27) * 1 * 0.8,2) -> 538654.03
A29: 5 | B29: Всего по смете: | O29: =ROUND(($O$28),2) -> 538654.03

Sheet Смета_№1.8_Подъездная автодоро
A1: Адепт: Проект v 2026.4.0 © ООО"Адепт" | E1: форма 2П
A3: Смета №1.8
A4: на проектные (изыскательские) работы
A6: Наименование предприятия, здания, сооружения, стадии проектирования, этапа, вида проектных или изыскательских работ | F6: Подъездная автодорога км 686,8
A8: Наименование проектной (изыскательской) организации | F8: ООО "Спецпроектстрой"
A10: Наименование организации заказчика | F10: ООО "Газпром проектирование"
A12: № пп | B12: Характеристика предприятия, здания, сооружения или виды работ | G12: Номер частей, глав, таблиц, процентов, параграфов и пунктов указаний к разделу Справочника базовых цен на проектные и изыскательские работы для строительства | K12: Расчет стоимости: (a+bx)*Ki, или (объем строительно-монтажных работ) * проц./100 или количество x цена | O12: Стоимость, руб.
A13: 1 | B13: 2 | G13: 3 | K13: 4 | O13: 5
A14: 1 | B14: Примыкание автомобильных дорог в одном уровне с устройством переходно-скоростных полос движения, островков безопасности. Категория сложности проектирования: 2. | G14: НЗ №51/пр Строительство, реконструкция и капитальный ремонт автомобильных дорог, их конструктивных элементов и сооружений на них. 2025 г. Таблица 3.7. Развязки, п.2.2 A = 1 440.8 тыс.руб; Количество = 2 (объект) | K14: A * Количество * Ктек * Кст * K1 1 440 800 руб. * 2 * 1.38 * 0.4 * 0.47 * 1.1155 | O14: =ROUND(1440800 * 2 * 1.38 * 0.4 * 0.47 * 1.1155, 2) -> 833950.37
B15: Коэффициенты
B16: Стадия: Проектная документация | G16: Кст = 0.4
B17: инд.2кв.2026г.к 01.01.2023 на пр.раб. | G17: Ктек = 1.38 Письмо Минстроя России от 08.04.2026 №20212-ИФ/09
B18: Пересечение (примыкание) автомобильных дорог в одном уровне определяется с корректирующим коэффициентом для примыканий без устройства переходно-скоростных полос | G18: K1 = 0.47 Табл.4, п.9 (Ценообразующий)
B19: Коэффициент, учитывающий природные факторы, усложняющие проектирование: опасные гидрологические и геологические явления (заболоченная территория). Коэффициент применяется к стоимости проектирования следующих разделов П+Р: ПЗУ (ППО в части вертикальной планировки и организации рельефа, транспорта); в полном объеме АР и КР (ТКР, ИЛО); в части монтажных элементов ИОС; доля СМ на выполняемый объем | G19: K2 = 1.15 (РПД 2,3.1-3.5,7) Методика, 707/пр. Приложение 5, табл.5.1, п.1.1 (Усложняющий)
B20: Разделы документации | K20: (2% + 8% * (1 + 0.15) + 4% * (1 + 0.15) + 26% * (1 + 0.15) + 4% * (1 + 0.15) + 8% * (1 + 0.15) + 14% * (1 + 0.15) + 11% + 9% + 1% + 13% * (1 + 0.15)) = 111.55%
A21: 2 | B21: Автомобильные дороги технической категории IV. Категория сложности проектирования: 2. Протяженность от 1 до 2 километров включительно. | G21: НЗ №51/пр Строительство, реконструкция и капитальный ремонт автомобильных дорог, их конструктивных элементов и сооружений на них. 2025 г. Таблица 3.5. Автомобильные дороги технической категории IV, п.4.2 A = 544 тыс.руб; B = 523.714 тыс.руб; Протяженность дороги L = 1.85 км; Количество = 1; | K21: (A + B * L) * Количество * Ктек * Кст (544 000 руб. + 523 714 руб. * 1.85) * 1 * 1.38 * 0.4 * 1.1245 | O21: =ROUND((544000 + 523714 * 1.85) * 1 * 1.38 * 0.4 * 1.1245, 2) -> 939075.28
B22: Коэффициенты
B23: Стадия: Проектная документация | G23: Кст = 0.4
B24: инд.2кв.2026г.к 01.01.2023 на пр.раб. | G24: Ктек = 1.38 Письмо Минстроя России от 08.04.2026 №20212-ИФ/09
B25: Коэффициент, учитывающий природные факторы, усложняющие проектирование: опасные гидрологические и геологические явления (заболоченная территория). Коэффициент применяется к стоимости проектирования следующих разделов П+Р: ПЗУ (ППО в части вертикальной планировки и организации рельефа, транспорта); в полном объеме АР и КР (ТКР, ИЛО); в части монтажных элементов ИОС; доля СМ на выполняемый объем | G25: K1 = 1.15 (РПД 2,3.1-3.5,7) Методика, 707/пр. Приложение 5, табл.5.1, п.1.1 (Усложняющий)
B26: Разделы документации | K26: (2% + 7% * (1 + 0.15) + 7% * (1 + 0.15) + 29% * (1 + 0.15) + 8% * (1 + 0.15) + 8% * (1 + 0.15) + 13% * (1 + 0.15) + 9% + 5% + 1% + 11% * (1 + 0.15)) = 112.45%
A27: 3 | B27: Водопропускные трубы на автомобильных дорогах протяженностью, м. Круглые и прямоугольные железобетонные трубы отверстием до 2000 мм. | G27: Искусственные сооружения. 2015 г. Таблица 2. Водопропускные трубы на железных и автомобильных дорогах, п.2.4 A = 5.61 тыс.руб; B = 0.24 тыс.руб; Xзад = 18 (м); Количество = 2 | K27: (A + B * Xзад) * Количество * Ктек * Кст * (1 + дроб. ч. K1) (5 610 руб. + 240 руб. * 18) * 2 * 7.1 * 0.34 * (1 + 0.15) | O27: =ROUND((5610 + 240 * 18) * 2 * 7.1 * 0.34 * (1 + 0.15), 2) -> 55133.35
B28: Коэффициенты
B29: Стадия: Проектная документация | G29: Кст = 0.34
B30: инд.2кв.2026г.к 01.01.2001 на пр.раб. | G30: Ктек = 7.1 Письмо Минстроя России от 08.04.2026 №20212-ИФ/09
B31: Разработка проектной документации на строительство предприятий, зданий и сооружений в сложных условиях:расположение площадки строительства в подтапливаемых зонах и др. | G31: K1 = 1.15 МУ 2009 г. Часть III п.3.7 (Усложняющий)
B32: Разделы документации | K32: (63% + 26% + 11%) = 100%
A33: 4 | B33: Водопропускные трубы на автомобильных дорогах протяженностью, м. Круглые и прямоугольные железобетонные трубы отверстием до 2000 мм трехочковые. | G33: Искусственные сооружения. 2015 г. Таблица 2. Водопропускные трубы на железных и автомобильных дорогах, п.2.6 A = 7.59 тыс.руб; B = 0.33 тыс.руб; Xзад = 12 (м); Количество = 1 | K33: (A + B * Xзад) * Количество * Ктек * Кст * (1 + дроб. ч. K1) (7 590 руб. + 330 руб. * 12) * 1 * 7.1 * 0.34 * (1 + 0.15) | O33: =ROUND((7590 + 330 * 12) * 1 * 7.1 * 0.34 * (1 + 0.15), 2) -> 32063.96
B34: Коэффициенты
B35: Стадия: Проектная документация | G35: Кст = 0.34
B36: инд.2кв.2026г.к 01.01.2001 на пр.раб. | G36: Ктек = 7.1 Письмо Минстроя России от 08.04.2026 №20212-ИФ/09
B37: Разработка проектной документации на строительство предприятий, зданий и сооружений в сложных условиях:расположение площадки строительства в подтапливаемых зонах и др. | G37: K1 = 1.15 МУ 2009 г. Часть III п.3.7 (Усложняющий)
B38: Разделы документации | K38: (63% + 26% + 11%) = 100%
A39: 5 | B39: Итого по смете: | O39: =ROUND(SUM($O$14:$O$33),2) -> 1860223
